Workbook
Name _AnnualCashFlowStatement: CFS!$A$2:$K$42
Name _AnnualIncomeStatement: IS!$A$3:$K$74
Name _AnnualSegmentIncomeStatement: Divisional!$A$2:$K$239
Name _EADSKeyPerformanceMeasures: 'Valuation Summary'!$A$1:$F$86
Name _QuarterlyIncomeStatement: IS!$A$3:$EQ$62
Name _QuarterlySegmentIncomeStatement: Divisional!$A$2:$AV$239
Name africa: 0
Name africaCountries: #REF!
Name allRegions: #REF!
Name americaRegion: #REF!
Name americas: 0.26
Name americasStates: #REF!
Name AppVersion: "GEG-1.0"
Name asiaPacific: 0.3
Name asiaPacificExJapan: 0.06
Name asiaPacificExJapanCountries: #REF!
Name asiaPacificRegion: #REF!
Name asiaPacificStates: #REF!
Name australasia: "NA"
Name BRICS: 0.24
Name centralEasternEurope: 0
Name centralEasternEuropeCountries: #REF!
Name china: 0.24
Name consumerDemandExposure: #REF!
Name consumersExposure: 0
Name countryList: "Country Mapping"
Name DCF_123465: #REF!
Name developedEuropeExUK: 0.4
Name developedEuropeExUKCountries: #REF!
Name domesticAndForeignExposure: #REF!
Name domesticCostExposure: #REF!
Name EEMEA: 0.04
Name endDemandExposure: #REF!
Name europe: 0.4
Name europeRegion: #REF!
Name europeStates: #REF!
Name india: 0
Name instructions: #REF!
Name italy: "NA"
Name japan: 0
Name latinAmerica: 0.02
Name latinAmericaCountries: #REF!
Name Linking_1: #REF!
Name Linking_10: #REF!
Name Linking_100: #REF!
Name Linking_101: #REF!
Name Linking_102: #REF!
Name Linking_103: #REF!
Name Linking_104: #REF!
Name Linking_105: #REF!
Name Linking_106: #REF!
Name Linking_108: #REF!
Name Linking_11: #REF!
Name Linking_116: #REF!
Name Linking_117: #REF!
Name Linking_118: #REF!
Name Linking_119: #REF!
Name Linking_12: #REF!
Name Linking_120: #REF!
Name Linking_121: IS!$A$2:$DG$66

Sheet ImportantDisclosures
A2: 20 Bank Street, Canary Wharf
A3: London E14 4AD
A4: United Kingdom
A5: Tel: +44 (0)20 7425 8000
A7: Authors: Ross Law,Marie-Ange Riggio
A8: Date: 14 Aug 2026
A10: Ticker: AIR.PA
A11: Stock Rating: Overweight
A12: Industry: Aerospace & Defence
A13: Industry View: Attractive
A14: Price as of 14 Aug 2026: 212.90
A15: Target Price: 255.00
... A133: Equal-weight and Not-Rated to hold and Underweight to sell recommendations, respectively.
B135: Coverage Universe | D135: Investment Banking Clients (IBC) | G135: Other Material Investment Services Clients (MISC)
A136: Stock Rating Category | B136: Count | C136: % of Total | D136: Count | E136: % of Total IBC | F136: % of Rating Category | G136: Count | H136: % of Total Other MISC
A137: Overweight/Buy | B137: 1529 | C137: 0.42 | D137: 442 | E137: 0.47 | F137: 0.29 | G137: 750 | H137: 0.43
A138: Equal-weight/Hold | B138: 1582 | C138: 0.43 | D138: 396 | E138: 0.42 | F138: 0.25 | G138: 773 | H138: 0.44
A139: Not-Rated/Hold | B139: 3 | C139: 0 | D139: 1 | E139: 0 | F139: 0.33 | G139: 1 | H139: 0
A140: Underweight/Sell | B140: 560 | C140: 0.15 | D140: 97 | E140: 0.1 | F140: 0.17 | G140: 217 | H140: 0.12
A141: Total | B141: 3674 | D141: 936 | G141: 1741
A143: Data include common stock and ADRs currently assigned ratings. Investment Banking Clients are companies
A144: from whom Morgan Stanley received investment banking compensation in the last 12 months. Due to rounding
A145: off of decimals, the percentages provided in the "% of total" column may not add up to exactly 100
A146: percent.
A148: Analyst Stock Ratings
A150: Overweight (O). The stock's total return is expected to exceed the average total return of the analyst's
A151: industry (or industry team's) coverage universe, on a risk-adjusted basis, over the next 12-18 months.
A153: Equal-weight (E). The stock's total return is expected to be in line with the average total return of
A154: the analyst's industry (or industry team's) coverage universe, on a risk-adjusted basis, over the next
A155: 12-18 months.
A157: Not-Rated (NR). Currently the analyst does not have adequate conviction about the stock's total return
A158: relative to the average total return of the analyst's industry (or industry team's) coverage universe,
... A436: © Copyright 2026 Morgan Stanley

Sheet Valuation Summary
A1: Airbus | AD1: 2022-25 CAGR | AE1: 2022-27 CAGR | AF1: 23-26 CAGR | AG1: 23-28 CAGR
A2: Year End December, EUR
A3: €m | B3: 2004 | C3: 2005 | D3: 2006 | E3: =D3+1 -> 2007 | F3: =E3+1 -> 2008 | G3: =F3+1 -> 2009 | H3: =G3+1 -> 2010 | I3: =H3+1 -> 2011 | J3: =I3+1 -> 2012 | K3: =J3+1 -> 2013 | L3: =K3+1 -> 2014 | ... AB3: =AA3+1 -> 2030
A4: Avg Share Price (€) | B4: 20.691 | C4: 26.146 | D4: 26.3216 | E4: 23.0649 | F4: 14.35 | G4: 12.478 | H4: 16.586 | I4: 21.513 | J4: 27.906 | K4: 43.38 | L4: 49.05 | M4: 58.84 | N4: 70 | O4: 85 | P4: 100 | Q4: 120 | R4: 120 | S4: 102 | T4: 95 | U4: 139.78 | V4: 154.78 | W4: 176.8891 | X4: 212.9 | Y4: =X4 -> 212.9 | Z4: =Y4 -> 212.9 | AA4: =Z4 -> 212.9 | AB4: =AA4 -> 212.9
A5: Avg Basic Shares (m) | B5: 804.08287 | C5: 800.21635 | D5: 804.31566 | E5: 805.5484 | F5: 807.59694 | G5: 811.19011 | H5: 810.69334 | I5: 813.702 | J5: 820.55193 | K5: 794.12781 | L5: =IS!AA70 -> 782.96239 | M5: =IS!AH70 -> 785.6211 | N5: =IS!AO70 -> 773.79884 | O5: =IS!AV70 -> 773.7727 | P5: =IS!BJ70 -> 775.16794 | Q5: =IS!BQ70 -> 777.03986 | R5: =IS!BX70 -> 783.17819 | S5: =IS!CE70 -> 785.32607 | T5: =IS!CL70 -> 787.08058 | U5: =IS!CS70 -> 788.72078 | V5: =IS!CZ70 -> 789.96167 | W5: =IS!DG70 -> 789.57321 | X5: =IS!DN70 -> 786.06495 | Y5: =IS!DU70 -> 781.8688 | Z5: =IS!EB70 -> 776.19772 | AA5: =IS!EI70 -> 771.26635 | AB5: =IS!EP70 -> 768.97269
A6: Market capitalisation | B6: =B4*B5 -> 16637.279 | C6: =C4*C5 -> 20922.457 | D6: =D4*D5 -> 21170.875 | E6: =E4*E5 -> 18579.893 | F6: =F4*F5 -> 11589.016 | G6: =G4*G5 -> 10122.03 | H6: =H4*H5 -> 13446.16 | I6: =I4*I5 -> 17505.171 | ... AB6: =AB4*AB5 -> 163714.28
A7: MS adj. (as for CE ex JV) | B7: =B62+B63+B64+B65+B68+B69+B66 -> 3916 | C7: =C62+C63+C64+C65+C68+C69+C66 -> 3589 | D7: =D62+D63+D64+D65+D68+D69+D66 -> 3400 | E7: =E62+E63+E64+E65+E68+E69+E66 -> -1011 | F7: =F62+F63+F64+F65+F68+F69+F66 -> -4638 | G7: =G62+G63+G64+G65+G68+G69+G66 -> -4476 | H7: =H62+H63+H64+H65+H68+H69+H66 -> -6850 | I7: =I62+I63+I64+I65+I68+I69+I66 -> -6331 | ... AB7: =AB62+AB63+AB64+AB65+AB68+AB69+AB66 -> -35016.022
A8: Dassault associate inv. | B8: -1901 | C8: -2484 | D8: -2896 | E8: -3359 | F8: -2421 | G8: -1921 | H8: -2725 | I8: -3027 | J8: -3223 | K8: -4167 | L8: -3981 | M8: -2443 | N8: -876 | O8: -1071 | P8: -999 | Q8: -968 | R8: -742 | S8: -786 | T8: -1309 | U8: -1483 | V8: -1632 | W8: -2146.5108 | X8: -2441.1154 | Y8: =X8 -> -2441.1154 | Z8: =Y8 -> -2441.1154 | AA8: =Z8 -> -2441.1154 | AB8: =AA8 -> -2441.1154
A9: Enterprise value - MS | B9: =B6+B7+B8 -> 18652.279 | C9: =C6+C7+C8 -> 22027.457 | D9: =D6+D7+D8 -> 21674.875 | E9: =E6+E7+E8 -> 14209.893 | F9: =F6+F7+F8 -> 4530.0161 | G9: =G6+G7+G8 -> 3725.0302 | H9: =H6+H7+H8 -> 3871.1597 | I9: =I6+I7+I8 -> 8147.1711 | ... AB9: =AB6+AB7+AB8 -> 126257.15
A11: Profitability
A12: Revenues | B12: =+IS!E8 -> 31761 | C12: =+IS!F8 -> 34206 | D12: =+IS!G8 -> 39434 | E12: =+IS!H8 -> 39123 | F12: =+IS!I8 -> 43265 | G12: =+IS!J8 -> 42822 | H12: =+IS!K8 -> 45752 | I12: =+IS!L8 -> 49128 | J12: =+IS!M8 -> 56480 | K12: =+IS!T8 -> 57567 | L12: =+IS!AA8 -> 60713 | M12: =+IS!AH8 -> 64450 | N12: =+IS!AO8 -> 66581 | O12: =+IS!AV8 -> 66767 | P12: =+IS!BJ8 -> 63707 | Q12: =+IS!BQ8 -> 70478 | R12: =+IS!BX8 -> 49912 | S12: =+IS!CE8 -> 52149 | T12: =+IS!CL8 -> 58763 | U12: =+IS!CS8 -> 65446 | V12: =+IS!CZ8 -> 69230 | W12: =+IS!DG8 -> 73420 | X12: =+IS!DN8 -> 80558.144 | Y12: =+IS!DU8 -> 89656.987 | Z12: =+IS!EB8 -> 97614.941 | AA12: =+IS!EI8 -> 102018.21 | AB12: =+IS!EP8 -> 105534.12 | AD12: =(W12/T12)^(1/3)-1 -> 0.077052336 | AE12: =(Y12/T12)^(1/5)-1 -> 0.088168215 | AF12: =(X12/U12)^(1/3)-1 -> 0.071705471 | AG12: =(Z12/U12)^(1/5)-1 -> 0.083244862
A13: EBITDA reported | B13: =IS!E18 -> 3836 | C13: =IS!F18 -> 4365 | D13: =IS!G18 -> 2033 | E13: =IS!H18 -> 1751 | F13: =IS!I18 -> 4439 | G13: =IS!J18 -> 1446 | H13: =IS!K18 -> 2769 | I13: =IS!L18 -> 3539 | J13: =IS!M18 -> 4201 | K13: =IS!T18 -> 4512 | L13: =IS!AA18 -> 6147 | M13: =IS!AH18 -> 6528 | N13: =IS!AO18 -> 4508 | O13: =IS!AV18 -> 5719 | P13: =IS!BJ18 -> 7492 | Q13: =IS!BQ18 -> 4266 | R13: =IS!BX18 -> 2321 | S13: =IS!CE18 -> 7667 | T13: =IS!CL18 -> 8041 | U13: =IS!CS18 -> 6845 | V13: =IS!CZ18 -> 8157 | W13: =IS!DG18 -> 9257 | X13: =IS!DN18 -> 11412.544 | Y13: =IS!DU18 -> 13580.968 | Z13: =IS!EB18 -> 16236.925 | AA13: =IS!EI18 -> 17426.398 | AB13: =IS!EP18 -> 18344.759 | AD13: =(W13/T13)^(1/3)-1 -> 0.048061418 | AE13: =(Y13/T13)^(1/5)-1 -> 0.11051425 | AF13: =(X13/U13)^(1/3)-1 -> 0.18577693 | AG13: =(Z13/U13)^(1/5)-1 -> 0.18857356
A14: EBITDA reported ex JV | B14: =IS!E18-IS!E17 -> 3752 | C14: =IS!F18-IS!F17 -> 4140 | D14: =IS!G18-IS!G17 -> 1844 | E14: =IS!H18-IS!H17 -> 1455 | F14: =IS!I18-IS!I17 -> 4228 | G14: =IS!J18-IS!J17 -> 1312 | H14: =IS!K18-IS!K17 -> 2624 | I14: =IS!L18-IS!L17 -> 3347 | J14: =IS!M18-IS!M17 -> 3954 | K14: =IS!T18-IS!T17 -> 4029 | L14: =IS!AA18-IS!AA17 -> 5252 | M14: =IS!AH18-IS!AH17 -> 5458 | N14: =IS!AO18-IS!AO17 -> 4256 | O14: =IS!AV18-IS!AV17 -> 5304 | P14: =IS!BJ18-IS!BJ17 -> 7053 | Q14: =IS!BQ18-IS!BQ17 -> 3963 | R14: =IS!BX18-IS!BX17 -> 2169 | S14: =IS!CE18-IS!CE17 -> 7551 | T14: =IS!CL18-IS!CL17 -> 7849 | U14: =IS!CS18-IS!CS17 -> 6542 | V14: =IS!CZ18-IS!CZ17 -> 7763 | W14: =IS!DG18-IS!DG17 -> 8902 | X14: =IS!DN18-IS!DN17 -> 11023.029 | Y14: =IS!DU18-IS!DU17 -> 13147.459 | Z14: =IS!EB18-IS!EB17 -> 15764.938 | AA14: =IS!EI18-IS!EI17 -> 16933.12 | AB14: =IS!EP18-IS!EP17 -> 17834.481 | AD14: =(W14/T14)^(1/3)-1 -> 0.042856183 | AE14: =(Y14/T14)^(1/5)-1 -> 0.10867819 | AF14: =(X14/U14)^(1/3)-1 -> 0.18995391 | AG14: =(Z14/U14)^(1/5)-1 -> 0.19232965
A15: EBITDA adjusted | B15: =Divisional!G31-IS!F20 -> 1912 | C15: =Divisional!H31-IS!G20 -> 5704 | D15: =Divisional!I31-IS!H20 -> 5029 | E15: =Divisional!J31-IS!I20 -> 3757 | F15: =Divisional!K31-IS!J20 -> 3109 | G15: =Divisional!L31-IS!K20 -> 3324 | H15: =Divisional!M31-IS!L20 -> 4849 | I15: =Divisional!T31-IS!M20 -> 5552 | J15: =Divisional!AA31-IS!T20 -> 5954 | K15: =Divisional!AH31-IS!AA20 -> 6239 | L15: =Divisional!AO31-IS!AH20 -> 6397 | M15: =Divisional!AV31-IS!AO20 -> 6503 | N15: =Divisional!BC31-IS!AV20 -> 5488 | O15: =Divisional!BJ31-IS!BC20 -> 8132 | P15: =Divisional!BQ31-IS!BJ20 -> 9390 | Q15: =Divisional!BX31-IS!BQ20 -> 9873 | R15: =Divisional!CE31-IS!BX20 -> 4537 | S15: =Divisional!CL31-IS!CE20 -> 7190 | T15: =Divisional!CS31-IS!CL20 -> 8343 | U15: =Divisional!CZ31-IS!CS20 -> 8080 | V15: =Divisional!DG31-IS!CZ20 -> 8207 | W15: =Divisional!DN31-IS!DG20 -> 10303 | X15: =Divisional!DU31-IS!DN20 -> 11544.544 | Y15: =Divisional!EB31-IS!DU20 -> 13580.968 | Z15: =Divisional!EI31-IS!EB20 -> 16236.925 | AA15: =Divisional!EP31-IS!EI20 -> 17426.398 | AB15: =Divisional!EW31-IS!EP20 -> 18344.759 | AD15: =(W15/T15)^(1/3)-1 -> 0.072870125 | AE15: =(Y15/T15)^(1/5)-1 -> 0.10235557 | AF15: =(X15/U15)^(1/3)-1 -> 0.12630272 | AG15: =(Z15/U15)^(1/5)-1 -> 0.14978989
A16: EBIT reported | B16: =IS!E22 -> 2432 | C16: =IS!F22 -> 2852 | D16: =IS!G22 -> 399 | E16: =IS!H22 -> 52 | F16: =IS!I22 -> 2830 | G16: =IS!J22 -> -322 | H16: =IS!K22 -> 1231 | I16: =IS!L22 -> 1696 | J16: =IS!M22 -> 2186 | K16: =IS!T22 -> 2624 | L16: =IS!AA22 -> 4040 | M16: =IS!AH22 -> 4086 | N16: =IS!AO22 -> 2258 | O16: =IS!BC22 -> 2665 | P16: =IS!BJ22 -> 5048 | Q16: =IS!BQ22 -> 1339 | R16: =IS!BX22 -> -510 | S16: =IS!CE22 -> 5342 | T16: =IS!CL22 -> 5325 | U16: =IS!CS22 -> 4603 | V16: =IS!CZ22 -> 5304 | W16: =IS!DG22 -> 6082 | X16: =IS!DN22 -> 7779.6032 | Y16: =IS!DU22 -> 9531.4017 | Z16: =IS!EB22 -> 11824.436 | AA16: =IS!EI22 -> 12814.391 | AB16: =IS!EP22 -> 13574.104 | AD16: =(W16/T16)^(1/3)-1 -> 0.045303171 | AE16: =(Y16/T16)^(1/5)-1 -> 0.1234854 | AF16: =(X16/U16)^(1/3)-1 -> 0.19116564 | AG16: =(Z16/U16)^(1/5)-1 -> 0.20766892
A17: EBIT adjusted | B17: 2432 | C17: 2852 | D17: 399 | E17: 52 | F17: 3300 | G17: 2150 | H17: 1340 | I17: 1794 | J17: 2964 | K17: 3574 | L17: =Divisional!AA31 -> 4066 | M17: =Divisional!AH31 -> 4132 | N17: =Divisional!AO31 -> 3955 | O17: =Divisional!BC31 -> 3190 | P17: =Divisional!BJ31 -> 5834 | Q17: =Divisional!BX31 -> 6946 | R17: =Divisional!CE31 -> 1706 | S17: =Divisional!CL31 -> 4865 | T17: =Divisional!CS31 -> 5627 | U17: =Divisional!CZ31 -> 5838 | V17: =Divisional!DG31 -> 5354 | W17: =Divisional!DN31 -> 7128 | X17: =Divisional!DU31 -> 7911.6032 | Y17: =Divisional!EB31 -> 9531.4017 | Z17: =Divisional!EI31 -> 11824.436 | AA17: =Divisional!EP31 -> 12814.391 | AB17: =Divisional!EW31 -> 13574.104 | AD17: =(W17/T17)^(1/3)-1 -> 0.082007469 | AE17: =(Y17/T17)^(1/5)-1 -> 0.11115839 | AF17: =(X17/U17)^(1/3)-1 -> 0.10662413 | AG17: =(Z17/U17)^(1/5)-1 -> 0.15160427
A18: EBIT adjusted ex JV | B18: 2348 | C18: 2642 | D18: 247 | E18: -158 | F18: 3112 | G18: 2035 | H18: 1213 | I18: 1630 | J18: 2723 | K18: 3279 | L18: 3561 | M18: 3818 | N18: 3703 | O18: 3838 | P18: 5395 | Q18: 6643 | R18: 1554 | S18: 4749 | T18: 5435 | U18: 5535 | V18: 4960 | W18: 6773 | X18: 7522.0889 | Y18: 9097.8927 | Z18: 11352.448 | AA18: 12321.113 | AB18: 13063.826 | AD18: =(W18/T18)^(1/3)-1 -> 0.07611952 | AE18: =(Y18/T18)^(1/5)-1 -> 0.10853205 | AF18: =(X18/U18)^(1/3)-1 -> 0.1076612 | AG18: =(Z18/U18)^(1/5)-1 -> 0.15450118
A19: PBT adjusted | B19: =Divisional!E31+IS!E36+IS!E55 -> 2102 | C19: =Divisional!F31+IS!F36+IS!F55 -> 2675 | D19: =Divisional!G31+IS!G36+IS!G55 -> 155 | E19: =Divisional!H31+IS!H36+IS!H55 -> 3333 | F19: =Divisional!I31+IS!I36+IS!I55 -> 2858 | G19: =Divisional!J31+IS!J36+IS!J55 -> 1649 | H19: =Divisional!K31+IS!K36+IS!K55 -> 929 | I19: =Divisional!L31+IS!L36+IS!L55 -> 1507 | J19: =Divisional!M31+IS!M36+IS!M55 -> 2541 | K19: =Divisional!T31+IS!T36+IS!T55 -> 3034 | L19: =Divisional!AA31+IS!AA36+IS!AA55 -> 3629 | M19: =Divisional!AH31+IS!AH36+IS!AH55 -> 3663 | N19: =Divisional!AO31+IS!AO36+IS!AO55 -> 3615 | O19: =Divisional!AV31+IS!AV36+IS!AV55 -> 3864 | P19: =Divisional!BJ31+IS!BJ36+IS!BJ55 -> 5558 | Q19: =Divisional!BQ31+IS!BQ36+IS!BQ55 -> 6789 | R19: =Divisional!CE31+IS!BX36+IS!BX55 -> 1410 | S19: =Divisional!CL31+IS!CE36+IS!CE55 -> 4600 | T19: =Divisional!CS31+IS!CL36+IS!CL55 -> 5403 | U19: =Divisional!CZ31+IS!CS36+IS!CS55 -> 5810 | V19: =Divisional!DG31+IS!CZ36+IS!CZ55 -> 5339 | W19: =Divisional!DN31+IS!DG36+IS!DG55 -> 7336 | X19: =Divisional!DU31+IS!DN36+IS!DN55 -> 7698.6032 | Y19: =Divisional!EB31+IS!DU36+IS!DU55 -> 9364.5096 | Z19: =Divisional!EI31+IS!EB36+IS!EB55 -> 11718.242 | AA19: =Divisional!EP31+IS!EI36+IS!EI55 -> 12818.165 | AB19: =Divisional!EW31+IS!EP36+IS!EP55 -> 13689.91 | AD19: =(W19/T19)^(1/3)-1 -> 0.10732418 | AE19: =(Y19/T19)^(1/5)-1 -> 0.11627196 | AF19: =(X19/U19)^(1/3)-1 -> 0.098361415 | AG19: =(Z19/U19)^(1/5)-1 -> 0.15063417
A20: Net Income adjusted | B20: 1342 | C20: 1769 | D20: 199 | E20: -433 | F20: 1613 | G20: 1219.8971 | H20: 632.5 | I20: 1132 | J20: 1807 | K20: 2236 | L20: =IS!AA57 -> 2601 | M20: =IS!AH57 -> 2662 | N20: =IS!AO57 -> 2562 | O20: =IS!AV57 -> 2836 | P20: =IS!BJ57 -> 4045 | Q20: =IS!BQ57 -> 4715 | R20: =IS!BX57 -> 1068 | S20: =IS!CE57 -> 3397 | T20: =IS!CL57 -> 4055 | U20: =IS!CS57 -> 4417 | V20: =IS!CZ57 -> 3992 | W20: =IS!DG57 -> 5437 | X20: =IS!DN57 -> 6023.9524 | Y20: =IS!DU57 -> 7273.3822 | Z20: =IS!EB57 -> 9038.6817 | AA20: =IS!EI57 -> 9863.6235 | AB20: =IS!EP57 -> 10517.433 | AD20: =(W20/T20)^(1/3)-1 -> 0.10269691 | AE20: =(Y20/T20)^(1/5)-1 -> 0.12395548 | AF20: =(X20/U20)^(1/3)-1 -> 0.10896552 | AG20: =(Z20/U20)^(1/5)-1 -> 0.15397271
A21: EPS adjusted (basic, €) | B21: =IS!E61 -> 1.501807 | C21: =IS!F61 -> 2.11014 | D21: =IS!G61 -> 0.12365248 | E21: =IS!H61 -> -0.55914825 | F21: =IS!I61 -> 1.9480066 | G21: =IS!J61 -> 1.5066057 | H21: =IS!K65 -> 0.7801967 | I21: =IS!L65 -> 1.3932188 | J21: =IS!M65 -> 2.2431642 | K21: =IS!T65 -> 2.811474 | L21: =IS!AA65 -> 3.3641463 | M21: =IS!AH65 -> 3.4100408 | N21: =IS!AO65 -> 3.310938 | O21: =IS!AV65 -> 3.665159 | P21: =IS!BJ65 -> 5.2182241 | Q21: =IS!BQ65 -> 6.0678998 | R21: =IS!BX65 -> 1.3636743 | S21: =IS!CE65 -> 4.3255918 | T21: =IS!CL65 -> 5.1519503 | U21: =IS!CS65 -> 5.6002075 | V21: =IS!CZ65 -> 5.0534097 | W21: =IS!DG65 -> 6.8859986 | X21: =IS!DN65 -> 7.6634283 | Y21: =IS!DU65 -> 9.302561 | Z21: =IS!EB65 -> 11.644819 | AA21: =IS!EI65 -> 12.788868 | AB21: =IS!EP65 -> 13.677252 | AD21: =(W21/T21)^(1/3)-1 -> 0.10153531 | AE21: =(Y21/T21)^(1/5)-1 -> 0.12544992 | AF21: =(X21/U21)^(1/3)-1 -> 0.11021305 | AG21: =(Z21/U21)^(1/5)-1 -> 0.15767251
A22: EPS adjusted (diluted, €) | B22: =IS!E62 -> 1.4961144 | C22: =IS!F62 -> 2.0944336 | D22: =IS!G62 -> 0.123086 | E22: =IS!H62 -> -0.55366009 | F22: =IS!I62 -> 1.9465155 | G22: =IS!J62 -> 1.5038363 | H22: =IS!K66 -> 0.78019637 | I22: =IS!L66 -> 1.3911727 | J22: =IS!M66 -> 2.2399557 | K22: =IS!T66 -> 2.8055937 | L22: =IS!AA66 -> 3.3590266 | M22: =IS!AH66 -> 3.3976262 | N22: =IS!AO66 -> 3.288369 | O22: =IS!AV66 -> 3.6391576 | P22: =IS!BJ66 -> 5.1796351 | Q22: =IS!BQ66 -> 6.0678998 | R22: =IS!BX66 -> 1.3636743 | S22: =IS!CE66 -> 4.3224219 | T22: =IS!CL66 -> 5.1475494 | U22: =IS!CS66 -> 5.5928341 | V22: =IS!CZ66 -> 5.0468332 | W22: =IS!DG66 -> 6.8745153 | X22: =IS!DN66 -> 7.6505916 | Y22: =IS!DU66 -> 9.2868952 | Z22: =IS!EB66 -> 11.625065 | AA22: =IS!EI66 -> 12.767036 | AB22: =IS!EP66 -> 13.653833 | AD22: =(W22/T22)^(1/3)-1 -> 0.1012363 | AE22: =(Y22/T22)^(1/5)-1 -> 0.12526291 | AF22: =(X22/U22)^(1/3)-1 -> 0.11008021 | AG22: =(Z22/U22)^(1/5)-1 -> 0.15758447
A23: DPS (€) | B23: =BS!E261 -> 0.5 | C23: =BS!F261 -> 0.65 | D23: =BS!G261 -> 0.12 | E23: =BS!H261 -> 0.12 | F23: =BS!I261 -> 0.2 | G23: =BS!J261 -> 0 | H23: =BS!K261 -> 0.22 | I23: =BS!L261 -> 0.45 | J23: =BS!M261 -> 0.6 | K23: =BS!T261 -> 0.75 | L23: =BS!AA261 -> 1.2 | M23: =BS!AH261 -> 1.3 | N23: =BS!AO261 -> 1.35 | O23: =BS!AV261 -> 1.5 | P23: =BS!BJ261 -> 1.65 | Q23: =BS!BQ261 -> 0 | R23: =BS!BX261 -> 0 | S23: =BS!CE261 -> 1.5 | T23: =BS!CL261 -> 1.8 | U23: =BS!CS261 -> 2.8 | V23: =BS!CZ261 -> 3 | W23: =BS!DG261 -> 3.2 | X23: =BS!DN261 -> 3.0653713 | Y23: =BS!DU261 -> 3.7210244 | Z23: =BS!EB261 -> 4.6579275 | AA23: =BS!EI261 -> 5.1155472 | AB23: =BS!EP261 -> 5.4709006 | AD23: =(W23/T23)^(1/3)-1 -> 0.21141373 | AE23: =(Y23/T23)^(1/5)-1 -> 0.15631991 | AF23: =(X23/U23)^(1/3)-1 -> 0.030643224 | AG23: =(Z23/U23)^(1/5)-1 -> 0.10715121
A24: FCF | B24: 1714 | C24: 2544 | D24: 2111 | E24: 3354 | F24: 2824 | G24: 606 | H24: 2745 | I24: 2493 | J24: 1449 | K24: -818 | L24: =CFS!AA74 -> 1109 | M24: =CFS!AH74 -> 1175 | N24: =CFS!AO74 -> 1156 | O24: =CFS!AV74 -> 2849 | P24: =CFS!BJ74 -> 2991 | Q24: =CFS!BQ74 -> 3567 | R24: =CFS!BX74 -> -6811 | S24: =CFS!CE58 -> 3425 | T24: =CFS!CL58 -> 4670 | U24: =CFS!CS58 -> 4097 | V24: =CFS!CZ58 -> 4461 | W24: =CFS!DG58 -> 4753 | X24: =CFS!DN58 -> 5119.7231 | Y24: =CFS!DU58 -> 6599.6673 | Z24: =CFS!EB58 -> 9061.9473 | AA24: =CFS!EI58 -> 9848.8051 | AB24: =CFS!EP58 -> 10717.474 | AD24: =(W24/T24)^(1/3)-1 -> 0.0058895845 | AE24: =(Y24/T24)^(1/5)-1 -> 0.071620549 | AF24: =(X24/U24)^(1/3)-1 -> 0.07711028 | AG24: =(Z24/U24)^(1/5)-1 -> 0.17206342
A25: FCF before Customer Financing | N25: =CFS!AO76 -> 1408 | O25: =CFS!BC76 -> 2949 | P25: =CFS!BJ76 -> 2912 | Q25: =CFS!BQ76 -> 3509 | R25: =CFS!BX76 -> -6935 | S25: =CFS!CE60 -> 3397 | T25: =CFS!CL60 -> 4816 | U25: =CFS!CS60 -> 4533 | V25: =CFS!CZ60 -> 4463 | W25: =CFS!DG60 -> 4574 | X25: =CFS!DN60 -> 4996.7231 | Y25: =CFS!DU60 -> 6599.6673 | Z25: =CFS!EB60 -> 9061.9473 | AA25: =CFS!EI60 -> 9848.8051 | AB25: =CFS!EP60 -> 10717.474 | AD25: =(W25/T25)^(1/3)-1 -> -0.017038381 | AE25: =(Y25/T25)^(1/5)-1 -> 0.065042928 | AF25: =(X25/U25)^(1/3)-1 -> 0.032998893 | AG25: =(Z25/U25)^(1/5)-1 -> 0.14859564
A27: Growth
A28: Revenue growth | C28: =C12/B12-1 -> 0.076981203 | D28: =D12/C12-1 -> 0.15283868 | E28: =E12/D12-1 -> -0.0078865953 | F28: =F12/E12-1 -> 0.10587123 | G28: =G12/F12-1 -> -0.010239223 | H28: =H12/G12-1 -> 0.068422773 | I28: =I12/H12-1 -> 0.073789124 | J28: =J12/I12-1 -> 0.14964989 | ... AB28: =AB12/AA12-1 -> 0.034463514
A29: EBITDA adjusted growth | C29: =C15/B15-1 -> 1.9832636 | D29: =D15/C15-1 -> -0.11833801 | E29: =E15/D15-1 -> -0.25293299 | F29: =F15/E15-1 -> -0.17247804 | G29: =G15/F15-1 -> 0.069154069 | H29: =H15/G15-1 -> 0.4587846 | I29: =I15/H15-1 -> 0.14497835 | J29: =J15/I15-1 -> 0.07240634 | ... AB29: =AB15/AA15-1 -> 0.052699414
A30: EBIT adjusted growth | C30: =C17/B17-1 -> 0.17269737 | D30: =D17/C17-1 -> -0.86009818 | E30: =E17/D17-1 -> -0.86967419 | F30: =F17/E17-1 -> 62.461538 | G30: =G17/F17-1 -> -0.34848485 | H30: =H17/G17-1 -> -0.37674419 | I30: =I17/H17-1 -> 0.33880597 | J30: =J17/I17-1 -> 0.65217391 | ... AB30: =AB17/AA17-1 -> 0.059285941
A31: EPS adjusted growth | C31: =C21/B21-1 -> 0.40506737 | D31: =D21/C21-1 -> -0.94140082 | E31: =E21/D21-1 -> -5.5219333 | F31: =F21/E21-1 -> -4.483882 | G31: =G21/F21-1 -> -0.22659106 | H31: =H21/G21-1 -> -0.48214938 | I31: =I21/H21-1 -> 0.78572759 | J31: =J21/I21-1 -> 0.61005886 | ... AB31: =AB21/AA21-1 -> 0.069465375
A33: Margins
A34: EBITDA adjusted Margin (%) | B34: =B15/B12 -> 0.060199616 | C34: =C15/C12 -> 0.16675437 | D34: =D15/D12 -> 0.12752954 | E34: =E15/E12 -> 0.096030468 | F34: =F15/F12 -> 0.071859471 | G34: =G15/G12 -> 0.077623651 | H34: =H15/H12 -> 0.10598444 | I34: =I15/I12 -> 0.11301091 | ... AB34: =AB15/AB12 -> 0.17382776
A35: EBIT adjusted Margin (%) | B35: =B17/B12 -> 0.076571896 | C35: =C17/C12 -> 0.083377185 | D35: =D17/D12 -> 0.010118172 | E35: =E17/E12 -> 0.0013291414 | F35: =F17/F12 -> 0.076274125 | G35: =G17/G12 -> 0.050207837 | H35: =H17/H12 -> 0.029288337 | I35: =I17/I12 -> 0.036516854 | ... AB35: =AB17/AB12 -> 0.1286229
A36: Dividend cover by EPS (x) | B36: =B21/B23 -> 3.0036139 | C36: =C21/C23 -> 3.2463692 | D36: =D21/D23 -> 1.0304373 | E36: =E21/E23 -> -4.6595688 | F36: =F21/F23 -> 9.7400328 | G36: nm | H36: =H21/H23 -> 3.5463486 | I36: =I21/I23 -> 3.0960417 | J36: =J21/J23 -> 3.738607 | K36: =K21/K23 -> 3.748632 | L36: =L21/L23 -> 2.8034552 | M36: =M21/M23 -> 2.6231083 | N36: =N21/N23 -> 2.4525467 | O36: =O21/O23 -> 2.4434393 | P36: =P21/P23 -> 3.16256 | Q36: =IFERROR(Q21/Q23,0) -> 0 | R36: =IFERROR(R21/R23,0) -> 0 | S36: =IFERROR(S21/S23,0) -> 2.8837278 | T36: =IFERROR(T21/T23,0) -> 2.8621946 | U36: =IFERROR(U21/U23,0) -> 2.0000741 | V36: =IFERROR(V21/V23,0) -> 1.6844699 | W36: =IFERROR(W21/W23,0) -> 2.1518745 | X36: =IFERROR(X21/X23,0) -> 2.5 | ... AB36: =IFERROR(AB21/AB23,0) -> 2.5
A37: Payout Ratio (%) | B37: =B23/B22 -> 0.33419903 | C37: =C23/C22 -> 0.31034644 | D37: =D23/D22 -> 0.97492808 | E37: =E23/E22 -> -0.21673948 | F37: =F23/F22 -> 0.1027477 | G37: =G23/G22 -> 0 | H37: =H23/H22 -> 0.28198029 | I37: =I23/I22 -> 0.32346811 | ... AB37: =AB23/AB22 -> 0.40068607
A38: P&L tax | B38: =IS!E40+IS!E56+IS!E24+IS!E26+IS!E50 -> -881 | C38: =IS!F40+IS!F56+IS!F24+IS!F26+IS!F50 -> -965 | D38: =IS!G40+IS!G56+IS!G24+IS!G26+IS!G50 -> 24 | E38: =IS!H40+IS!H56+IS!H24+IS!H26+IS!H50 -> 260 | F38: =IS!I40+IS!I56+IS!I24+IS!I26+IS!I50 -> -761 | G38: =IS!J40+IS!J56+IS!J24+IS!J26+IS!J50 -> -418.10288 | H38: =IS!K40+IS!K56+IS!K24+IS!K26+IS!K50 -> -280.5 | I38: =IS!L40+IS!L56+IS!L24+IS!L26+IS!L50 -> -379 | J38: =IS!M40+IS!M56+IS!M24+IS!M26+IS!M50 -> -702 | K38: =IS!T40+IS!T56+IS!T24+IS!T26+IS!T50 -> -796 | L38: =IS!AA40+IS!AA56+IS!AA24+IS!AA26+IS!AA50 -> -988 | M38: =IS!AH40+IS!AH56+IS!AH24+IS!AH26+IS!AH50 -> -982 | N38: =IS!AO40+IS!AO56+IS!AO24+IS!AO26+IS!AO50 -> -1048 | O38: =IS!AV40+IS!AV56+IS!AV24+IS!AV26+IS!AV50 -> -1024 | P38: =IS!BJ40+IS!BJ56+IS!BJ24+IS!BJ26+IS!BJ50 -> -1556 | Q38: =IS!BQ40+IS!BQ56+IS!BQ24+IS!BQ26+IS!BQ50 -> -2037 | R38: =IS!BX40+IS!BX56+IS!BX24+IS!BX26+IS!BX50 -> -378 | S38: =IS!CE40+IS!CE56+IS!CE24+IS!CE26+IS!CE50 -> -1242 | T38: =IS!CL40+IS!CL56+IS!CL24+IS!CL26+IS!CL50 -> -1459 | U38: =IS!CS40+IS!CS56+IS!CS24+IS!CS26+IS!CS50 -> -1569 | V38: =IS!CZ40+IS!CZ56+IS!CZ24+IS!CZ26+IS!CZ50 -> -1501 | W38: =IS!DG40+IS!DG56+IS!DG24+IS!DG26+IS!DG50 -> -2160 | X38: =IS!DN40+IS!DN56+IS!DN24+IS!DN26+IS!DN50 -> -1924.6508 | Y38: =IS!DU40+IS!DU56+IS!DU24+IS!DU26+IS!DU50 -> -2341.1274 | Z38: =IS!EB40+IS!EB56+IS!EB24+IS!EB26+IS!EB50 -> -2929.5606 | AA38: =IS!EI40+IS!EI56+IS!EI24+IS!EI26+IS!EI50 -> -3204.5412 | AB38: =IS!EP40+IS!EP56+IS!EP24+IS!EP26+IS!EP50 -> -3422.4776
A39: Cash tax | B39: =IS!E40+CFS!E8 -> -127 | C39: =IS!F40+CFS!F8 -> -265 | D39: =IS!G40+CFS!G8 -> -239 | E39: =IS!H40+CFS!H8 -> 36 | F39: =IS!I40+CFS!I8 -> -252 | G39: =IS!J40+CFS!J8 -> 4 | H39: =IS!K40+CFS!K8 -> -140 | I39: =IS!L40+CFS!L8 -> -100 | J39: =IS!M40+CFS!M8 -> -409 | K39: =IS!T40+CFS!T8 -> -243 | L39: =IS!AA40+CFS!AA8 -> -115 | M39: =IS!AH40+CFS!AH8 -> -595 | N39: =IS!AO40+CFS!AO8 -> -559 | O39: =IS!AV40+CFS!AV8 -> -152 | P39: =IS!BJ40+CFS!BJ8 -> -897 | Q39: =IS!BQ40+CFS!BQ8 -> -1476 | R39: =IS!BX40+CFS!BX8 -> 79 | S39: =IS!CE40+CFS!CE8 -> -321 | T39: =IS!CL40+CFS!CL8 -> -790 | U39: =IS!CS40+CFS!CS8 -> -544 | V39: =IS!CZ40+CFS!CZ8 -> -947 | W39: =IS!DG40+CFS!DG8 -> -965 | X39: =IS!DN40+CFS!DN8 -> -1936.9008 | Y39: =IS!DU40+CFS!DU8 -> -2341.1274 | Z39: =IS!EB40+CFS!EB8 -> -2929.5606 | AA39: =IS!EI40+CFS!EI8 -> -3204.5412 | AB39: =IS!EP40+CFS!EP8 -> -3422.4776
A40: P&L tax rate (%) | B40: =-B38/B19 -> 0.41912464 | C40: =-C38/C19 -> 0.36074766 | D40: =-D38/D19 -> -0.15483871 | E40: =-E38/E19 -> -0.078007801 | F40: =-F38/F19 -> 0.26627012 | G40: =-G38/G19 -> 0.25354935 | H40: =-H38/H19 -> 0.30193757 | I40: =-I38/I19 -> 0.25149303 | ... AB40: =-AB38/AB19 -> 0.25
A41: Cash tax rate (%) | B41: =-B39/B19 -> 0.060418649 | C41: =-C39/C19 -> 0.099065421 | D41: =-D39/D19 -> 1.5419355 | E41: =-E39/E19 -> -0.01080108 | F41: =-F39/F19 -> 0.088173548 | G41: =-G39/G19 -> -0.0024257126 | H41: =-H39/H19 -> 0.15069968 | I41: =-I39/I19 -> 0.066357001 | ... AB41: =-AB39/AB19 -> 0.25
A42: FCF margin (%) | B42: =+B24/B12 -> 0.053965555 | C42: =+C24/C12 -> 0.074372917 | D42: =+D24/D12 -> 0.053532485 | E42: =+E24/E12 -> 0.085729622 | F42: =+F24/F12 -> 0.06527216 | G42: =+G24/G12 -> 0.014151604 | H42: =+H24/H12 -> 0.059997377 | I42: =+I24/I12 -> 0.050744993 | ... M42: =+M24/M12 -> 0.018231187 | N42: =+N25/N12 -> 0.021147174 | O42: =+O25/O12 -> 0.044168526 | P42: =+P25/P12 -> 0.045709263 | Q42: =+Q25/Q12 -> 0.049788587 | R42: =+R25/R12 -> -0.13894454 | S42: =+S25/S12 -> 0.065140271 | T42: =+T25/T12 -> 0.081956333 | U42: =+U25/U12 -> 0.069263209 | ... AB42: =+AB25/AB12 -> 0.10155459
A43: Cash conversion (%) | B43: =+B24/B20 -> 1.2771982 | C43: =+C24/C20 -> 1.4381006 | D43: =+D24/D20 -> 10.60804 | E43: =+E24/E20 -> -7.7459584 | F43: =+F24/F20 -> 1.750775 | G43: =+G24/G20 -> 0.4967632 | H43: =+H24/H20 -> 4.3399209 | I43: =+I24/I20 -> 2.2022968 | ... M43: =+M24/M20 -> 0.44139745 | N43: =+N25/N20 -> 0.54957065 | O43: =+O25/O20 -> 1.0398449 | P43: =+P25/P20 -> 0.71990111 | Q43: =+Q25/Q20 -> 0.74422057 | R43: =+R25/R20 -> -6.4934457 | S43: =+S25/S20 -> 1 | T43: =+T25/T20 -> 1.1876695 | U43: =+U25/U20 -> 1.0262622 | ... AB43: =+AB25/AB20 -> 1.01902
...

Sheet Divisional
AV1: as rep'd | BC1: IFRS 15 | BJ1: IFRS 15 | BQ1: IFRS 15 | BX1: IFRS 15 | CE1: IFRS 15 | CL1: IFRS 15 | CS1: IFRS 15 | CZ1: IFRS 15 | DG1: IFRS 15 | DH1: 1Q25 | DI1: 2Q25 | DJ1: 3Q25 | DN1: IFRS 15 | DO1: 1Q26 | DP1: 2Q25 | DU1: IFRS 15 | EB1: IFRS 15 | EI1: IFRS 15 | EP1: IFRS 15 | EW1: IFRS 15
B2: 2001 | C2: 2002 | D2: 2003 | E2: 2004 | F2: 2005 | G2: 2006 | H2: 2007 | I2: 2008 | J2: 2009 | K2: 2010 | L2: 2011 | M2: 2012 | N2: Q1 | O2: Q2 | P2: Q3 | Q2: Q4 | R2: H1 | S2: H2 | T2: 2013 | U2: Q1 | V2: Q2 | W2: Q3 | X2: Q4 | Y2: H1 | Z2: H2 | AA2: 2014 | AB2: Q1 | AC2: Q2 | AD2: Q3 | AE2: Q4 | AF2: H1 | AG2: H2 | AH2: 2015 | AI2: Q1 | AJ2: Q2 | AK2: Q3 | AL2: Q4 | AM2: H1 | AN2: H2 | AO2: 2016 | AP2: Q1 | AQ2: Q2 | AR2: Q3 | AS2: Q4 | AT2: H1 | AU2: H2 | AV2: 2017 | AW2: Q1 | AX2: Q2 | AY2: Q3 | AZ2: Q4 | BA2: H1 | BB2: H2 | BC2: 2017 | BD2: Q1 | BE2: Q2 | BF2: Q3 | BG2: Q4 | BH2: H1 | BI2: H2 | BJ2: 2018 | BK2: Q1 | BL2: Q2 | BM2: Q3 | BN2: Q4 | BO2: H1 | BP2: H2 | BQ2: 2019 | BR2: Q1 | BS2: Q2 | BT2: Q3 | BU2: Q4 | BV2: H1 | BW2: H2 | BX2: 2019 rest. | BY2: Q1 | BZ2: Q2 | CA2: Q3 | CB2: Q4 | CC2: H1 | CD2: H2 | CE2: 2020 | CF2: Q1 | CG2: Q2 | CH2: Q3 | CI2: Q4 | CJ2: H1 | CK2: H2 | CL2: 2021 | CM2: Q1 | CN2: Q2 | CO2: Q3 | CP2: Q4 | CQ2: H1 | CR2: H2 | CS2: 2022 | CT2: Q1 | CU2: Q2 | CV2: Q3 | CW2: Q4 | CX2: H1 | CY2: H2 | CZ2: 2023 | DA2: Q1 | DB2: Q2 | DC2: Q3 | DD2: Q4 | DE2: H1 | DF2: H2 | DG2: 2024 | DH2: Q1 | DI2: Q2 | DJ2: Q3 | DK2: Q4 | DL2: H1 | DM2: H2 | DN2: 2025 | DO2: Q1 | DP2: Q2 | DQ2: Q3 | DR2: Q4 | DS2: H1 | DT2: H2 | DU2: 2026e | DV2: Q1 | DW2: Q2 | DX2: Q3 | DY2: Q4 | DZ2: H1 | EA2: H2 | EB2: 2027e | EC2: Q1 | ED2: Q2 | EE2: Q3 | EF2: Q4 | EG2: H1 | EH2: H2 | EI2: 2028e | EJ2: Q1 | EK2: Q2 | EL2: Q3 | EM2: Q4 | EN2: H1 | EO2: H2 | EP2: 2029e | EQ2: Q1 | ER2: Q2 | ES2: Q3 | ET2: Q4 | EU2: H1 | EV2: H2 | EW2: 2030e
A3: Revenue
A4: Airbus | B4: 20549 | C4: 19512 | D4: 19048 | E4: 20224 | F4: 22179 | G4: 25190 | H4: 25216 | I4: 26524 | J4: 26370 | K4: 27673 | L4: 31159 | M4: 36943 | N4: 8759 | O4: =R4-N4 -> 9343 | P4: =27328-R4 -> 9226 | Q4: =S4-P4 -> 12166 | R4: 18102 | S4: =T4-R4 -> 21392 | T4: 39494 | U4: 8937 | V4: =Y4-U4 -> 10492 | W4: =28820-Y4 -> 9391 | X4: =Z4-W4 -> 13460 | Y4: 19429 | Z4: =AA4-Y4 -> 22851 | AA4: 42280 | AB4: 8565 | AC4: =AF4-AB4 -> 12516 | AD4: =31119-AF4 -> 10038 | AE4: =AG4-AD4 -> 14735 | AF4: 21081 | AG4: =AH4-AF4 -> 24773 | AH4: 45854 | AI4: 8668 | AJ4: =AM4-AI4 -> 12393 | AK4: =31511-AM4 -> 10450 | AL4: =AN4-AK4 -> 17726 | AM4: 21061 | AN4: =AO4-AM4 -> 28176 | AO4: 49237 | AP4: 9825 | AQ4: =AT4-AP4 -> 11964 | AR4: 10854 | AS4: =AU4-AR4 -> 18315 | AT4: 21789 | AU4: =AV4-AT4 -> 29169 | AV4: 50958 | AW4: 8166 | AX4: =BA4-AW4 -> 10016 | AY4: =27579-BA4 -> 9397 | AZ4: =BB4-AY4 -> 15907 | BA4: 18182 | BB4: =BC4-BA4 -> 25304 | BC4: 43486 | BD4: 7222 | BE4: 11324 | BF4: =30478-BH4 -> 11932 | BG4: =BI4-BF4 -> 17492 | BH4: =BD4+BE4 -> 18546 | BI4: =BJ4-BH4 -> 29424 | BJ4: 47970 | BK4: 9697 | BL4: 14346 | BM4: 11529 | BN4: =BP4-BM4 -> 19203 | BO4: =BK4+BL4 -> 24043 | BP4: =BQ4-BO4 -> 30732 | BQ4: 54775 | BR4: 9697 | BS4: 14346 | BT4: 11529 | BU4: =BW4-BT4 -> 19203 | BV4: =BR4+BS4 -> 24043 | BW4: =BX4-BV4 -> 30732 | BX4: =BQ4 -> 54775 | BY4: 7569 | BZ4: 4964 | CA4: 7738 | CB4: =CD4-CA4 -> 13979 | CC4: =BY4+BZ4 -> 12533 | CD4: =CE4-CC4 -> 21717 | CE4: 34250 | CF4: 7272 | CG4: =CJ4-CF4 -> 10541 | CH4: 6805 | CI4: =CK4-CH4 -> 11546 | CJ4: 17813 | CK4: =CL4-CJ4 -> 18351 | CL4: 36164 | CM4: 8541 | CN4: 8992 | CO4: 9121 | CP4: =CR4-CO4 -> 14774 | CQ4: =+CM4+CN4 -> 17533 | CR4: =CS4-CQ4 -> 23895 | CS4: 41428 | CT4: 8110 | CU4: =CX4-CT4 -> 12239 | CV4: 11158 | CW4: =CY4-CV4 -> 16256 | CX4: 20349 | CY4: =CZ4-CX4 -> 27414 | CZ4: 47763 | DA4: 9167 | DB4: =DE4-DA4 -> 12048 | DC4: 11664 | DD4: =DF4-DC4 -> 17767 | DE4: 21215 | DF4: =DG4-DE4 -> 29431 | DG4: 50646 | DH4: 9521 | DI4: =DL4-DH4 -> 11308 | DJ4: 13057 | DK4: =DM4-DJ4 -> 18691 | DL4: 20829 | DM4: =DN4-DL4 -> 31748 | DN4: 52577 | DO4: 8436 | DP4: =DS4-DO4 -> 15441 | DQ4: =Airbus!DK11 -> 14465.159 | DR4: =Airbus!DL11 -> 19996.6 | DS4: 23877 | DT4: =Airbus!DN11 -> 34461.759 | DU4: =Airbus!DO11 -> 58338.759 | DV4: =Airbus!DP11 -> 15947.903 | DW4: =Airbus!DQ11 -> 16847.493 | DX4: =Airbus!DR11 -> 16890.459 | DY4: =Airbus!DS11 -> 16547.132 | DZ4: =Airbus!DT11 -> 32795.397 | EA4: =Airbus!DU11 -> 33437.591 | ... EW4: =Airbus!EQ11 -> 78628.532
A5: Airbus Helicopters | B5: =5065*0.55 -> 2785.75 | C5: =3834*0.7 -> 2683.8 | D5: 2586 | E5: 2786 | F5: 3211 | G5: 3803 | H5: 4172 | I5: 4486 | J5: 4570 | K5: 4830 | L5: 5415 | M5: 6264 | N5: 1038 | O5: =R5-N5 -> 1546 | P5: =4132-R5 -> 1548 | Q5: =S5-P5 -> 2165 | R5: 2584 | S5: =T5-R5 -> 3713 | T5: 6297 | U5: 1182 | V5: =Y5-U5 -> 1619 | W5: =4260-Y5 -> 1459 | X5: =Z5-W5 -> 2264 | Y5: 2801 | Z5: =AA5-Y5 -> 3723 | AA5: 6524 | AB5: 1285 | AC5: =AF5-AB5 -> 1665 | AD5: =4423-AF5 -> 1473 | AE5: =AG5-AD5 -> 2363 | AF5: 2950 | AG5: =AH5-AF5 -> 3836 | AH5: 6786 | AI5: 1158 | AJ5: =AM5-AI5 -> 1529 | AK5: =4282-AM5 -> 1595 | AL5: =AN5-AK5 -> 2370 | AM5: 2687 | AN5: =AO5-AM5 -> 3965 | AO5: 6652 | AP5: 1291 | AQ5: =AT5-AP5 -> 1630 | AR5: 1467 | AS5: =AU5-AR5 -> 2062 | AT5: 2921 | AU5: =AV5-AT5 -> 3529 | AV5: 6450 | AW5: 1176 | AX5: =BA5-AW5 -> 1540 | AY5: =4197-BA5 -> 1481 | AZ5: =BB5-AY5 -> 2138 | BA5: 2716 | BB5: =BC5-BA5 -> 3619 | BC5: 6335 | BD5: 961 | BE5: 1427 | BF5: =3755-BH5 -> 1367 | BG5: =BI5-BF5 -> 2179 | BH5: =BD5+BE5 -> 2388 | BI5: =BJ5-BH5 -> 3546 | BJ5: 5934 | BK5: 1007 | BL5: 1364 | BM5: 1341 | BN5: =BP5-BM5 -> 2295 | BO5: =BK5+BL5 -> 2371 | BP5: =BQ5-BO5 -> 3636 | BQ5: 6007 | BR5: 1007 | BS5: 1364 | BT5: 1341 | BU5: =BW5-BT5 -> 2295 | BV5: =BR5+BS5 -> 2371 | BW5: =BX5-BV5 -> 3636 | BX5: =BQ5 -> 6007 | BY5: 1202 | BZ5: 1131 | CA5: 1290 | CB5: =CD5-CA5 -> 2628 | CC5: =BY5+BZ5 -> 2333 | CD5: =CE5-CC5 -> 3918 | CE5: 6251 | CF5: 1177 | CG5: =CJ5-CF5 -> 1417 | CH5: 1543 | CI5: =CK5-CH5 -> 2372 | CJ5: 2594 | CK5: =CL5-CJ5 -> 3915 | CL5: 6509 | CM5: 1265 | CN5: 1479 | CO5: 1771 | CP5: =CR5-CO5 -> 2533 | CQ5: =+CM5+CN5 -> 2744 | CR5: =CS5-CQ5 -> 4304 | CS5: 7048 | CT5: 1598 | CU5: =CX5-CT5 -> 1596 | CV5: 1468 | CW5: =CY5-CV5 -> 2675 | CX5: 3194 | CY5: =CZ5-CX5 -> 4143 | CZ5: 7337 | DA5: 1461 | DB5: =DE5-DA5 -> 1730 | DC5: 1684 | DD5: =DF5-DC5 -> 3066 | DE5: 3191 | DF5: =DG5-DE5 -> 4750 | DG5: 7941 | DH5: 1600 | DI5: =DL5-DH5 -> 2093 | DJ5: 1959 | DK5: =DM5-DJ5 -> 3320 | DL5: 3693 | DM5: =DN5-DL5 -> 5279 | DN5: 8972 | DO5: 1604 | DP5: =DS5-DO5 -> 2076 | DQ5: =Helicopters!DC4 -> 2081.9272 | DR5: =Helicopters!DD4 -> 3609.578 | DS5: 3680 | DT5: =Helicopters!DF4 -> 5691.5052 | DU5: =Helicopters!DG4 -> 9371.5052 | DV5: =Helicopters!DH4 -> 1677.8867 | DW5: =Helicopters!DI4 -> 2169.5092 | DX5: =Helicopters!DJ4 -> 2175.713 | DY5: =Helicopters!DK4 -> 3765.8934 | DZ5: =Helicopters!DL4 -> 3847.3958 | EA5: =Helicopters!DM4 -> 5941.6064 | ... EW5: =Helicopters!EI4 -> 11157.829
A6: Airbus Defence & Space | N6: 2664 | O6: =R6-N6 -> 2900 | P6: =8382-R6 -> 2818 | Q6: =S6-P6 -> 4739 | R6: 5564 | S6: =T6-R6 -> 7557 | T6: 13121 | U6: 2743 | V6: =Y6-U6 -> 2773 | W6: =8197-Y6 -> 2681 | X6: =Z6-W6 -> 4828 | Y6: 5516 | Z6: =AA6-Y6 -> 7509 | AA6: 13025 | AB6: 2603 | AC6: =AF6-AB6 -> 2928 | AD6: =8383-AF6 -> 2852 | AE6: =AG6-AD6 -> 4697 | AF6: 5531 | AG6: =AH6-AF6 -> 7549 | AH6: 13080 | AI6: 2534 | AJ6: =AM6-AI6 -> 2906 | AK6: =7714-AM6 -> 2274 | AL6: =AN6-AK6 -> 4140 | AM6: 5440 | AN6: =AO6-AM6 -> 6414 | AO6: 11854 | AP6: 2114 | AQ6: =AT6-AP6 -> 2511 | AR6: 2108 | AS6: =AU6-AR6 -> 4071 | AT6: 4625 | AU6: =AV6-AT6 -> 6179 | AV6: 10804 | AW6: 2340 | AX6: =BA6-AW6 -> 2560 | AY6: =7052-BA6 -> 2152 | AZ6: =BB6-AY6 -> 3544 | BA6: 4900 | BB6: =BC6-BA6 -> 5696 | BC6: 10596 | BD6: 2217 | BE6: 2435 | BF6: =7051-BH6 -> 2399 | BG6: =BI6-BF6 -> 4012 | BH6: =BD6+BE6 -> 4652 | BI6: =BJ6-BH6 -> 6411 | BJ6: 11063 | BK6: 2112 | BL6: 2903 | BM6: 2691 | BN6: =BP6-BM6 -> 3201 | BO6: =BK6+BL6 -> 5015 | BP6: =BQ6-BO6 -> 5892 | BQ6: 10907 | BR6: 2112 | BS6: 2903 | BT6: 2691 | BU6: =BW6-BT6 -> 3201 | BV6: =BR6+BS6 -> 5015 | BW6: =BX6-BV6 -> 5892 | BX6: =BQ6 -> 10907 | BY6: 2111 | BZ6: 2440 | CA6: 2385 | CB6: =CD6-CA6 -> 3510 | CC6: =BY6+BZ6 -> 4551 | CD6: =CE6-CC6 -> 5895 | CE6: 10446 | CF6: 2115 | CG6: =CJ6-CF6 -> 2423 | CH6: 2343 | CI6: =CK6-CH6 -> 3305 | CJ6: 4538 | CK6: =CL6-CJ6 -> 5648 | CL6: 10186 | CM6: 2453 | CN6: 2603 | CO6: 2537 | CP6: =CR6-CO6 -> 3666 | CQ6: =+CM6+CN6 -> 5056 | CR6: =CS6-CQ6 -> 6203 | CS6: 11259 | CT6: 2299 | CU6: =CX6-CT6 -> 2354 | CV6: 2480 | CW6: =CY6-CV6 -> 4362 | CX6: 4653 | CY6: =CZ6-CX6 -> 6842 | CZ6: 11495 | DA6: 2399 | DB6: =DE6-DA6 -> 2586 | DC6: 2624 | DD6: =DF6-DC6 -> 4473 | DE6: 4985 | DF6: =DG6-DE6 -> 7097 | DG6: 12082 | DH6: 2656 | DI6: =DL6-DH6 -> 3157 | DJ6: 3063 | DK6: =DM6-DJ6 -> 4529 | DL6: 5813 | DM6: =DN6-DL6 -> 7592 | DN6: 13405 | DO6: 2832 | DP6: =DS6-DO6 -> 3484 | DQ6: ='Defence & Space'!CQ4 -> 3343.2645 | DR6: ='Defence & Space'!CR4 -> 4871.7555 | DS6: 6316 | DT6: ='Defence & Space'!CT4 -> 8215.02 | DU6: ='Defence & Space'!CU4 -> 14531.02 | DV6: ='Defence & Space'!CV4 -> 3021.036 | DW6: ='Defence & Space'!CW4 -> 3719.715 | DX6: ='Defence & Space'!CX4 -> 3566.0212 | DY6: ='Defence & Space'!CY4 -> 5201.4723 | DZ6: ='Defence & Space'!CZ4 -> 6740.751 | EA6: ='Defence & Space'!DA4 -> 8767.4935 | ... EW6: ='Defence & Space'!DW4 -> 17952.732
A7: Airbus Military | B7: 547 | C7: 524 | D7: 934 | E7: 1304 | F7: 763 | G7: 2200 | H7: 1140 | I7: 2759 | J7: 2235 | K7: 2684 | L7: 2504 | M7: 2131
A8: Cassidian | B8: 3345 | C8: 4770 | D8: 5165 | E8: 5385 | F8: 5636 | G8: 5864 | H8: 5392 | I8: 5668 | J8: 5363 | K8: 5933 | L8: 5803 | M8: 5740
A9: Astrium | B9: 2439 | C9: 2216 | D9: 2424 | E9: 2592 | F9: 2698 | G9: 3212 | H9: 3550 | I9: 4289 | J9: 4799 | K9: 5003 | L9: 4964 | M9: 5817
A10: Other Businesses | B10: =5065*0.45 -> 2279.25 | C10: =3834*0.3 -> 1150.2 | D10: 1217 | E10: 1090 | F10: 1155 | G10: 1257 | H10: 1407 | I10: 1338 | J10: 1096 | K10: 1182 | L10: 1252 | M10: 1524
A11: Subtotal | B11: =+SUM(B4:B10) -> 31945 | C11: =+SUM(C4:C10) -> 30856 | D11: =+SUM(D4:D10) -> 31374 | E11: =+SUM(E4:E10) -> 33381 | F11: =+SUM(F4:F10) -> 35642 | G11: =+SUM(G4:G10) -> 41526 | H11: =+SUM(H4:H10) -> 40877 | I11: =+SUM(I4:I10) -> 45064 | ... BB11: =+SUM(BB4:BB10) -> 34619 | BC11: =+BC4+BC6+BC5 -> 60417 | BD11: =+SUM(BD4:BD10) -> 10400 | BE11: =+SUM(BE4:BE10) -> 15186 | BF11: =+SUM(BF4:BF10) -> 15698 | BG11: =+SUM(BG4:BG10) -> 23683 | BH11: =+SUM(BH4:BH10) -> 25586 | BI11: =+SUM(BI4:BI10) -> 39381 | BJ11: =+SUM(BJ4:BJ10) -> 64967 | BK11: =+SUM(BK4:BK10) -> 12816 | ... EW11: =+SUM(EW4:EW10) -> 107739.09
A12: HQ/Eliminations & other businesses | B12: -1147 | C12: -955 | D12: -1241 | E12: -1620 | F12: -1436 | G12: -2092 | H12: -1754 | I12: -1799 | J12: =-1639+28 -> -1611 | K12: =-1582+29 -> -1553 | L12: -1969 | M12: -1939 | N12: -367 | O12: =R12-N12 -> -213 | P12: =-895-R12 -> -315 | Q12: =S12-P12 -> -450 | R12: -580 | S12: =T12-R12 -> -765 | T12: -1345 | U12: -214 | V12: =Y12-U12 -> -332 | W12: =-780-Y12 -> -234 | X12: =Z12-W12 -> -336 | Y12: -546 | Z12: =AA12-Y12 -> -570 | AA12: =482-1598 -> -1116 | AB12: -375 | AC12: =AF12-AB12 -> -294 | AD12: =-960-AF12 -> -291 | AE12: =AG12-AD12 -> -310 | AF12: =-792+123 -> -669 | AG12: =AH12-AF12 -> -601 | AH12: =296-1566 -> -1270 | AI12: -177 | AJ12: =AM12-AI12 -> -256 | AK12: =-802-AM12 -> -369 | AL12: =AN12-AK12 -> -360 | AM12: =-588+155 -> -433 | AN12: =AO12-AM12 -> -729 | AO12: =57-1219 -> -1162 | AP12: -242 | AQ12: =AT12-AP12 -> -384 | AR12: -185 | AS12: =AU12-AR12 -> -634 | AT12: -626 | AU12: =AV12-AT12 -> -819 | AV12: -1445 | AW12: -240 | AX12: =BA12-AW12 -> -383 | AY12: =-821-BA12 -> -198 | AZ12: =BB12-AY12 -> -574 | BA12: -623 | BB12: =BC12-BA12 -> -772 | BC12: -1395 | BD12: -281 | BE12: -335 | BF12: =-863-BH12 -> -247 | BG12: =BI12-BF12 -> -397 | BH12: =BD12+BE12 -> -616 | BI12: =BJ12-BH12 -> -644 | BJ12: -1260 | BK12: -267 | BL12: -296 | BM12: -259 | BN12: =BP12-BM12 -> -389 | BO12: =BK12+BL12 -> -563 | BP12: =BQ12-BO12 -> -648 | BQ12: -1211 | BR12: -267 | BS12: -296 | BT12: -259 | BU12: =BW12-BT12 -> -389 | BV12: =BR12+BS12 -> -563 | BW12: =BX12-BV12 -> -648 | BX12: -1211 | BY12: -251 | BZ12: -218 | CA12: -200 | CB12: =CD12-CA12 -> -366 | CC12: =BY12+BZ12 -> -469 | CD12: =CE12-CC12 -> -566 | CE12: -1035 | CF12: -104 | CG12: =CJ12-CF12 -> -204 | CH12: -173 | CI12: =CK12-CH12 -> -229 | CJ12: -308 | CK12: =CL12-CJ12 -> -402 | CL12: -710 | CM12: -259 | CN12: -264 | CO12: -120 | CP12: =CR12-CO12 -> -329 | CQ12: =+CM12+CN12 -> -523 | CR12: =CS12-CQ12 -> -449 | CS12: -972 | CT12: -244 | CU12: =CX12-CT12 -> -289 | CV12: -209 | CW12: =CY12-CV12 -> -407 | CX12: -533 | CY12: =CZ12-CX12 -> -616 | CZ12: -1149 | DA12: -197 | DB12: =DE12-DA12 -> -369 | DC12: -283 | DD12: =DF12-DC12 -> -590 | DE12: -566 | DF12: =DG12-DE12 -> -873 | DG12: -1439 | DH12: -235 | DI12: =DL12-DH12 -> -490 | DJ12: -253 | DK12: =DM12-DJ12 -> -556 | DL12: -725 | DM12: =DN12-DL12 -> -809 | DN12: -1534 | DO12: -221 | DP12: =DS12-DO12 -> -476 | DQ12: =DT12/2 -> -493.07037 | DR12: =DT12-DQ12 -> -493.07037 | DS12: -697 | DT12: =DU12-DS12 -> -986.14073 | DU12: =DN12*(1+((DU11/DN11)-1)) -> -1683.1407 | DV12: =DZ12/2 -> -468.31183 | DW12: =DZ12-DV12 -> -468.31183 | DX12: =EA12/2 -> -468.31183 | DY12: =EA12-DX12 -> -468.31183 | DZ12: =EB12/2 -> -936.62366 | EA12: =EB12-DZ12 -> -936.62366 | EB12: =DU12*(1+((EB11/DU11)-1)) -> -1873.2473 | EC12: =EG12/2 -> -509.87919 | ED12: =EG12-EC12 -> -509.87919 | EE12: =EH12/2 -> -509.87919 | EF12: =EH12-EE12 -> -509.87919 | EG12: =EI12/2 -> -1019.7584 | EH12: =EI12-EG12 -> -1019.7584 | EI12: =EB12*(1+((EI11/EB11)-1)) -> -2039.5167 | EJ12: =EN12/2 -> -532.87911 | EK12: =EN12-EJ12 -> -532.87911 | EL12: =EO12/2 -> -532.87911 | EM12: =EO12-EL12 -> -532.87911 | EN12: =EP12/2 -> -1065.7582 | EO12: =EP12-EN12 -> -1065.7582 | EP12: =EI12*(1+((EP11/EI11)-1)) -> -2131.5164 | EQ12: =EU12/2 -> -551.24399 | ER12: =EU12-EQ12 -> -551.24399 | ES12: =EV12/2 -> -551.24399 | ET12: =EV12-ES12 -> -551.24399 | EU12: =EW12/2 -> -1102.488 | EV12: =EW12-EU12 -> -1102.488 | EW12: =EP12*(1+((EW11/EP11)-1)) -> -2204.976
A13: Total Revenue | B13: =+B11+B12 -> 30798 | C13: =+C11+C12 -> 29901 | D13: =+D11+D12 -> 30133 | E13: =+E11+E12 -> 31761 | F13: =+F11+F12 -> 34206 | G13: =+G11+G12 -> 39434 | H13: =+H11+H12 -> 39123 | I13: =+I11+I12 -> 43265 | ... EW13: =+EW11+EW12 -> 105534.12
A15: Revenue Growth %
A16: =A4 -> Airbus | C16: =C4/B4-1 -> -0.050464743 | D16: =D4/C4-1 -> -0.023780238 | E16: =E4/D4-1 -> 0.061738765 | F16: =F4/E4-1 -> 0.096667326 | G16: =G4/F4-1 -> 0.13575905 | H16: =H4/G4-1 -> 0.0010321556 | I16: =I4/H4-1 -> 0.051871827 | J16: =J4/I4-1 -> -0.0058060624 | ... M16: =M4/L4-1 -> 0.18562855 | T16: =T4/M4-1 -> 0.069052324 | U16: =U4/N4-1 -> 0.020321955 | V16: =V4/O4-1 -> 0.12297977 | W16: =W4/P4-1 -> 0.01788424 | X16: =X4/Q4-1 -> 0.10636199 | Y16: =Y4/R4-1 -> 0.073306817 | Z16: =Z4/S4-1 -> 0.068203067 | AA16: =AA4/T4-1 -> 0.070542361 | ... AV16: =AV4/AO4-1 -> 0.034953389 | AW16: =AW4/AI4-1 -> -0.057914167 | AX16: =AX4/AJ4-1 -> -0.19180182 | AY16: =AY4/AK4-1 -> -0.10076555 | AZ16: =AZ4/AL4-1 -> -0.10261762 | BA16: =BA4/AM4-1 -> -0.13669816 | BB16: =BB4/AN4-1 -> -0.10193072 | BC16: =BC4/AO4-1 -> -0.1168024 | BD16: =BD4/AW4-1 -> -0.11560127 | BE16: =BE4/AX4-1 -> 0.13059105 | BF16: =BF4/AY4-1 -> 0.26976695 | BG16: =BG4/AZ4-1 -> 0.099641667 | BH16: =BH4/BA4-1 -> 0.0200198 | BI16: =BI4/BB4-1 -> 0.16282011 | BJ16: =BJ4/BC4-1 -> 0.10311365 | BK16: =BK4/BD4-1 -> 0.34270285 | ... BQ16: =BQ4/BJ4-1 -> 0.1418595 | BR16: =BR4/BD4-1 -> 0.34270285 | BS16: =BS4/BE4-1 -> 0.26686683 | BT16: =BT4/BF4-1 -> -0.033774723 | BU16: =BU4/BG4-1 -> 0.097816145 | BV16: =BV4/BH4-1 -> 0.29639815 | BW16: =BW4/BI4-1 -> 0.044453507 | BX16: =BX4/BJ4-1 -> 0.1418595 | BY16: =BY4/BR4-1 -> -0.21944931 | BZ16: =BZ4/BS4-1 -> -0.6539802 | CA16: =CA4/BT4-1 -> -0.32882297 | CB16: =CB4/BU4-1 -> -0.27204083 | CC16: =CC4/BV4-1 -> -0.47872562 | CD16: =CD4/BW4-1 -> -0.29334244 | CE16: =CE4/BQ4-1 -> -0.37471474 | CF16: =CF4/BY4-1 -> -0.039239001 | CG16: =CG4/BZ4-1 -> 1.1234891 | CH16: =CH4/CA4-1 -> -0.12057379 | CI16: =CI4/CB4-1 -> -0.17404678 | CJ16: =CJ4/CC4-1 -> 0.4212878 | CK16: =CK4/CD4-1 -> -0.15499378 | CL16: =CL4/CE4-1 -> 0.055883212 | CM16: =CM4/CF4-1 -> 0.17450495 | ... EW16: =EW4/EP4-1 -> 0.029565456
A17: Airbus Helicopters | C17: =C5/B5-1 -> -0.036596967 | D17: =D5/C5-1 -> -0.036440867 | E17: =E5/D5-1 -> 0.07733952 | F17: =F5/E5-1 -> 0.15254846 | G17: =G5/F5-1 -> 0.18436624 | H17: =H5/G5-1 -> 0.097028662 | I17: =I5/H5-1 -> 0.075263663 | J17: =J5/I5-1 -> 0.018724922 | ... M17: =M5/L5-1 -> 0.1567867 | T17: =T5/M5-1 -> 0.0052681992 | U17: =U5/N5-1 -> 0.13872832 | V17: =V5/O5-1 -> 0.047218629 | W17: =W5/P5-1 -> -0.05749354 | X17: =X5/Q5-1 -> 0.045727483 | Y17: =Y5/R5-1 -> 0.083978328 | Z17: =Z5/S5-1 -> 0.00269324 | AA17: =AA5/T5-1 -> 0.036048912 | ... AV17: =AV5/AO5-1 -> -0.030366807 | AW17: =AW5/AI5-1 -> 0.015544041 | AX17: =AX5/AJ5-1 -> 0.0071942446 | AY17: =AY5/AK5-1 -> -0.071473354 | AZ17: =AZ5/AL5-1 -> -0.097890295 | BA17: =BA5/AM5-1 -> 0.010792706 | BB17: =BB5/AN5-1 -> -0.087263556 | BC17: =BC5/AO5-1 -> -0.047654841 | BD17: =BD5/AW5-1 -> -0.18282313 | BE17: =BE5/AX5-1 -> -0.073376623 | BF17: =BF5/AY5-1 -> -0.076975017 | BG17: =BG5/AZ5-1 -> 0.019176801 | BH17: =BH5/BA5-1 -> -0.12076583 | BI17: =BI5/BB5-1 -> -0.020171318 | BJ17: =BJ5/BC5-1 -> -0.063299132 | BK17: =BK5/BD5-1 -> 0.047866805 | ... BQ17: =BQ5/BJ5-1 -> 0.012301989 | BR17: =BR5/BD5-1 -> 0.047866805 | BS17: =BS5/BE5-1 -> -0.044148563 | BT17: =BT5/BF5-1 -> -0.019019751 | BU17: =BU5/BG5-1 -> 0.053235429 | BV17: =BV5/BH5-1 -> -0.007118928 | BW17: =BW5/BI5-1 -> 0.025380711 | BX17: =BX5/BJ5-1 -> 0.012301989 | BY17: =BY5/BR5-1 -> 0.19364449 | BZ17: =BZ5/BS5-1 -> -0.17082111 | CA17: =CA5/BT5-1 -> -0.03803132 | CB17: =CB5/BU5-1 -> 0.14509804 | CC17: =CC5/BV5-1 -> -0.016026993 | CD17: =CD5/BW5-1 -> 0.077557756 | CE17: =CE5/BQ5-1 -> 0.040619278 | CF17: =CF5/BY5-1 -> -0.020798669 | CG17: =CG5/BZ5-1 -> 0.25287356 | CH17: =CH5/CA5-1 -> 0.19612403 | CI17: =CI5/CB5-1 -> -0.097412481 | CJ17: =CJ5/CC5-1 -> 0.11187312 | CK17: =CK5/CD5-1 -> -0.00076569678 | CL17: =CL5/CE5-1 -> 0.041273396 | CM17: =CM5/CF5-1 -> 0.074766355 | ... EW17: =EW5/EP5-1 -> 0.04461466
A18: Airbus Defence & Space | U18: =U6/N6-1 -> 0.029654655 | V18: =V6/O6-1 -> -0.043793103 | W18: =W6/P6-1 -> -0.04861604 | X18: =X6/Q6-1 -> 0.018780333 | Y18: =Y6/R6-1 -> -0.0086268871 | Z18: =Z6/S6-1 -> -0.0063517269 | AA18: =AA6/T6-1 -> -0.0073165155 | AB18: =AB6/U6-1 -> -0.051039008 | ... AV18: =AV6/AO6-1 -> -0.088577695 | AW18: =AW6/AI6-1 -> -0.0765588 | AX18: =AX6/AJ6-1 -> -0.11906401 | AY18: =AY6/AK6-1 -> -0.053649956 | AZ18: =AZ6/AL6-1 -> -0.14396135 | BA18: =BA6/AM6-1 -> -0.099264706 | BB18: =BB6/AN6-1 -> -0.11194263 | BC18: =BC6/AO6-1 -> -0.10612451 | BD18: =BD6/AW6-1 -> -0.052564103 | BE18: =BE6/AX6-1 -> -0.048828125 | BF18: =BF6/AY6-1 -> 0.11477695 | BG18: =BG6/AZ6-1 -> 0.13205418 | BH18: =BH6/BA6-1 -> -0.050612245 | BI18: =BI6/BB6-1 -> 0.12552669 | BJ18: =BJ6/BC6-1 -> 0.044073235 | BK18: =BK6/BD6-1 -> -0.047361299 | ... BQ18: =BQ6/BJ6-1 -> -0.014101058 | BR18: =BR6/BD6-1 -> -0.047361299 | BS18: =BS6/BE6-1 -> 0.19219713 | BT18: =BT6/BF6-1 -> 0.12171738 | BU18: =BU6/BG6-1 -> -0.20214357 | BV18: =BV6/BH6-1 -> 0.078030954 | BW18: =BW6/BI6-1 -> -0.080954609 | BX18: =BX6/BJ6-1 -> -0.014101058 | BY18: =BY6/BR6-1 -> -0.00047348485 | BZ18: =BZ6/BS6-1 -> -0.15949018 | CA18: =CA6/BT6-1 -> -0.11371237 | CB18: =CB6/BU6-1 -> 0.096532334 | CC18: =CC6/BV6-1 -> -0.092522433 | CD18: =CD6/BW6-1 -> 0.00050916497 | CE18: =CE6/BQ6-1 -> -0.042266434 | CF18: =CF6/BY6-1 -> 0.0018948366 | CG18: =CG6/BZ6-1 -> -0.0069672131 | CH18: =CH6/CA6-1 -> -0.017610063 | CI18: =CI6/CB6-1 -> -0.058404558 | CJ18: =CJ6/CC6-1 -> -0.0028565151 | CK18: =CK6/CD6-1 -> -0.041899915 | CL18: =CL6/CE6-1 -> -0.02488991 | CM18: =CM6/CF6-1 -> 0.15981087 | ... EW18: =EW6/EP6-1 -> 0.05
A19: =A7 -> Airbus Military | C19: =C7/B7-1 -> -0.042047532 | D19: =D7/C7-1 -> 0.78244275 | E19: =E7/D7-1 -> 0.39614561 | F19: =F7/E7-1 -> -0.4148773 | G19: =G7/F7-1 -> 1.8833552 | H19: =H7/G7-1 -> -0.48181818 | I19: =I7/H7-1 -> 1.4201754 | J19: =J7/I7-1 -> -0.18992389 | ... M19: =M7/L7-1 -> -0.14896166
A20: =A8 -> Cassidian | C20: =C8/B8-1 -> 0.42600897 | D20: =D8/C8-1 -> 0.082809224 | E20: =E8/D8-1 -> 0.042594385 | F20: =F8/E8-1 -> 0.046610956 | G20: =G8/F8-1 -> 0.040454223 | H20: =H8/G8-1 -> -0.080491132 | I20: =I8/H8-1 -> 0.051186944 | J20: =J8/I8-1 -> -0.053810868 | ... M20: =M8/L8-1 -> -0.010856454
A21: =A9 -> Astrium | C21: =C9/B9-1 -> -0.091430914 | D21: =D9/C9-1 -> 0.093862816 | E21: =E9/D9-1 -> 0.069306931 | F21: =F9/E9-1 -> 0.040895062 | G21: =G9/F9-1 -> 0.19051149 | H21: =H9/G9-1 -> 0.10523039 | I21: =I9/H9-1 -> 0.20816901 | J21: =J9/I9-1 -> 0.11890884 | ... M21: =M9/L9-1 -> 0.17183723
A22: =A10 -> Other Businesses | C22: =C10/B10-1 -> -0.49536032 | D22: =D10/C10-1 -> 0.058076856 | E22: =E10/D10-1 -> -0.10435497 | F22: =F10/E10-1 -> 0.059633028 | G22: =G10/F10-1 -> 0.088311688 | H22: =H10/G10-1 -> 0.11933174 | I22: =I10/H10-1 -> -0.049040512 | J22: =J10/I10-1 -> -0.18086697 | ... M22: =M10/L10-1 -> 0.2172524
A23: Total | C23: =C13/B13-1 -> -0.029125268 | D23: =D13/C13-1 -> 0.0077589378 | E23: =E13/D13-1 -> 0.054027146 | F23: =F13/E13-1 -> 0.076981203 | G23: =G13/F13-1 -> 0.15283868 | H23: =H13/G13-1 -> -0.0078865953 | I23: =I13/H13-1 -> 0.10587123 | J23: =J13/I13-1 -> -0.010239223 | ... M23: =M13/L13-1 -> 0.14964989 | T23: =T13/M13-1 -> 0.019245751 | U23: =U13/N13-1 -> 0.045807839 | V23: =V13/O13-1 -> 0.071891573 | W23: =W13/P13-1 -> 0.0015063644 | X23: =X13/Q13-1 -> 0.085714286 | Y23: =Y13/R13-1 -> 0.059602649 | Z23: =Z13/S13-1 -> 0.050663072 | AA23: =AA13/T13-1 -> 0.054649365 | ... AV23: =AV13/AO13-1 -> 0.0027935898 | AW23: =AW13/AI13-1 -> -0.060822458 | AX23: =AX13/AJ13-1 -> -0.17131306 | AY23: =AY13/AK13-1 -> -0.080143369 | AZ23: =AZ13/AL13-1 -> -0.11982744 | BA23: =BA13/AM13-1 -> -0.12450009 | BB23: =BB13/AN13-1 -> -0.1051922 | BC23: =BC13/AO13-1 -> -0.11353089 | BD23: =BD13/AW13-1 -> -0.11562664 | BE23: =BE13/AX13-1 -> 0.081409743 | BF23: =BF13/AY13-1 -> 0.20409913 | BG23: =BG13/AZ13-1 -> 0.10806567 | BH23: =BH13/BA13-1 -> -0.008142999 | BI23: =BI13/BB13-1 -> 0.14447366 | BJ23: =BJ13/BC13-1 -> 0.079377181 | BK23: =BK13/BD13-1 -> 0.24014231 | ... BQ23: =BQ13/BJ13-1 -> 0.10628345 | BR23: =BR13/BD13-1 -> 0.24014231 | BS23: =BS13/BE13-1 -> 0.23338496 | BT23: =BT13/BF13-1 -> -0.0096433888 | BU23: =BU13/BG13-1 -> 0.043974921 | BV23: =BV13/BH13-1 -> 0.23612335 | BW23: =BW13/BI13-1 -> 0.022588223 | BX23: =BX13/BJ13-1 -> 0.10628345 | BY23: =BY13/BR13-1 -> -0.15284086 | BZ23: =BZ13/BS13-1 -> -0.54594093 | CA23: =CA13/BT13-1 -> -0.26721997 | CB23: =CB13/BU13-1 -> -0.18753599 | CC23: =CC13/BV13-1 -> -0.38612065 | CD23: =CD13/BW13-1 -> -0.21831768 | CE23: =CE13/BQ13-1 -> -0.29180737 | CF23: =CF13/BY13-1 -> -0.016085034 | CG23: =CG13/BZ13-1 -> 0.70458098 | CH23: =CH13/CA13-1 -> -0.061981628 | CI23: =CI13/CB13-1 -> -0.13958787 | CJ23: =CJ13/CC13-1 -> 0.30024277 | CK23: =CK13/CD13-1 -> -0.1114843 | CL23: =CL13/CE13-1 -> 0.044818881 | CM23: =CM13/CF13-1 -> 0.14722753 | ... EW23: =EW13/EP13-1 -> 0.034463514
A25: EBIT Adjusted
A26: Airbus | N26: 608 | O26: =R26-N26 -> 623 | P26: =1712-R26 -> 481 | Q26: =S26-P26 -> 502 | R26: 1231 | S26: =T26-R26 -> 983 | T26: 2214 | U26: 527 | V26: =Y26-U26 -> 760 | W26: =1780-Y26 -> 493 | X26: =Z26-W26 -> 749 | Y26: 1287 | Z26: =AA26-Y26 -> 1242 | AA26: 2529 | AB26: 569 | AC26: =AF26-AB26 -> 964 | AD26: =2226-AF26 -> 693 | AE26: =AG26-AD26 -> 554 | AF26: 1533 | AG26: =AH26-AF26 -> 1247 | AH26: 2780 | AI26: 406 | AJ26: =AM26-AI26 -> 863 | AK26: =1836-AM26 -> 567 | AL26: =AN26-AK26 -> 975 | AM26: 1269 | AN26: =AO26-AM26 -> 1542 | AO26: 2811 | AP26: 281 | AQ26: =AT26-AP26 -> 673 | AR26: 591 | AS26: =AU26-AR26 -> 2009 | AT26: 954 | AU26: =AV26-AT26 -> 2600 | AV26: 3554 | AW26: -103 | AX26: =BA26-AW26 -> 360 | AY26: =806-BA26 -> 549 | AZ26: =BB26-AY26 -> 1577 | BA26: 257 | BB26: =BC26-BA26 -> 2126 | BC26: 2383 | BD26: -41 | BE26: 908 | BF26: =2340-BH26 -> 1473 | BG26: =BI26-BF26 -> 2468 | BH26: =BD26+BE26 -> 867 | BI26: =BJ26-BH26 -> 3941 | BJ26: 4808 | BK26: 536 | BL26: 1802 | BM26: 1495 | BN26: =BP26-BM26 -> 2525 | BO26: =BK26+BL26 -> 2338 | BP26: =BQ26-BO26 -> 4020 | BQ26: 6358 | BR26: =536-73 -> 463 | BS26: =1802-145+73 -> 1730 | BT26: =1495-240+145 -> 1400 | BU26: =BW26-BT26 -> 2354 | BV26: =BR26+BS26 -> 2193 | BW26: =BX26-BV26 -> 3754 | BX26: =BQ26-411 -> 5947 | BY26: 191 | BZ26: -1498 | CA26: 666 | CB26: =CD26-CA26 -> 1259 | CC26: =BY26+BZ26 -> -1307 | CD26: =CE26-CC26 -> 1925 | CE26: 618 | CF26: 533 | CG26: =CJ26-CF26 -> 1758 | CH26: 448 | CI26: =CK26-CH26 -> 831 | CJ26: 2291 | CK26: =CL26-CJ26 -> 1279 | CL26: 3570 | CM26: 1065 | CN26: 1211 | CO26: 599 | CP26: =CR26-CO26 -> 1725 | CQ26: =CM26+CN26 -> 2276 | CR26: =CS26-CQ26 -> 2324 | CS26: 4600 | CT26: 580 | CU26: =CX26-CT26 -> 1676 | CV26: 960 | CW26: =CY26-CV26 -> 1602 | CX26: 2256 | CY26: =CZ26-CX26 -> 2562 | CZ26: 4818 | DA26: 507 | DB26: =DE26-DA26 -> 1447 | DC26: 1074 | DD26: =DF26-DC26 -> 2065 | DE26: 1954 | DF26: =DG26-DE26 -> 3139 | DG26: 5093 | DH26: 494 | DI26: =DL26-DH26 -> 1220 | DJ26: 1556 | DK26: =DM26-DJ26 -> 2200 | DL26: 1714 | DM26: =DN26-DL26 -> 3756 | DN26: 5470 | DO26: 81 | DP26: =DS26-DO26 -> 1906 | DQ26: =Airbus!DK45 -> 1587.1268 | DR26: =Airbus!DL45 -> 2343.5513 | DS26: 1987 | DT26: =Airbus!DN45 -> 3930.678 | DU26: =Airbus!DO45 -> 5917.678 | DV26: =Airbus!DP45 -> 1717.4956 | DW26: =Airbus!DQ45 -> 1876.7178 | DX26: =Airbus!DR45 -> 1879.2567 | DY26: =Airbus!DS45 -> 1839.2901 | DZ26: =Airbus!DT45 -> 3594.2134 | EA26: =Airbus!DU45 -> 3718.5467 | ... EW26: =Airbus!EQ45 -> 10793.437
A27: Airbus Helicopters | N27: 20 | O27: =R27-N27 -> 108 | P27: =217-R27 -> 89 | Q27: =S27-P27 -> 180 | R27: 128 | S27: =T27-R27 -> 269 | T27: 397 | U27: 58 | V27: =Y27-U27 -> 92 | W27: =241-Y27 -> 91 | X27: =Z27-W27 -> 172 | Y27: 150 | Z27: =AA27-Y27 -> 263 | AA27: 413 | AB27: 52 | AC27: =AF27-AB27 -> 110 | AD27: =241-AF27 -> 79 | AE27: =AG27-AD27 -> 186 | AF27: 162 | AG27: =AH27-AF27 -> 265 | AH27: 427 | AI27: 33 | AJ27: =AM27-AI27 -> 111 | AK27: =200-AM27 -> 56 | AL27: =AN27-AK27 -> 150 | AM27: 144 | AN27: =AO27-AM27 -> 206 | AO27: 350 | AP27: -2 | AQ27: =AT27-AP27 -> 95 | AR27: 72 | AS27: =AU27-AR27 -> 172 | AT27: 93 | AU27: =AV27-AT27 -> 244 | AV27: 337 | AW27: -6 | AX27: =BA27-AW27 -> 86 | AY27: =161-BA27 -> 81 | AZ27: =BB27-AY27 -> 86 | BA27: 80 | BB27: =BC27-BA27 -> 167 | BC27: 247 | BD27: -3 | BE27: 138 | BF27: =202-BH27 -> 67 | BG27: =BI27-BF27 -> 178 | BH27: =BD27+BE27 -> 135 | BI27: =BJ27-BH27 -> 245 | BJ27: 380 | BK27: 15 | BL27: 110 | BM27: 80 | BN27: =BP27-BM27 -> 217 | BO27: =BK27+BL27 -> 125 | BP27: =BQ27-BO27 -> 297 | BQ27: 422 | BR27: 15 | BS27: 110 | BT27: 80 | BU27: =BW27-BT27 -> 217 | BV27: =BR27+BS27 -> 125 | BW27: =BX27-BV27 -> 297 | BX27: 422 | BY27: 53 | BZ27: 99 | CA27: 86 | CB27: =CD27-CA27 -> 233 | CC27: =BY27+BZ27 -> 152 | CD27: =CE27-CC27 -> 319 | CE27: 471 | CF27: 62 | CG27: =CJ27-CF27 -> 121 | CH27: 131 | CI27: =CK27-CH27 -> 221 | CJ27: 183 | CK27: =CL27-CJ27 -> 352 | CL27: 535 | CM27: 90 | CN27: 125 | CO27: 165 | CP27: =CR27-CO27 -> 259 | CQ27: =CM27+CN27 -> 215 | CR27: =CS27-CQ27 -> 424 | CS27: 639 | CT27: 156 | CU27: =CX27-CT27 -> 118 | CV27: 143 | CW27: =CY27-CV27 -> 318 | CX27: 274 | CY27: =CZ27-CX27 -> 461 | CZ27: 735 | DA27: 71 | DB27: =DE27-DA27 -> 159 | DC27: 190 | DD27: =DF27-DC27 -> 398 | DE27: 230 | DF27: =DG27-DE27 -> 588 | DG27: 818 | DH27: 78 | DI27: =DL27-DH27 -> 171 | DJ27: 246 | DK27: =DM27-DJ27 -> 430 | DL27: 249 | DM27: =DN27-DL27 -> 676 | DN27: 925 | DO27: 65 | DP27: =DS27-DO27 -> 175 | DQ27: =Helicopters!DC7 -> 260.24091 | DR27: =Helicopters!DD7 -> 463.51285 | DS27: 240 | DT27: =Helicopters!DF7 -> 723.75376 | DU27: =Helicopters!DG7 -> 963.75376 | DV27: =Helicopters!DH7 -> 179.59914 | DW27: =Helicopters!DI7 -> 233.3748 | DX27: =Helicopters!DJ7 -> 234.03693 | DY27: =Helicopters!DK7 -> 408.51238 | DZ27: =Helicopters!DL7 -> 412.97394 | EA27: =Helicopters!DM7 -> 642.5493 | ... EW27: =Helicopters!EI7 -> 1289.7011
A28: Airbus Defence & Space | N28: 84 | O28: =R28-N28 -> 132 | P28: =356-R28 -> 140 | Q28: =S28-P28 -> 555 | R28: 216 | S28: =T28-R28 -> 695 | T28: 911 | U28: 85 | V28: =Y28-U28 -> 138 | W28: =370-Y28 -> 147 | X28: =Z28-W28 -> 550 | Y28: 223 | Z28: =AA28-Y28 -> 697 | AA28: 920 | AB28: 90 | AC28: =AF28-AB28 -> 177 | AD28: =431-AF28 -> 164 | AE28: =AG28-AD28 -> 629 | AF28: 267 | AG28: =AH28-AF28 -> 793 | AH28: 1060 | AI28: 107 | AJ28: =AM28-AI28 -> 215 | AK28: =436-AM28 -> 114 | AL28: =AN28-AK28 -> 566 | AM28: 322 | AN28: =AO28-AM28 -> 680 | AO28: 1002 | AP28: 63 | AQ28: =AT28-AP28 -> 185 | AR28: 109 | AS28: =AU28-AR28 -> 515 | AT28: 248 | AU28: =AV28-AT28 -> 624 | AV28: 872 | AW28: 118 | AX28: =BA28-AW28 -> 180 | AY28: =397-BA28 -> 99 | AZ28: =BB28-AY28 -> 418 | BA28: 298 | BB28: =BC28-BA28 -> 517 | BC28: 815 | BD28: 112 | BE28: 197 | BF28: =409-BH28 -> 100 | BG28: =BI28-BF28 -> 526 | BH28: =BD28+BE28 -> 309 | BI28: =BJ28-BH28 -> 626 | BJ28: 935 | BK28: 101 | BL28: 132 | BM28: 122 | BN28: =BP28-BM28 -> 210 | BO28: =BK28+BL28 -> 233 | BP28: =BQ28-BO28 -> 332 | BQ28: 565 | BR28: 101 | BS28: 132 | BT28: 122 | BU28: =BW28-BT28 -> 210 | BV28: =BR28+BS28 -> 233 | BW28: =BX28-BV28 -> 332 | BX28: =BQ28 -> 565 | BY28: 15 | BZ28: 171 | CA28: 80 | CB28: =CD28-CA28 -> 394 | CC28: =BY28+BZ28 -> 186 | CD28: =CE28-CC28 -> 474 | CE28: 660 | CF28: 59 | CG28: =CJ28-CF28 -> 170 | CH28: 55 | CI28: =CK28-CH28 -> 412 | CJ28: 229 | CK28: =CL28-CJ28 -> 467 | CL28: 696 | CM28: 106 | CN28: 49 | CO28: 76 | CP28: =CR28-CO28 -> 153 | CQ28: =CM28+CN28 -> 155 | CR28: =CS28-CQ28 -> 229 | CS28: 384 | CT28: 36 | CU28: =CX28-CT28 -> 42 | CV28: -79 | CW28: =CY28-CV28 -> 230 | CX28: 78 | CY28: =CZ28-CX28 -> 151 | CZ28: 229 | DA28: -9 | DB28: =DE28-DA28 -> -798 | DC28: 146 | DD28: =DF28-DC28 -> 95 | DE28: -807 | DF28: =DG28-DE28 -> 241 | DG28: -566 | DH28: 77 | DI28: =DL28-DH28 -> 188 | DJ28: 155 | DK28: =DM28-DJ28 -> 378 | DL28: 265 | DM28: =DN28-DL28 -> 533 | DN28: 798 | DO28: 130 | DP28: =DS28-DO28 -> 357 | DQ28: ='Defence & Space'!CQ9 -> 211.79113 | DR28: ='Defence & Space'!CR9 -> 318.38027 | DS28: 487 | DT28: ='Defence & Space'!CT9 -> 530.1714 | DU28: ='Defence & Space'!CU9 -> 1017.1714 | DV28: ='Defence & Space'!CV9 -> 226.5777 | DW28: ='Defence & Space'!CW9 -> 278.97862 | DX28: ='Defence & Space'!CX9 -> 267.45159 | DY28: ='Defence & Space'!CY9 -> 390.11042 | DZ28: ='Defence & Space'!CZ9 -> 505.55633 | EA28: ='Defence & Space'!DA9 -> 657.56201 | ... EW28: ='Defence & Space'!DW9 -> 1490.9659
A29: Subtotal | N29: =SUM(N26:N28) -> 712 | O29: =SUM(O26:O28) -> 863 | P29: =SUM(P26:P28) -> 710 | Q29: =SUM(Q26:Q28) -> 1237 | R29: =SUM(R26:R28) -> 1575 | S29: =SUM(S26:S28) -> 1947 | T29: =T26+T28+T27 -> 3522 | U29: =SUM(U26:U28) -> 670 | V29: =SUM(V26:V28) -> 990 | W29: =SUM(W26:W28) -> 731 | X29: =SUM(X26:X28) -> 1471 | Y29: =SUM(Y26:Y28) -> 1660 | Z29: =SUM(Z26:Z28) -> 2202 | AA29: =AA26+AA28+AA27 -> 3862 | AB29: =SUM(AB26:AB28) -> 711 | AC29: =SUM(AC26:AC28) -> 1251 | AD29: =SUM(AD26:AD28) -> 936 | AE29: =SUM(AE26:AE28) -> 1369 | AF29: =SUM(AF26:AF28) -> 1962 | AG29: =SUM(AG26:AG28) -> 2305 | AH29: =AH26+AH28+AH27 -> 4267 | AI29: =SUM(AI26:AI28) -> 546 | AJ29: =SUM(AJ26:AJ28) -> 1189 | AK29: =SUM(AK26:AK28) -> 737 | AL29: =SUM(AL26:AL28) -> 1691 | AM29: =SUM(AM26:AM28) -> 1735 | AN29: =SUM(AN26:AN28) -> 2428 | AO29: =SUM(AO26:AO28) -> 4163 | AP29: =AP26+AP28+AP27 -> 342 | AQ29: =AQ26+AQ28+AQ27 -> 953 | AR29: =AR26+AR28+AR27 -> 772 | AS29: =AS26+AS28+AS27 -> 2696 | AT29: =AT26+AT28+AT27 -> 1295 | AU29: =AU26+AU28+AU27 -> 3468 | AV29: =AV26+AV28+AV27 -> 4763 | AW29: =AW26+AW28+AW27 -> 9 | ... BB29: =BB26+BB28+BB27 -> 2810 | BC29: =+BC26+BC28+BC27 -> 3445 | BD29: =BD26+BD28+BD27 -> 68 | BE29: =BE26+BE28+BE27 -> 1243 | BF29: =BF26+BF28+BF27 -> 1640 | BG29: =BG26+BG28+BG27 -> 3172 | BH29: =BH26+BH28+BH27 -> 1311 | BI29: =BI26+BI28+BI27 -> 4812 | BJ29: =BJ26+BJ28+BJ27 -> 6123 | BK29: =BK26+BK28+BK27 -> 652 | ... EW29: =EW26+EW28+EW27 -> 13574.104
