Workbook
Name _div08: #REF!
Name _div09: #REF!
Name _div10: #REF!
Name _ShH3: #REF!
Name A_ALL_AIR.PA: #REF!
Name A_ALL_AIR.PA: #REF!
Name A_ALL_AIR.PA_: #REF!
Name A_ALL_AIR.PA_: #REF!
Name A_ALL_AIR.PA_: #REF!
Name A_ALL_AIR.PA_: #REF!
Name A_ALL_AIR.PA_: #REF!
Name A_ALL_BAES.L_: #REF!
Name A_ALL_BAES.L_: #REF!
Name A_ALL_BAES.L_: #REF!
Name A_ALL_BAES.L_: #REF!
Name A_ALL_BAES.L_: #REF!
Name A_ALL_COB.L: #REF!
Name A_ALL_COB.L: #REF!
Name A_ALL_COB.L: #REF!
Name A_ALL_KEYWORDS_TYPE_ScalarContributed_EQTY_200000267: #REF!,#REF!
Name A_ALL_KEYWORDS_TYPE_ScalarContributed_EQTY_200003162: #REF!,#REF!
Name A_ALL_KEYWORDS_TYPE_ScalarContributed_EQTY_200003162: #REF!,#REF!
Name A_ALL_KEYWORDS_TYPE_ScalarContributed_EQTY_200003162: #REF!,#REF!
Name A_ALL_KEYWORDS_TYPE_ScalarContributed_EQTY_200003170: #REF!,#REF!
Name A_ALL_KEYWORDS_TYPE_ScalarContributed_EQTY_200003170: #REF!,#REF!
Name A_ALL_KEYWORDS_TYPE_ScalarContributed_EQTY_200003170: #REF!,#REF!
Name A_ALL_KEYWORDS_TYPE_ScalarContributed_EQTY_200003173: #REF!,#REF!
Name A_ALL_KEYWORDS_TYPE_ScalarContributed_EQTY_200003173: #REF!,#REF!
Name A_ALL_KEYWORDS_TYPE_ScalarContributed_EQTY_200003173: #REF!,#REF!
Name A_ALL_KEYWORDS_TYPE_ScalarContributed_EQTY_200003183: #REF!,#REF!
Name A_ALL_KEYWORDS_TYPE_ScalarContributed_EQTY_200003183: #REF!,#REF!
Name A_ALL_KEYWORDS_TYPE_ScalarContributed_EQTY_200003183: #REF!,#REF!
Name A_ALL_KEYWORDS_TYPE_ScalarContributed_EQTY_200003821: #REF!,#REF!
Name A_ALL_KEYWORDS_TYPE_ScalarContributed_EQTY_200003821: #REF!,#REF!
Name A_ALL_KEYWORDS_TYPE_ScalarContributed_EQTY_200003821: #REF!,#REF!
Name A_ALL_KEYWORDS_TYPE_ScalarContributed_EQTY_200004285: #REF!,#REF!
Name A_ALL_KEYWORDS_TYPE_ScalarContributed_EQTY_200004285: #REF!,#REF!
Name A_ALL_KEYWORDS_TYPE_ScalarContributed_EQTY_200005121: #REF!,#REF!
Name A_ALL_KEYWORDS_TYPE_ScalarContributed_EQTY_200005121: #REF!,#REF!
Name A_ALL_KEYWORDS_TYPE_ScalarContributed_EQTY_200005121: #REF!,#REF!
Name A_ALL_KEYWORDS_TYPE_ScalarContributed_EQTY_200007513: #REF!,#REF!
Name A_ALL_KEYWORDS_TYPE_ScalarContributed_EQTY_200007513: #REF!,#REF!
Name A_ALL_KEYWORDS_TYPE_ScalarContributed_EQTY_200007513: #REF!,#REF!
Name A_ALL_KEYWORDS_TYPE_ScalarContributed_EQTY_200008448: #REF!,#REF!,#REF!
Name A_ALL_KEYWORDS_TYPE_ScalarContributed_EQTY_200008448: #REF!,#REF!,#REF!
Name A_ALL_KEYWORDS_TYPE_ScalarContributed_EQTY_200009618: #REF!,#REF!
Name A_ALL_KEYWORDS_TYPE_ScalarContributed_EQTY_200009618: #REF!,#REF!
Name A_ALL_KEYWORDS_TYPE_ScalarContributed_EQTY_200009618: #REF!,#REF!
Name A_ALL_KEYWORDS_TYPE_ScalarContributed_EQTY_200009619: #REF!,#REF!
Name A_ALL_KEYWORDS_TYPE_ScalarContributed_EQTY_200009619: #REF!,#REF!
Name A_ALL_KEYWORDS_TYPE_ScalarContributed_EQTY_200009619: #REF!,#REF!
Name A_ALL_KEYWORDS_TYPE_ScalarContributed_EQTY_200009620: #REF!,#REF!
Name A_ALL_KEYWORDS_TYPE_ScalarContributed_EQTY_200009620: #REF!,#REF!
Name A_ALL_KEYWORDS_TYPE_ScalarContributed_EQTY_200009620: #REF!,#REF!
Name A_ALL_KEYWORDS_TYPE_ScalarContributed_EQTY_200011295: #REF!,#REF!
Name A_ALL_KEYWORDS_TYPE_ScalarContributed_EQTY_200011295: #REF!,#REF!
Name A_ALL_KEYWORDS_TYPE_ScalarContributed_ISSR_208000023: #REF!,#REF!,#REF!,#REF!,#REF!,#REF!,#REF!,#REF!,#REF!,#REF!
Name A_ALL_KEYWORDS_TYPE_ScalarContributed_ISSR_208001092: #REF!,#REF!
Name A_ALL_KEYWORDS_TYPE_ScalarContributed_ISSR_208001092: #REF!,#REF!
Name A_ALL_KEYWORDS_TYPE_ScalarContributed_ISSR_208001095: #REF!,#REF!

Sheet _QP_SAF.PA
A1: 1311101 | F1: 1998 | G1: 1999 | H1: 2000 | I1: 2001 | J1: 2002 | K1: 2003 | L1: 2004 | M1: 2005 | N1: 2006 H1 | O1: 2006 H2 | P1: 2006 | Q1: 2007 H1 | R1: 2007 H2 | S1: 2007 | T1: 2008 H1 | U1: 2008 H2 | V1: 2008 | W1: 2009 H1 | X1: 2009 H2 | Y1: 2009 | Z1: 2010 H1 | AA1: 2010 H2 | AB1: 2010 | AC1: 2011 H1 | AD1: 2011 H2 | AE1: 2011 | AF1: 2012 | AG1: 2013 | AH1: 2014 | AI1: 2015 | AJ1: 2016
A2: AUTO-GENERATED BY TIGR NUMBERS SUBMISSION. DO NOT MODIFY OR DELETE!
B4: ACC_END_DATE | D4: EUR | F4: 36160 | G4: 36525 | H4: 36891 | I4: 37256 | J4: 37621 | K4: 37986 | L4: 38352 | M4: 38717 | N4: 38898 | O4: 39082 | P4: 39082 | Q4: 39263 | R4: 39447 | S4: 39447 | T4: 39629 | U4: 39813 | V4: 39813 | W4: 39994 | X4: 40178 | Y4: 40178 | Z4: 40359 | AA4: 40543 | AB4: 40543 | AC4: 40724 | AD4: 40908 | AE4: 40908 | AF4: 41274 | AG4: 41639 | AH4: 42004 | AI4: 42369 | AJ4: 42735
B5: EURO_LIST | D5: EUR
B6: EURO_CONVICTION | D6: EUR
B7: LEGAL_RATING | D7: EUR | E7: Coverage Suspended
B8: TARGET_PRICE | D8: EUR
B9: TP_PERIOD | D9: EUR
B10: NUM_SH1 | D10: EUR | E10: 404.73546
B11: FREE_FLOAT | D11: EUR | E11: 0.466
B12: BVPS_PUB | D12: EUR | M12: 10.963251 | P12: 10.404538 | S12: 10.40214 | V12: 9.3517537 | Y12: 10.900213 | AB12: 10.862539 | AE12: 11.912824
B13: DPS_PUB | D13: EUR | M13: 0.35968671 | P13: 0.22060785 | S13: 0.40045121 | V13: 0.25 | Y13: 0.38 | AB13: 0.5 | AE13: 0.62
B14: EBITDA_PUB | D14: EUR | M14: 1019 | P14: 884 | S14: 1069 | V14: 1182 | Y14: 1107 | AB14: 1313.5 | AE14: 1681
B15: EPS_PUB | D15: EUR | M15: 1.2240036 | P15: 0.4320298 | S15: 0.98837802 | V15: 0.63154612 | Y15: 0.94172621 | AB15: 1.2714211 | AE15: 1.5911628
B16: EV_ADJ_PUB | D16: EUR | F16: 0 | G16: 0 | H16: 0 | I16: 0 | J16: 0 | K16: 0 | M16: 486.3324 | N16: 0 | O16: 0 | P16: 838.35458 | Q16: 0 | S16: 1109.3546 | V16: 1064.3546 | Y16: 1044.3546 | AB16: 1100.3546 | AE16: 1144.3546
B17: NET_DEBT_PUB | D17: EUR | M17: 473 | P17: 419 | S17: 169 | V17: 635 | W17: -690 | X17: 498 | Y17: 498 | AB17: -24 | AE17: 997
B18: NI_PUB | D18: EUR | M18: 501 | P18: 177 | S18: 406 | V18: 256 | W18: 207 | X18: 169 | Y18: 376 | Z18: 261 | AA18: 247 | AB18: 508 | AC18: 317.05748 | AD18: 321.616 | AE18: 644
B19: EBIT_PUB | D19: EUR | M19: 762 | P19: 465 | S19: 706 | V19: 798 | W19: 347 | X19: 351 | Y19: 698 | Z19: 428 | AA19: 450 | AB19: 878 | AC19: 554.05748 | AD19: 632.616 | AE19: 1189
B20: PTP_PUB | D20: EUR | M20: 678 | P20: 391 | S20: 645 | V20: 605 | W20: 265 | X20: 227 | Y20: 492 | Z20: 337 | AA20: 369 | AB20: 706 | AC20: 442.05748 | AD20: 510.616 | AE20: 955
B21: REVS_PUB | D21: EUR | M21: 10577 | P21: 11329 | S21: 12003 | V21: 10329 | W21: 5149 | X21: 5299 | Y21: 10448 | Z21: 5197 | AA21: 5563 | AB21: 10760 | AC21: 5622 | AD21: 6114 | AE21: 11736
B22: EQ_PUB | D22: EUR | M22: 4736 | P22: 4512 | S22: 4505 | V22: 3874 | Y22: 4501 | AB22: 4705 | AE22: 5122
B23: SALES | D23: EUR | M23: 10577 | P23: 11329 | S23: 12003 | V23: 10329 | Y23: 10448 | AB23: 10760 | AE23: 11736
B24: COST_GD_SD | D24: EUR
B25: SEL_GL_AD | D25: EUR | F25: 0 | G25: 0 | H25: 0 | I25: 0 | J25: 0 | K25: 0 | L25: 0 | M25: 0 | N25: 0 | O25: 0 | P25: 0 | Q25: 0 | S25: 0
B26: OP_COST | D26: EUR | F26: 0 | G26: 0 | H26: 0 | I26: 0 | J26: 0 | K26: 0 | M26: -9558 | N26: 0 | O26: 0 | P26: -10445 | Q26: 0 | S26: -10934 | V26: -8708 | Y26: -8847 | AB26: -9040.5 | AE26: -9560
B27: RD_EXP | D27: EUR
B28: OTH_OP_INC_EXP | D28: EUR | F28: 0 | G28: 0 | H28: 0 | I28: 0 | J28: 0 | K28: 0 | N28: 0 | O28: 0 | Q28: 0 | V28: -439 | Y28: -494 | AB28: -406 | AE28: -495
B29: TOT_OPS_EXP_DDA | D29: EUR | M29: -9815 | P29: -10864 | S29: -11297 | V29: -9531 | Y29: -9750 | AB29: -9882 | AE29: -10547
B30: TOT_OPS_EXP | D30: EUR | M30: -9558 | P30: -10445 | S30: -10934 | V30: -9147 | Y30: -9341 | AB30: -9446.5 | AE30: -10055
B31: EBITDA_CALC | D31: EUR | M31: 1019 | P31: 884 | S31: 1069 | V31: 1182 | Y31: 1107 | AB31: 1313.5 | AE31: 1681
B32: DEPREC | D32: EUR | F32: 0 | G32: 0 | H32: 0 | I32: 0 | J32: 0 | K32: 0 | M32: -257 | N32: 0 | O32: 0 | P32: -306 | Q32: 0 | S32: -287 | V32: -278 | Y32: -279 | AB32: -291 | AE32: -321
B33: GOODWILL_AMORT | D33: EUR | F33: 0 | G33: 0 | H33: 0 | I33: 0 | J33: 0 | K33: 0 | N33: 0 | O33: 0 | P33: -113 | Q33: 0 | S33: -76 | V33: -106 | Y33: -130 | AB33: -144.5 | AE33: -171
B34: EBIT | D34: EUR | M34: 762 | P34: 465 | S34: 706 | V34: 798 | Y34: 698 | AB34: 878 | AE34: 1189
B35: INT_INC_IND | D35: EUR
B36: INT_EXP_IND | D36: EUR
B37: NET_INT_EXP | D37: EUR | M37: -87 | P37: -78 | S37: -65 | V37: -203 | Y37: -174 | AB37: -168 | AE37: -215
B38: ASSOCIATE | D38: EUR | F38: 0 | G38: 0 | H38: 0 | I38: 0 | J38: 0 | K38: 0 | L38: 0 | M38: 3 | N38: 0 | O38: 0 | P38: 4 | Q38: 0 | S38: 4 | V38: 10 | Y38: 3 | AB38: 9 | AE38: 10
B39: PROFIT_ON_DISP | D39: EUR | F39: 0 | G39: 0 | H39: 0 | I39: 0 | J39: 0 | K39: 0 | L39: 0 | M39: 0 | N39: 0 | O39: 0 | P39: 0 | Q39: 0 | S39: 0
B40: OTH_COST_INC | D40: EUR | F40: 0 | G40: 0 | H40: 0 | I40: 0 | J40: 0 | K40: 0 | L40: 0 | M40: 0 | N40: 0 | O40: 0 | P40: 0 | Q40: 0 | S40: 0 | AB40: -13 | AE40: -29
B41: PT_PROF | D41: EUR | M41: 678 | P41: 391 | S41: 645 | V41: 605 | Y41: 527 | AB41: 706 | AE41: 955
...

Sheet Cover Page
A2: GOLDMAN SACHS
A3: GLOBAL INVESTMENT RESEARCH
A4: Multi-Industry
B6: SAF.PA
B7: Published as of | C7: 45968 | I7: Rating Suspended
B9: Team Contacts:
B10: Primary Analysts
B11: Sam Burgess, sam.burgess@gs.com, +44 20 7774-9651 Goldman Sachs International
B12: Supporting Analyst
B13: Jubril Moronfolu, jubril.x.moronfolu@gs.com, +44 20 7051-0985 Goldman Sachs International
B14: Milind Sikchi, milind.sikchi@gs.com, +1 332 245-7985, Goldman Sachs International

Sheet DCF Valuation
B4: Calendar year | C4: 2026 | D4: 2027 | E4: 2028 | F4: 2029 | G4: 2030 | H4: 2031 | I4: 2032 | J4: 2033 | K4: 2034 | L4: 2035
B5: Adj. EBIT | C5: ='DCF Feed'!C4 -> 6143.3638 | D5: ='DCF Feed'!D4 -> 6980.0222 | E5: ='DCF Feed'!E4 -> 7702.6228 | F5: ='DCF Feed'!F4 -> 8235.9281 | G5: ='DCF Feed'!G4 -> 8787.0465
B6: Tax Rate | C6: =-'DCF Feed'!C10 -> 0.25 | D6: =-'DCF Feed'!D10 -> 0.25 | E6: =-'DCF Feed'!E10 -> 0.25 | F6: =-'DCF Feed'!F10 -> 0.25 | G6: =-'DCF Feed'!G10 -> 0.25
B7: NOPAT | C7: =C5*(1-C6) -> 4607.5228 | D7: =D5*(1-D6) -> 5235.0166 | E7: =E5*(1-E6) -> 5776.9671 | F7: =F5*(1-F6) -> 6176.946 | G7: =G5*(1-G6) -> 6590.2848
B8: D&A | C8: =INDEX('Income Statement'!192:192, MATCH('DCF Valuation'!C4,'Income Statement'!3:3,0)) -> 1878.871 | D8: =INDEX('Income Statement'!192:192, MATCH('DCF Valuation'!D4,'Income Statement'!3:3,0)) -> 1989.0011 | E8: =INDEX('Income Statement'!192:192, MATCH('DCF Valuation'!E4,'Income Statement'!3:3,0)) -> 2143.6064 | F8: =INDEX('Income Statement'!192:192, MATCH('DCF Valuation'!F4,'Income Statement'!3:3,0)) -> 2262.166 | G8: =INDEX('Income Statement'!192:192, MATCH('DCF Valuation'!G4,'Income Statement'!3:3,0)) -> 2371.9984
B9: Change in working capital | C9: =INDEX('Cashflow Statement'!22:22, MATCH('DCF Valuation'!C4,'Cashflow Statement'!2:2,0)) -> 254.32099 | D9: =INDEX('Cashflow Statement'!22:22, MATCH('DCF Valuation'!D4,'Cashflow Statement'!2:2,0)) -> -104.50791 | E9: =INDEX('Cashflow Statement'!22:22, MATCH('DCF Valuation'!E4,'Cashflow Statement'!2:2,0)) -> -454.17326 | F9: =INDEX('Cashflow Statement'!22:22, MATCH('DCF Valuation'!F4,'Cashflow Statement'!2:2,0)) -> -643.49968 | G9: =INDEX('Cashflow Statement'!22:22, MATCH('DCF Valuation'!G4,'Cashflow Statement'!2:2,0)) -> -903.4025
B10: Capex & Intangibles | C10: =(INDEX('Cashflow Statement'!69:69, MATCH('DCF Valuation'!C4,'Cashflow Statement'!2:2,0)))+INDEX('Cashflow Statement'!70:70, MATCH('DCF Valuation'!C4,'Cashflow Statement'!2:2,0)) -> -2154.4179 | D10: =(INDEX('Cashflow Statement'!69:69, MATCH('DCF Valuation'!D4,'Cashflow Statement'!2:2,0)))+INDEX('Cashflow Statement'!70:70, MATCH('DCF Valuation'!D4,'Cashflow Statement'!2:2,0)) -> -2119.3017 | E10: =(INDEX('Cashflow Statement'!69:69, MATCH('DCF Valuation'!E4,'Cashflow Statement'!2:2,0)))+INDEX('Cashflow Statement'!70:70, MATCH('DCF Valuation'!E4,'Cashflow Statement'!2:2,0)) -> -2029.8732 | F10: =(INDEX('Cashflow Statement'!69:69, MATCH('DCF Valuation'!F4,'Cashflow Statement'!2:2,0)))+INDEX('Cashflow Statement'!70:70, MATCH('DCF Valuation'!F4,'Cashflow Statement'!2:2,0)) -> -1888.6195 | G10: =(INDEX('Cashflow Statement'!69:69, MATCH('DCF Valuation'!G4,'Cashflow Statement'!2:2,0)))+INDEX('Cashflow Statement'!70:70, MATCH('DCF Valuation'!G4,'Cashflow Statement'!2:2,0)) -> -1719.6767
B11: Sustainable FCF | C11: =C7+C8+C9+C10 -> 4586.2969 | D11: =D7+D8+D9+D10 -> 5000.2081 | E11: =E7+E8+E9+E10 -> 5436.527 | F11: =F7+F8+F9+F10 -> 5906.9928 | G11: =G7+G8+G9+G10 -> 6339.204 | H11: =G11*(1+H12) -> 6763.4006 | I11: =H11*(1+I12) -> 7153.5627 | J11: =I11*(1+J12) -> 7500.2114 | K11: =J11*(1+K12) -> 7794.4379 | L11: =K11*(1+L12) -> 8028.271
B12: Annual growth | D12: ='DCF Feed'!D5 -> 0.13618897 | E12: ='DCF Feed'!E5 -> 0.10352412 | F12: ='DCF Feed'!F5 -> 0.069236834 | G12: ='DCF Feed'!G5 -> 0.066916368 | H12: =G12 -> 0.066916368 | I12: =H12+(($L$12-$H$12)/4) -> 0.057687276 | J12: =I12+(($L$12-$H$12)/4) -> 0.048458184 | K12: =J12+(($L$12-$H$12)/4) -> 0.039229092 | L12: =$D$33 -> 0.03
B13: WACC | D13: =$D$32 -> 0.0746 | E13: =$D$32 -> 0.0746 | F13: =$D$32 -> 0.0746 | G13: =$D$32 -> 0.0746 | H13: =$D$32 -> 0.0746 | I13: =$D$32 -> 0.0746 | J13: =$D$32 -> 0.0746 | K13: =$D$32 -> 0.0746 | L13: =$D$32 -> 0.0746
B14: Discount Factor | D14: 1 | E14: =D14+1 -> 2 | F14: =E14+1 -> 3 | G14: =F14+1 -> 4 | H14: =G14+1 -> 5 | I14: =H14+1 -> 6 | J14: =I14+1 -> 7 | K14: =J14+1 -> 8 | L14: =K14+1 -> 9
B15: Discounted FCF | D15: =D11/((1+D13)^D14) -> 4653.0878 | E15: =E11/((1+E13)^E14) -> 4707.907 | F15: =F11/((1+F13)^F14) -> 4760.2081 | G15: =G11/((1+G13)^G14) -> 4753.8709 | H15: =H11/((1+H13)^H14) -> 4719.8797 | I15: =I11/((1+I13)^I14) -> 4645.5953 | J15: =J11/((1+J13)^J14) -> 4532.5818 | K15: =K11/((1+K13)^K14) -> 4383.39 | L15: =L11/((1+L13)^L14) -> 4201.4626 | M15: =SUM(C15:L15) -> 41357.983
B18: DCF Valuation
B19: Risk free rate | C19: % | D19: 0.035
B20: Equity Risk premium | C20: % | D20: 0.045
B22: Beta | C22: x | D22: 0.88
B23: Cost of equity | C23: % | D23: =D19+D22*(D20) -> 0.0746
B25: Cost of debt | C25: % | D25: 0.04
B26: Tax | C26: % | D26: =C6 -> 0.25
B27: Post tax cost of debt | C27: % | D27: =D25*(1-D26) -> 0.03
B29: MV Equity / (MV Equity + Net Debt) | C29: % | D29: 1
B30: Net Debt / (MV Equity + Net Debt) | C30: % | D30: 0
B32: WACC | C32: % | D32: =(D23*D29)+(D30*D27) -> 0.0746
B33: Terminal growth rate | C33: % | D33: 0.03
B35: DCF Valuation
B36: Sum of discounted cash flows | C36: EUR (mn) | D36: =M15 -> 41357.983
B37: Undiscounted value of TV | C37: EUR (mn) | D37: =L11/(D32-D33) -> 180006.08
B38: Discounted value of TV | C38: EUR (mn) | D38: =D37/(1+L13)^L14 -> 94203.196
B39: Enterprise value | C39: EUR (mn) | D39: =D36+D38 -> 135561.18
B40: Net cash (debt) and lease | C40: EUR (mn) | D40: ='DCF Feed'!C8 -> 3593.3944
B41: Pension underfunding | C41: EUR (mn) | D41: ='DCF Feed'!C9 -> -23
B42: Pension tax shield | C42: EUR (mn) | D42: =-D41*(D26) -> 5.75
B43: Equity value | C43: EUR (mn) | D43: =SUM(D39:D42) -> 139137.32
B44: Number of shares | C44: million | D44: ='DCF Feed'!C12 -> 411.74891
B45: Equity value per share | C45: EUR | D45: =ROUND(D43/D44,-1) -> 340

Sheet Sheet5

Sheet Sheet4

Sheet MigrationOutput_QP_SAF.PA
B2: Congratulations! You have successfully migrated | F2: =HYPERLINK("[cleanSafran model WIP.xlsx]SAF.PA_Exchange_Sheet!$A$1","SAF.PA_Exchange_Sheet") -> SAF.PA_Exchange_Sheet
B3: Please review non-migrated data on: | F3: =HYPERLINK("[cleanSafran model WIP.xlsx]QP_SAF.PA_migrated!$A$1","QP_SAF.PA_migrated") -> QP_SAF.PA_migrated
B5: Final cleanup Items
B6: Keyword | C6: Description | E6: Action

Sheet QP_SAF.PA_migrated
A1: Quantum submission sheet for SAF.PA | F1: 1998 | G1: 1999 | H1: 2000 | I1: 2001 | J1: 2002 | K1: 2003 | L1: 2004 | M1: 2005 | N1: 2006 H1 | O1: 2006 H2 | P1: 2006 | Q1: 2007 H1 | R1: 2007 H2 | S1: 2007 | T1: 2008 H1 | U1: 2008 H2 | V1: 2008 | W1: 2009 H1 | X1: 2009 H2 | Y1: 2009 | Z1: 2010 H1 | AA1: 2010 H2 | AB1: 2010 | AC1: 2011 H1 | AD1: 2011 H2 | AE1: 2011 | AF1: 2012 | AG1: 2013 | AH1: 2014 | AI1: 2015 | AJ1: 2016 | AK1: 2017 | AL1: 2018 | AM1: 2019 | AN1: 2020
F2: Actual | G2: Actual | H2: Actual | I2: Actual | J2: Actual | K2: Actual | L2: Actual | M2: Actual | N2: Actual | O2: Actual | P2: Actual | Q2: Actual | R2: Actual | S2: Actual | T2: Actual | U2: Actual | V2: Actual | W2: Actual | X2: Actual | Y2: Actual | Z2: Actual | AA2: Actual | AB2: Actual | AC2: Actual | AD2: Actual | AE2: Actual | AF2: Actual | AG2: Estimate | AH2: Estimate | AI2: Estimate | AJ2: Estimate | AK2: Estimate | AL2: Estimate | AM2: Estimate | AN2: Estimate
F3: 36160 | G3: 36525 | H3: 36891 | I3: 37256 | J3: 37621 | K3: 37986 | L3: 38352 | M3: 38717 | N3: 38898 | O3: 39082 | P3: 39082 | Q3: 39263 | R3: 39447 | S3: 39447 | T3: 39629 | U3: 39813 | V3: 39813 | W3: 39994 | X3: 40178 | Y3: 40178 | Z3: 40359 | AA3: 40543 | AB3: 40543 | AC3: 40724 | AD3: 40908 | AE3: 40908 | AF3: 41274 | AG3: 41639 | AH3: 42004 | AI3: 42369 | AJ3: 42735 | AK3: 43100 | AL3: 43465 | AM3: 43830 | AN3: 44196
A5: Reference data | D5: #0
B6: Ticker | C6: Ticker_1 | E6: SAF.PA
B7: Company name | C7: Company name | E7: Safran
B8: Interim type | C8: Interim type | E8: Semiannual
B9: Reporting currency | C9: Reporting currency | E9: EUR
B10: Publishing currency | C10: Publishing currency | E10: EUR
B11: Pricing currency | C11: Pricing currency_1 | E11: EUR
A13: General Information | D13: #10
B14: Pan Europe Investment List | C14: EURO_LIST
B15: Pan Europe Conviction List | C15: EURO_CONVICTION
B16: Legal rating | C16: LEGAL_RATING
B17: Target price | C17: TARGET_PRICE | D17: EUR
B18: Target price period | C18: TP_PERIOD
B19: Current shares outstanding (mn) | C19: NUM_SH1
B20: Free float | C20: FREE_FLOAT
A22: Publishing Items | D22: #20
B23: Book value per share, BVPS (Pub) | C23: BVPS_PUB | D23: EUR | AK23: =AK116/AK75 -> #REF! | AL23: =AL116/AL75 -> #REF! | AM23: =AM116/AM75 -> #REF! | AN23: =AN116/AN75 -> #REF!
B24: DPS, dividend per share (Pub) | C24: DPS_PUB | D24: EUR | AK24: =#REF! -> #REF! | AL24: =#REF! -> #REF! | AM24: =#REF! -> #REF! | AN24: =#REF! -> #REF!
B25: EBITDA (Pub) | C25: EBITDA_PUB | D25: EUR | AK25: =#REF! -> #REF! | AL25: =#REF! -> #REF! | AM25: =#REF! -> #REF! | AN25: =#REF! -> #REF! | AO25: CH: GS A&D standard EBITDA (company defined underlying EBIT exclusing any additional depreciation, amortisation or impairments)
B26: EPS (Pub) | C26: EPS_PUB | D26: EUR | AK26: =#REF! -> #REF! | AL26: =#REF! -> #REF! | AM26: =#REF! -> #REF! | AN26: =#REF! -> #REF!
B27: EV adjustment (Pub) | C27: EV_ADJ_PUB | D27: EUR
B28: Long-term EPS growth estimate (Pub)
B29: Net debt (Pub) | C29: NET_DEBT_PUB | D29: EUR | AK29: =#REF! -> #REF! | AL29: =#REF! -> #REF! | AM29: =#REF! -> #REF! | AN29: =#REF! -> #REF!
B30: Net income (Pub) | C30: NI_PUB | D30: EUR | AK30: =#REF! -> #REF! | AL30: =#REF! -> #REF! | AM30: =#REF! -> #REF! | AN30: =#REF! -> #REF!
B31: EBIT, operating profit (Pub) | C31: EBIT_PUB | D31: EUR | AK31: =#REF! -> #REF! | AL31: =#REF! -> #REF! | AM31: =#REF! -> #REF! | AN31: =#REF! -> #REF!
B32: Pre-tax profit (Pub) | C32: PTP_PUB | D32: EUR | AK32: =#REF! -> #REF! | AL32: =#REF! -> #REF! | AM32: =#REF! -> #REF! | AN32: =#REF! -> #REF!
B33: Sales, revenue (Pub) | C33: REVS_PUB | D33: EUR | AK33: =#REF! -> #REF! | AL33: =#REF! -> #REF! | AM33: =#REF! -> #REF! | AN33: =#REF! -> #REF!
B34: Total shareholders' equity (Pub) | C34: EQ_PUB | D34: EUR | AK34: =AK116 -> #REF! | AL34: =AL116 -> #REF! | AM34: =AM116 -> #REF! | AN34: =AN116 -> #REF!
A36: Other & Corporate Income Statement | D36: #29
B37: EBITDA (Pub) | D37: EUR | M37: 724
B38: Pre-tax profit (Pub) | D38: EUR | M38: 383
B39: Net income (Pub) | D39: EUR | M39: 279.96755
B40: EPS (Pub) | D40: EUR | M40: 0.68399457
A42: Income Statement | D42: #30
B43: Sales, net revenue | C43: SALES | D43: EUR | AK43: =#REF! -> #REF! | AL43: =#REF! -> #REF! | AM43: =#REF! -> #REF! | AN43: =#REF! -> #REF!
B44: Cost of goods sold, COGS | C44: COST_GD_SD | D44: EUR
B45: SG&A, selling, general and admin. expense | C45: SEL_GL_AD | D45: EUR
...

Sheet DCF
B1: =C34 -> 309 | Z1: SAF.PA
B2: Valuation date | C2: 45918
B3: Explicit growth (EBIT) | C3: ='DCF Feed'!H4 -> 0.10989743
B4: Mid-term growth | C4: 0.1
B5: Long term growth | C5: 0.03
B6: Discount rate | C6: 0.09
B7: Tax rate | C7: =-'DCF Feed'!E10 -> 0.25
B8: Cash conversion | C8: 1.05
B9: EV/EBIT | C9: =N19*(1-C7) -> 23.443403
B12: Calendar year | C12: =YEAR(TODAY()) -> 2025 | D12: =C12+1 -> 2026 | E12: =D12+1 -> 2027 | F12: =E12+1 -> 2028 | G12: =F12+1 -> 2029 | H12: =G12+1 -> 2030 | I12: =H12+1 -> 2031 | J12: =I12+1 -> 2032 | K12: =J12+1 -> 2033 | ... M12: =L12+1 -> 2035 | N12: Terminal value
C13: 0 | D13: =C13+1 -> 1 | E13: =D13+1 -> 2 | F13: =E13+1 -> 3 | G13: =F13+1 -> 4 | H13: =G13+1 -> 5 | I13: =H13+1 -> 6 | J13: =I13+1 -> 7 | K13: =J13+1 -> 8 | ... M13: =L13+1 -> 10
B14: =C2+365 -> 46283 | C14: 45809 | D14: =C14+365 -> 46174 | E14: =D14+365 -> 46539 | F14: =E14+365 -> 46904 | G14: =F14+365 -> 47269 | H14: =G14+365 -> 47634 | I14: =H14+365 -> 47999 | J14: =I14+365 -> 48364 | K14: =J14+365 -> 48729 | ... M14: =L14+365 -> 49459
B15: Cumulative growth | C15: 1 | D15: =C15*(1+D16) -> 1.1775451 | E15: =D15*(1+E16) -> 1.3379137 | F15: =E15*(1+F16) -> 1.4764201 | G15: =F15*(1+G16) -> 1.5786428 | H15: =C15*(1+C3)^5 -> 1.6842798 | I15: =H15*(1+I16) -> 1.8527078 | J15: =I15*(1+J16) -> 2.0055562 | K15: =J15*(1+K16) -> 2.1359173 | L15: =K15*(1+L16) -> 2.2373734 | M15: =L15*(1+M16) -> 2.3044946 | N15: =M15/(C6-C5) -> 38.408243
B16: Annual growth | D16: =INDEX('DCF Feed'!5:5,MATCH(DCF!D12,'DCF Feed'!1:1,0)) -> 0.1775451 | E16: =INDEX('DCF Feed'!5:5,MATCH(DCF!E12,'DCF Feed'!1:1,0)) -> 0.13618897 | F16: =INDEX('DCF Feed'!5:5,MATCH(DCF!F12,'DCF Feed'!1:1,0)) -> 0.10352412 | G16: =INDEX('DCF Feed'!5:5,MATCH(DCF!G12,'DCF Feed'!1:1,0)) -> 0.069236834 | H16: =INDEX('DCF Feed'!5:5,MATCH(DCF!H12,'DCF Feed'!1:1,0)) -> 0.066916368 | I16: =$C$4 -> 0.1 | J16: =I16+(($M$16-$I$16)/4) -> 0.0825 | K16: =J16+(($M$16-$I$16)/4) -> 0.065 | L16: =K16+(($M$16-$I$16)/4) -> 0.0475 | M16: =$C$5 -> 0.03
B17: Cash conversion | D17: =INDEX('DCF Feed'!7:7,MATCH(DCF!D12,'DCF Feed'!1:1,0)) -> 0.96065356 | E17: =INDEX('DCF Feed'!7:7,MATCH(DCF!E12,'DCF Feed'!1:1,0)) -> 0.97047348 | F17: =INDEX('DCF Feed'!7:7,MATCH(DCF!F12,'DCF Feed'!1:1,0)) -> 0.958557 | G17: =INDEX('DCF Feed'!7:7,MATCH(DCF!G12,'DCF Feed'!1:1,0)) -> 0.96911592 | H17: =INDEX('DCF Feed'!7:7,MATCH(DCF!H12,'DCF Feed'!1:1,0)) -> 0.97251994 | I17: =$C$8 -> 1.05 | J17: =$C$8 -> 1.05 | K17: =$C$8 -> 1.05 | L17: =$C$8 -> 1.05 | M17: =$C$8 -> 1.05
B18: Discounted value | D18: =1/(1+$C$6)^((D14-$B$14)/365) -> 1.0260693 | E18: =1/(1+$C$6)^((E14-$B$14)/365) -> 0.94134795 | F18: =1/(1+$C$6)^((F14-$B$14)/365) -> 0.86362197 | G18: =1/(1+$C$6)^((G14-$B$14)/365) -> 0.79231374 | H18: =1/(1+$C$6)^((H14-$B$14)/365) -> 0.72689334 | I18: =1/(1+$C$6)^((I14-$B$14)/365) -> 0.66687462 | J18: =1/(1+$C$6)^((J14-$B$14)/365) -> 0.61181158 | K18: =1/(1+$C$6)^((K14-$B$14)/365) -> 0.56129503 | ... M18: =1/(1+$C$6)^((M14-$B$14)/365) -> 0.47243079
B19: PV | D19: =D15*D17*D18 -> 1.1607028 | E19: =E15*E17*E18 -> 1.2222554 | F19: =F15*F17*F18 -> 1.2222262 | G19: =G15*G17*G18 -> 1.2121511 | H19: =H15*H17*H18 -> 1.1906481 | I19: =I15*I17*I18 -> 1.2973 | J19: =J15*J17*J18 -> 1.2883736 | K19: =K15*K17*K18 -> 1.2588238 | L19: =L15*L17*L18 -> 1.2097412 | M19: =(M15+N15)*M17*M18 -> 20.195649 | N19: =SUM(D19:M19) -> 31.257871
B24: Year | C24: =C12 -> 2025
B25: Target EV/EBIT | C25: =C9 -> 23.443403
B26: EBIT | C26: =INDEX('DCF Feed'!4:4,MATCH(DCF!$C$24,'DCF Feed'!$1:$1,0)) -> 5217.0943
B27: Target EV | C27: =C25*C26 -> 122306.44
B28: Net Cash (Debt) | C28: ='DCF Feed'!B8 -> 2263.3518
B29: Other
B30: Pension underfunding | C30: =INDEX('DCF Feed'!9:9,MATCH(DCF!C24,'DCF Feed'!1:1,0)) -> -23
B31: Pension tax shield | C31: =-C30*C7 -> 5.75
B32: Target Market Cap | C32: =SUM(C27:C31) -> 124552.55
B33: Number of shares | C33: ='DCF Feed'!E12 -> 402.77548
B34: Target price | C34: =MROUND(C32/C33,1) -> 309
B35: Current Share Price | C35: Error: RTD method of WorksheetFunction class failed
B36: Upside/(Downside) | C36: =C34/C35-1 -> #VALUE!
B39: Share Price | D39: WACC
C40: =$C$34 -> 309 | D40: =E40-0.5% -> 0.08 | E40: =F40-0.5% -> 0.085 | F40: 0.09 | G40: =F40+0.5% -> 0.095 | H40: =G40+0.5% -> 0.1
B41: 5Yr EBIT CAGR | C41: =C42-2% -> 0.0639199 | D41: 309 | E41: 282 | F41: 260 | G41: 241 | H41: 225
C42: =C43-2% -> 0.0839199 | D42: 334 | E42: 305 | F42: 281 | G42: 260 | H42: 242
B43: Explicit PROF Grow | C43: 0.1039199 | D43: 361 | E43: 329 | F43: 302 | G43: 280 | H43: 261
C44: =C43+2% -> 0.1239199 | D44: 390 | E44: 355 | F44: 326 | G44: 301 | H44: 280
C45: =C44+2% -> 0.1439199 | D45: 421 | E45: 383 | F45: 351 | G45: 324 | H45: 301
D48: Cash Conversion Ratio | F48: CC
C49: =$C$34 -> 309 | D49: =E49-10% -> 0.85 | E49: =F49-10% -> 0.95 | F49: 1.05 | G49: =F49+10% -> 1.15 | H49: =G49+10% -> 1.25
B50: 5Yr EBIT CAGR | C50: =C51-3% -> 0.0439199 | D50: 207 | E50: 224 | F50: 241 | G50: 259 | H50: 276
...

Sheet DCF Feed
A1: €mn | B1: 2025 | C1: =B1+1 -> 2026 | D1: =C1+1 -> 2027 | E1: =D1+1 -> 2028 | F1: =E1+1 -> 2029 | G1: =F1+1 -> 2030 | H1: 5yr. CAGR
A2: Sales | B2: =INDEX('Income Statement'!39:39,MATCH(B1,'Income Statement'!38:38,0)) -> 31556.569 | C2: =INDEX('Income Statement'!39:39,MATCH(C1,'Income Statement'!38:38,0)) -> 35653.732 | D2: =INDEX('Income Statement'!39:39,MATCH(D1,'Income Statement'!38:38,0)) -> 39232.543 | E2: =INDEX('Income Statement'!39:39,MATCH(E1,'Income Statement'!38:38,0)) -> 42282.093 | F2: =INDEX('Income Statement'!39:39,MATCH(F1,'Income Statement'!38:38,0)) -> 44620.651 | G2: =INDEX('Income Statement'!39:39,MATCH(G1,'Income Statement'!38:38,0)) -> 46787.067 | H2: =(G2/B2)^(1/5)-1 -> 0.081950044
A3: Sales growth | C3: =C2/B2-1 -> 0.12983551 | D3: =D2/C2-1 -> 0.10037691 | E3: =E2/D2-1 -> 0.077730101 | F3: =F2/E2-1 -> 0.055308477 | G3: =G2/F2-1 -> 0.048551861
A4: Adj. EBIT | B4: =INDEX('Income Statement'!74:74,MATCH(B1,'Income Statement'!$38:$38,0)) -> 5217.0943 | C4: =INDEX('Income Statement'!74:74,MATCH(C1,'Income Statement'!$38:$38,0)) -> 6143.3638 | D4: =INDEX('Income Statement'!74:74,MATCH(D1,'Income Statement'!$38:$38,0)) -> 6980.0222 | E4: =INDEX('Income Statement'!74:74,MATCH(E1,'Income Statement'!$38:$38,0)) -> 7702.6228 | F4: =INDEX('Income Statement'!74:74,MATCH(F1,'Income Statement'!$38:$38,0)) -> 8235.9281 | G4: =INDEX('Income Statement'!74:74,MATCH(G1,'Income Statement'!$38:$38,0)) -> 8787.0465 | H4: =(G4/B4)^(1/5)-1 -> 0.10989743
A5: Growth | C5: =C4/B4-1 -> 0.1775451 | D5: =D4/C4-1 -> 0.13618897 | E5: =E4/D4-1 -> 0.10352412 | F5: =F4/E4-1 -> 0.069236834 | G5: =G4/F4-1 -> 0.066916368
A6: GS Defined Op Cash Flow | B6: =INDEX('Cashflow Statement'!71:71, MATCH('DCF Feed'!B1,'Cashflow Statement'!2:2,0)) -> 4875.1458 | C6: =INDEX('Cashflow Statement'!71:71, MATCH('DCF Feed'!C1,'Cashflow Statement'!2:2,0)) -> 5901.6443 | D6: =INDEX('Cashflow Statement'!71:71, MATCH('DCF Feed'!D1,'Cashflow Statement'!2:2,0)) -> 6773.9264 | E6: =INDEX('Cashflow Statement'!71:71, MATCH('DCF Feed'!E1,'Cashflow Statement'!2:2,0)) -> 7383.403 | F6: =INDEX('Cashflow Statement'!71:71, MATCH('DCF Feed'!F1,'Cashflow Statement'!2:2,0)) -> 7981.569 | G6: =INDEX('Cashflow Statement'!71:71, MATCH('DCF Feed'!G1,'Cashflow Statement'!2:2,0)) -> 8545.5779 | H6: =(G6/B6)^(1/5)-1 -> 0.11879564
A7: Cash Conversion | B7: =B6/B4 -> 0.93445614 | C7: =C6/C4 -> 0.96065356 | D7: =D6/D4 -> 0.97047348 | E7: =E6/E4 -> 0.958557 | F7: =F6/F4 -> 0.96911592 | G7: =G6/G4 -> 0.97251994 | H7: =AVERAGE(B7:G7) -> 0.96096268
A8: Net Cash (Debt) | B8: =INDEX('Balance Sheet'!$93:$93,MATCH('DCF Feed'!B1,'Balance Sheet'!$88:$88,0)) -> 2263.3518 | C8: =INDEX('Balance Sheet'!93:93,MATCH('DCF Feed'!C1,'Balance Sheet'!88:88,0)) -> 3593.3944 | D8: =INDEX('Balance Sheet'!93:93,MATCH('DCF Feed'!D1,'Balance Sheet'!88:88,0)) -> 5128.5417 | E8: =INDEX('Balance Sheet'!93:93,MATCH('DCF Feed'!E1,'Balance Sheet'!88:88,0)) -> 7063.3546 | F8: =INDEX('Balance Sheet'!93:93,MATCH('DCF Feed'!F1,'Balance Sheet'!88:88,0)) -> 10517.022 | G8: =INDEX('Balance Sheet'!93:93,MATCH('DCF Feed'!G1,'Balance Sheet'!88:88,0)) -> 14268.618
A9: Pension underfunding | B9: =INDEX('Balance Sheet'!$140:$140,MATCH('DCF Feed'!B1,'Balance Sheet'!$88:$88,0)) -> -23 | C9: =INDEX('Balance Sheet'!$140:$140,MATCH('DCF Feed'!C1,'Balance Sheet'!$88:$88,0)) -> -23 | D9: =INDEX('Balance Sheet'!$140:$140,MATCH('DCF Feed'!D1,'Balance Sheet'!$88:$88,0)) -> -23 | E9: =INDEX('Balance Sheet'!$140:$140,MATCH('DCF Feed'!E1,'Balance Sheet'!$88:$88,0)) -> -23 | F9: =INDEX('Balance Sheet'!$140:$140,MATCH('DCF Feed'!F1,'Balance Sheet'!$88:$88,0)) -> -23 | G9: =INDEX('Balance Sheet'!$140:$140,MATCH('DCF Feed'!G1,'Balance Sheet'!$88:$88,0)) -> -23
A10: Tax rate (adjusted) | B10: =INDEX('Income Statement'!91:91,MATCH(B1,'Income Statement'!$38:$38,0)) -> -0.32 | C10: =INDEX('Income Statement'!91:91,MATCH(C1,'Income Statement'!$38:$38,0)) -> -0.25 | D10: =INDEX('Income Statement'!91:91,MATCH(D1,'Income Statement'!$38:$38,0)) -> -0.25 | E10: =INDEX('Income Statement'!91:91,MATCH(E1,'Income Statement'!$38:$38,0)) -> -0.25 | F10: =INDEX('Income Statement'!91:91,MATCH(F1,'Income Statement'!$38:$38,0)) -> -0.25 | G10: =INDEX('Income Statement'!91:91,MATCH(G1,'Income Statement'!$38:$38,0)) -> -0.25
A11: Other
A12: No. of shares | B12: =INDEX('Income Statement'!117:117,MATCH(B1,'Income Statement'!$38:$38,0))/1000 -> 416.23563 | C12: =INDEX('Income Statement'!117:117,MATCH(C1,'Income Statement'!$38:$38,0))/1000 -> 411.74891 | D12: =INDEX('Income Statement'!117:117,MATCH(D1,'Income Statement'!$38:$38,0))/1000 -> 407.2622 | E12: =INDEX('Income Statement'!117:117,MATCH(E1,'Income Statement'!$38:$38,0))/1000 -> 402.77548 | F12: =INDEX('Income Statement'!117:117,MATCH(F1,'Income Statement'!$38:$38,0))/1000 -> 402.77548 | G12: =INDEX('Income Statement'!117:117,MATCH(G1,'Income Statement'!$38:$38,0))/1000 -> 402.77548

Sheet Income Statement
A1: ='DCF Valuation'!D45 -> 340
A2: Divisional Summary
A3: Revenues | B3: =B38 -> 2000 | C3: =C38 -> 2001 | D3: =D38 -> 2002 | E3: =E38 -> 2003 | F3: =F38 -> 2004 | G3: =G38 -> 2005 | H3: =H38 -> 2006 | I3: =I38 -> 2007 | ... Z3: =Z38 -> 2024 | AA3: =Z3+1 -> 2025 | AB3: =AA3+1 -> 2026 | AC3: =AB3+1 -> 2027 | AD3: =AC3+1 -> 2028 | AE3: =AD3+1 -> 2029 | AF3: =AE3+1 -> 2030
A4: Adjusted Revenues
A5: Aerospace Propulsion | H5: 5073 | I5: 5917 | J5: 5803 | K5: 5673 | L5: 5604 | M5: 6110 | N5: 7005 | O5: ='Aerospace Propulsion Division'!O6 -> 7589 | P5: ='Aerospace Propulsion Division'!P6 -> 8153 | Q5: ='Aerospace Propulsion Division'!Q6 -> 9319 | R5: ='Aerospace Propulsion Division'!R6 -> 9391 | S5: ='Aerospace Propulsion Division'!S6 -> 9357 | T5: ='Aerospace Propulsion Division'!T6 -> 10579 | U5: ='Aerospace Propulsion Division'!U6 -> 12045 | V5: ='Aerospace Propulsion Division'!V6 -> 7663 | ... Z5: ='Aerospace Propulsion Division'!Z6 -> 13652 | AA5: =Z5*(1+AA12) -> 15834.377 | AB5: =AA5*(1+AB12) -> 17806.597 | AC5: =AB5*(1+AC12) -> 19932.222 | AD5: =AC5*(1+AD12) -> 21615.123 | AE5: =AD5*(1+AE12) -> 22915.426 | AF5: =AE5*(1+AF12) -> 24191.629
A6: Equipment & Defense | T6: ='Equipment and Defense'!T6 -> 7942 | U6: ='Equipment and Defense'!U6 -> 9256 | V6: ='Equipment and Defense'!V6 -> 6893 | W6: ='Equipment and Defense'!W6 -> 6325 | X6: ='Equipment and Defense'!X6 -> 7535 | Y6: ='Equipment and Defense'!Y6 -> 8835 | Z6: ='Equipment and Defense'!Z6 -> 10618 | AA6: =Z6*(1+AA13) -> 12288.332 | AB6: =AA6*(1+AB13) -> 14054.01 | AC6: =AB6*(1+AC13) -> 15155.733 | AD6: =AC6*(1+AD13) -> 16185.108 | AE6: =AD6*(1+AE13) -> 17078.608 | AF6: =AE6*(1+AF13) -> 17837.766
A7: Aircraft Interiors | T7: ='Aircraft Interiors Division'!H6 -> 2511 | U7: ='Aircraft Interiors Division'!I6 -> 3321 | V7: ='Aircraft Interiors Division'!J6 -> 1922 | W7: ='Aircraft Interiors Division'!K6 -> 1475 | X7: ='Aircraft Interiors Division'!L6 -> 1978 | Y7: ='Aircraft Interiors Division'!M6 -> 2477 | Z7: ='Aircraft Interiors Division'!N6 -> 3037 | AA7: =Z7*(1+AA14) -> 3423.86 | AB7: =AA7*(1+AB14) -> 3783.125 | AC7: =AB7*(1+AC14) -> 4134.5881 | AD7: =AC7*(1+AD14) -> 4471.8616 | AE7: =AD7*(1+AE14) -> 4616.6169 | AF7: =AE7*(1+AF14) -> 4747.6719
A8: Other | H8: =H9-H5 -> 6256 | I8: =I9-I5 -> 4305 | J8: =J9-J5 -> 4526 | K8: =K9-K5 -> 4775 | L8: =L9-L5 -> 5156 | M8: =M9-M5 -> 5626 | N8: =N9-N5 -> 6555 | O8: =O9-O5 -> 6774 | ... S8: =S9-S5 -> 6596 | T8: 18 | U8: 18 | V8: 20 | W8: 18 | X8: 16 | Y8: 11 | Z8: 10 | AA8: =Z8 -> 10 | AB8: =AA8 -> 10 | AC8: =AB8 -> 10 | AD8: =AC8 -> 10 | AE8: =AD8 -> 10 | AF8: =AE8 -> 10
A9: Group | H9: 11329 | I9: 10222 | J9: 10329 | K9: 10448 | L9: 10760 | M9: 11736 | N9: 13560 | O9: 14363 | P9: 15355 | Q9: 17414 | R9: 15781 | S9: 15953 | T9: =SUM(T5,T6,T7,T8) -> 21050 | U9: =SUM(U5,U6,U7,U8) -> 24640 | V9: =SUM(V5,V6,V7,V8) -> 16498 | W9: =SUM(W5,W6,W7,W8) -> 15257 | X9: =SUM(X5,X6,X7,X8) -> 19035 | Y9: =SUM(Y5,Y6,Y7,Y8) -> 23199 | Z9: =SUM(Z5,Z6,Z7,Z8) -> 27317 | AA9: =SUM(AA5,AA6,AA7,AA8) -> 31556.569 | ... AF9: =SUM(AF5,AF6,AF7,AF8) -> 46787.067
A11: Revenue Growth
A12: Aerospace Propulsion | I12: =I5/H5-1 -> 0.16637098 | J12: =J5/I5-1 -> -0.01926652 | K12: =K5/J5-1 -> -0.022402206 | L12: =L5/K5-1 -> -0.012162877 | M12: =M5/L5-1 -> 0.090292648 | N12: =N5/M5-1 -> 0.14648118 | O12: =O5/N5-1 -> 0.083369022 | P12: =P5/O5-1 -> 0.074318092 | ... Z12: =Z5/Y5-1 -> 0.1495453 | AA12: ='Aerospace Propulsion Division'!AA7 -> 0.15985768 | AB12: ='Aerospace Propulsion Division'!AB7 -> 0.12455304 | AC12: ='Aerospace Propulsion Division'!AC7 -> 0.11937292 | AD12: ='Aerospace Propulsion Division'!AD7 -> 0.084431186 | AE12: ='Aerospace Propulsion Division'!AE7 -> 0.060157086 | AF12: ='Aerospace Propulsion Division'!AF7 -> 0.055691852
A13: Equipment & Defense | U13: =U6/T6-1 -> 0.16544951 | V13: =V6/U6-1 -> -0.25529386 | W13: =W6/V6-1 -> -0.082402437 | X13: =X6/W6-1 -> 0.19130435 | Y13: =Y6/X6-1 -> 0.1725282 | Z13: =Z6/Y6-1 -> 0.20181098 | AA13: ='Equipment and Defense'!AA7 -> 0.15731132 | AB13: ='Equipment and Defense'!AB7 -> 0.1436874 | AC13: ='Equipment and Defense'!AC7 -> 0.078392078 | AD13: ='Equipment and Defense'!AD7 -> 0.067919832 | AE13: ='Equipment and Defense'!AE7 -> 0.05520507 | AF13: ='Equipment and Defense'!AF7 -> 0.04445082
A14: Aircraft Interiors | U14: =U7/T7-1 -> 0.32258065 | V14: =V7/U7-1 -> -0.42125866 | W14: =W7/V7-1 -> -0.23257024 | X14: =X7/W7-1 -> 0.34101695 | Y14: =Y7/X7-1 -> 0.25227503 | Z14: =Z7/Y7-1 -> 0.22607994 | AA14: ='Aircraft Interiors Division'!O7 -> 0.12738229 | AB14: ='Aircraft Interiors Division'!P7 -> 0.10492982 | AC14: ='Aircraft Interiors Division'!Q7 -> 0.092902847 | AD14: ='Aircraft Interiors Division'!R7 -> 0.081573672 | AE14: ='Aircraft Interiors Division'!S7 -> 0.032370256 | AF14: ='Aircraft Interiors Division'!T7 -> 0.028387668
A15: Other | K15: =K8/J8-1 -> 0.055015466 | L15: =L8/K8-1 -> 0.079790576 | M15: =M8/L8-1 -> 0.091155935 | N15: =N8/M8-1 -> 0.1651262 | O15: =O8/N8-1 -> 0.033409611 | P15: =P8/O8-1 -> 0.063182758 | Q15: =Q8/P8-1 -> 0.12399334 | R15: =R8/Q8-1 -> -0.21062384 | ... AF15: =AF8/AE8-1 -> 0
A16: Group | I16: =I9/H9-1 -> -0.097713832 | J16: =J9/I9-1 -> 0.010467619 | K16: =K9/J9-1 -> 0.01152096 | L16: =L9/K9-1 -> 0.029862175 | M16: =M9/L9-1 -> 0.09070632 | N16: =N9/M9-1 -> 0.15541922 | O16: =O9/N9-1 -> 0.059218289 | P16: =P9/O9-1 -> 0.069066351 | ... AF16: =AF9/AE9-1 -> 0.048551861
A18: Adj. EBIT
A19: Aerospace Propulsion | H19: 561 | I19: 636 | J19: 584 | K19: 628 | L19: 663 | M19: 909 | N19: 1076 | O19: ='Aerospace Propulsion Division'!O19 -> 0 | P19: ='Aerospace Propulsion Division'!P19 -> 0 | Q19: ='Aerospace Propulsion Division'!Q19 -> 0 | R19: ='Aerospace Propulsion Division'!R19 -> 0 | S19: 1516 | T19: ='Aerospace Propulsion Division'!T19 -> 2030 | U19: ='Aerospace Propulsion Division'!U19 -> 2485 | V19: ='Aerospace Propulsion Division'!V19 -> 1192 | W19: ='Aerospace Propulsion Division'!W19 -> 1342 | X19: ='Aerospace Propulsion Division'!X19 -> 1710 | Y19: ='Aerospace Propulsion Division'!Y19 -> 2390 | Z19: ='Aerospace Propulsion Division'!Z19 -> 2819 | AA19: =AA5*AA26 -> 3573.1909 | AB19: =AB5*AB26 -> 4022.7156 | AC19: =AC5*AC26 -> 4530.2242 | AD19: =AD5*AD26 -> 4955.689 | AE19: =AE5*AE26 -> 5298.5022 | AF19: =AF5*AF26 -> 5689.8015
A20: Equipment & Defense | S20: 619 | T20: ='Equipment and Defense'!T14 -> 992 | U20: ='Equipment and Defense'!U14 -> 1209 | V20: ='Equipment and Defense'!V14 -> 687 | W20: ='Equipment and Defense'!W14 -> 650 | X20: ='Equipment and Defense'!X14 -> 874 | Y20: ='Equipment and Defense'!Y14 -> 992 | Z20: ='Equipment and Defense'!Z14 -> 1298 | AA20: =AA6*AA27 -> 1566.0906 | AB20: =AB6*AB27 -> 1952.7463 | AC20: =AC6*AC27 -> 2176.3225 | AD20: =AD6*AD27 -> 2384.4683 | AE20: =AE6*AE27 -> 2546.349 | AF20: =AF6*AF27 -> 2693.8536
A21: Aircraft Interiors | S21: 93 | T21: ='Aircraft Interiors Division'!H19 -> 81 | U21: ='Aircraft Interiors Division'!I19 -> 188 | V21: ='Aircraft Interiors Division'!J19 -> -174 | W21: ='Aircraft Interiors Division'!K19 -> -167 | X21: ='Aircraft Interiors Division'!L19 -> -140 | Y21: ='Aircraft Interiors Division'!M19 -> -116 | Z21: ='Aircraft Interiors Division'!N19 -> 27 | AA21: =AA7*AA28 -> 106.69282 | AB21: =AB7*AB28 -> 200.53141 | AC21: =AC7*AC28 -> 309.38034 | AD21: =AD7*AD28 -> 401.1613 | AE21: =AE7*AE28 -> 431.91276 | AF21: =AF7*AF28 -> 446.20993
A22: Other | H22: -16 | I22: -23 | J22: 82 | K22: -67 | L22: -95 | M22: -119 | N22: -142 | O22: -158 | P22: -175 | Q22: -82 | R22: -25 | S22: -36 | T22: -80 | U22: -62 | V22: -19 | W22: -20 | X22: -36 | Y22: -100 | Z22: -25 | AA22: =Z22*(AA9/Z9) -> -28.879973 | AB22: =AA22*(AB9/AA9) -> -32.629619 | AC22: =AB22*(AC9/AB9) -> -35.904879 | AD22: =AC22*(AD9/AC9) -> -38.695769 | AE22: =AD22*(AE9/AD9) -> -40.835973 | AF22: =AE22*(AF9/AE9) -> -42.818635
A23: Group | H23: =SUM(H19:H22) -> 545 | I23: =SUM(I19:I22) -> 613 | J23: =SUM(J19:J22) -> 666 | K23: =SUM(K19:K22) -> 561 | L23: =SUM(L19:L22) -> 568 | M23: =SUM(M19:M22) -> 790 | N23: =SUM(N19:N22) -> 934 | O23: =SUM(O19:O22) -> -158 | ... S23: =SUM(S19:S22) -> 2192 | T23: =SUM(T19,T20,T21,T22) -> 3023 | U23: =SUM(U19,U20,U21,U22) -> 3820 | V23: =SUM(V19,V20,V21,V22) -> 1686 | W23: =SUM(W19,W20,W21,W22) -> 1805 | X23: =SUM(X19,X20,X21,X22) -> 2408 | Y23: =SUM(Y19,Y20,Y21,Y22) -> 3166 | Z23: =SUM(Z19,Z20,Z21,Z22) -> 4119 | AA23: =SUM(AA19,AA20,AA21,AA22) -> 5217.0943 | ... AF23: =SUM(AF19,AF20,AF21,AF22) -> 8787.0465
A25: Adj. EBIT Margin
A26: Aerospace Propulsion | H26: =H19/H5 -> 0.11058545 | I26: =I19/I5 -> 0.1074869 | J26: =J19/J5 -> 0.1006376 | K26: =K19/K5 -> 0.11069981 | L26: =L19/L5 -> 0.11830835 | M26: =M19/M5 -> 0.1487725 | N26: =N19/N5 -> 0.15360457 | O26: =O19/O5 -> 0 | ... Z26: =Z19/Z5 -> 0.20648989 | AA26: ='Aerospace Propulsion Division'!AA20 -> 0.22566034 | AB26: ='Aerospace Propulsion Division'!AB20 -> 0.22591154 | AC26: ='Aerospace Propulsion Division'!AC20 -> 0.22728144 | AD26: ='Aerospace Propulsion Division'!AD20 -> 0.22926952 | AE26: ='Aerospace Propulsion Division'!AE20 -> 0.23121989 | AF26: ='Aerospace Propulsion Division'!AF20 -> 0.23519712
A27: Equipment & Defense | T27: =T20/T6 -> 0.12490557 | U27: =U20/U6 -> 0.13061798 | V27: =V20/V6 -> 0.099666328 | W27: =W20/W6 -> 0.1027668 | X27: =X20/X6 -> 0.11599204 | Y27: =Y20/Y6 -> 0.1122807 | Z27: =Z20/Z6 -> 0.12224524 | AA27: ='Equipment and Defense'!AA15 -> 0.12744534 | AB27: ='Equipment and Defense'!AB15 -> 0.13894585 | AC27: ='Equipment and Defense'!AC15 -> 0.14359731 | AD27: ='Equipment and Defense'!AD15 -> 0.14732483 | AE27: ='Equipment and Defense'!AE15 -> 0.14909582 | AF27: ='Equipment and Defense'!AF15 -> 0.15101968
A28: Aircraft Interiors | T28: =T21/T7 -> 0.032258065 | U28: =U21/U7 -> 0.056609455 | V28: =V21/V7 -> -0.090530697 | W28: =W21/W7 -> -0.11322034 | X28: =X21/X7 -> -0.070778564 | Y28: =Y21/Y7 -> -0.046830844 | Z28: =Z21/Z7 -> 0.0088903523 | AA28: ='Aircraft Interiors Division'!O20 -> 0.031161559 | AB28: ='Aircraft Interiors Division'!P20 -> 0.053006815 | AC28: ='Aircraft Interiors Division'!Q20 -> 0.074827367 | AD28: ='Aircraft Interiors Division'!R20 -> 0.089707897 | AE28: ='Aircraft Interiors Division'!S20 -> 0.093556118 | AF28: ='Aircraft Interiors Division'!T20 -> 0.093984998
A29: Group | H29: =H23/H9 -> 0.048106629 | I29: =I23/I9 -> 0.059968695 | J29: =J23/J9 -> 0.064478652 | K29: =K23/K9 -> 0.053694487 | L29: =L23/L9 -> 0.052788104 | M29: =M23/M9 -> 0.067314247 | N29: =N23/N9 -> 0.068879056 | O29: =O23/O9 -> -0.011000487 | ... AF29: =AF23/AF9 -> 0.1878093
A31: Adj. EBIT growth
A32: Aerospace Propulsion | I32: =I19/H19-1 -> 0.13368984 | J32: =J19/I19-1 -> -0.081761006 | K32: =K19/J19-1 -> 0.075342466 | L32: =L19/K19-1 -> 0.055732484 | M32: =M19/L19-1 -> 0.37104072 | N32: =N19/M19-1 -> 0.18371837 | O32: =O19/N19-1 -> -1 | P32: =P19/O19-1 -> #DIV/0! | ... AF32: =AF19/AE19-1 -> 0.073850922
A33: Equipment & Defense | U33: =U20/T20-1 -> 0.21875 | V33: =V20/U20-1 -> -0.43176179 | W33: =W20/V20-1 -> -0.053857351 | X33: =X20/W20-1 -> 0.34461538 | Y33: =Y20/X20-1 -> 0.13501144 | Z33: =Z20/Y20-1 -> 0.30846774 | AA33: =AA20/Z20-1 -> 0.20654126 | AB33: =AB20/AA20-1 -> 0.24689236 | ... AF33: =AF20/AE20-1 -> 0.057927884
A34: Aircraft Interiors | U34: =U21/T21-1 -> 1.3209877 | V34: =V21/U21-1 -> -1.9255319 | W34: =W21/V21-1 -> -0.040229885 | X34: =-(X21/W21-1) -> 0.16167665 | Y34: =-(Y21/X21-1) -> 0.17142857 | Z34: =-(Z21/Y21-1) -> 1.2327586 | AA34: =(AA21/Z21-1) -> 2.9515858 | AB34: =AB21/AA21-1 -> 0.87952118 | AC34: =AC21/AB21-1 -> 0.54280242 | AD34: =AD21/AC21-1 -> 0.29666061 | AE34: =AE21/AD21-1 -> 0.076656091 | AF34: =AF21/AE21-1 -> 0.033101997
A35: Group | I35: =I23/H23-1 -> 0.12477064 | J35: =J23/I23-1 -> 0.086460033 | K35: =K23/J23-1 -> -0.15765766 | L35: =L23/K23-1 -> 0.012477718 | M35: =M23/L23-1 -> 0.39084507 | N35: =N23/M23-1 -> 0.18227848 | O35: =O23/N23-1 -> -1.1691649 | P35: =P23/O23-1 -> 0.10759494 | ... AF35: =AF23/AE23-1 -> 0.066916368
A38: Income Statement (consolidated) | B38: 2000 | C38: 2001 | D38: 2002 | E38: 2003 | F38: 2004 | G38: 2005 | H38: 2006 | I38: 2007 | J38: 2008 | K38: 2009 | L38: 2010 | M38: 2011 | N38: 2012 | O38: 2013 | P38: 2014 | Q38: 2015 | R38: 2016 | S38: 2017 | T38: 2018 | U38: 2019 | V38: 2020 | W38: 2021 | X38: 2022 | Y38: 2023 | Z38: 2024 | AA38: =Z38+1 -> 2025 | AB38: =AA38+1 -> 2026 | AC38: =AB38+1 -> 2027 | AD38: =AC38+1 -> 2028 | AE38: =AD38+1 -> 2029 | AF38: =AE38+1 -> 2030
A39: Adjusted Revenues | H39: =H9 -> 11329 | I39: =I9 -> 10222 | J39: =J9 -> 10329 | K39: =K9 -> 10448 | L39: =L9 -> 10760 | M39: =M9 -> 11736 | N39: =N9 -> 13560 | O39: =O9 -> 14363 | ... AF39: =AF9 -> 46787.067
A40: Adjustments | L40: 268 | M40: -78 | N40: 55 | O40: 127 | P40: -311 | Q40: -1192 | R40: 701 | S40: 423 | T40: -25 | U40: 458 | V40: 133 | W40: -124 | X40: 488 | Y40: 452 | Z40: 399 | AA40: 0 | AB40: =AA40 -> 0 | AC40: =AB40 -> 0 | AD40: =AC40 -> 0 | AE40: =AD40 -> 0 | AF40: =AE40 -> 0
A41: Sales (Reported) | H41: 10841 | I41: 9714 | J41: 10281 | K41: 10559 | L41: 11028 | M41: 11658 | N41: 13615 | O41: 14490 | P41: 15044 | Q41: 16222 | R41: 16482 | S41: 16376 | T41: 21025 | U41: 25098 | V41: 16631 | W41: 15133 | X41: 19523 | Y41: 23651 | Z41: 27716 | AA41: ='Income Statement'!AA9 -> 31556.569 | AB41: ='Income Statement'!AB9 -> 35653.732 | AC41: ='Income Statement'!AC9 -> 39232.543 | AD41: ='Income Statement'!AD9 -> 42282.093 | AE41: ='Income Statement'!AE9 -> 44620.651 | AF41: ='Income Statement'!AF9 -> 46787.067
A42: growth | I42: =I41/H41-1 -> -0.1039572 | J42: =J41/I41-1 -> 0.058369364 | K42: =K41/J41-1 -> 0.027040171 | L42: =L41/K41-1 -> 0.044417085 | M42: =M41/L41-1 -> 0.057127312 | N42: =N41/M41-1 -> 0.16786756 | O42: =O41/N41-1 -> 0.064267352 | P42: =P41/O41-1 -> 0.038233264 | ... AF42: =AF41/AE41-1 -> 0.048551861
A43: Other Income | H43: 74 | I43: 66 | J43: 127 | K43: 156 | L43: 200 | M43: 216 | N43: 209 | O43: 264 | P43: 291 | Q43: 285 | R43: 277 | S43: 280 | T43: 321 | U43: 297 | V43: 267 | W43: 373 | X43: 440 | Y43: 474 | Z43: 438 | AA43: =AA44*AA41 -> 498.69307 | AB43: =AB44*AB41 -> 563.44114 | AC43: =AC44*AC41 -> 619.99762 | AD43: =AD44*AD41 -> 668.19009 | AE43: =AE44*AE41 -> 705.14667 | AF43: =AF44*AF41 -> 739.38285
A44: as a % of sales | H44: =H43/H$41 -> 0.0068259386 | I44: =I43/I$41 -> 0.0067943175 | J44: =J43/J$41 -> 0.012352884 | K44: =K43/K$41 -> 0.014774126 | L44: =L43/L$41 -> 0.018135655 | M44: =M43/M$41 -> 0.018528049 | N44: =N43/N$41 -> 0.015350716 | O44: =O43/O$41 -> 0.018219462 | ... Z44: =Z43/Z$41 -> 0.015803146 | AA44: =Z44 -> 0.015803146 | AB44: =AA44 -> 0.015803146 | AC44: =AB44 -> 0.015803146 | AD44: =AC44 -> 0.015803146 | AE44: =AD44 -> 0.015803146 | AF44: =AE44 -> 0.015803146
A45: Changes in Inventories of finished goods and Work-in-progress | H45: 360 | I45: 316 | J45: 276 | K45: -268 | L45: -43 | M45: 125 | N45: 340 | O45: -32 | P45: 255 | Q45: 257 | R45: 308 | S45: 195 | T45: 3 | U45: 453 | V45: -865 | W45: -199 | X45: 1204 | Y45: 1000 | Z45: 989 | AA45: =AA46*AA$41 -> 1126.0444 | AB45: =AB46*AB$41 -> 1272.2449 | AC45: =AC46*AC$41 -> 1399.949 | AD45: =AD46*AD$41 -> 1508.7671 | AE45: =AE46*AE$41 -> 1592.2147 | AF45: =AF46*AF$41 -> 1669.5197
A46: as a % of sales | H46: =H45/H$41 -> 0.033207269 | I46: =I45/I$41 -> 0.032530369 | J46: =J45/J$41 -> 0.026845638 | K46: =K45/K$41 -> -0.025381191 | L46: =L45/L$41 -> -0.0038991658 | M46: =M45/M$41 -> 0.010722251 | N46: =N45/N$41 -> 0.024972457 | O46: =O45/O$41 -> -0.0022084196 | ... Z46: =Z45/Z$41 -> 0.03568336 | AA46: =Z46 -> 0.03568336 | AB46: =AA46 -> 0.03568336 | AC46: =AB46 -> 0.03568336 | AD46: =AC46 -> 0.03568336 | AE46: =AD46 -> 0.03568336 | AF46: =AE46 -> 0.03568336
...

Sheet Balance Sheet
A1: ='DCF Valuation'!D45 -> 340
A2: Balance Sheet | B2: 2000 | C2: 2001 | D2: 2002 | E2: 2003 | F2: 2004 | G2: 2005 | H2: 2006 | I2: 2007 | J2: 2008 | K2: 2009 | L2: 2010 | M2: 2011 | N2: 2012 | O2: 2013 | P2: 2014 | Q2: 2015 | R2: 2016 | S2: 2017 | T2: 2018 | U2: 2019 | V2: 2020 | W2: 2021 | X2: 2022 | Y2: 2023 | Z2: 2024 | AA2: 2025E | AB2: 2026E | AC2: 2027E | AD2: 2028E | AE2: 2029E | AF2: 2030E | AI2: Comments
A4: Goodwill | H4: 1589 | I4: 1561 | J4: 1756 | K4: 2126 | L4: 2298 | M4: 3126 | N4: 3078 | O4: 3399 | P4: 3420 | Q4: 3590 | R4: 1864 | S4: 1831 | T4: 5173 | U4: 5199 | V4: 5060 | W4: 5068 | X4: 4994 | Y4: 4706 | Z4: 4937 | AA4: =Z4-'Cashflow Statement'!AA32-'Cashflow Statement'!AA9 -> 5109 | AB4: =AA4-'Cashflow Statement'!AB32-'Cashflow Statement'!AB9 -> 5281 | AC4: =AB4-'Cashflow Statement'!AC32-'Cashflow Statement'!AC9 -> 5453 | AD4: =AC4-'Cashflow Statement'!AD32-'Cashflow Statement'!AD9 -> 5625 | AE4: =AD4-'Cashflow Statement'!AE32-'Cashflow Statement'!AE9 -> 5797 | AF4: =AE4-'Cashflow Statement'!AF32-'Cashflow Statement'!AF9 -> 5969
A5: Intangible Assets | H5: 3056 | I5: 2981 | J5: 3112 | K5: 3217 | L5: 3130 | M5: 3498 | N5: 3872 | O5: =4641-200 -> 4441 | P5: 5536 | Q5: 5321 | R5: 5178 | S5: 5596 | T5: 9757 | U5: 9479 | V5: 8676 | W5: 8382 | X5: 8096 | Y5: 7830 | Z5: 7947 | AA5: =Z5-'Cashflow Statement'!AA7-'Cashflow Statement'!AA26 -> 7612.4352 | AB5: =AA5-'Cashflow Statement'!AB7-'Cashflow Statement'!AB26 -> 7092.8232 | AC5: =AB5-'Cashflow Statement'!AC7-'Cashflow Statement'!AC26 -> 6544.312 | AD5: =AC5-'Cashflow Statement'!AD7-'Cashflow Statement'!AD26 -> 5910.4134 | AE5: =AD5-'Cashflow Statement'!AE7-'Cashflow Statement'!AE26 -> 5211.0352 | AF5: =AE5-'Cashflow Statement'!AF7-'Cashflow Statement'!AF26 -> 4450.9973
A6: PP&E | H6: 1826 | I6: 1847 | J6: 2107 | K6: 2201 | L6: 2253 | M6: 2486 | N6: 2604 | O6: =2740-98 -> 2642 | P6: 2928 | Q6: 3272 | R6: 3169 | S6: 3518 | T6: 4454 | U6: 4398 | V6: 4055 | W6: 3937 | X6: 3847 | Y6: 4121 | Z6: 4629 | AA6: =Z6-'Cashflow Statement'!AA5-'Cashflow Statement'!AA28-'Cashflow Statement'!AA31 -> 5662.5658 | AB6: =AA6-'Cashflow Statement'!AB5-'Cashflow Statement'!AB28-'Cashflow Statement'!AB31 -> 6629.7247 | AC6: =AB6-'Cashflow Statement'!AC5-'Cashflow Statement'!AC28-'Cashflow Statement'!AC31 -> 7480.5365 | AD6: =AC6-'Cashflow Statement'!AD5-'Cashflow Statement'!AD28-'Cashflow Statement'!AD31 -> 8172.7019 | AE6: =AD6-'Cashflow Statement'!AE5-'Cashflow Statement'!AE28-'Cashflow Statement'!AE31 -> 8670.5337 | AF6: =AE6-'Cashflow Statement'!AF5-'Cashflow Statement'!AF28-'Cashflow Statement'!AF31 -> 8950.2498
A7: Non-current financial assets | H7: 364 | I7: 286 | J7: 203 | K7: 220 | L7: 215 | M7: 246 | N7: 281 | O7: 384 | P7: 446 | Q7: 419 | R7: 382 | S7: 324 | T7: 416 | U7: 429 | V7: 431 | W7: 688 | X7: 752 | Y7: 997 | Z7: 1073 | AA7: =Z7 -> 1073 | AB7: =AA7 -> 1073 | AC7: =AB7 -> 1073 | AD7: =AC7 -> 1073 | AE7: =AD7 -> 1073 | AF7: =AE7 -> 1073
A8: Investments in associates | H8: 32 | I8: 34 | J8: 244 | K8: 238 | L8: 236 | M8: 253 | N8: 281 | O8: 680 | P8: 771 | Q8: 765 | R8: 2175 | S8: 2127 | T8: 2253 | U8: 2211 | V8: 2126 | W8: 1969 | X8: 1974 | Y8: 1928 | Z8: 1894 | AA8: =Z8 -> 1894 | AB8: =AA8 -> 1894 | AC8: =AB8 -> 1894 | AD8: =AC8 -> 1894 | AE8: =AD8 -> 1894 | AF8: =AE8 -> 1894
A9: Non-current derivatives | M9: 20 | N9: 62 | O9: 0 | P9: 29 | Q9: 35 | R9: 28 | S9: 16 | T9: 13 | U9: 33 | V9: 52 | W9: 23 | X9: 18 | Y9: 0 | Z9: 4 | AA9: =Z9 -> 4 | AB9: =AA9 -> 4 | AC9: =AB9 -> 4 | AD9: =AC9 -> 4 | AE9: =AD9 -> 4 | AF9: =AE9 -> 4
A10: Deferred tax assets | H10: 120 | I10: 158 | J10: 295 | K10: 263 | L10: 194 | M10: 251 | N10: 243 | O10: 201 | P10: 228 | Q10: 984 | R10: 1351 | S10: 251 | T10: 391 | U10: 251 | V10: 316 | W10: 449 | X10: 1576 | Y10: 1122 | Z10: 2349 | AA10: =Z10 -> 2349 | AB10: =AA10 -> 2349 | AC10: =AB10 -> 2349 | AD10: =AC10 -> 2349 | AE10: =AD10 -> 2349 | AF10: =AE10 -> 2349
A11: Right of use Asset | U11: 732 | V11: 623 | W11: 606 | X11: 566 | Y11: 582 | Z11: 653 | AA11: =Z11 -> 653 | AB11: =AA11 -> 653 | AC11: =AB11 -> 653 | AD11: =AC11 -> 653 | AE11: =AD11 -> 653 | AF11: =AE11 -> 653
A12: Other non-current financial assets | H12: 16 | I12: 10 | J12: 9 | K12: 1 | L12: 12 | M12: 12 | N12: 13 | O12: 0 | P12: 0 | Q12: =P12 -> 0 | R12: =Q12 -> 0 | S12: =R12 -> 0 | T12: 4 | U12: =T12 -> 4 | V12: 4 | W12: 11 | X12: 8 | Y12: 7 | Z12: 3 | AA12: =Z12 -> 3 | AB12: =AA12 -> 3 | AC12: =AB12 -> 3 | AD12: =AC12 -> 3 | AE12: =AD12 -> 3 | AF12: =AE12 -> 3
A13: Other | H13: =H14-SUM(H4:H12) -> 0 | I13: =I14-SUM(I4:I12) -> 0 | J13: =J14-SUM(J4:J12) -> 0 | K13: =K14-SUM(K4:K12) -> 0 | L13: =L14-SUM(L4:L12) -> 0 | M13: =M14-SUM(M4:M12) -> 0 | N13: =N14-SUM(N4:N12) -> 0 | O13: =O14-SUM(O4:O12) -> 0 | ... Z13: =Z14-SUM(Z4:Z12) -> 0 | AA13: 0 | AB13: 0 | AC13: 0 | AD13: 0 | AE13: 0 | AF13: 0
A14: Non-current assets | H14: 7003 | I14: 6877 | J14: 7726 | K14: 8266 | L14: 8338 | M14: 9892 | N14: 10434 | O14: =(3399+7083+680+585) -> 11747 | P14: 13358 | Q14: 14386 | R14: =SUM(R4:R12) -> 14147 | S14: =SUM(S4:S12) -> 13663 | T14: =SUM(T4:T12) -> 22461 | U14: =SUM(U4:U12) -> 22736 | V14: =SUM(V4:V12) -> 21343 | W14: =SUM(W4:W12) -> 21133 | X14: =SUM(X4:X12) -> 21831 | Y14: =SUM(Y4:Y12) -> 21293 | Z14: =SUM(Z4:Z12) -> 23489 | AA14: =SUM(AA4:AA13) -> 24360.001 | AB14: =SUM(AB4:AB13) -> 24979.548 | AC14: =SUM(AC4:AC13) -> 25453.848 | AD14: =SUM(AD4:AD13) -> 25684.115 | AE14: =SUM(AE4:AE13) -> 25654.569 | AF14: =SUM(AF4:AF13) -> 25346.247
A16: Current financial assets | H16: 108 | I16: 107 | J16: 108 | K16: 75 | L16: 110 | M16: 101 | N16: 176 | O16: 198 | P16: 221 | Q16: 247 | R16: 147 | S16: 2113 | T16: 185 | U16: 143 | V16: 126 | W16: 104 | X16: 242 | Y16: 270 | Z16: 243 | AA16: =Z16 -> 243 | AB16: =AA16 -> 243 | AC16: =AB16 -> 243 | AD16: =AC16 -> 243 | AE16: =AD16 -> 243 | AF16: =AE16 -> 243
A17: Current derivatives | H17: 397 | I17: 126 | J17: 138 | K17: 63 | L17: 128 | M17: 259 | N17: 585 | O17: 864 | P17: 377 | Q17: 373 | R17: 592 | S17: 566 | T17: 740 | U17: 674 | V17: 694 | W17: 705 | X17: 540 | Y17: 1577 | Z17: 952 | AA17: =Z17 -> 952 | AB17: =AA17 -> 952 | AC17: =AB17 -> 952 | AD17: =AC17 -> 952 | AE17: =AD17 -> 952 | AF17: =AE17 -> 952
A18: Inventories and work-in-progress | H18: 3240 | I18: 3240 | J18: 3673 | K18: 3382 | L18: 3508 | M18: 3799 | N18: 4131 | O18: 3998 | P18: 4265 | Q18: 4518 | R18: 4247 | S18: 3954 | T18: 5558 | U18: 6312 | V18: 5190 | W18: 5063 | X18: 6408 | Y18: 7903 | Z18: 9491 | AA18: =-AA19*'Income Statement'!AA49/365 -> 10156.157 | AB18: =-AB19*'Income Statement'!AB49/365 -> 10293.559 | AC18: =-AC19*'Income Statement'!AC49/365 -> 11141.109 | AD18: =-AD19*'Income Statement'!AD49/365 -> 12007.109 | AE18: =-AE19*'Income Statement'!AE49/365 -> 12811.995 | AF18: =-AF19*'Income Statement'!AF49/365 -> 13507.855
A19: DIO | W19: =-W18/'Income Statement'!W49*365 -> 231.02825 | X19: =-X18/'Income Statement'!X49*365 -> 199.49846 | Y19: =-Y18/'Income Statement'!Y49*365 -> 204.98827 | Z19: =-Z18/'Income Statement'!Z49*365 -> 217.05608 | AA19: 204 | AB19: 183 | AC19: 180 | AD19: 180 | AE19: 182 | AF19: 183
A20: Trade and Other receivables | H20: 4218 | I20: 3926 | J20: 3881 | K20: 4158 | L20: 4219 | M20: 5005 | N20: 5025 | O20: 4967 | P20: 5827 | Q20: 6515 | R20: 6252 | S20: 4952 | T20: 6580 | U20: 7639 | V20: 5769 | W20: 6504 | X20: 7904 | Y20: 9417 | Z20: 10572 | AA20: ='Income Statement'!AA39*'Balance Sheet'!AA21/365 -> 11152.869 | AB20: ='Income Statement'!AB39*'Balance Sheet'!AB21/365 -> 12503.226 | AC20: ='Income Statement'!AC39*'Balance Sheet'!AC21/365 -> 13435.802 | AD20: ='Income Statement'!AD39*'Balance Sheet'!AD21/365 -> 14364.327 | AE20: ='Income Statement'!AE39*'Balance Sheet'!AE21/365 -> 15158.796 | AF20: ='Income Statement'!AF39*'Balance Sheet'!AF21/365 -> 15894.784
A21: DSO | W21: =W20/'Income Statement'!W39*365 -> 155.59809 | X21: =X20/'Income Statement'!X39*365 -> 151.56081 | Y21: =Y20/'Income Statement'!Y39*365 -> 148.16177 | Z21: =Z20/'Income Statement'!Z39*365 -> 141.25929 | AA21: 129 | AB21: 128 | AC21: 125 | AD21: 124 | AE21: =AD21 -> 124 | AF21: =AE21 -> 124
A22: Tax assets | H22: 68 | I22: 27 | J22: 127 | K22: 145 | L22: 146 | M22: 215 | N22: 421 | O22: 392 | P22: 452 | Q22: 623 | R22: 513 | S22: 596 | T22: 752 | U22: 458 | V22: 481 | W22: 555 | X22: 358 | Y22: 422 | Z22: 364 | AA22: =Z22 -> 364 | AB22: =AA22 -> 364 | AC22: =AB22 -> 364 | AD22: =AC22 -> 364 | AE22: =AD22 -> 364 | AF22: =AE22 -> 364
A23: Cash and Cash equivalents | H23: 743 | I23: 730 | J23: 919 | K23: 2080 | L23: 2062 | M23: 1431 | N23: 2193 | O23: 1547 | P23: 1633 | Q23: 1845 | R23: 1926 | S23: 4914 | T23: 2330 | U23: 2632 | V23: 3747 | W23: 5247 | X23: 6687 | Y23: 6676 | Z23: 6514 | AA23: ='Cashflow Statement'!AA55 -> 7326.3518 | AB23: ='Cashflow Statement'!AB55 -> 8656.3944 | AC23: ='Cashflow Statement'!AC55 -> 10191.542 | AD23: ='Cashflow Statement'!AD55 -> 12126.355 | AE23: ='Cashflow Statement'!AE55 -> 15580.022 | AF23: ='Cashflow Statement'!AF55 -> 19331.618
A24: Contract costs | S24: 261 | T24: 470 | U24: 471 | V24: 486 | W24: 552 | X24: 664 | Y24: 753 | Z24: 884 | AA24: =Z24 -> 884 | AB24: =AA24 -> 884 | AC24: =AB24 -> 884 | AD24: =AC24 -> 884 | AE24: =AD24 -> 884 | AF24: =AE24 -> 884
A25: Contract assets | S25: 1366 | T25: 1544 | U25: 1743 | V25: 1695 | W25: 1853 | X25: 1982 | Y25: 2157 | Z25: 2503 | AA25: =Z25 -> 2503 | AB25: =AA25 -> 2503 | AC25: =AB25 -> 2503 | AD25: =AC25 -> 2503 | AE25: =AD25 -> 2503 | AF25: =AE25 -> 2503
A26: Other | H26: =H27-SUM(H16:H23) -> 151 | I26: =I27-SUM(I16:I23) -> 1142 | J26: =J27-SUM(J16:J23) -> 264 | K26: =K27-SUM(K16:K23) -> 0 | L26: =L27-SUM(L16:L23) -> 0 | M26: =M27-SUM(M16:M23) -> 0 | N26: =N27-SUM(N16:N23) -> 0 | O26: =O27-SUM(O16:O23) -> -15 | ... Q26: =Q27-SUM(Q16:Q23) -> 0 | R26: 3234 | S26: 0 | T26: =S26 -> 0 | U26: 0 | X26: 212 | Y26: 0 | Z26: 0 | AA26: =Z26 -> 0 | AB26: =AA26 -> 0 | AC26: =AB26 -> 0 | AD26: =AC26 -> 0 | AE26: =AD26 -> 0 | AF26: =AE26 -> 0
A27: Current Assets | H27: 8925 | I27: =8519+779 -> 9298 | J27: =9049+61 -> 9110 | K27: 9903 | L27: 10173 | M27: 10810 | N27: 12531 | O27: =(864+3998+4967+1547+575) -> 11951 | P27: 12775 | Q27: 14121 | R27: =SUM(R16:R26) -> 16911 | S27: =SUM(S16:S26) -> 18722 | T27: =SUM(T16:T26) -> 18159 | U27: =SUM(U16:U26) -> 20072 | V27: =SUM(V16:V26) -> 18188 | W27: =SUM(W16:W26)-W19-W21 -> 20583 | X27: =SUM(X16:X26)-X19-X21 -> 24997 | Y27: =SUM(Y16:Y26)-Y19-Y21 -> 29175 | Z27: =SUM(Z16:Z26)-Z19-Z21 -> 31523 | AA27: =SUM(AA16:AA26)-AA19-AA21 -> 33581.378 | AB27: =SUM(AB16:AB26)-AB19-AB21 -> 36399.18 | AC27: =SUM(AC16:AC26)-AC19-AC21 -> 39714.454 | AD27: =SUM(AD16:AD26)-AD19-AD21 -> 43443.791 | ... AF27: =SUM(AF16:AF26)-AF19-AF21 -> 53680.256
A29: Provisions | H29: -976 | I29: -1052 | J29: -1078 | K29: -1315 | L29: -1310 | M29: -1374 | N29: -1823 | O29: =-1751+10 -> -1741 | P29: -1870 | Q29: -1802 | R29: -1706 | S29: -1263 | T29: -1588 | U29: -2093 | V29: -1942 | W29: -1798 | X29: -1549 | Y29: -1547 | Z29: -1835 | AA29: =Z29-'Cashflow Statement'!AA10 -> -1935 | AB29: =AA29-'Cashflow Statement'!AB10 -> -2035 | AC29: =AB29-'Cashflow Statement'!AC10 -> -2135 | AD29: =AC29-'Cashflow Statement'!AD10 -> -2235 | AE29: =AD29-'Cashflow Statement'!AE10 -> -2335 | AF29: =AE29-'Cashflow Statement'!AF10 -> -2435
A30: Borrowings subject to specific conditions | H30: -573 | I30: -590 | J30: -698 | K30: -696 | L30: -701 | M30: -682 | N30: -670 | O30: -670 | P30: -713 | Q30: -708 | R30: -699 | S30: -569 | T30: -585 | U30: -505 | V30: -426 | W30: -327 | X30: -302 | Y30: -292 | Z30: -287 | AA30: =Z30 -> -287 | AB30: =AA30 -> -287 | AC30: =AB30 -> -287 | AD30: =AC30 -> -287 | AE30: =AD30 -> -287 | AF30: =AE30 -> -287
A31: Non-current interest-bearing financial liabilities | H31: -463 | I31: -397 | J31: -418 | K31: -1208 | L31: -1483 | M31: -1447 | N31: -2259 | O31: =-1295-6 -> -1301 | P31: -1658 | Q31: -1752 | R31: -2392 | S31: -3246 | T31: -3384 | U31: -3239 | V31: -4082 | W31: -5094 | X31: -5378 | Y31: -4691 | Z31: -3788 | AA31: =Z31-'Cashflow Statement'!AA39 -> -3788 | AB31: =AA31-'Cashflow Statement'!AB39 -> -3788 | AC31: =AB31-'Cashflow Statement'!AC39 -> -3788 | AD31: =AC31-'Cashflow Statement'!AD39 -> -3788 | AE31: =AD31-'Cashflow Statement'!AE39 -> -3788 | AF31: =AE31-'Cashflow Statement'!AF39 -> -3788
A32: Non-current derivatives | M32: -5 | N32: -12 | O32: -36 | R32: 0 | S32: =R32 -> 0 | T32: -7 | U32: -5 | V32: -18 | W32: -8 | X32: -18 | Y32: -8 | Z32: -15 | AA32: =Z32 -> -15 | AB32: =AA32 -> -15 | AC32: =AB32 -> -15 | AD32: =AC32 -> -15 | AE32: =AD32 -> -15 | AF32: =AE32 -> -15
A33: Deferred tax liabilities | H33: -929 | I33: -745 | J33: -618 | K33: -833 | L33: -685 | M33: -718 | N33: -981 | O33: -1293 | P33: -728 | Q33: -677 | R33: -987 | S33: -674 | T33: -1662 | U33: -1340 | V33: -1285 | W33: -1275 | X33: -1164 | Y33: -1022 | Z33: -911 | AA33: =Z33-('Cashflow Statement'!AA17) -> -1241 | AB33: =AA33-('Cashflow Statement'!AB17) -> -1111 | AC33: =AB33-('Cashflow Statement'!AC17) -> -911 | AD33: =AC33-('Cashflow Statement'!AD17) -> -911 | AE33: =AD33-('Cashflow Statement'!AE17) -> -911 | AF33: =AE33-('Cashflow Statement'!AF17) -> -911
A34: Other non-current financial liabilities | H34: -112 | I34: -96 | J34: -139 | K34: -208 | L34: -186 | M34: -199 | N34: -81 | O34: =-119+8 -> -111 | P34: -101 | Q34: -26 | R34: -5 | S34: -8 | T34: -2 | U34: -2 | V34: -2 | W34: -116 | X34: -75 | Y34: -43 | Z34: -11 | AA34: =Z34 -> -11 | AB34: =AA34 -> -11 | AC34: =AB34 -> -11 | AD34: =AC34 -> -11 | AE34: =AD34 -> -11 | AF34: =AE34 -> -11
A35: Other | H35: =H36-SUM(H29:H34) -> 0 | I35: =I36-SUM(I29:I34) -> 0 | J35: =J36-SUM(J29:J34) -> 0 | K35: =K36-SUM(K29:K34) -> 0 | L35: =L36-SUM(L29:L34) -> 0 | M35: =M36-SUM(M29:M34) -> 0 | N35: =N36-SUM(N29:N34) -> 0 | O35: =O36-SUM(O29:O34) -> 13 | ... R35: =R36-SUM(R29:R34) -> 0 | S35: 0 | T35: 0 | U35: =U36-SUM(U29:U34) -> 0 | V35: =V36-SUM(V29:V34) -> 0 | W35: =W36-SUM(W29:W34) -> 0 | X35: -49 | Y35: 0 | Z35: =Y35 -> 0 | AA35: =Z35 -> 0 | AB35: =AA35 -> 0 | AC35: =AB35 -> 0 | AD35: =AC35 -> 0 | AE35: =AD35 -> 0 | AF35: =AE35 -> 0
A36: Non-current liabilities | H36: -3053 | I36: -2880 | J36: -2951 | K36: -4260 | L36: -4365 | M36: -4425 | N36: -5826 | O36: -5139 | P36: -5070 | Q36: -4965 | R36: =SUM(R29:R34) -> -5789 | S36: =SUM(S29:S34) -> -5760 | T36: =SUM(T29:T34) -> -7228 | U36: =SUM(U29:U34) -> -7184 | V36: =SUM(V29:V34) -> -7755 | W36: =SUM(W29:W34) -> -8618 | X36: =SUM(X29:X35) -> -8535 | Y36: =SUM(Y29:Y35) -> -7603 | Z36: =SUM(Z29:Z35) -> -6847 | AA36: =SUM(AA29:AA35) -> -7277 | AB36: =SUM(AB29:AB35) -> -7247 | AC36: =SUM(AC29:AC35) -> -7147 | AD36: =SUM(AD29:AD35) -> -7247 | AE36: =SUM(AE29:AE35) -> -7347 | AF36: =SUM(AF29:AF35) -> -7447
