Workbook
Name _div08: #REF!
Name _div09: #REF!
Name _div10: #REF!
Name _ShH3: #REF!
Name A_ALL_AIR.PA: #REF!
Name A_ALL_AIR.PA: #REF!
Name A_ALL_AIR.PA_: #REF!
Name A_ALL_AIR.PA_: #REF!
Name A_ALL_AIR.PA_: #REF!
Name A_ALL_AIR.PA_: #REF!
Name A_ALL_AIR.PA_: #REF!
Name A_ALL_AIR.PA_: #REF!
Name A_ALL_AIR.PA_: #REF!
Name A_ALL_BAES.L_: #REF!
Name A_ALL_BAES.L_: #REF!
Name A_ALL_BAES.L_: #REF!
Name A_ALL_BAES.L_: #REF!
Name A_ALL_BAES.L_: #REF!
Name A_ALL_BAES.L_: #REF!
Name A_ALL_BAES.L_: #REF!
Name A_ALL_COB.L: #REF!
Name A_ALL_COB.L: #REF!
Name A_ALL_COB.L: #REF!
Name A_ALL_KEYWORDS_TYPE_ScalarContributed_EQTY_200000267: #REF!,#REF!
Name A_ALL_KEYWORDS_TYPE_ScalarContributed_EQTY_200003162: #REF!,#REF!
Name A_ALL_KEYWORDS_TYPE_ScalarContributed_EQTY_200003162: #REF!,#REF!
Name A_ALL_KEYWORDS_TYPE_ScalarContributed_EQTY_200003162: #REF!,#REF!
Name A_ALL_KEYWORDS_TYPE_ScalarContributed_EQTY_200003170: #REF!,#REF!
Name A_ALL_KEYWORDS_TYPE_ScalarContributed_EQTY_200003170: #REF!,#REF!
Name A_ALL_KEYWORDS_TYPE_ScalarContributed_EQTY_200003170: #REF!,#REF!
Name A_ALL_KEYWORDS_TYPE_ScalarContributed_EQTY_200003173: #REF!,#REF!
Name A_ALL_KEYWORDS_TYPE_ScalarContributed_EQTY_200003173: #REF!,#REF!
Name A_ALL_KEYWORDS_TYPE_ScalarContributed_EQTY_200003173: #REF!,#REF!
Name A_ALL_KEYWORDS_TYPE_ScalarContributed_EQTY_200003183: #REF!,#REF!
Name A_ALL_KEYWORDS_TYPE_ScalarContributed_EQTY_200003183: #REF!,#REF!
Name A_ALL_KEYWORDS_TYPE_ScalarContributed_EQTY_200003183: #REF!,#REF!
Name A_ALL_KEYWORDS_TYPE_ScalarContributed_EQTY_200003821: #REF!,#REF!
Name A_ALL_KEYWORDS_TYPE_ScalarContributed_EQTY_200003821: #REF!,#REF!
Name A_ALL_KEYWORDS_TYPE_ScalarContributed_EQTY_200003821: #REF!,#REF!
Name A_ALL_KEYWORDS_TYPE_ScalarContributed_EQTY_200004285: #REF!,#REF!
Name A_ALL_KEYWORDS_TYPE_ScalarContributed_EQTY_200004285: #REF!,#REF!
Name A_ALL_KEYWORDS_TYPE_ScalarContributed_EQTY_200005121: #REF!,#REF!
Name A_ALL_KEYWORDS_TYPE_ScalarContributed_EQTY_200005121: #REF!,#REF!
Name A_ALL_KEYWORDS_TYPE_ScalarContributed_EQTY_200005121: #REF!,#REF!
Name A_ALL_KEYWORDS_TYPE_ScalarContributed_EQTY_200007513: #REF!,#REF!
Name A_ALL_KEYWORDS_TYPE_ScalarContributed_EQTY_200007513: #REF!,#REF!
Name A_ALL_KEYWORDS_TYPE_ScalarContributed_EQTY_200007513: #REF!,#REF!
Name A_ALL_KEYWORDS_TYPE_ScalarContributed_EQTY_200008448: #REF!,#REF!,#REF!
Name A_ALL_KEYWORDS_TYPE_ScalarContributed_EQTY_200009618: #REF!,#REF!
Name A_ALL_KEYWORDS_TYPE_ScalarContributed_EQTY_200009618: #REF!,#REF!
Name A_ALL_KEYWORDS_TYPE_ScalarContributed_EQTY_200009618: #REF!,#REF!
Name A_ALL_KEYWORDS_TYPE_ScalarContributed_EQTY_200009619: #REF!,#REF!
Name A_ALL_KEYWORDS_TYPE_ScalarContributed_EQTY_200009619: #REF!,#REF!
Name A_ALL_KEYWORDS_TYPE_ScalarContributed_EQTY_200009619: #REF!,#REF!
Name A_ALL_KEYWORDS_TYPE_ScalarContributed_EQTY_200009620: #REF!,#REF!
Name A_ALL_KEYWORDS_TYPE_ScalarContributed_EQTY_200009620: #REF!,#REF!
Name A_ALL_KEYWORDS_TYPE_ScalarContributed_EQTY_200009620: #REF!,#REF!
Name A_ALL_KEYWORDS_TYPE_ScalarContributed_EQTY_200011295: #REF!,#REF!
Name A_ALL_KEYWORDS_TYPE_ScalarContributed_EQTY_200011295: #REF!,#REF!
Name A_ALL_KEYWORDS_TYPE_ScalarContributed_ISSR_208000023: #REF!,#REF!,#REF!,#REF!,#REF!,#REF!,#REF!,#REF!,#REF!,#REF!

Sheet _QP_SAF.PA
A1: 1311101 | F1: 1998 | G1: 1999 | H1: 2000 | I1: 2001 | J1: 2002 | K1: 2003 | L1: 2004 | M1: 2005 | N1: 2006 H1 | O1: 2006 H2 | P1: 2006 | Q1: 2007 H1 | R1: 2007 H2 | S1: 2007 | T1: 2008 H1 | U1: 2008 H2 | V1: 2008 | W1: 2009 H1 | X1: 2009 H2 | Y1: 2009 | Z1: 2010 H1 | AA1: 2010 H2 | AB1: 2010 | AC1: 2011 H1 | AD1: 2011 H2 | AE1: 2011 | AF1: 2012 | AG1: 2013 | AH1: 2014 | AI1: 2015 | AJ1: 2016
A2: AUTO-GENERATED BY TIGR NUMBERS SUBMISSION. DO NOT MODIFY OR DELETE!
B4: ACC_END_DATE | D4: EUR | F4: 36160 | G4: 36525 | H4: 36891 | I4: 37256 | J4: 37621 | K4: 37986 | L4: 38352 | M4: 38717 | N4: 38898 | O4: 39082 | P4: 39082 | Q4: 39263 | R4: 39447 | S4: 39447 | T4: 39629 | U4: 39813 | V4: 39813 | W4: 39994 | X4: 40178 | Y4: 40178 | Z4: 40359 | AA4: 40543 | AB4: 40543 | AC4: 40724 | AD4: 40908 | AE4: 40908 | AF4: 41274 | AG4: 41639 | AH4: 42004 | AI4: 42369 | AJ4: 42735
B5: EURO_LIST | D5: EUR
B6: EURO_CONVICTION | D6: EUR
B7: LEGAL_RATING | D7: EUR | E7: Coverage Suspended
B8: TARGET_PRICE | D8: EUR
B9: TP_PERIOD | D9: EUR
B10: NUM_SH1 | D10: EUR | E10: 404.73546
B11: FREE_FLOAT | D11: EUR | E11: 0.466
B12: BVPS_PUB | D12: EUR | M12: 10.963251 | P12: 10.404538 | S12: 10.40214 | V12: 9.3517537 | Y12: 10.900213 | AB12: 10.862539 | AE12: 11.912824
B13: DPS_PUB | D13: EUR | M13: 0.35968671 | P13: 0.22060785 | S13: 0.40045121 | V13: 0.25 | Y13: 0.38 | AB13: 0.5 | AE13: 0.62
B14: EBITDA_PUB | D14: EUR | M14: 1019 | P14: 884 | S14: 1069 | V14: 1182 | Y14: 1107 | AB14: 1313.5 | AE14: 1681
B15: EPS_PUB | D15: EUR | M15: 1.2240036 | P15: 0.4320298 | S15: 0.98837802 | V15: 0.63154612 | Y15: 0.94172621 | AB15: 1.2714211 | AE15: 1.5911628
B16: EV_ADJ_PUB | D16: EUR | F16: 0 | G16: 0 | H16: 0 | I16: 0 | J16: 0 | K16: 0 | M16: 486.3324 | N16: 0 | O16: 0 | P16: 838.35458 | Q16: 0 | S16: 1109.3546 | V16: 1064.3546 | Y16: 1044.3546 | AB16: 1100.3546 | AE16: 1144.3546
B17: NET_DEBT_PUB | D17: EUR | M17: 473 | P17: 419 | S17: 169 | V17: 635 | W17: -690 | X17: 498 | Y17: 498 | AB17: -24 | AE17: 997
B18: NI_PUB | D18: EUR | M18: 501 | P18: 177 | S18: 406 | V18: 256 | W18: 207 | X18: 169 | Y18: 376 | Z18: 261 | AA18: 247 | AB18: 508 | AC18: 317.05748 | AD18: 321.616 | AE18: 644
B19: EBIT_PUB | D19: EUR | M19: 762 | P19: 465 | S19: 706 | V19: 798 | W19: 347 | X19: 351 | Y19: 698 | Z19: 428 | AA19: 450 | AB19: 878 | AC19: 554.05748 | AD19: 632.616 | AE19: 1189
B20: PTP_PUB | D20: EUR | M20: 678 | P20: 391 | S20: 645 | V20: 605 | W20: 265 | X20: 227 | Y20: 492 | Z20: 337 | AA20: 369 | AB20: 706 | AC20: 442.05748 | AD20: 510.616 | AE20: 955
B21: REVS_PUB | D21: EUR | M21: 10577 | P21: 11329 | S21: 12003 | V21: 10329 | W21: 5149 | X21: 5299 | Y21: 10448 | Z21: 5197 | AA21: 5563 | AB21: 10760 | AC21: 5622 | AD21: 6114 | AE21: 11736
B22: EQ_PUB | D22: EUR | M22: 4736 | P22: 4512 | S22: 4505 | V22: 3874 | Y22: 4501 | AB22: 4705 | AE22: 5122
B23: SALES | D23: EUR | M23: 10577 | P23: 11329 | S23: 12003 | V23: 10329 | Y23: 10448 | AB23: 10760 | AE23: 11736
B24: COST_GD_SD | D24: EUR
B25: SEL_GL_AD | D25: EUR | F25: 0 | G25: 0 | H25: 0 | I25: 0 | J25: 0 | K25: 0 | L25: 0 | M25: 0 | N25: 0 | O25: 0 | P25: 0 | Q25: 0 | S25: 0
B26: OP_COST | D26: EUR | F26: 0 | G26: 0 | H26: 0 | I26: 0 | J26: 0 | K26: 0 | M26: -9558 | N26: 0 | O26: 0 | P26: -10445 | Q26: 0 | S26: -10934 | V26: -8708 | Y26: -8847 | AB26: -9040.5 | AE26: -9560
B27: RD_EXP | D27: EUR
B28: OTH_OP_INC_EXP | D28: EUR | F28: 0 | G28: 0 | H28: 0 | I28: 0 | J28: 0 | K28: 0 | N28: 0 | O28: 0 | Q28: 0 | V28: -439 | Y28: -494 | AB28: -406 | AE28: -495
B29: TOT_OPS_EXP_DDA | D29: EUR | M29: -9815 | P29: -10864 | S29: -11297 | V29: -9531 | Y29: -9750 | AB29: -9882 | AE29: -10547
B30: TOT_OPS_EXP | D30: EUR | M30: -9558 | P30: -10445 | S30: -10934 | V30: -9147 | Y30: -9341 | AB30: -9446.5 | AE30: -10055
B31: EBITDA_CALC | D31: EUR | M31: 1019 | P31: 884 | S31: 1069 | V31: 1182 | Y31: 1107 | AB31: 1313.5 | AE31: 1681
B32: DEPREC | D32: EUR | F32: 0 | G32: 0 | H32: 0 | I32: 0 | J32: 0 | K32: 0 | M32: -257 | N32: 0 | O32: 0 | P32: -306 | Q32: 0 | S32: -287 | V32: -278 | Y32: -279 | AB32: -291 | AE32: -321
B33: GOODWILL_AMORT | D33: EUR | F33: 0 | G33: 0 | H33: 0 | I33: 0 | J33: 0 | K33: 0 | N33: 0 | O33: 0 | P33: -113 | Q33: 0 | S33: -76 | V33: -106 | Y33: -130 | AB33: -144.5 | AE33: -171
B34: EBIT | D34: EUR | M34: 762 | P34: 465 | S34: 706 | V34: 798 | Y34: 698 | AB34: 878 | AE34: 1189
B35: INT_INC_IND | D35: EUR
B36: INT_EXP_IND | D36: EUR
B37: NET_INT_EXP | D37: EUR | M37: -87 | P37: -78 | S37: -65 | V37: -203 | Y37: -174 | AB37: -168 | AE37: -215
B38: ASSOCIATE | D38: EUR | F38: 0 | G38: 0 | H38: 0 | I38: 0 | J38: 0 | K38: 0 | L38: 0 | M38: 3 | N38: 0 | O38: 0 | P38: 4 | Q38: 0 | S38: 4 | V38: 10 | Y38: 3 | AB38: 9 | AE38: 10
B39: PROFIT_ON_DISP | D39: EUR | F39: 0 | G39: 0 | H39: 0 | I39: 0 | J39: 0 | K39: 0 | L39: 0 | M39: 0 | N39: 0 | O39: 0 | P39: 0 | Q39: 0 | S39: 0
B40: OTH_COST_INC | D40: EUR | F40: 0 | G40: 0 | H40: 0 | I40: 0 | J40: 0 | K40: 0 | L40: 0 | M40: 0 | N40: 0 | O40: 0 | P40: 0 | Q40: 0 | S40: 0 | AB40: -13 | AE40: -29
B41: PT_PROF | D41: EUR | M41: 678 | P41: 391 | S41: 645 | V41: 605 | Y41: 527 | AB41: 706 | AE41: 955
...

Sheet Cover Page
A2: GOLDMAN SACHS
A3: GLOBAL INVESTMENT RESEARCH
A4: Multi-Industry
B6: SAF.PA
B7: Published as of | C7: 45919 | I7: Rating Suspended
B9: Team Contacts:
B10: Primary Analysts
B11: Sam Burgess, sam.burgess@gs.com, +44 20 7774-9651 Goldman Sachs International
B12: Supporting Analyst
B13: Jubril Moronfolu, jubril.x.moronfolu@gs.com, +44 20 7051-0985 Goldman Sachs International
B14: Milind Sikchi, milind.sikchi@gs.com, +1 332 245-7985, Goldman Sachs International

Sheet DCF Valuation
B4: Calendar year | C4: 2026 | D4: 2027 | E4: 2028 | F4: 2029 | G4: 2030 | H4: 2031 | I4: 2032 | J4: 2033 | K4: 2034 | L4: 2035 | O4: Adj. EBIT
B5: Adj. EBIT | C5: ='DCF Feed'!C4 -> 6014.9129 | D5: ='DCF Feed'!D4 -> 6844.9824 | E5: ='DCF Feed'!E4 -> 7604.1887 | F5: ='DCF Feed'!F4 -> 8050.4884 | G5: ='DCF Feed'!G4 -> 8490.6102 | O5: 3 | P5: 2025
B6: Tax Rate | C6: =-'DCF Feed'!C10 -> 0.25 | D6: =-'DCF Feed'!D10 -> 0.25 | E6: =-'DCF Feed'!E10 -> 0.25 | F6: =-'DCF Feed'!F10 -> 0.25 | G6: =-'DCF Feed'!G10 -> 0.25 | O6: =12-O5 -> 9 | P6: =+P5+1 -> 2026
B7: NOPAT | C7: =C5*(1-C6) -> 4511.1846 | D7: =D5*(1-D6) -> 5133.7368 | E7: =E5*(1-E6) -> 5703.1415 | F7: =F5*(1-F6) -> 6037.8663 | G7: =G5*(1-G6) -> 6367.9577
B8: D&A | C8: =INDEX('Income Statement'!192:192, MATCH('DCF Valuation'!C4,'Income Statement'!3:3,0)) -> 1819.1631 | D8: =INDEX('Income Statement'!192:192, MATCH('DCF Valuation'!D4,'Income Statement'!3:3,0)) -> 1935.1626 | E8: =INDEX('Income Statement'!192:192, MATCH('DCF Valuation'!E4,'Income Statement'!3:3,0)) -> 2098.9075 | F8: =INDEX('Income Statement'!192:192, MATCH('DCF Valuation'!F4,'Income Statement'!3:3,0)) -> 2201.9772 | G8: =INDEX('Income Statement'!192:192, MATCH('DCF Valuation'!G4,'Income Statement'!3:3,0)) -> 2308.5662 | O8: =(#REF!*0.3)+(C5*0.9) -> #REF!
B9: Change in working capital | C9: =INDEX('Cashflow Statement'!22:22, MATCH('DCF Valuation'!C4,'Cashflow Statement'!2:2,0)) -> 228.01264 | D9: =INDEX('Cashflow Statement'!22:22, MATCH('DCF Valuation'!D4,'Cashflow Statement'!2:2,0)) -> -54.587281 | E9: =INDEX('Cashflow Statement'!22:22, MATCH('DCF Valuation'!E4,'Cashflow Statement'!2:2,0)) -> -501.92972 | F9: =INDEX('Cashflow Statement'!22:22, MATCH('DCF Valuation'!F4,'Cashflow Statement'!2:2,0)) -> -444.89697 | G9: =INDEX('Cashflow Statement'!22:22, MATCH('DCF Valuation'!G4,'Cashflow Statement'!2:2,0)) -> -599.47322
B10: Capex & Intangibles | C10: =(INDEX('Cashflow Statement'!69:69, MATCH('DCF Valuation'!C4,'Cashflow Statement'!2:2,0)))+INDEX('Cashflow Statement'!70:70, MATCH('DCF Valuation'!C4,'Cashflow Statement'!2:2,0)) -> -2103.4318 | D10: =(INDEX('Cashflow Statement'!69:69, MATCH('DCF Valuation'!D4,'Cashflow Statement'!2:2,0)))+INDEX('Cashflow Statement'!70:70, MATCH('DCF Valuation'!D4,'Cashflow Statement'!2:2,0)) -> -2076.8236 | E10: =(INDEX('Cashflow Statement'!69:69, MATCH('DCF Valuation'!E4,'Cashflow Statement'!2:2,0)))+INDEX('Cashflow Statement'!70:70, MATCH('DCF Valuation'!E4,'Cashflow Statement'!2:2,0)) -> -1999.0147 | F10: =(INDEX('Cashflow Statement'!69:69, MATCH('DCF Valuation'!F4,'Cashflow Statement'!2:2,0)))+INDEX('Cashflow Statement'!70:70, MATCH('DCF Valuation'!F4,'Cashflow Statement'!2:2,0)) -> -1853.0033 | G10: =(INDEX('Cashflow Statement'!69:69, MATCH('DCF Valuation'!G4,'Cashflow Statement'!2:2,0)))+INDEX('Cashflow Statement'!70:70, MATCH('DCF Valuation'!G4,'Cashflow Statement'!2:2,0)) -> -1688.3971
B11: Sustainable FCF | C11: =C7+C8+C9+C10 -> 4454.9286 | D11: =D7+D8+D9+D10 -> 4937.4884 | E11: =E7+E8+E9+E10 -> 5301.1047 | F11: =F7+F8+F9+F10 -> 5941.9433 | G11: =G7+G8+G9+G10 -> 6388.6536 | H11: =G11*(1+H12) -> 6737.9225 | I11: =H11*(1+I12) -> 7064.7296 | J11: =I11*(1+J12) -> 7363.8157 | K11: =J11*(1+K12) -> 7630.1468 | L11: =K11*(1+L12) -> 7859.0512
B12: Annual growth | D12: ='DCF Feed'!D5 -> 0.13800192 | E12: ='DCF Feed'!E5 -> 0.11091429 | F12: ='DCF Feed'!F5 -> 0.058691293 | G12: ='DCF Feed'!G5 -> 0.054670199 | H12: =G12 -> 0.054670199 | I12: =H12+(($L$12-$H$12)/4) -> 0.048502649 | J12: =I12+(($L$12-$H$12)/4) -> 0.042335099 | K12: =J12+(($L$12-$H$12)/4) -> 0.03616755 | L12: =$D$33 -> 0.03
B13: WACC | D13: =$D$32 -> 0.07325 | E13: =$D$32 -> 0.07325 | F13: =$D$32 -> 0.07325 | G13: =$D$32 -> 0.07325 | H13: =$D$32 -> 0.07325 | I13: =$D$32 -> 0.07325 | J13: =$D$32 -> 0.07325 | K13: =$D$32 -> 0.07325 | L13: =$D$32 -> 0.07325
B14: Discount Factor | D14: 1 | E14: =D14+1 -> 2 | F14: =E14+1 -> 3 | G14: =F14+1 -> 4 | H14: =G14+1 -> 5 | I14: =H14+1 -> 6 | J14: =I14+1 -> 7 | K14: =J14+1 -> 8 | L14: =K14+1 -> 9
B15: Discounted FCF | D15: =D11/((1+D13)^D14) -> 4600.5017 | E15: =E11/((1+E13)^E14) -> 4602.1905 | F15: =F11/((1+F13)^F14) -> 4806.4653 | G15: =G11/((1+G13)^G14) -> 4815.1049 | H15: =H11/((1+H13)^H14) -> 4731.7471 | I15: =I11/((1+I13)^I14) -> 4622.641 | J15: =J11/((1+J13)^J14) -> 4489.4861 | K15: =K11/((1+K13)^K14) -> 4334.3674 | L15: =L11/((1+L13)^L14) -> 4159.7003 | M15: =SUM(C15:L15) -> 41162.204
B18: DCF Valuation
B19: Risk free rate | C19: % | D19: 0.035
B20: Equity Risk premium | C20: % | D20: 0.045
B22: Beta | C22: x | D22: 0.85
B23: Cost of equity | C23: % | D23: =D19+D22*(D20) -> 0.07325
B25: Cost of debt | C25: % | D25: 0.04
B26: Tax | C26: % | D26: =C6 -> 0.25
B27: Post tax cost of debt | C27: % | D27: =D25*(1-D26) -> 0.03
B29: MV Equity / (MV Equity + Net Debt) | C29: % | D29: 1
B30: Net Debt / (MV Equity + Net Debt) | C30: % | D30: 0
B32: WACC | C32: % | D32: =(D23*D29)+(D30*D27) -> 0.07325
B33: Terminal growth rate | C33: % | D33: 0.03
B35: DCF Valuation
B36: Sum of discounted cash flows | C36: EUR (mn) | D36: =M15 -> 41162.204
B37: Undiscounted value of TV | C37: EUR (mn) | D37: =L11/(D32-D33) -> 181712.17
B38: Discounted value of TV | C38: EUR (mn) | D38: =D37/(1+L13)^L14 -> 96178.043
B39: Enterprise value | C39: EUR (mn) | D39: =D36+D38 -> 137340.25
B40: Net cash (debt) and lease | C40: EUR (mn) | D40: ='DCF Feed'!C8 -> 3382.4906
B41: Pension underfunding | C41: EUR (mn) | D41: ='DCF Feed'!C9 -> -23
B42: Pension tax shield | C42: EUR (mn) | D42: =-D41*(D26) -> 5.75
B43: Equity value | C43: EUR (mn) | D43: =SUM(D39:D42) -> 140705.49
B44: Number of shares | C44: million | D44: ='DCF Feed'!C12 -> 411.74891
B45: Equity value per share | C45: EUR | D45: =ROUND(D43/D44,-1) -> 340

Sheet Sheet5

Sheet Sheet4

Sheet MigrationOutput_QP_SAF.PA
B2: Congratulations! You have successfully migrated | F2: =HYPERLINK("[cleanSafran model WIP.xlsx]SAF.PA_Exchange_Sheet!$A$1","SAF.PA_Exchange_Sheet") -> SAF.PA_Exchange_Sheet
B3: Please review non-migrated data on: | F3: =HYPERLINK("[cleanSafran model WIP.xlsx]QP_SAF.PA_migrated!$A$1","QP_SAF.PA_migrated") -> QP_SAF.PA_migrated
B5: Final cleanup Items
B6: Keyword | C6: Description | E6: Action

Sheet QP_SAF.PA_migrated
A1: Quantum submission sheet for SAF.PA | F1: 1998 | G1: 1999 | H1: 2000 | I1: 2001 | J1: 2002 | K1: 2003 | L1: 2004 | M1: 2005 | N1: 2006 H1 | O1: 2006 H2 | P1: 2006 | Q1: 2007 H1 | R1: 2007 H2 | S1: 2007 | T1: 2008 H1 | U1: 2008 H2 | V1: 2008 | W1: 2009 H1 | X1: 2009 H2 | Y1: 2009 | Z1: 2010 H1 | AA1: 2010 H2 | AB1: 2010 | AC1: 2011 H1 | AD1: 2011 H2 | AE1: 2011 | AF1: 2012 | AG1: 2013 | AH1: 2014 | AI1: 2015 | AJ1: 2016 | AK1: 2017 | AL1: 2018 | AM1: 2019 | AN1: 2020
F2: Actual | G2: Actual | H2: Actual | I2: Actual | J2: Actual | K2: Actual | L2: Actual | M2: Actual | N2: Actual | O2: Actual | P2: Actual | Q2: Actual | R2: Actual | S2: Actual | T2: Actual | U2: Actual | V2: Actual | W2: Actual | X2: Actual | Y2: Actual | Z2: Actual | AA2: Actual | AB2: Actual | AC2: Actual | AD2: Actual | AE2: Actual | AF2: Actual | AG2: Estimate | AH2: Estimate | AI2: Estimate | AJ2: Estimate | AK2: Estimate | AL2: Estimate | AM2: Estimate | AN2: Estimate
F3: 36160 | G3: 36525 | H3: 36891 | I3: 37256 | J3: 37621 | K3: 37986 | L3: 38352 | M3: 38717 | N3: 38898 | O3: 39082 | P3: 39082 | Q3: 39263 | R3: 39447 | S3: 39447 | T3: 39629 | U3: 39813 | V3: 39813 | W3: 39994 | X3: 40178 | Y3: 40178 | Z3: 40359 | AA3: 40543 | AB3: 40543 | AC3: 40724 | AD3: 40908 | AE3: 40908 | AF3: 41274 | AG3: 41639 | AH3: 42004 | AI3: 42369 | AJ3: 42735 | AK3: 43100 | AL3: 43465 | AM3: 43830 | AN3: 44196
A5: Reference data | D5: #0
B6: Ticker | C6: Ticker_1 | E6: SAF.PA
B7: Company name | C7: Company name | E7: Safran
B8: Interim type | C8: Interim type | E8: Semiannual
B9: Reporting currency | C9: Reporting currency | E9: EUR
B10: Publishing currency | C10: Publishing currency | E10: EUR
B11: Pricing currency | C11: Pricing currency_1 | E11: EUR
A13: General Information | D13: #10
B14: Pan Europe Investment List | C14: EURO_LIST
B15: Pan Europe Conviction List | C15: EURO_CONVICTION
B16: Legal rating | C16: LEGAL_RATING
B17: Target price | C17: TARGET_PRICE | D17: EUR
B18: Target price period | C18: TP_PERIOD
B19: Current shares outstanding (mn) | C19: NUM_SH1
B20: Free float | C20: FREE_FLOAT
A22: Publishing Items | D22: #20
B23: Book value per share, BVPS (Pub) | C23: BVPS_PUB | D23: EUR | AK23: =AK116/AK75 -> #REF! | AL23: =AL116/AL75 -> #REF! | AM23: =AM116/AM75 -> #REF! | AN23: =AN116/AN75 -> #REF!
B24: DPS, dividend per share (Pub) | C24: DPS_PUB | D24: EUR | AK24: =#REF! -> #REF! | AL24: =#REF! -> #REF! | AM24: =#REF! -> #REF! | AN24: =#REF! -> #REF!
B25: EBITDA (Pub) | C25: EBITDA_PUB | D25: EUR | AK25: =#REF! -> #REF! | AL25: =#REF! -> #REF! | AM25: =#REF! -> #REF! | AN25: =#REF! -> #REF! | AO25: CH: GS A&D standard EBITDA (company defined underlying EBIT exclusing any additional depreciation, amortisation or impairments)
B26: EPS (Pub) | C26: EPS_PUB | D26: EUR | AK26: =#REF! -> #REF! | AL26: =#REF! -> #REF! | AM26: =#REF! -> #REF! | AN26: =#REF! -> #REF!
B27: EV adjustment (Pub) | C27: EV_ADJ_PUB | D27: EUR
B28: Long-term EPS growth estimate (Pub)
B29: Net debt (Pub) | C29: NET_DEBT_PUB | D29: EUR | AK29: =#REF! -> #REF! | AL29: =#REF! -> #REF! | AM29: =#REF! -> #REF! | AN29: =#REF! -> #REF!
B30: Net income (Pub) | C30: NI_PUB | D30: EUR | AK30: =#REF! -> #REF! | AL30: =#REF! -> #REF! | AM30: =#REF! -> #REF! | AN30: =#REF! -> #REF!
B31: EBIT, operating profit (Pub) | C31: EBIT_PUB | D31: EUR | AK31: =#REF! -> #REF! | AL31: =#REF! -> #REF! | AM31: =#REF! -> #REF! | AN31: =#REF! -> #REF!
B32: Pre-tax profit (Pub) | C32: PTP_PUB | D32: EUR | AK32: =#REF! -> #REF! | AL32: =#REF! -> #REF! | AM32: =#REF! -> #REF! | AN32: =#REF! -> #REF!
B33: Sales, revenue (Pub) | C33: REVS_PUB | D33: EUR | AK33: =#REF! -> #REF! | AL33: =#REF! -> #REF! | AM33: =#REF! -> #REF! | AN33: =#REF! -> #REF!
B34: Total shareholders' equity (Pub) | C34: EQ_PUB | D34: EUR | AK34: =AK116 -> #REF! | AL34: =AL116 -> #REF! | AM34: =AM116 -> #REF! | AN34: =AN116 -> #REF!
A36: Other & Corporate Income Statement | D36: #29
B37: EBITDA (Pub) | D37: EUR | M37: 724
B38: Pre-tax profit (Pub) | D38: EUR | M38: 383
B39: Net income (Pub) | D39: EUR | M39: 279.96755
B40: EPS (Pub) | D40: EUR | M40: 0.68399457
A42: Income Statement | D42: #30
B43: Sales, net revenue | C43: SALES | D43: EUR | AK43: =#REF! -> #REF! | AL43: =#REF! -> #REF! | AM43: =#REF! -> #REF! | AN43: =#REF! -> #REF!
B44: Cost of goods sold, COGS | C44: COST_GD_SD | D44: EUR
B45: SG&A, selling, general and admin. expense | C45: SEL_GL_AD | D45: EUR
...

Sheet DCF
B1: =C34 -> 300 | Z1: SAF.PA
B2: Valuation date | C2: 45918
B3: Explicit growth (EBIT) | C3: ='DCF Feed'!H4 -> 0.1039199
B4: Mid-term growth | C4: 0.1
B5: Long term growth | C5: 0.03
B6: Discount rate | C6: 0.09
B7: Tax rate | C7: =-'DCF Feed'!E10 -> 0.25
B8: Cash conversion | C8: 1.05
B9: EV/EBIT | C9: =N19*(1-C7) -> 22.912496
B12: Calendar year | C12: =YEAR(TODAY()) -> 2025 | D12: =C12+1 -> 2026 | E12: =D12+1 -> 2027 | F12: =E12+1 -> 2028 | G12: =F12+1 -> 2029 | H12: =G12+1 -> 2030 | I12: =H12+1 -> 2031 | J12: =I12+1 -> 2032 | K12: =J12+1 -> 2033 | ... M12: =L12+1 -> 2035 | N12: Terminal value
C13: 0 | D13: =C13+1 -> 1 | E13: =D13+1 -> 2 | F13: =E13+1 -> 3 | G13: =F13+1 -> 4 | H13: =G13+1 -> 5 | I13: =H13+1 -> 6 | J13: =I13+1 -> 7 | K13: =J13+1 -> 8 | ... M13: =L13+1 -> 10
B14: =C2+365 -> 46283 | C14: 45809 | D14: =C14+365 -> 46174 | E14: =D14+365 -> 46539 | F14: =E14+365 -> 46904 | G14: =F14+365 -> 47269 | H14: =G14+365 -> 47634 | I14: =H14+365 -> 47999 | J14: =I14+365 -> 48364 | K14: =J14+365 -> 48729 | ... M14: =L14+365 -> 49459
B15: Cumulative growth | C15: 1 | D15: =C15*(1+D16) -> 1.1613904 | E15: =D15*(1+E16) -> 1.3216646 | F15: =E15*(1+F16) -> 1.468256 | G15: =F15*(1+G16) -> 1.5544299 | H15: =C15*(1+C3)^5 -> 1.6394109 | I15: =H15*(1+I16) -> 1.803352 | J15: =I15*(1+J16) -> 1.9521285 | K15: =J15*(1+K16) -> 2.0790169 | L15: =K15*(1+L16) -> 2.1777702 | M15: =L15*(1+M16) -> 2.2431033 | N15: =M15/(C6-C5) -> 37.385054
B16: Annual growth | D16: =INDEX('DCF Feed'!5:5,MATCH(DCF!D12,'DCF Feed'!1:1,0)) -> 0.16139044 | E16: =INDEX('DCF Feed'!5:5,MATCH(DCF!E12,'DCF Feed'!1:1,0)) -> 0.13800192 | F16: =INDEX('DCF Feed'!5:5,MATCH(DCF!F12,'DCF Feed'!1:1,0)) -> 0.11091429 | G16: =INDEX('DCF Feed'!5:5,MATCH(DCF!G12,'DCF Feed'!1:1,0)) -> 0.058691293 | H16: =INDEX('DCF Feed'!5:5,MATCH(DCF!H12,'DCF Feed'!1:1,0)) -> 0.054670199 | I16: =$C$4 -> 0.1 | J16: =I16+(($M$16-$I$16)/4) -> 0.0825 | K16: =J16+(($M$16-$I$16)/4) -> 0.065 | L16: =K16+(($M$16-$I$16)/4) -> 0.0475 | M16: =$C$5 -> 0.03
B17: Cash conversion | D17: =INDEX('DCF Feed'!7:7,MATCH(DCF!D12,'DCF Feed'!1:1,0)) -> 0.95509426 | E17: =INDEX('DCF Feed'!7:7,MATCH(DCF!E12,'DCF Feed'!1:1,0)) -> 0.97572869 | F17: =INDEX('DCF Feed'!7:7,MATCH(DCF!F12,'DCF Feed'!1:1,0)) -> 0.95005885 | G17: =INDEX('DCF Feed'!7:7,MATCH(DCF!G12,'DCF Feed'!1:1,0)) -> 0.99026338 | H17: =INDEX('DCF Feed'!7:7,MATCH(DCF!H12,'DCF Feed'!1:1,0)) -> 1.00393 | I17: =$C$8 -> 1.05 | J17: =$C$8 -> 1.05 | K17: =$C$8 -> 1.05 | L17: =$C$8 -> 1.05 | M17: =$C$8 -> 1.05
B18: Discounted value | D18: =1/(1+$C$6)^((D14-$B$14)/365) -> 1.0260693 | E18: =1/(1+$C$6)^((E14-$B$14)/365) -> 0.94134795 | F18: =1/(1+$C$6)^((F14-$B$14)/365) -> 0.86362197 | G18: =1/(1+$C$6)^((G14-$B$14)/365) -> 0.79231374 | H18: =1/(1+$C$6)^((H14-$B$14)/365) -> 0.72689334 | I18: =1/(1+$C$6)^((I14-$B$14)/365) -> 0.66687462 | J18: =1/(1+$C$6)^((J14-$B$14)/365) -> 0.61181158 | K18: =1/(1+$C$6)^((K14-$B$14)/365) -> 0.56129503 | ... M18: =1/(1+$C$6)^((M14-$B$14)/365) -> 0.47243079
B19: PV | D19: =D15*D17*D18 -> 1.1381543 | E19: =E15*E17*E18 -> 1.2139492 | F19: =F15*F17*F18 -> 1.2046919 | G19: =G15*G17*G18 -> 1.2196046 | H19: =H15*H17*H18 -> 1.1963601 | I19: =I15*I17*I18 -> 1.2627401 | J19: =J15*J17*J18 -> 1.2540516 | K19: =K15*K17*K18 -> 1.2252889 | L19: =L15*L17*L18 -> 1.1775139 | M19: =(M15+N15)*M17*M18 -> 19.65764 | N19: =SUM(D19:M19) -> 30.549995
B24: Year | C24: =C12 -> 2025
B25: Target EV/EBIT | C25: =C9 -> 22.912496
B26: EBIT | C26: =INDEX('DCF Feed'!4:4,MATCH(DCF!$C$24,'DCF Feed'!$1:$1,0)) -> 5179.0618
B27: Target EV | C27: =C25*C26 -> 118665.23
B28: Net Cash (Debt) | C28: ='DCF Feed'!B8 -> 2168.7677
B29: Other
B30: Pension underfunding | C30: =INDEX('DCF Feed'!9:9,MATCH(DCF!C24,'DCF Feed'!1:1,0)) -> -23
B31: Pension tax shield | C31: =-C30*C7 -> 5.75
B32: Target Market Cap | C32: =SUM(C27:C31) -> 120816.75
B33: Number of shares | C33: ='DCF Feed'!E12 -> 402.77548
B34: Target price | C34: =MROUND(C32/C33,1) -> 300
B35: Current Share Price | C35: Error: RTD method of WorksheetFunction class failed
B36: Upside/(Downside) | C36: =C34/C35-1 -> #VALUE!
B39: Share Price | D39: WACC
C40: =$C$34 -> 300 | D40: =E40-0.5% -> 0.08 | E40: =F40-0.5% -> 0.085 | F40: 0.09 | G40: =F40+0.5% -> 0.095 | H40: =G40+0.5% -> 0.1
B41: 5Yr EBIT CAGR | C41: =C42-2% -> 0.0639199 | D41: 307 | E41: 280 | F41: 258 | G41: 239 | H41: 223
C42: =C43-2% -> 0.0839199 | D42: 331 | E42: 302 | F42: 278 | G42: 258 | H42: 240
B43: Explicit PROF Grow | C43: 0.1039199 | D43: 358 | E43: 326 | F43: 300 | G43: 278 | H43: 258
C44: =C43+2% -> 0.1239199 | D44: 387 | E44: 352 | F44: 323 | G44: 299 | H44: 278
C45: =C44+2% -> 0.1439199 | D45: 418 | E45: 380 | F45: 348 | G45: 322 | H45: 299
D48: Cash Conversion Ratio | F48: CC
C49: =$C$34 -> 300 | D49: =E49-10% -> 0.85 | E49: =F49-10% -> 0.95 | F49: 1.05 | G49: =F49+10% -> 1.15 | H49: =G49+10% -> 1.25
B50: 5Yr EBIT CAGR | C50: =C51-3% -> 0.0439199 | D50: 205 | E50: 222 | F50: 239 | G50: 256 | H50: 274
...

Sheet DCF Feed
A1: €mn | B1: 2025 | C1: =B1+1 -> 2026 | D1: =C1+1 -> 2027 | E1: =D1+1 -> 2028 | F1: =E1+1 -> 2029 | G1: =F1+1 -> 2030 | H1: 5yr. CAGR
A2: Sales | B2: =INDEX('Income Statement'!39:39,MATCH(B1,'Income Statement'!38:38,0)) -> 30995.967 | C2: =INDEX('Income Statement'!39:39,MATCH(C1,'Income Statement'!38:38,0)) -> 34520.707 | D2: =INDEX('Income Statement'!39:39,MATCH(D1,'Income Statement'!38:38,0)) -> 38170.591 | E2: =INDEX('Income Statement'!39:39,MATCH(E1,'Income Statement'!38:38,0)) -> 41400.419 | F2: =INDEX('Income Statement'!39:39,MATCH(F1,'Income Statement'!38:38,0)) -> 43433.442 | G2: =INDEX('Income Statement'!39:39,MATCH(G1,'Income Statement'!38:38,0)) -> 45535.884 | H2: =(G2/B2)^(1/5)-1 -> 0.079965089
A3: Sales growth | C3: =C2/B2-1 -> 0.11371608 | D3: =D2/C2-1 -> 0.10573028 | E3: =E2/D2-1 -> 0.084615614 | F3: =F2/E2-1 -> 0.049106341 | G3: =G2/F2-1 -> 0.048406068
A4: Adj. EBIT | B4: =INDEX('Income Statement'!74:74,MATCH(B1,'Income Statement'!$38:$38,0)) -> 5179.0618 | C4: =INDEX('Income Statement'!74:74,MATCH(C1,'Income Statement'!$38:$38,0)) -> 6014.9129 | D4: =INDEX('Income Statement'!74:74,MATCH(D1,'Income Statement'!$38:$38,0)) -> 6844.9824 | E4: =INDEX('Income Statement'!74:74,MATCH(E1,'Income Statement'!$38:$38,0)) -> 7604.1887 | F4: =INDEX('Income Statement'!74:74,MATCH(F1,'Income Statement'!$38:$38,0)) -> 8050.4884 | G4: =INDEX('Income Statement'!74:74,MATCH(G1,'Income Statement'!$38:$38,0)) -> 8490.6102 | H4: =(G4/B4)^(1/5)-1 -> 0.1039199
A5: Growth | C5: =C4/B4-1 -> 0.16139044 | D5: =D4/C4-1 -> 0.13800192 | E5: =E4/D4-1 -> 0.11091429 | F5: =F4/E4-1 -> 0.058691293 | G5: =G4/F4-1 -> 0.054670199
A6: GS Defined Op Cash Flow | B6: =INDEX('Cashflow Statement'!71:71, MATCH('DCF Feed'!B1,'Cashflow Statement'!2:2,0)) -> 4768.3913 | C6: =INDEX('Cashflow Statement'!71:71, MATCH('DCF Feed'!C1,'Cashflow Statement'!2:2,0)) -> 5744.8087 | D6: =INDEX('Cashflow Statement'!71:71, MATCH('DCF Feed'!D1,'Cashflow Statement'!2:2,0)) -> 6678.8457 | E6: =INDEX('Cashflow Statement'!71:71, MATCH('DCF Feed'!E1,'Cashflow Statement'!2:2,0)) -> 7224.4268 | F6: =INDEX('Cashflow Statement'!71:71, MATCH('DCF Feed'!F1,'Cashflow Statement'!2:2,0)) -> 7972.1038 | G6: =INDEX('Cashflow Statement'!71:71, MATCH('DCF Feed'!G1,'Cashflow Statement'!2:2,0)) -> 8523.9782 | H6: =(G6/B6)^(1/5)-1 -> 0.12319222
A7: Cash Conversion | B7: =B6/B4 -> 0.92070562 | C7: =C6/C4 -> 0.95509426 | D7: =D6/D4 -> 0.97572869 | E7: =E6/E4 -> 0.95005885 | F7: =F6/F4 -> 0.99026338 | G7: =G6/G4 -> 1.00393 | H7: =AVERAGE(B7:G7) -> 0.96596346
A8: Net Cash (Debt) | B8: =INDEX('Balance Sheet'!$93:$93,MATCH('DCF Feed'!B1,'Balance Sheet'!$88:$88,0)) -> 2168.7677 | C8: =INDEX('Balance Sheet'!93:93,MATCH('DCF Feed'!C1,'Balance Sheet'!88:88,0)) -> 3382.4906 | D8: =INDEX('Balance Sheet'!93:93,MATCH('DCF Feed'!D1,'Balance Sheet'!88:88,0)) -> 4867.2613 | E8: =INDEX('Balance Sheet'!93:93,MATCH('DCF Feed'!E1,'Balance Sheet'!88:88,0)) -> 6676.9131 | F8: =INDEX('Balance Sheet'!93:93,MATCH('DCF Feed'!F1,'Balance Sheet'!88:88,0)) -> 10162.36 | G8: =INDEX('Balance Sheet'!93:93,MATCH('DCF Feed'!G1,'Balance Sheet'!88:88,0)) -> 13985.148
A9: Pension underfunding | B9: =INDEX('Balance Sheet'!$140:$140,MATCH('DCF Feed'!B1,'Balance Sheet'!$88:$88,0)) -> -23 | C9: =INDEX('Balance Sheet'!$140:$140,MATCH('DCF Feed'!C1,'Balance Sheet'!$88:$88,0)) -> -23 | D9: =INDEX('Balance Sheet'!$140:$140,MATCH('DCF Feed'!D1,'Balance Sheet'!$88:$88,0)) -> -23 | E9: =INDEX('Balance Sheet'!$140:$140,MATCH('DCF Feed'!E1,'Balance Sheet'!$88:$88,0)) -> -23 | F9: =INDEX('Balance Sheet'!$140:$140,MATCH('DCF Feed'!F1,'Balance Sheet'!$88:$88,0)) -> -23 | G9: =INDEX('Balance Sheet'!$140:$140,MATCH('DCF Feed'!G1,'Balance Sheet'!$88:$88,0)) -> -23
A10: Tax rate (adjusted) | B10: =INDEX('Income Statement'!91:91,MATCH(B1,'Income Statement'!$38:$38,0)) -> -0.32 | C10: =INDEX('Income Statement'!91:91,MATCH(C1,'Income Statement'!$38:$38,0)) -> -0.25 | D10: =INDEX('Income Statement'!91:91,MATCH(D1,'Income Statement'!$38:$38,0)) -> -0.25 | E10: =INDEX('Income Statement'!91:91,MATCH(E1,'Income Statement'!$38:$38,0)) -> -0.25 | F10: =INDEX('Income Statement'!91:91,MATCH(F1,'Income Statement'!$38:$38,0)) -> -0.25 | G10: =INDEX('Income Statement'!91:91,MATCH(G1,'Income Statement'!$38:$38,0)) -> -0.25
A11: Other
A12: No. of shares | B12: =INDEX('Income Statement'!117:117,MATCH(B1,'Income Statement'!$38:$38,0))/1000 -> 416.23563 | C12: =INDEX('Income Statement'!117:117,MATCH(C1,'Income Statement'!$38:$38,0))/1000 -> 411.74891 | D12: =INDEX('Income Statement'!117:117,MATCH(D1,'Income Statement'!$38:$38,0))/1000 -> 407.2622 | E12: =INDEX('Income Statement'!117:117,MATCH(E1,'Income Statement'!$38:$38,0))/1000 -> 402.77548 | F12: =INDEX('Income Statement'!117:117,MATCH(F1,'Income Statement'!$38:$38,0))/1000 -> 402.77548 | G12: =INDEX('Income Statement'!117:117,MATCH(G1,'Income Statement'!$38:$38,0))/1000 -> 402.77548

Sheet Income Statement
A1: ='DCF Valuation'!D45 -> 340
A2: Divisional Summary
A3: Revenues | B3: =B38 -> 2000 | C3: =C38 -> 2001 | D3: =D38 -> 2002 | E3: =E38 -> 2003 | F3: =F38 -> 2004 | G3: =G38 -> 2005 | H3: =H38 -> 2006 | I3: =I38 -> 2007 | ... Z3: =Z38 -> 2024 | AA3: =Z3+1 -> 2025 | AB3: =AA3+1 -> 2026 | AC3: =AB3+1 -> 2027 | AD3: =AC3+1 -> 2028 | AE3: =AD3+1 -> 2029 | AF3: =AE3+1 -> 2030
A4: Adjusted Revenues
A5: Aerospace Propulsion | H5: 5073 | I5: 5917 | J5: 5803 | K5: 5673 | L5: 5604 | M5: 6110 | N5: 7005 | O5: ='Aerospace Propulsion Division'!O6 -> 7589 | P5: ='Aerospace Propulsion Division'!P6 -> 8153 | Q5: ='Aerospace Propulsion Division'!Q6 -> 9319 | R5: ='Aerospace Propulsion Division'!R6 -> 9391 | S5: ='Aerospace Propulsion Division'!S6 -> 9357 | T5: ='Aerospace Propulsion Division'!T6 -> 10579 | U5: ='Aerospace Propulsion Division'!U6 -> 12045 | V5: ='Aerospace Propulsion Division'!V6 -> 7663 | ... Z5: ='Aerospace Propulsion Division'!Z6 -> 13652 | AA5: =Z5*(1+AA12) -> 15370.63 | AB5: =AA5*(1+AB12) -> 17237.134 | AC5: =AB5*(1+AC12) -> 19144.031 | AD5: =AC5*(1+AD12) -> 20696.681 | AE5: =AD5*(1+AE12) -> 21724.522 | AF5: =AE5*(1+AF12) -> 22805.291 | AG5: =(AD5/Z5)^(1/4)-1 -> 0.10962467
A6: Equipment & Defense | T6: ='Equipment and Defense'!T6 -> 7942 | U6: ='Equipment and Defense'!U6 -> 9256 | V6: ='Equipment and Defense'!V6 -> 6893 | W6: ='Equipment and Defense'!W6 -> 6325 | X6: ='Equipment and Defense'!X6 -> 7535 | Y6: ='Equipment and Defense'!Y6 -> 8835 | Z6: ='Equipment and Defense'!Z6 -> 10618 | AA6: =Z6*(1+AA13) -> 12191.477 | AB6: =AA6*(1+AB13) -> 13490.448 | AC6: =AB6*(1+AC13) -> 14881.972 | AD6: =AC6*(1+AD13) -> 16221.876 | AE6: =AD6*(1+AE13) -> 17082.303 | AF6: =AE6*(1+AF13) -> 17972.921
A7: Aircraft Interiors | T7: ='Aircraft Interiors Division'!H6 -> 2511 | U7: ='Aircraft Interiors Division'!I6 -> 3321 | V7: ='Aircraft Interiors Division'!J6 -> 1922 | W7: ='Aircraft Interiors Division'!K6 -> 1475 | X7: ='Aircraft Interiors Division'!L6 -> 1978 | Y7: ='Aircraft Interiors Division'!M6 -> 2477 | Z7: ='Aircraft Interiors Division'!N6 -> 3037 | AA7: =Z7*(1+AA14) -> 3423.86 | AB7: =AA7*(1+AB14) -> 3783.125 | AC7: =AB7*(1+AC14) -> 4134.5881 | AD7: =AC7*(1+AD14) -> 4471.8616 | AE7: =AD7*(1+AE14) -> 4616.6169 | AF7: =AE7*(1+AF14) -> 4747.6719
A8: Other | H8: =H9-H5 -> 6256 | I8: =I9-I5 -> 4305 | J8: =J9-J5 -> 4526 | K8: =K9-K5 -> 4775 | L8: =L9-L5 -> 5156 | M8: =M9-M5 -> 5626 | N8: =N9-N5 -> 6555 | O8: =O9-O5 -> 6774 | ... S8: =S9-S5 -> 6596 | T8: 18 | U8: 18 | V8: 20 | W8: 18 | X8: 16 | Y8: 11 | Z8: 10 | AA8: =Z8 -> 10 | AB8: =AA8 -> 10 | AC8: =AB8 -> 10 | AD8: =AC8 -> 10 | AE8: =AD8 -> 10 | AF8: =AE8 -> 10
A9: Group | H9: 11329 | I9: 10222 | J9: 10329 | K9: 10448 | L9: 10760 | M9: 11736 | N9: 13560 | O9: 14363 | P9: 15355 | Q9: 17414 | R9: 15781 | S9: 15953 | T9: =SUM(T5,T6,T7,T8) -> 21050 | U9: =SUM(U5,U6,U7,U8) -> 24640 | V9: =SUM(V5,V6,V7,V8) -> 16498 | W9: =SUM(W5,W6,W7,W8) -> 15257 | X9: =SUM(X5,X6,X7,X8) -> 19035 | Y9: =SUM(Y5,Y6,Y7,Y8) -> 23199 | Z9: =SUM(Z5,Z6,Z7,Z8) -> 27317 | AA9: =SUM(AA5,AA6,AA7,AA8) -> 30995.967 | ... AF9: =SUM(AF5,AF6,AF7,AF8) -> 45535.884 | AG9: Below on Revenues for all years
A11: Revenue Growth
A12: Aerospace Propulsion | I12: =I5/H5-1 -> 0.16637098 | J12: =J5/I5-1 -> -0.01926652 | K12: =K5/J5-1 -> -0.022402206 | L12: =L5/K5-1 -> -0.012162877 | M12: =M5/L5-1 -> 0.090292648 | N12: =N5/M5-1 -> 0.14648118 | O12: =O5/N5-1 -> 0.083369022 | P12: =P5/O5-1 -> 0.074318092 | ... Z12: =Z5/Y5-1 -> 0.1495453 | AA12: ='Aerospace Propulsion Division'!AA7 -> 0.12588853 | AB12: ='Aerospace Propulsion Division'!AB7 -> 0.12143315 | AC12: ='Aerospace Propulsion Division'!AC7 -> 0.11062724 | AD12: ='Aerospace Propulsion Division'!AD7 -> 0.081103612 | AE12: ='Aerospace Propulsion Division'!AE7 -> 0.049662117 | AF12: ='Aerospace Propulsion Division'!AF7 -> 0.049748801
A13: Equipment & Defense | U13: =U6/T6-1 -> 0.16544951 | V13: =V6/U6-1 -> -0.25529386 | W13: =W6/V6-1 -> -0.082402437 | X13: =X6/W6-1 -> 0.19130435 | Y13: =Y6/X6-1 -> 0.1725282 | Z13: =Z6/Y6-1 -> 0.20181098 | AA13: ='Equipment and Defense'!AA7 -> 0.14818956 | AB13: ='Equipment and Defense'!AB7 -> 0.10654745 | AC13: ='Equipment and Defense'!AC7 -> 0.10314887 | AD13: ='Equipment and Defense'!AD7 -> 0.090035408 | AE13: ='Equipment and Defense'!AE7 -> 0.053041139 | AF13: ='Equipment and Defense'!AF7 -> 0.052136895
A14: Aircraft Interiors | U14: =U7/T7-1 -> 0.32258065 | V14: =V7/U7-1 -> -0.42125866 | W14: =W7/V7-1 -> -0.23257024 | X14: =X7/W7-1 -> 0.34101695 | Y14: =Y7/X7-1 -> 0.25227503 | Z14: =Z7/Y7-1 -> 0.22607994 | AA14: ='Aircraft Interiors Division'!O7 -> 0.12738229 | AB14: ='Aircraft Interiors Division'!P7 -> 0.10492982 | AC14: ='Aircraft Interiors Division'!Q7 -> 0.092902847 | AD14: ='Aircraft Interiors Division'!R7 -> 0.081573672 | AE14: ='Aircraft Interiors Division'!S7 -> 0.032370256 | AF14: ='Aircraft Interiors Division'!T7 -> 0.028387668
A15: Other | K15: =K8/J8-1 -> 0.055015466 | L15: =L8/K8-1 -> 0.079790576 | M15: =M8/L8-1 -> 0.091155935 | N15: =N8/M8-1 -> 0.1651262 | O15: =O8/N8-1 -> 0.033409611 | P15: =P8/O8-1 -> 0.063182758 | Q15: =Q8/P8-1 -> 0.12399334 | R15: =R8/Q8-1 -> -0.21062384 | ... AF15: =AF8/AE8-1 -> 0
A16: Group | I16: =I9/H9-1 -> -0.097713832 | J16: =J9/I9-1 -> 0.010467619 | K16: =K9/J9-1 -> 0.01152096 | L16: =L9/K9-1 -> 0.029862175 | M16: =M9/L9-1 -> 0.09070632 | N16: =N9/M9-1 -> 0.15541922 | O16: =O9/N9-1 -> 0.059218289 | P16: =P9/O9-1 -> 0.069066351 | ... AF16: =AF9/AE9-1 -> 0.048406068
A18: Adj. EBIT
A19: Aerospace Propulsion | H19: 561 | I19: 636 | J19: 584 | K19: 628 | L19: 663 | M19: 909 | N19: 1076 | O19: ='Aerospace Propulsion Division'!O19 -> 0 | P19: ='Aerospace Propulsion Division'!P19 -> 0 | Q19: ='Aerospace Propulsion Division'!Q19 -> 0 | R19: ='Aerospace Propulsion Division'!R19 -> 0 | S19: 1516 | T19: ='Aerospace Propulsion Division'!T19 -> 2030 | U19: ='Aerospace Propulsion Division'!U19 -> 2485 | V19: ='Aerospace Propulsion Division'!V19 -> 1192 | W19: ='Aerospace Propulsion Division'!W19 -> 1342 | X19: ='Aerospace Propulsion Division'!X19 -> 1710 | Y19: ='Aerospace Propulsion Division'!Y19 -> 2390 | Z19: ='Aerospace Propulsion Division'!Z19 -> 2819 | AA19: =AA5*AA26 -> 3498.7921 | AB19: =AB5*AB26 -> 3987.5039 | AC19: =AC5*AC26 -> 4435.8248 | AD19: =AD5*AD26 -> 4851.2678 | AE19: =AE5*AE26 -> 5134.0822 | AF19: =AF5*AF26 -> 5445.7704 | AG19: =(AF19/AA19)^(1/5)-1 -> 0.092517087
A20: Equipment & Defense | S20: 619 | T20: ='Equipment and Defense'!T14 -> 992 | U20: ='Equipment and Defense'!U14 -> 1209 | V20: ='Equipment and Defense'!V14 -> 687 | W20: ='Equipment and Defense'!W14 -> 650 | X20: ='Equipment and Defense'!X14 -> 874 | Y20: ='Equipment and Defense'!Y14 -> 992 | Z20: ='Equipment and Defense'!Z14 -> 1298 | AA20: =AA6*AA27 -> 1601.9438 | AB20: =AB6*AB27 -> 1858.4703 | AC20: =AC6*AC27 -> 2134.7102 | AD20: =AD6*AD27 -> 2389.6485 | AE20: =AE6*AE27 -> 2524.2429 | AF20: =AF6*AF27 -> 2640.3034
A21: Aircraft Interiors | S21: 93 | T21: ='Aircraft Interiors Division'!H19 -> 81 | U21: ='Aircraft Interiors Division'!I19 -> 188 | V21: ='Aircraft Interiors Division'!J19 -> -174 | W21: ='Aircraft Interiors Division'!K19 -> -167 | X21: ='Aircraft Interiors Division'!L19 -> -140 | Y21: ='Aircraft Interiors Division'!M19 -> -116 | Z21: ='Aircraft Interiors Division'!N19 -> 27 | AA21: =AA7*AA28 -> 106.69282 | AB21: =AB7*AB28 -> 200.53141 | AC21: =AC7*AC28 -> 309.38034 | AD21: =AD7*AD28 -> 401.1613 | AE21: =AE7*AE28 -> 431.91276 | AF21: =AF7*AF28 -> 446.20993
A22: Other | H22: -16 | I22: -23 | J22: 82 | K22: -67 | L22: -95 | M22: -119 | N22: -142 | O22: -158 | P22: -175 | Q22: -82 | R22: -25 | S22: -36 | T22: -80 | U22: -62 | V22: -19 | W22: -20 | X22: -36 | Y22: -100 | Z22: -25 | AA22: =Z22*(AA9/Z9) -> -28.366921 | AB22: =AA22*(AB9/AA9) -> -31.592696 | AC22: =AB22*(AC9/AB9) -> -34.933 | AD22: =AC22*(AD9/AC9) -> -37.888878 | AE22: =AD22*(AE9/AD9) -> -39.749462 | AF22: =AE22*(AF9/AE9) -> -41.673577
A23: Group | H23: =SUM(H19:H22) -> 545 | I23: =SUM(I19:I22) -> 613 | J23: =SUM(J19:J22) -> 666 | K23: =SUM(K19:K22) -> 561 | L23: =SUM(L19:L22) -> 568 | M23: =SUM(M19:M22) -> 790 | N23: =SUM(N19:N22) -> 934 | O23: =SUM(O19:O22) -> -158 | ... S23: =SUM(S19:S22) -> 2192 | T23: =SUM(T19,T20,T21,T22) -> 3023 | U23: =SUM(U19,U20,U21,U22) -> 3820 | V23: =SUM(V19,V20,V21,V22) -> 1686 | W23: =SUM(W19,W20,W21,W22) -> 1805 | X23: =SUM(X19,X20,X21,X22) -> 2408 | Y23: =SUM(Y19,Y20,Y21,Y22) -> 3166 | Z23: =SUM(Z19,Z20,Z21,Z22) -> 4119 | AA23: =SUM(AA19,AA20,AA21,AA22) -> 5179.0618 | ... AF23: =SUM(AF19,AF20,AF21,AF22) -> 8490.6102 | AG23: 5-51.bn FY25 new guidance
AG24: Below cons on all years
A25: Adj. EBIT Margin
A26: Aerospace Propulsion | H26: =H19/H5 -> 0.11058545 | I26: =I19/I5 -> 0.1074869 | J26: =J19/J5 -> 0.1006376 | K26: =K19/K5 -> 0.11069981 | L26: =L19/L5 -> 0.11830835 | M26: =M19/M5 -> 0.1487725 | N26: =N19/N5 -> 0.15360457 | O26: =O19/O5 -> 0 | ... Z26: =Z19/Z5 -> 0.20648989 | AA26: ='Aerospace Propulsion Division'!AA20 -> 0.22762841 | AB26: ='Aerospace Propulsion Division'!AB20 -> 0.23133218 | AC26: ='Aerospace Propulsion Division'!AC20 -> 0.23170799 | AD26: ='Aerospace Propulsion Division'!AD20 -> 0.23439835 | AE26: ='Aerospace Propulsion Division'!AE20 -> 0.23632659 | AF26: ='Aerospace Propulsion Division'!AF20 -> 0.23879417
A27: Equipment & Defense | T27: =T20/T6 -> 0.12490557 | U27: =U20/U6 -> 0.13061798 | V27: =V20/V6 -> 0.099666328 | W27: =W20/W6 -> 0.1027668 | X27: =X20/X6 -> 0.11599204 | Y27: =Y20/Y6 -> 0.1122807 | Z27: =Z20/Z6 -> 0.12224524 | AA27: ='Equipment and Defense'!AA15 -> 0.13139866 | AB27: ='Equipment and Defense'!AB15 -> 0.13776194 | AC27: ='Equipment and Defense'!AC15 -> 0.1434427 | AD27: ='Equipment and Defense'!AD15 -> 0.14731024 | AE27: ='Equipment and Defense'!AE15 -> 0.14776947 | AF27: ='Equipment and Defense'!AF15 -> 0.14690452
A28: Aircraft Interiors | T28: =T21/T7 -> 0.032258065 | U28: =U21/U7 -> 0.056609455 | V28: =V21/V7 -> -0.090530697 | W28: =W21/W7 -> -0.11322034 | X28: =X21/X7 -> -0.070778564 | Y28: =Y21/Y7 -> -0.046830844 | Z28: =Z21/Z7 -> 0.0088903523 | AA28: ='Aircraft Interiors Division'!O20 -> 0.031161559 | AB28: ='Aircraft Interiors Division'!P20 -> 0.053006815 | AC28: ='Aircraft Interiors Division'!Q20 -> 0.074827367 | AD28: ='Aircraft Interiors Division'!R20 -> 0.089707897 | AE28: ='Aircraft Interiors Division'!S20 -> 0.093556118 | AF28: ='Aircraft Interiors Division'!T20 -> 0.093984998
A29: Group | H29: =H23/H9 -> 0.048106629 | I29: =I23/I9 -> 0.059968695 | J29: =J23/J9 -> 0.064478652 | K29: =K23/K9 -> 0.053694487 | L29: =L23/L9 -> 0.052788104 | M29: =M23/M9 -> 0.067314247 | N29: =N23/N9 -> 0.068879056 | O29: =O23/O9 -> -0.011000487 | ... AF29: =AF23/AF9 -> 0.18645976
A31: Adj. EBIT growth
A32: Aerospace Propulsion | I32: =I19/H19-1 -> 0.13368984 | J32: =J19/I19-1 -> -0.081761006 | K32: =K19/J19-1 -> 0.075342466 | L32: =L19/K19-1 -> 0.055732484 | M32: =M19/L19-1 -> 0.37104072 | N32: =N19/M19-1 -> 0.18371837 | O32: =O19/N19-1 -> -1 | P32: =P19/O19-1 -> #DIV/0! | ... AF32: =AF19/AE19-1 -> 0.060709632
A33: Equipment & Defense | U33: =U20/T20-1 -> 0.21875 | V33: =V20/U20-1 -> -0.43176179 | W33: =W20/V20-1 -> -0.053857351 | X33: =X20/W20-1 -> 0.34461538 | Y33: =Y20/X20-1 -> 0.13501144 | Z33: =Z20/Y20-1 -> 0.30846774 | AA33: =AA20/Z20-1 -> 0.23416315 | AB33: =AB20/AA20-1 -> 0.16013453 | ... AF33: =AF20/AE20-1 -> 0.045978341
A34: Aircraft Interiors | U34: =U21/T21-1 -> 1.3209877 | V34: =V21/U21-1 -> -1.9255319 | W34: =W21/V21-1 -> -0.040229885 | X34: =-(X21/W21-1) -> 0.16167665 | Y34: =-(Y21/X21-1) -> 0.17142857 | Z34: =-(Z21/Y21-1) -> 1.2327586 | AA34: =(AA21/Z21-1) -> 2.9515858 | AB34: =AB21/AA21-1 -> 0.87952118 | AC34: =AC21/AB21-1 -> 0.54280242 | AD34: =AD21/AC21-1 -> 0.29666061 | AE34: =AE21/AD21-1 -> 0.076656091 | AF34: =AF21/AE21-1 -> 0.033101997
A35: Group | I35: =I23/H23-1 -> 0.12477064 | J35: =J23/I23-1 -> 0.086460033 | K35: =K23/J23-1 -> -0.15765766 | L35: =L23/K23-1 -> 0.012477718 | M35: =M23/L23-1 -> 0.39084507 | N35: =N23/M23-1 -> 0.18227848 | O35: =O23/N23-1 -> -1.1691649 | P35: =P23/O23-1 -> 0.10759494 | ... AF35: =AF23/AE23-1 -> 0.054670199
A38: Income Statement (consolidated) | B38: 2000 | C38: 2001 | D38: 2002 | E38: 2003 | F38: 2004 | G38: 2005 | H38: 2006 | I38: 2007 | J38: 2008 | K38: 2009 | L38: 2010 | M38: 2011 | N38: 2012 | O38: 2013 | P38: 2014 | Q38: 2015 | R38: 2016 | S38: 2017 | T38: 2018 | U38: 2019 | V38: 2020 | W38: 2021 | X38: 2022 | Y38: 2023 | Z38: 2024 | AA38: =Z38+1 -> 2025 | AB38: =AA38+1 -> 2026 | AC38: =AB38+1 -> 2027 | AD38: =AC38+1 -> 2028 | AE38: =AD38+1 -> 2029 | AF38: =AE38+1 -> 2030
A39: Adjusted Revenues | H39: =H9 -> 11329 | I39: =I9 -> 10222 | J39: =J9 -> 10329 | K39: =K9 -> 10448 | L39: =L9 -> 10760 | M39: =M9 -> 11736 | N39: =N9 -> 13560 | O39: =O9 -> 14363 | ... AF39: =AF9 -> 45535.884
A40: Adjustments | L40: 268 | M40: -78 | N40: 55 | O40: 127 | P40: -311 | Q40: -1192 | R40: 701 | S40: 423 | T40: -25 | U40: 458 | V40: 133 | W40: -124 | X40: 488 | Y40: 452 | Z40: 399 | AA40: 0 | AB40: =AA40 -> 0 | AC40: =AB40 -> 0 | AD40: =AC40 -> 0 | AE40: =AD40 -> 0 | AF40: =AE40 -> 0
A41: Sales (Reported) | H41: 10841 | I41: 9714 | J41: 10281 | K41: 10559 | L41: 11028 | M41: 11658 | N41: 13615 | O41: 14490 | P41: 15044 | Q41: 16222 | R41: 16482 | S41: 16376 | T41: 21025 | U41: 25098 | V41: 16631 | W41: 15133 | X41: 19523 | Y41: 23651 | Z41: 27716 | AA41: ='Income Statement'!AA9 -> 30995.967 | AB41: ='Income Statement'!AB9 -> 34520.707 | AC41: ='Income Statement'!AC9 -> 38170.591 | AD41: ='Income Statement'!AD9 -> 41400.419 | AE41: ='Income Statement'!AE9 -> 43433.442 | AF41: ='Income Statement'!AF9 -> 45535.884
A42: growth | I42: =I41/H41-1 -> -0.1039572 | J42: =J41/I41-1 -> 0.058369364 | K42: =K41/J41-1 -> 0.027040171 | L42: =L41/K41-1 -> 0.044417085 | M42: =M41/L41-1 -> 0.057127312 | N42: =N41/M41-1 -> 0.16786756 | O42: =O41/N41-1 -> 0.064267352 | P42: =P41/O41-1 -> 0.038233264 | ... AF42: =AF41/AE41-1 -> 0.048406068
A43: Other Income | H43: 74 | I43: 66 | J43: 127 | K43: 156 | L43: 200 | M43: 216 | N43: 209 | O43: 264 | P43: 291 | Q43: 285 | R43: 277 | S43: 280 | T43: 321 | U43: 297 | V43: 267 | W43: 373 | X43: 440 | Y43: 474 | Z43: 438 | AA43: =AA44*AA41 -> 489.8338 | AB43: =AB44*AB41 -> 545.53577 | AC43: =AC44*AC41 -> 603.21543 | AD43: =AD44*AD41 -> 654.25687 | AE43: =AE44*AE41 -> 686.38503 | AF43: =AF44*AF41 -> 719.61023
A44: as a % of sales | H44: =H43/H$41 -> 0.0068259386 | I44: =I43/I$41 -> 0.0067943175 | J44: =J43/J$41 -> 0.012352884 | K44: =K43/K$41 -> 0.014774126 | L44: =L43/L$41 -> 0.018135655 | M44: =M43/M$41 -> 0.018528049 | N44: =N43/N$41 -> 0.015350716 | O44: =O43/O$41 -> 0.018219462 | ... Z44: =Z43/Z$41 -> 0.015803146 | AA44: =Z44 -> 0.015803146 | AB44: =AA44 -> 0.015803146 | AC44: =AB44 -> 0.015803146 | AD44: =AC44 -> 0.015803146 | AE44: =AD44 -> 0.015803146 | AF44: =AE44 -> 0.015803146
A45: Changes in Inventories of finished goods and Work-in-progress | H45: 360 | I45: 316 | J45: 276 | K45: -268 | L45: -43 | M45: 125 | N45: 340 | O45: -32 | P45: 255 | Q45: 257 | R45: 308 | S45: 195 | T45: 3 | U45: 453 | V45: -865 | W45: -199 | X45: 1204 | Y45: 1000 | Z45: 989 | AA45: =AA46*AA$41 -> 1106.0402 | AB45: =AB46*AB$41 -> 1231.8148 | AC45: =AC46*AC$41 -> 1362.0549 | AD45: =AD46*AD$41 -> 1477.306 | AE45: =AE46*AE$41 -> 1549.8511 | AF45: =AF46*AF$41 -> 1624.8733
...

Sheet Cashflow Statement
A1: ='DCF Valuation'!D45 -> 340
A2: Cash Flow Statement | B2: 2000 | C2: 2001 | D2: 2002 | E2: 2003 | F2: 2004 | G2: 2005 | H2: 2006 | I2: 2007 | J2: 2008 | K2: 2009 | L2: 2010 | M2: 2011 | N2: 2012 | O2: 2013 | P2: 2014 | Q2: 2015 | R2: 2016 | S2: 2017 | T2: 2018 | U2: 2019 | V2: 2020 | W2: 2021 | X2: 2022 | Y2: 2023 | Z2: 2024 | AA2: =Z2+1 -> 2025 | AB2: =AA2+1 -> 2026 | AC2: =AB2+1 -> 2027 | AD2: =AC2+1 -> 2028 | AE2: =AD2+1 -> 2029 | AF2: =AE2+1 -> 2030 | AG2: Comments
A4: Reported Net Income | H4: ='Income Statement'!H92+'Income Statement'!H94-'Income Statement'!H95 -> 33 | I4: ='Income Statement'!I92+'Income Statement'!I94-'Income Statement'!I95 -> 53 | J4: ='Income Statement'!J92+'Income Statement'!J94-'Income Statement'!J95 -> -183 | K4: ='Income Statement'!K92+'Income Statement'!K94-'Income Statement'!K95 -> 641 | L4: ='Income Statement'!L92+'Income Statement'!L94-'Income Statement'!L95 -> 207 | M4: ='Income Statement'!M92+'Income Statement'!M94-'Income Statement'!M95 -> 478 | N4: ='Income Statement'!N92+'Income Statement'!N94-'Income Statement'!N95 -> 1282 | O4: ='Income Statement'!O92+'Income Statement'!O94-'Income Statement'!O95 -> 1255 | ... AF4: ='Income Statement'!AF92+'Income Statement'!AF94-'Income Statement'!AF95 -> 6311.1175
A5: Depreciation | H5: =575-H7 -> 298 | I5: =513-I7 -> 281 | J5: =540-J7 -> 273 | K5: =573-K7 -> 274 | L5: 291 | M5: =695-M7-M9-M10 -> 321 | N5: =962-N7-N9-N10 -> 340 | O5: =941-O7-O9-O10 -> 363 | P5: 366 | Q5: =741*(P5/(P5+P7)) -> 331.54768 | R5: =726*(Q5/(Q5+Q7)) -> 324.83619 | S5: =788*(R5/(R5+R7)) -> 352.57702 | T5: =1209*(S5/(S5+S7)) -> 540.94621 | U5: =1463*(T5/(T5+T7)) -> 654.59413 | V5: =1447*(U5/(U5+U7)) -> 647.43521 | W5: =1380*(V5/(V5+V7)) -> 617.45721 | X5: =1373*(W5/(W5+W7)) -> 614.32518 | Y5: =1336*(X5/(X5+X7)) -> 597.77017 | Z5: =1406*(Y5/(Y5+Y7)) -> 629.09046 | AA5: =AA6*'Income Statement'!AA$41 -> 703.53829 | AB5: =AB6*'Income Statement'!AB$41 -> 783.5419 | AC5: =AC6*'Income Statement'!AC$41 -> 866.38601 | AD5: =AD6*'Income Statement'!AD$41 -> 939.6958 | AE5: =AE6*'Income Statement'!AE$41 -> 985.84082 | AF5: =AF6*'Income Statement'!AF$41 -> 1033.5615
A6: as a % of sales | H6: =H5/'Income Statement'!H$41 -> 0.027488239 | I6: =I5/'Income Statement'!I$41 -> 0.028927321 | J6: =J5/'Income Statement'!J$41 -> 0.026553837 | K6: =K5/'Income Statement'!K$41 -> 0.025949427 | L6: =L5/'Income Statement'!L$41 -> 0.026387378 | M6: =M5/'Income Statement'!M$41 -> 0.02753474 | N6: =N5/'Income Statement'!N$41 -> 0.024972457 | O6: =O5/'Income Statement'!O$41 -> 0.02505176 | ... Q6: =Q5/'Income Statement'!Q$41 -> 0.02043815 | R6: =$I6 -> 0.028927321 | S6: =R6 -> 0.028927321 | T6: =T5/'Income Statement'!T41 -> 0.025728714 | U6: =U5/'Income Statement'!U41 -> 0.026081526 | V6: =V5/'Income Statement'!V41 -> 0.038929421 | W6: =W5/'Income Statement'!W41 -> 0.040802036 | X6: =X5/'Income Statement'!X41 -> 0.031466741 | Y6: =Y5/'Income Statement'!Y41 -> 0.025274626 | Z6: =Z5/'Income Statement'!Z41 -> 0.022697736 | AA6: =Z6 -> 0.022697736 | AB6: =AA6 -> 0.022697736 | AC6: =AB6 -> 0.022697736 | AD6: =AC6 -> 0.022697736 | AE6: =AD6 -> 0.022697736 | AF6: =AE6 -> 0.022697736
A7: Amortisation | H7: 277 | I7: 232 | J7: 267 | K7: 299 | L7: 315 | M7: 341 | N7: 381 | O7: 399 | P7: 452 | Q7: =741-Q5 -> 409.45232 | R7: =726-R5 -> 401.16381 | S7: =788-S5 -> 435.42298 | T7: =1209-T5 -> 668.05379 | U7: =1463-U5 -> 808.40587 | V7: =1447-V5 -> 799.56479 | W7: =1380-W5 -> 762.54279 | X7: =1373-X5 -> 758.67482 | Y7: =1336-Y5 -> 738.22983 | Z7: =1406-Z5 -> 776.90954 | AA7: =AA8*'Income Statement'!AA$41 -> 868.85057 | AB7: =AB8*'Income Statement'!AB$41 -> 1035.6212 | AC7: =AC8*'Income Statement'!AC$41 -> 1068.7765 | AD7: =AD8*'Income Statement'!AD$41 -> 1159.2117 | AE7: =AE8*'Income Statement'!AE$41 -> 1216.1364 | AF7: =AF8*'Income Statement'!AF$41 -> 1275.0048
A8: as a % of sales | H8: =H7/'Income Statement'!H$41 -> 0.025551148 | I8: =I7/'Income Statement'!I$41 -> 0.023883055 | J8: =J7/'Income Statement'!J$41 -> 0.025970236 | K8: =K7/'Income Statement'!K$41 -> 0.028317075 | L8: =L7/'Income Statement'!L$41 -> 0.028563656 | M8: =M7/'Income Statement'!M$41 -> 0.0292503 | N8: =N7/'Income Statement'!N$41 -> 0.027983841 | O8: =O7/'Income Statement'!O$41 -> 0.027536232 | ... Q8: =Q7/'Income Statement'!Q$41 -> 0.025240557 | R8: =AVERAGE(M8:Q8) -> 0.028011226 | S8: =R8 -> 0.028011226 | T8: =T7/'Income Statement'!T41 -> 0.031774259 | U8: =U7/'Income Statement'!U41 -> 0.032209972 | V8: =V7/'Income Statement'!V41 -> 0.048076772 | W8: =W7/'Income Statement'!W41 -> 0.0503894 | X8: =X7/'Income Statement'!X41 -> 0.038860565 | Y8: =Y7/'Income Statement'!Y41 -> 0.031213472 | Z8: =Z7/'Income Statement'!Z41 -> 0.028031084 | AA8: =Z8 -> 0.028031084 | AB8: 0.03 | AC8: 0.028 | AD8: 0.028 | AE8: 0.028 | AF8: 0.028
A9: Impairment | H9: 129 | I9: 210 | J9: -10 | K9: 177 | L9: -3 | M9: 62 | N9: 54 | O9: 103 | P9: 137 | Q9: 1004 | R9: 243 | S9: 60 | T9: -19 | U9: -42 | V9: 377 | W9: 91 | X9: 411 | Y9: 148 | Z9: 0 | AA9: =Z9 -> 0 | AB9: =AA9 -> 0 | AC9: =AB9 -> 0 | AD9: =AC9 -> 0 | AE9: =AD9 -> 0 | AF9: =AE9 -> 0
A10: Change in Provisions | H10: 247 | I10: 178 | J10: 160 | K10: 25 | L10: 46 | M10: -29 | N10: 187 | O10: 76 | P10: 205 | Q10: 114 | R10: -42 | S10: 178 | T10: 45 | U10: 168 | V10: -259 | W10: 171 | X10: -169 | Y10: -51 | Z10: 285 | AA10: 100 | AB10: 100 | AC10: 100 | AD10: 100 | AE10: 100 | AF10: 100
A11: Share of profit in associates (net of dividends received) | H11: 4 | I11: 4 | J11: -4 | K11: -2 | L11: -9 | M11: -10 | N11: -19 | O11: =-'Income Statement'!O83 -> -15 | P11: -36 | Q11: -20 | R11: -63 | S11: -100 | T11: -124 | U11: -87 | V11: 22 | W11: 702 | X11: 11 | Y11: -83 | Z11: -120 | AA11: =-'Income Statement'!AA83 -> 0 | AB11: =-'Income Statement'!AB83 -> 0 | AC11: =-'Income Statement'!AC83 -> 0 | AD11: =-'Income Statement'!AD83 -> 0 | AE11: =-'Income Statement'!AE83 -> 0 | AF11: =-'Income Statement'!AF83 -> 0
A12: Change in fair value of derivatives | H12: 135 | I12: 368 | J12: 546 | K12: -546 | L12: 310 | M12: 2 | N12: -779 | O12: -432 | P12: 1934 | Q12: 2475 | R12: 81 | S12: -3608 | T12: 316 | U12: -152 | V12: 209 | W12: 538 | X12: 4207 | Y12: -2161 | Z12: 4684
A13: Capital gains on asset disposals | H13: -39 | I13: 7 | J13: -127 | K13: 6 | L13: 31 | M13: 16 | N13: 10 | O13: -382 | P13: -12 | Q13: -453 | R13: -364 | S13: -20 | T13: 12 | U13: -41 | V13: 20 | W13: -57 | X13: 289 | Y13: 344 | Z13: -47
A14: Profit/(Loss) before tax from discontinued operations | H14: 0 | I14: -36 | J14: 308 | K14: -1 | L14: 5 | M14: -4 | N14: -1 | Q14: -26 | R14: -110 | S14: -997
A15: Profit attributable to non-controlling interests | H15: 12 | I15: 7 | J15: 11 | K15: 13 | L15: 18 | M15: 19 | N15: 24 | O15: 29 | P15: ='Income Statement'!P95 -> 58 | Q15: ='Income Statement'!Q95 -> 47 | R15: 55 | S15: 60 | T15: 58 | U15: 65 | V15: ='Income Statement'!V95 -> 34 | W15: ='Income Statement'!W95 -> 25 | X15: ='Income Statement'!X95 -> 33 | Y15: ='Income Statement'!Y95 -> 76 | Z15: ='Income Statement'!Z95 -> 92 | AA15: ='Income Statement'!AA95 -> 102.88746 | AB15: ='Income Statement'!AB95 -> 114.58742 | AC15: ='Income Statement'!AC95 -> 126.70278 | ... AF15: ='Income Statement'!AF95 -> 151.15101
A16: Co-detailed Other | H16: =7-19 -> -12 | I16: =22+4 -> 26 | J16: =25+6 -> 31 | K16: =-24+7 -> -17 | L16: =4+6 -> 10 | M16: 4 | N16: 222 | O16: 457 | P16: -510 | Q16: -821 | R16: 217 | S16: 1150 | T16: 318 | U16: 221 | V16: -328 | W16: -707 | X16: -880 | Y16: 459 | Z16: -907
A17: Cash Tax adjustment | H17: =-202-'Income Statement'!H86 -> -93 | I17: =-212-'Income Statement'!I86 -> -187 | J17: =-257-'Income Statement'!J86 -> -399 | K17: =-73-'Income Statement'!K86 -> 162 | L17: =-103-'Income Statement'!L86 -> -89 | M17: 42 | N17: 337 | O17: -14 | AA17: 330 | AB17: -130 | AC17: -200
A18: Change in Inventory and Work in Progress | H18: -461 | I18: -421 | J18: -337 | K18: 387 | L18: 55 | M18: -134 | N18: -388 | O18: 45 | P18: -185 | Q18: -280 | R18: -347 | S18: -280 | T18: -393 | U18: -590 | V18: 1016 | W18: 296 | X18: -1545 | Y18: -1494 | Z18: -1452 | AA18: =-('Balance Sheet'!AA18-'Balance Sheet'!Z18) -> -558.08419 | AB18: =-('Balance Sheet'!AB18-'Balance Sheet'!AA18) -> -80.744285 | AC18: =-('Balance Sheet'!AC18-'Balance Sheet'!AB18) -> -709.71164 | AD18: =-('Balance Sheet'!AD18-'Balance Sheet'!AC18) -> -917.19435 | AE18: =-('Balance Sheet'!AE18-'Balance Sheet'!AD18) -> -714.37538 | AF18: =-('Balance Sheet'!AF18-'Balance Sheet'!AE18) -> -675.51688
A19: Change in operating receivables and payables | H19: 254 | I19: 318 | J19: 228 | K19: -45 | L19: 185 | M19: 216 | N19: 228 | O19: 178 | P19: -58 | Q19: 210 | R19: 219 | S19: 890 | T19: -280 | U19: -563 | V19: 41 | W19: -53 | X19: -81 | Y19: 478 | Z19: 549 | AA19: =-'Balance Sheet'!AA80-'Balance Sheet'!AA81 -> 692.32885 | AB19: =-'Balance Sheet'!AB80-'Balance Sheet'!AB81 -> 308.75692 | AC19: =-'Balance Sheet'!AC80-'Balance Sheet'!AC81 -> 655.12436 | AD19: =-'Balance Sheet'!AD80-'Balance Sheet'!AD81 -> 415.26463 | AE19: =-'Balance Sheet'!AE80-'Balance Sheet'!AE81 -> 269.47841 | AF19: =-'Balance Sheet'!AF80-'Balance Sheet'!AF81 -> 76.043666
A20: Change in contract assets and liabilities | S20: =86+10 -> 96 | T20: =746+2 -> 748 | U20: =218+11 -> 229 | V20: =-982-17 -> -999 | W20: =131-43 -> 88 | X20: =2451-118 -> 2333 | Y20: =2073-103 -> 1970 | Z20: =1004-89 -> 915 | AA20: =-('Balance Sheet'!AA44-'Balance Sheet'!Z44)-('Balance Sheet'!AA25-'Balance Sheet'!Z25) -> 0 | AB20: =-('Balance Sheet'!AB44-'Balance Sheet'!AA44)-('Balance Sheet'!AB25-'Balance Sheet'!AA25) -> 0 | AC20: =-('Balance Sheet'!AC44-'Balance Sheet'!AB44)-('Balance Sheet'!AC25-'Balance Sheet'!AB25) -> 0 | AD20: =-('Balance Sheet'!AD44-'Balance Sheet'!AC44)-('Balance Sheet'!AD25-'Balance Sheet'!AC25) -> 0 | AE20: =-('Balance Sheet'!AE44-'Balance Sheet'!AD44)-('Balance Sheet'!AE25-'Balance Sheet'!AD25) -> 0 | AF20: =-('Balance Sheet'!AF44-'Balance Sheet'!AE44)-('Balance Sheet'!AF25-'Balance Sheet'!AE25) -> 0
A21: Change in other receivables and payables | H21: 58 | I21: -10 | J21: 18 | K21: -5 | L21: 77 | M21: -35 | N21: 75 | O21: -68 | P21: 132 | Q21: 75 | R21: -40 | S21: -15 | T21: -102 | U21: 27 | V21: -66 | W21: -81 | X21: 22 | Y21: -196 | Z21: -5
A22: Change in Working Capital | W22: =W18+W19+W20+W21 -> 250 | X22: =X18+X19+X20+X21 -> 729 | Y22: =Y18+Y19+Y20+Y21 -> 758 | Z22: =Z18+Z19+Z20+Z21 -> 7 | AA22: =AA18+AA19+AA20+AA21 -> 134.24466 | AB22: =AB18+AB19+AB20+AB21 -> 228.01264 | AC22: =AC18+AC19+AC20+AC21 -> -54.587281 | AD22: =AD18+AD19+AD20+AD21 -> -501.92972 | ... AF22: =AF18+AF19+AF20+AF21 -> -599.47322
A23: Other | H23: =H24-SUM(H4:H21) -> 11.946961 | I23: =I24-SUM(I4:I21) -> 77.94719 | J23: =J24-SUM(J4:J21) -> -156.05252 | K23: =K24-SUM(K4:K21) -> 39.945733 | L23: =L24-SUM(L4:L21) -> -19.054951 | M23: =M24-SUM(M4:M5,M7,M9:M21) -> -52 | N23: =N24-SUM(N4:N5,N7,N9:N21) -> -336 | O23: =O24-SUM(O4:O5,O7,O9:O21) -> 145 | P23: =P24-SUM(P4:P5,P7,P9:P21) -> 0 | Q23: =Q24-SUM(Q4:Q5,Q7,Q9:Q21) -> -11 | R23: =R24-SUM(R4:R5,R7,R9:R21) -> 0 | S23: =S24-SUM(S4:S5,S7,S9:S21) -> 0 | T23: =T24-SUM(T4:T5,T7,T9:T21) -> 0 | ... AF23: =AF24-SUM(AF4:AF5,AF7,AF9:AF21) -> 0
A24: Cash flow from Operations | H24: 854 | I24: =1013+95 -> 1108 | J24: =720-94 -> 626 | K24: =1403+5 -> 1408 | L24: =1459-29 -> 1430 | M24: =1247-10 -> 1237 | N24: 1617 | O24: 2139 | P24: 2357 | Q24: 2631 | R24: =SUM(R4:R5,R7,R9:R21) -> 2483 | S24: =SUM(S4:S5,S7,S9:S21) -> 2752 | T24: =SUM(T4:T5,T7,T9:T21) -> 3071 | U24: =SUM(U4:U5,U7,U9:U21) -> 3145 | V24: =SUM(V4:V5,V7,V9:V21) -> 1866 | W24: =SUM(W4:W5,W7,W9:W17)+W22 -> 2436 | X24: =SUM(X4:X5,X7,X9:X17)+X22 -> 3545 | Y24: =SUM(Y4:Y5,Y7,Y9:Y17)+Y22 -> 4270 | Z24: =SUM(Z4:Z5,Z7,Z9:Z17)+Z22 -> 4733 | AA24: =SUM(AA4:AA5,AA7,AA9:AA17)+AA22 -> 5618.3997 | AB24: =SUM(AB4:AB5,AB7,AB9:AB21) -> 6309.7085 | AC24: =SUM(AC4:AC5,AC7,AC9:AC21) -> 6952.3116 | AD24: =SUM(AD4:AD5,AD7,AD9:AD21) -> 7448.6352 | AE24: =SUM(AE4:AE5,AE7,AE9:AE21) -> 7959.234 | AF24: =SUM(AF4:AF5,AF7,AF9:AF21) -> 8271.3616
A26: Purchase of Intangible assets (net of disposals) | H26: -343 | I26: -252 | J26: -230 | K26: -292 | L26: -254 | M26: -363 | N26: -634 | O26: =-720-215 -> -935 | P26: =-676-267 -> -943 | Q26: =-495-502 -> -997 | R26: -324 | S26: =-225-349 -> -574 | T26: =-183-327 -> -510 | U26: =-333-134 -> -467 | V26: =-287-57 -> -344 | W26: =-316-53 -> -369 | X26: =-283-98 -> -381 | Y26: =-323-179 -> -502 | Z26: =-328-172 -> -500 | AA26: =Z26-50 -> -550 | AB26: =AA26 -> -550 | AC26: =AB26 -> -550 | AD26: =AC26 -> -550 | AE26: =AD26 -> -550 | AF26: =AE26 -> -550 | AG26: pretty flat over CMD plan
A27: as a % of sales | H27: =H26/'Income Statement'!H$41 -> -0.031639148 | I27: =I26/'Income Statement'!I$41 -> -0.025941939 | J27: =J26/'Income Statement'!J$41 -> -0.022371365 | K27: =K26/'Income Statement'!K$41 -> -0.027654134 | L27: =L26/'Income Statement'!L$41 -> -0.023032281 | M27: =M26/'Income Statement'!M$41 -> -0.031137416 | N27: =N26/'Income Statement'!N$41 -> -0.046566287 | O27: =O26/'Income Statement'!O$41 -> -0.06452726 | ... AF27: =AF26/'Income Statement'!AF$41 -> -0.012078386
A28: Purchase of PP&E (net of disposals) | H28: -346 | I28: -387 | J28: -441 | K28: -293 | L28: -271 | M28: -352 | N28: -419 | O28: -492 | P28: -674 | Q28: -705 | R28: -704 | S28: -740 | T28: -780 | U28: -695 | V28: -449 | W28: -387 | X28: -498 | Y28: -823 | Z28: -1044 | AA28: =AA29*'Income Statement'!AA$41 -> -1549.7983 | AB28: =AB29*'Income Statement'!AB$41 -> -1553.4318 | AC28: =AC29*'Income Statement'!AC$41 -> -1526.8236 | AD28: =AD29*'Income Statement'!AD$41 -> -1449.0147 | AE28: =AE29*'Income Statement'!AE$41 -> -1303.0033 | AF28: =AF29*'Income Statement'!AF$41 -> -1138.3971 | AG28: Use of Cash Analysis
A29: as a % of sales | H29: =H28/'Income Statement'!H$41 -> -0.031915875 | I29: =I28/'Income Statement'!I$41 -> -0.039839407 | J29: =J28/'Income Statement'!J$41 -> -0.04289466 | K29: =K28/'Income Statement'!K$41 -> -0.02774884 | L29: =L28/'Income Statement'!L$41 -> -0.024573812 | M29: =M28/'Income Statement'!M$41 -> -0.030193858 | N29: =N28/'Income Statement'!N$41 -> -0.030774881 | O29: =O28/'Income Statement'!O$41 -> -0.033954451 | ... Z29: =Z28/'Income Statement'!Z$41 -> -0.037667773 | AA29: -0.05 | AB29: =AA29+0.005 -> -0.045 | AC29: =AB29+0.005 -> -0.04 | AD29: =AC29+0.005 -> -0.035 | AE29: =AD29+0.005 -> -0.03 | AF29: =AE29+0.005 -> -0.025 | AG29: CMD'24 p77: c.4% tangible capex with a peak @5% in 2025
A30: Proceeds/(Payments) from Investments | H30: =-53+14 -> -39 | I30: -68 | J30: -221 | K30: -560 | L30: -122 | M30: -1176 | N30: -193 | O30: =-733+353 -> -380 | P30: =-272+5 -> -267 | Q30: =622-39 -> 583 | R30: -810 | S30: -54 | T30: -4172 | U30: -29 | V30: -21 | W30: -33 | X30: -490 | Y30: -328 | Z30: -344 | AA30: =Z30 -> -344 | AB30: =AA30 -> -344 | AC30: =AB30 -> -344 | AD30: =AC30 -> -344 | AE30: =AD30 -> -344 | AF30: =AE30 -> -344
A31: of which additions to PP&E | R31: =R30*0.5 -> -405 | S31: =S30*0.5 -> -27 | T31: =T30*0.5 -> -2086 | U31: =U30*0.5 -> -14.5 | V31: =V30*0.5 -> -10.5 | W31: =W30*0.5 -> -16.5 | X31: =X30*0.5 -> -245 | Y31: =Y30*0.5 -> -164 | ... AF31: =AF30*0.5 -> -172 | AG31: historical goodwill/purchase price has been 50/50
