Workbook
Name _div08: [1]OVERVIEW!$AY$74
Name _div09: [1]OVERVIEW!$AZ$74
Name _div10: [1]OVERVIEW!$BA$74
Name _ShH3: #REF!
Name A_ALL_AIR.PA: #REF!
Name A_ALL_AIR.PA: #REF!
Name A_ALL_AIR.PA_: #REF!
Name A_ALL_AIR.PA_: #REF!
Name A_ALL_BAES.L_: #REF!
Name A_ALL_BAES.L_: #REF!
Name A_ALL_COB.L: '[4]COB.L_Annotation_Sheet'!$A$1:$AV$348
Name A_ALL_COB.L: #REF!
Name A_ALL_KEYWORDS_TYPE_ScalarContributed_EQTY_200000267: [5]ATCOa.ST_Annotation_Sheet!$562:$564,[5]ATCOa.ST_Annotation_Sheet!$510:$519
Name A_ALL_KEYWORDS_TYPE_ScalarContributed_EQTY_200003162: [6]BAES.L_Annotation_Sheet!$339:$345,[6]BAES.L_Annotation_Sheet!$384:$386
Name A_ALL_KEYWORDS_TYPE_ScalarContributed_EQTY_200003162: #REF!,#REF!
Name A_ALL_KEYWORDS_TYPE_ScalarContributed_EQTY_200003170: #REF!,#REF!
Name A_ALL_KEYWORDS_TYPE_ScalarContributed_EQTY_200003173: #REF!,#REF!
Name A_ALL_KEYWORDS_TYPE_ScalarContributed_EQTY_200003183: #REF!,#REF!
Name A_ALL_KEYWORDS_TYPE_ScalarContributed_EQTY_200003821: #REF!,#REF!
Name A_ALL_KEYWORDS_TYPE_ScalarContributed_EQTY_200004285: #REF!,#REF!
Name A_ALL_KEYWORDS_TYPE_ScalarContributed_EQTY_200005121: [8]EAD.PA_Annotation_Sheet!$339:$348,[8]EAD.PA_Annotation_Sheet!$387:$389
Name A_ALL_KEYWORDS_TYPE_ScalarContributed_EQTY_200007513: #REF!,#REF!
Name A_ALL_KEYWORDS_TYPE_ScalarContributed_EQTY_200009618: #REF!,#REF!
Name A_ALL_KEYWORDS_TYPE_ScalarContributed_EQTY_200009619: '[4]COB.L_Annotation_Sheet'!$298:$305,'[4]COB.L_Annotation_Sheet'!$346:$348
Name A_ALL_KEYWORDS_TYPE_ScalarContributed_EQTY_200009619: #REF!,#REF!
Name A_ALL_KEYWORDS_TYPE_ScalarContributed_EQTY_200009620: [9]MGGT.L_Annotation_Sheet!$344:$350,[9]MGGT.L_Annotation_Sheet!$389:$391
Name A_ALL_KEYWORDS_TYPE_ScalarContributed_EQTY_200009620: #REF!,#REF!
Name A_ALL_KEYWORDS_TYPE_ScalarContributed_EQTY_200011295: #REF!,#REF!
Name A_ALL_KEYWORDS_TYPE_ScalarContributed_ISSR_208001092: #REF!,#REF!
Name A_ALL_KEYWORDS_TYPE_ScalarContributed_ISSR_208001095: #REF!,#REF!
Name A_ALL_KEYWORDS_TYPE_ScalarContributed_ISSR_208001100: #REF!,#REF!
Name A_ALL_KEYWORDS_TYPE_ScalarContributed_ISSR_208001219: #REF!,#REF!,#REF!,#REF!,#REF!,#REF!,#REF!,#REF!
Name A_ALL_KEYWORDS_TYPE_ScalarContributed_ISSR_208001433: #REF!,#REF!
Name A_ALL_KEYWORDS_TYPE_ScalarContributed_ISSR_208001433: [10]AIR.PA_Annotation_Sheet!$9:$9,[10]AIR.PA_Annotation_Sheet!$42:$42
Name A_ALL_KEYWORDS_TYPE_ScalarContributed_ISSR_208006659: #REF!,#REF!,#REF!
Name A_ALL_KEYWORDS_TYPE_ScalarContributed_ISSR_208007415: #REF!,#REF!
Name A_ALL_KEYWORDS_TYPE_ScalarContributed_ISSR_208008646: #REF!,#REF!
Name A_ALL_KEYWORDS_TYPE_ScalarReference_EQTY_200007513: #REF!
Name A_ALL_KEYWORDS_TYPE_ScalarReference_EQTY_200007513: #REF!
Name A_ALL_KEYWORDS_TYPE_ScalarReference_ISSR_208002861: #REF!
Name A_ALL_KEYWORDS_TYPE_ScalarReference_ISSR_208002861: #REF!
Name A_ALL_KEYWORDS_TYPE_Vector_EQTY_200000267: [5]ATCOa.ST_Annotation_Sheet!$537:$552,[5]ATCOa.ST_Annotation_Sheet!$554:$556,[5]ATCOa.ST_Annotation_Sheet!$558:$558,[5]ATCOa.ST_Annotation_Sheet!$560:$560,[5]ATCOa.ST_Annotation_Sheet!$521:$535
Name A_ALL_KEYWORDS_TYPE_Vector_EQTY_200003162: [6]BAES.L_Annotation_Sheet!$347:$357,[6]BAES.L_Annotation_Sheet!$359:$374,[6]BAES.L_Annotation_Sheet!$376:$378,[6]BAES.L_Annotation_Sheet!$380:$380,[6]BAES.L_Annotation_Sheet!$382:$382
Name A_ALL_KEYWORDS_TYPE_Vector_EQTY_200003162: #REF!,#REF!,#REF!,#REF!,#REF!
Name A_ALL_KEYWORDS_TYPE_Vector_EQTY_200003169: #REF!,#REF!,#REF!,#REF!,#REF!
Name A_ALL_KEYWORDS_TYPE_Vector_EQTY_200003170: #REF!,#REF!,#REF!,#REF!,#REF!
Name A_ALL_KEYWORDS_TYPE_Vector_EQTY_200003173: #REF!,#REF!,#REF!,#REF!,#REF!
Name A_ALL_KEYWORDS_TYPE_Vector_EQTY_200003183: #REF!,#REF!,#REF!,#REF!,#REF!
Name A_ALL_KEYWORDS_TYPE_Vector_EQTY_200003821: #REF!,#REF!,#REF!,#REF!,#REF!
Name A_ALL_KEYWORDS_TYPE_Vector_EQTY_200004285: #REF!,#REF!,#REF!,#REF!,#REF!
Name A_ALL_KEYWORDS_TYPE_Vector_EQTY_200005121: #REF!,#REF!,#REF!,#REF!,#REF!
Name A_ALL_KEYWORDS_TYPE_Vector_EQTY_200005121: [8]EAD.PA_Annotation_Sheet!$350:$360,[8]EAD.PA_Annotation_Sheet!$362:$377,[8]EAD.PA_Annotation_Sheet!$379:$381,[8]EAD.PA_Annotation_Sheet!$383:$383,[8]EAD.PA_Annotation_Sheet!$385:$385
Name A_ALL_KEYWORDS_TYPE_Vector_EQTY_200007513: #REF!,#REF!,#REF!,#REF!,#REF!
Name A_ALL_KEYWORDS_TYPE_Vector_EQTY_200008448: #REF!,#REF!,#REF!,#REF!,#REF!
Name A_ALL_KEYWORDS_TYPE_Vector_EQTY_200009618: #REF!,#REF!,#REF!,#REF!,#REF!
Name A_ALL_KEYWORDS_TYPE_Vector_EQTY_200009619: '[4]COB.L_Annotation_Sheet'!$307:$317,'[4]COB.L_Annotation_Sheet'!$320:$336,'[4]COB.L_Annotation_Sheet'!$338:$340,'[4]COB.L_Annotation_Sheet'!$342:$342,'[4]COB.L_Annotation_Sheet'!$344:$344
Name A_ALL_KEYWORDS_TYPE_Vector_EQTY_200009619: #REF!,#REF!,#REF!,#REF!,#REF!
Name A_ALL_KEYWORDS_TYPE_Vector_EQTY_200009620: [9]MGGT.L_Annotation_Sheet!$352:$362,[9]MGGT.L_Annotation_Sheet!$364:$379,[9]MGGT.L_Annotation_Sheet!$381:$383,[9]MGGT.L_Annotation_Sheet!$385:$385,[9]MGGT.L_Annotation_Sheet!$387:$387
Name A_ALL_KEYWORDS_TYPE_Vector_EQTY_200009620: #REF!,#REF!,#REF!,#REF!,#REF!
Name A_ALL_KEYWORDS_TYPE_Vector_EQTY_200011295: #REF!,#REF!,#REF!,#REF!,#REF!

Sheet __FDSCACHE__
B1: This sheet contains FactSet XML data for use with this workbook's =FDS codes. Modifying the worksheet's contents may damage the workbook's =FDS functionality.

Sheet Cover Page
A2: GOLDMAN SACHS
A3: GLOBAL INVESTMENT RESEARCH
A4: Multi-Industry
B6: AIR.PA
B7: Published as of | C7: 46260 | I7: Rating Suspended
B9: Team Contacts:
B10: Primary Analyst
B11: Sam Burgess, sam.burgess@gs.com, +44 20 7774-9651 Goldman Sachs International
B12: Supporting Analysts
B13: Jubril Moronfolu, jubril.x.moronfolu@gs.com, +44 20 7051-0985 Goldman Sachs International
B14: Milind Sikchi, milind.sikchi@gs.com, +1 332 245-7985, Goldman Sachs International

Sheet DCF Valuation
B2: 12m forward date:
B3: 46625
C5: 2026 | D5: 2027 | E5: =D5+1 -> 2028 | F5: =E5+1 -> 2029 | G5: =F5+1 -> 2030 | H5: =G5+1 -> 2031 | I5: =H5+1 -> 2032 | J5: =I5+1 -> 2033 | K5: =J5+1 -> 2034 | L5: =K5+1 -> 2035 | M5: =L5+1 -> 2036
B6: Calendar year | D6: =DATE(YEAR(B3),6,1) -> 46539 | E6: =EDATE(DATE(YEAR(D6),6,1),12) -> 46905 | F6: =EDATE(DATE(YEAR(E6),6,1),12) -> 47270 | G6: =EDATE(DATE(YEAR(F6),6,1),12) -> 47635 | H6: =EDATE(DATE(YEAR(G6),6,1),12) -> 48000 | I6: =EDATE(DATE(YEAR(H6),6,1),12) -> 48366 | J6: =EDATE(DATE(YEAR(I6),6,1),12) -> 48731 | K6: =EDATE(DATE(YEAR(J6),6,1),12) -> 49096 | L6: =EDATE(DATE(YEAR(K6),6,1),12) -> 49461 | M6: =EDATE(DATE(YEAR(L6),6,1),12) -> 49827
B7: Adj. EBIT | C7: ='DCF Feed'!B4 -> 7612.6223 | D7: ='DCF Feed'!C4 -> 9281.3937 | E7: ='DCF Feed'!D4 -> 11593.857 | F7: ='DCF Feed'!E4 -> 13254.654 | G7: ='DCF Feed'!F4 -> 14127.451 | H7: ='DCF Feed'!G4 -> 14752.725 | I7: =H7*(1+I8) -> 15785.415 | J7: =I7*(1+J8) -> 16732.54 | K7: =J7*(1+K8) -> 17569.167 | L7: =K7*(1+L8) -> 18271.934 | M7: =L7*(1+M8) -> 18820.092
B8: YoY growth | D8: =D7/C7-1 -> 0.21921111 | E8: =E7/D7-1 -> 0.24915041 | F8: =F7/E7-1 -> 0.14324808 | G8: =G7/F7-1 -> 0.065848287 | H8: =H7/G7-1 -> 0.044259502 | I8: =$D$21 -> 0.07 | J8: =I8+(($M$8-$I$8)/4) -> 0.06 | K8: =J8+(($M$8-$I$8)/4) -> 0.05 | L8: =K8+(($M$8-$I$8)/4) -> 0.04 | M8: =$D$39 -> 0.03
B9: Tax Rate | C9: =-'DCF Feed'!B11 -> 0.26995769 | D9: =-'DCF Feed'!C11 -> 0.26995769 | E9: =-'DCF Feed'!D11 -> 0.26995769 | F9: =-'DCF Feed'!E11 -> 0.26995769 | G9: =-'DCF Feed'!F11 -> 0.26995769 | H9: =-'DCF Feed'!G11 -> 0.26995769 | I9: =H9 -> 0.26995769 | J9: =I9 -> 0.26995769 | K9: =J9 -> 0.26995769 | L9: =K9 -> 0.26995769 | M9: =L9 -> 0.26995769
B10: NOPAT | C10: =C7*(1-C9) -> 5557.5364 | D10: =D7*(1-D9) -> 6775.8102 | E10: =E7*(1-E9) -> 8464.006 | F10: =F7*(1-F9) -> 9676.4586 | G10: =G7*(1-G9) -> 10313.637 | H10: =H7*(1-H9) -> 10770.113 | I10: =I7*(1-I9) -> 11524.021 | J10: =J7*(1-J9) -> 12215.462 | ... M10: =M7*(1-M9) -> 13739.464
B11: D&A | C11: =INDEX('Income Statement'!153:153, MATCH(C5,'Income Statement'!2:2,0)) -> 3211.5501 | D11: =INDEX('Income Statement'!153:153, MATCH(D5,'Income Statement'!2:2,0)) -> 3469.6347 | E11: =INDEX('Income Statement'!153:153, MATCH(E5,'Income Statement'!2:2,0)) -> 3062.0877 | F11: =INDEX('Income Statement'!153:153, MATCH(F5,'Income Statement'!2:2,0)) -> 3424.6146 | G11: =INDEX('Income Statement'!153:153, MATCH(G5,'Income Statement'!2:2,0)) -> 3697.5801 | H11: =INDEX('Income Statement'!153:153, MATCH(H5,'Income Statement'!2:2,0)) -> 3879.6435
B12: Change in working capital | C12: =INDEX('Cash Flow Statement'!23:23, MATCH(C5,'Cash Flow Statement'!2:2,0)) -> 286.29731 | D12: =INDEX('Cash Flow Statement'!23:23, MATCH(D5,'Cash Flow Statement'!2:2,0)) -> 1076.5364 | E12: =INDEX('Cash Flow Statement'!23:23, MATCH(E5,'Cash Flow Statement'!2:2,0)) -> 2094.6614 | F12: =INDEX('Cash Flow Statement'!23:23, MATCH(F5,'Cash Flow Statement'!2:2,0)) -> 2770.782 | G12: =INDEX('Cash Flow Statement'!23:23, MATCH(G5,'Cash Flow Statement'!2:2,0)) -> 2833.2116 | H12: =INDEX('Cash Flow Statement'!23:23, MATCH(H5,'Cash Flow Statement'!2:2,0)) -> 986.59515
B13: Capex & Intangibles | C13: =INDEX('Cash Flow Statement'!73:73, MATCH(C5,'Cash Flow Statement'!2:2,0)) -> -4175.2212 | D13: =INDEX('Cash Flow Statement'!73:73, MATCH(D5,'Cash Flow Statement'!2:2,0)) -> -4567.2086 | E13: =INDEX('Cash Flow Statement'!73:73, MATCH(E5,'Cash Flow Statement'!2:2,0)) -> -5029.5828 | F13: =INDEX('Cash Flow Statement'!73:73, MATCH(F5,'Cash Flow Statement'!2:2,0)) -> -5340.9763 | G13: =INDEX('Cash Flow Statement'!73:73, MATCH(G5,'Cash Flow Statement'!2:2,0)) -> -5495.0067 | H13: =INDEX('Cash Flow Statement'!73:73, MATCH(H5,'Cash Flow Statement'!2:2,0)) -> -5587.5175
B14: Sustainable FCF | C14: =C10+C11+C12+C13 -> 4880.1627 | D14: =D10+D11+D12+D13 -> 6754.7727 | E14: =E10+E11+E12+E13 -> 8591.1724 | F14: =F10+F11+F12+F13 -> 10530.879 | G14: =G10+G11+G12+G13 -> 11349.422 | H14: =H10+H11+H12+H13 -> 10048.834 | I14: =I10*I15 -> 10560.886 | J14: =J10*J15 -> 10991.69 | K14: =K10*K15 -> 11328.283 | L14: =L10*L15 -> 11559.903 | M14: =M10*M15 -> 11678.544
B15: Cash Conversion (Sustainable FCF/NOPAT) | C15: =C14/C10 -> 0.87811619 | D15: =D14/D10 -> 0.99689521 | E15: =E14/E10 -> 1.0150244 | F15: =F14/F10 -> 1.0882989 | G15: =G14/G10 -> 1.1004287 | H15: =H14/H10 -> 0.9330296 | I15: =H15+(($M$15-$H$15)/5) -> 0.91642368 | J15: =I15+(($M$15-$H$15)/5) -> 0.89981776 | K15: =J15+(($M$15-$H$15)/5) -> 0.88321184 | L15: =K15+(($M$15-$H$15)/5) -> 0.86660592 | M15: =$D$22 -> 0.85
B16: WACC | D16: =$D$38 -> 0.08952 | E16: =$D$38 -> 0.08952 | F16: =$D$38 -> 0.08952 | G16: =$D$38 -> 0.08952 | H16: =$D$38 -> 0.08952 | I16: =$D$38 -> 0.08952 | J16: =$D$38 -> 0.08952 | K16: =$D$38 -> 0.08952 | ... M16: =$D$38 -> 0.08952
B17: Discount Factor | D17: =1/(1+$D$38)^((D6-$B$3)/365) -> 1.0204065 | E17: =1/(1+$D$38)^((E6-$B$3)/365) -> 0.93634524 | F17: =1/(1+$D$38)^((F6-$B$3)/365) -> 0.85941078 | G17: =1/(1+$D$38)^((G6-$B$3)/365) -> 0.78879762 | H17: =1/(1+$D$38)^((H6-$B$3)/365) -> 0.72398636 | I17: =1/(1+$D$38)^((I6-$B$3)/365) -> 0.66434422 | J17: =1/(1+$D$38)^((J6-$B$3)/365) -> 0.60975863 | K17: =1/(1+$D$38)^((K6-$B$3)/365) -> 0.55965804 | ... M17: =1/(1+$D$38)^((M6-$B$3)/365) -> 0.47135739
B18: Discounted FCF | D18: =D14*D17 -> 6892.6141 | E18: =E14*E17 -> 8044.3033 | F18: =F14*F17 -> 9050.3509 | G18: =G14*G17 -> 8952.3969 | H18: =H14*H17 -> 7275.2191 | I18: =I14*I17 -> 7016.0635 | J18: =J14*J17 -> 6702.2779 | K18: =K14*K17 -> 6339.9648 | ... M18: =M14*M17 -> 5504.768 | N18: =SUM(C18:M18) -> 71715.98
B20: Assumption
B21: Mid-term Adj. EBIT growth rate | C21: % | D21: 0.07
B22: Cash Conversion LT | C22: % | D22: 0.85
B24: DCF Valuation
B25: Risk free rate | C25: % | D25: 0.04
B26: Equity Risk premium | C26: % | D26: 0.04
B28: Beta | C28: x | D28: 1.238
B29: Cost of equity | C29: % | D29: =D25+D28*(D26) -> 0.08952
B31: Cost of debt | C31: % | D31: ='Income Statement'!V130 -> 0.052
B32: Tax | C32: % | D32: =C9 -> 0.26995769
B33: Post tax cost of debt | C33: % | D33: =D31*(1-D32) -> 0.0379622
B35: MV Equity / (MV Equity + Net Debt) | C35: % | D35: 1
B36: Net Debt / (MV Equity + Net Debt) | C36: % | D36: 0
B38: WACC | C38: % | D38: =(D29*D35)+(D36*D33) -> 0.08952
B39: Terminal growth rate | C39: % | D39: 0.03
B41: DCF Valuation
B42: Sum of discounted cash flows | C42: EUR (mn) | D42: =N18 -> 71715.98
B43: Undiscounted value of TV | C43: EUR (mn) | D43: =M14*(1+D39)/(D38-D39) -> 202098.46
B44: Discounted value of TV | C44: EUR (mn) | D44: =D43*M17 -> 95260.603
B45: Enterprise value | C45: EUR (mn) | D45: =D42+D44 -> 166976.58
B46: Net cash (debt) and lease | C46: EUR (mn) | D46: ='DCF Feed'!C8 -> 16271.149
B47: Pension underfunding | C47: EUR (mn) | D47: ='DCF Feed'!C9 -> 356
B48: Pension tax shield | C48: EUR (mn) | D48: =-D47*(D32) -> -96.104937
B49: Equity value | C49: EUR (mn) | D49: =SUM(D45:D48) -> 183507.63
...

Sheet DCF Feed
A1: EURm | B1: 2026 | C1: =B1+1 -> 2027 | D1: =C1+1 -> 2028 | E1: =D1+1 -> 2029 | F1: =E1+1 -> 2030 | G1: =F1+1 -> 2031 | H1: CAGR 26-31
A2: Sales | B2: =INDEX('Income Statement'!$14:$14,MATCH('DCF Feed'!B1,'Income Statement'!$4:$4,0)) -> 80292.715 | C2: =INDEX('Income Statement'!$14:$14,MATCH('DCF Feed'!C1,'Income Statement'!$4:$4,0)) -> 91344.172 | D2: =INDEX('Income Statement'!$14:$14,MATCH('DCF Feed'!D1,'Income Statement'!$4:$4,0)) -> 102644.55 | E2: =INDEX('Income Statement'!$14:$14,MATCH('DCF Feed'!E1,'Income Statement'!$4:$4,0)) -> 111270.34 | F2: =INDEX('Income Statement'!$14:$14,MATCH('DCF Feed'!F1,'Income Statement'!$4:$4,0)) -> 116915.04 | G2: =INDEX('Income Statement'!$14:$14,MATCH('DCF Feed'!G1,'Income Statement'!$4:$4,0)) -> 121467.77 | H2: =(G2/B2)^(1/5)-1 -> 0.086318022
A3: Growth | C3: =C2/B2-1 -> 0.1376396 | D3: =D2/C2-1 -> 0.12371206 | E3: =E2/D2-1 -> 0.08403556 | F3: =F2/E2-1 -> 0.050729576 | G3: =G2/F2-1 -> 0.038940547
A4: EBIT | B4: =INDEX('Income Statement'!$84:$84,MATCH('DCF Feed'!B1,'Income Statement'!$4:$4,0)) -> 7612.6223 | C4: =INDEX('Income Statement'!$84:$84,MATCH('DCF Feed'!C1,'Income Statement'!$4:$4,0)) -> 9281.3937 | D4: =INDEX('Income Statement'!$84:$84,MATCH('DCF Feed'!D1,'Income Statement'!$4:$4,0)) -> 11593.857 | E4: =INDEX('Income Statement'!$84:$84,MATCH('DCF Feed'!E1,'Income Statement'!$4:$4,0)) -> 13254.654 | F4: =INDEX('Income Statement'!$84:$84,MATCH('DCF Feed'!F1,'Income Statement'!$4:$4,0)) -> 14127.451 | G4: =INDEX('Income Statement'!$84:$84,MATCH('DCF Feed'!G1,'Income Statement'!$4:$4,0)) -> 14752.725 | H4: =(G4/B4)^(1/5)-1 -> 0.14147812
A5: Growth | C5: =C4/B4-1 -> 0.21921111 | D5: =D4/C4-1 -> 0.24915041 | E5: =E4/D4-1 -> 0.14324808 | F5: =F4/E4-1 -> 0.065848287 | G5: =G4/F4-1 -> 0.044259502
A6: GS Defined Op Cash Flow | B6: =INDEX('Cash Flow Statement'!75:75, MATCH('DCF Feed'!B1,'Cash Flow Statement'!2:2,0)) -> 6164.9986 | C6: =INDEX('Cash Flow Statement'!75:75, MATCH('DCF Feed'!C1,'Cash Flow Statement'!2:2,0)) -> 8652.0938 | D6: =INDEX('Cash Flow Statement'!75:75, MATCH('DCF Feed'!D1,'Cash Flow Statement'!2:2,0)) -> 11095.947 | E6: =INDEX('Cash Flow Statement'!75:75, MATCH('DCF Feed'!E1,'Cash Flow Statement'!2:2,0)) -> 13466.345 | F6: =INDEX('Cash Flow Statement'!75:75, MATCH('DCF Feed'!F1,'Cash Flow Statement'!2:2,0)) -> 14501.97 | G6: =INDEX('Cash Flow Statement'!75:75, MATCH('DCF Feed'!G1,'Cash Flow Statement'!2:2,0)) -> 13350.717 | H6: =(G6/B6)^(1/5)-1 -> 0.1671168
A7: Cash Conversion | C7: =C6/C4 -> 0.93219769 | D7: =D6/D4 -> 0.95705404 | E7: =E6/E4 -> 1.0159711 | F7: =F6/F4 -> 1.02651 | G7: =G6/G4 -> 0.90496616 | H7: =AVERAGE(C7:G7) -> 0.9673398
A8: Net Cash (debt) | B8: =INDEX('Balance Sheet'!65:65,MATCH('DCF Feed'!B$1,'Balance Sheet'!$2:$2,0)) -> 14247.337 | C8: =INDEX('Balance Sheet'!65:65,MATCH('DCF Feed'!C1,'Balance Sheet'!$2:$2,0)) -> 16271.149 | D8: =INDEX('Balance Sheet'!65:65,MATCH('DCF Feed'!D1,'Balance Sheet'!$2:$2,0)) -> 19589.53 | E8: =INDEX('Balance Sheet'!65:65,MATCH('DCF Feed'!E1,'Balance Sheet'!$2:$2,0)) -> 26112.194 | F8: =INDEX('Balance Sheet'!65:65,MATCH('DCF Feed'!F1,'Balance Sheet'!$2:$2,0)) -> 33061.678 | G8: =INDEX('Balance Sheet'!65:65,MATCH('DCF Feed'!G1,'Balance Sheet'!$2:$2,0)) -> 38198.225
A9: Pension underfunding | B9: =INDEX('Balance Sheet'!119:119,MATCH('DCF Feed'!B$1,'Balance Sheet'!$2:$2,0)) -> -144 | C9: =INDEX('Balance Sheet'!119:119,MATCH('DCF Feed'!C1,'Balance Sheet'!$2:$2,0)) -> 356 | D9: =INDEX('Balance Sheet'!119:119,MATCH('DCF Feed'!D1,'Balance Sheet'!$2:$2,0)) -> 856 | E9: =INDEX('Balance Sheet'!119:119,MATCH('DCF Feed'!E1,'Balance Sheet'!$2:$2,0)) -> 1356 | F9: =INDEX('Balance Sheet'!119:119,MATCH('DCF Feed'!F1,'Balance Sheet'!$2:$2,0)) -> 1856 | G9: =INDEX('Balance Sheet'!119:119,MATCH('DCF Feed'!G1,'Balance Sheet'!$2:$2,0)) -> 2356
A10: Launch Aid | B10: =INDEX('Balance Sheet'!125:125,MATCH('DCF Feed'!B$1,'Balance Sheet'!$2:$2,0)) -> -3874.5338 | C10: =INDEX('Balance Sheet'!125:125,MATCH('DCF Feed'!C$1,'Balance Sheet'!$2:$2,0)) -> -3886.3152 | D10: =INDEX('Balance Sheet'!125:125,MATCH('DCF Feed'!D$1,'Balance Sheet'!$2:$2,0)) -> -3900.3517 | E10: =INDEX('Balance Sheet'!125:125,MATCH('DCF Feed'!E$1,'Balance Sheet'!$2:$2,0)) -> -3916.3786 | F10: =INDEX('Balance Sheet'!125:125,MATCH('DCF Feed'!F$1,'Balance Sheet'!$2:$2,0)) -> -3934.1658 | G10: =INDEX('Balance Sheet'!125:125,MATCH('DCF Feed'!G$1,'Balance Sheet'!$2:$2,0)) -> -3953.5131
A11: Tax rate (adjusted) | B11: =INDEX('Income Statement'!97:97,MATCH('DCF Feed'!B1,'Income Statement'!2:2,0)) -> -0.26995769 | C11: =INDEX('Income Statement'!97:97,MATCH('DCF Feed'!C1,'Income Statement'!2:2,0)) -> -0.26995769 | D11: =INDEX('Income Statement'!97:97,MATCH('DCF Feed'!D1,'Income Statement'!2:2,0)) -> -0.26995769 | E11: =INDEX('Income Statement'!97:97,MATCH('DCF Feed'!E1,'Income Statement'!2:2,0)) -> -0.26995769 | F11: =INDEX('Income Statement'!97:97,MATCH('DCF Feed'!F1,'Income Statement'!2:2,0)) -> -0.26995769 | G11: =INDEX('Income Statement'!97:97,MATCH('DCF Feed'!G1,'Income Statement'!2:2,0)) -> -0.26995769
A12: Other
A13: Number of shares (mn) | B13: =INDEX('Income Statement'!114:114,MATCH('DCF Feed'!B$1,'Income Statement'!$2:$2,0))/1000 -> 785.62897 | C13: =INDEX('Income Statement'!114:114,MATCH('DCF Feed'!C$1,'Income Statement'!$2:$2,0))/1000 -> 775.10265 | D13: =INDEX('Income Statement'!114:114,MATCH('DCF Feed'!D$1,'Income Statement'!$2:$2,0))/1000 -> 764.57634 | E13: =INDEX('Income Statement'!114:114,MATCH('DCF Feed'!E$1,'Income Statement'!$2:$2,0))/1000 -> 764.57634 | F13: =INDEX('Income Statement'!114:114,MATCH('DCF Feed'!F$1,'Income Statement'!$2:$2,0))/1000 -> 764.57634 | G13: =INDEX('Income Statement'!114:114,MATCH('DCF Feed'!G$1,'Income Statement'!$2:$2,0))/1000 -> 764.57634
A25: Goldman Sachs adjusted EV | B25: ='Income Statement'!B2 -> 2006 | C25: ='Income Statement'!C2 -> 2007 | D25: ='Income Statement'!D2 -> 2008 | E25: ='Income Statement'!E2 -> 2009 | F25: ='Income Statement'!F2 -> 2010 | G25: ='Income Statement'!G2 -> 2011 | H25: ='Income Statement'!H2 -> 2012 | I25: ='Income Statement'!I2 -> 2013 | ... P25: ='Income Statement'!P2 -> 2020 | Q25: ='Income Statement'!Q$2 -> 2021 | R25: ='Income Statement'!R$2 -> 2022 | S25: ='Income Statement'!S$2 -> 2023 | T25: ='Income Statement'!T$2 -> 2024 | U25: ='Income Statement'!U$2 -> 2025 | V25: ='Income Statement'!V$2 -> 2026 | W25: ='Income Statement'!W$2 -> 2027 | X25: ='Income Statement'!X$2 -> 2028 | ... Z25: ='Income Statement'!Z$2 -> 2030
A26: Avg. no. of shares (m) | B26: ='Income Statement'!B113/1000 -> 800.18516 | C26: ='Income Statement'!C113/1000 -> 803.12822 | D26: ='Income Statement'!D113/1000 -> 806.9788 | E26: ='Income Statement'!E113/1000 -> 809.69863 | F26: ='Income Statement'!F113/1000 -> 810.69334 | G26: ='Income Statement'!G113/1000 -> 812.50729 | H26: ='Income Statement'!H113/1000 -> 819.37826 | I26: ='Income Statement'!I113/1000 -> 792.46686 | ... Z26: ='Income Statement'!Z113/1000 -> 763.25742
A27: Share price - average | B27: 26.32 | C27: 23.06 | D27: 14.34 | E27: 12.48 | F27: 16.59 | G27: 21.497 | H27: 27.8623 | I27: 41.2545 | J27: ='Income Statement'!J120 -> 55.8 | K27: ='Income Statement'!K120 -> 55.8 | L27: ='Income Statement'!L120 -> 110 | M27: =L27 -> 110 | N27: ='Income Statement'!N120 -> 109.68 | O27: 137 | P27: =O27 -> 137 | Q27: =P27 -> 137 | R27: =Q27 -> 137 | S27: =R27 -> 137 | T27: =S27 -> 137 | U27: =T27 -> 137 | V27: =U27 -> 137 | W27: =V27 -> 137 | ... Z27: =Y27 -> 137
A28: GS target Price | I28: =I27*1.35 -> 55.693575 | J28: =I28 -> 55.693575 | K28: =J28 -> 55.693575 | L28: =K28 -> 55.693575 | M28: =L28 -> 55.693575 | N28: =M28 -> 55.693575 | O28: =N28 -> 55.693575 | P28: =O28 -> 55.693575 | Q28: =P28 -> 55.693575 | ... Z28: =Y28 -> 55.693575
A29: Enterprise value calculation
A30: Market value - average | B30: =B27*B26 -> 21060.874 | C30: =C27*C26 -> 18520.137 | D30: =D27*D26 -> 11572.076 | E30: =E27*E26 -> 10105.039 | F30: =F27*F26 -> 13449.402 | G30: =G27*G26 -> 17466.469 | H30: =H27*H26 -> 22829.763 | I30: =I27*I26 -> 32692.824 | ... Z30: =Z27*Z26 -> 104566.27
A31: Market value of minorities - average | B31: =B30/SUM('Balance Sheet'!B49:B53)*'Balance Sheet'!B$54+2750 -> 2976.6002 | C31: =C30/SUM('Balance Sheet'!C49:C53)*'Balance Sheet'!C$54 -> 120.26063 | D31: =D30/SUM('Balance Sheet'!D49:D53)*'Balance Sheet'!D$54 -> 109.19034 | E31: =E30/SUM('Balance Sheet'!E49:E53)*'Balance Sheet'!E$54 -> 101.67386 | F31: =F30/SUM('Balance Sheet'!F49:F53)*'Balance Sheet'!F$54 -> 144.51909 | G31: =G30/SUM('Balance Sheet'!G49:G53)*'Balance Sheet'!G$54 -> 29.604185 | H31: =H30/SUM('Balance Sheet'!H49:H53)*'Balance Sheet'!H$54 -> 37.30712 | I31: =I30/SUM('Balance Sheet'!I49:I53)*'Balance Sheet'!I$54 -> 127.67155 | J31: =J30/SUM('Balance Sheet'!J49:J53)*'Balance Sheet'!J$54 -> 111.37338 | ... Z31: =Z30/SUM('Balance Sheet'!Z49:Z53)*'Balance Sheet'!Z$54 -> 181.20953
A32: Company Defined Net Debt (Cash) | B32: ='Balance Sheet'!B65 -> 4229 | C32: ='Balance Sheet'!C65 -> 7024 | D32: ='Balance Sheet'!D65 -> 9193 | E32: ='Balance Sheet'!E65 -> 9797 | F32: ='Balance Sheet'!F65 -> 11918 | G32: ='Balance Sheet'!G65 -> 11681 | H32: ='Balance Sheet'!H65 -> 12292 | I32: ='Balance Sheet'!I65 -> 9054 | ... Z32: ='Balance Sheet'!Z65 -> 33061.678
A33: Net Pension Deficit | B33: ='Balance Sheet'!B119 -> -4986 | C33: ='Balance Sheet'!C119 -> -4174 | D33: ='Balance Sheet'!D119 -> -3958 | E33: ='Balance Sheet'!E119 -> -5306 | F33: ='Balance Sheet'!F119 -> -5221 | G33: ='Balance Sheet'!G119 -> -5821 | H33: ='Balance Sheet'!H119 -> -6433 | I33: ='Balance Sheet'!I119 -> -6615 | ... Z33: ='Balance Sheet'!Z119 -> 1856
A34: Other Adjustments | B34: =SUM(B35:B41) -> -9508.4283 | C34: =SUM(C35:C41) -> -7625.7939 | D34: =SUM(D35:D41) -> -8414.2227 | E34: =SUM(E35:E41) -> -8368.2639 | F34: =SUM(F35:F41) -> -8004.6498 | G34: =SUM(G35:G41) -> -11452.389 | H34: =SUM(H35:H41) -> -8672 | I34: =SUM(I35:I41) -> -9930 | ... Z34: =SUM(Z35:Z41) -> -1208.6189
A35: Excess customer advances | B35: =B87 -> -12484 | C35: =C87 -> -13470 | D35: =D87 -> -14082 | E35: =E87 -> -15703 | F35: =F87 -> -15249 | G35: =G87 -> -16522 | H35: =H87 -> -17352 | I35: =I87 -> -18890 | ... Z35: =Z87 -> 0
A36: Launch aid | B36: =-'Balance Sheet'!B125 -> 5418 | C36: =-'Balance Sheet'!C125 -> 5315 | D36: =-'Balance Sheet'!D125 -> 4920 | E36: =-'Balance Sheet'!E125 -> 5294 | F36: =-'Balance Sheet'!F125 -> 6020 | G36: =-'Balance Sheet'!G125 -> 5737 | H36: =-'Balance Sheet'!H125 -> 6112 | I36: =-'Balance Sheet'!I125 -> 6112 | ... Z36: =-'Balance Sheet'!Z125 -> 3934.1658
A37: Net customer financing exposure | B37: =B60 -> 526 | C37: =C60 -> 440 | D37: =D60 -> 415 | E37: =E60 -> 429 | F37: =F60 -> 427 | G37: =G60 -> 363 | H37: =H60 -> 181 | I37: =I60 -> 181 | ... Z37: =Z60 -> 4
A38: Provisions/obligations for aircraft leassing
A39: Less Investments | B39: =B64 -> -3900.4283 | C39: =C64 -> -3309.7939 | D39: =D64 -> -3150.2227 | E39: =E64 -> -2836.2639 | F39: =F64 -> -4148.6498 | G39: =G64 -> -4575.3887 | H39: =H64 -> -1518 | I39: =I64 -> -1354 | ... Z39: =Z64 -> -9367.7847
A40: Cash provisions to be utilised | B40: =B74 -> 1990 | C40: =C74 -> 4258 | D40: =D74 -> 4220 | E40: =E74 -> 5100 | F40: =F74 -> 5478 | G40: =G74 -> 4000 | H40: =H74 -> 4250 | I40: =I74 -> 4250 | ... Z40: =Z74 -> 4250
A41: Non-recourse Debt (adjustment) | B41: =B80 -> -1058 | C41: =C80 -> -859 | D41: =D80 -> -737 | E41: =E80 -> -652 | F41: =F80 -> -532 | G41: =G80 -> -455 | H41: =H80 -> -345 | I41: =I80 -> -229 | ... Z41: =Z80 -> -29
A42: EV - average | B42: =SUM(B30:B34) -> 13772.045 | C42: =SUM(C30:C34) -> 13864.604 | D42: =SUM(D30:D34) -> 8502.0437 | E42: =SUM(E30:E34) -> 6329.4489 | F42: =SUM(F30:F34) -> 12286.272 | G42: =SUM(G30:G34) -> 11903.685 | H42: =SUM(H30:H34) -> 20054.07 | I42: =SUM(I30:I34) -> 25329.496 | ... Z42: =SUM(Z30:Z34) -> 138456.54
A43: as a multiple of Company defined EBIT | B43: =B42/'Income Statement'!B84 -> 34.516405 | C43: =C42/'Income Statement'!C84 -> 266.62699 | D43: =D42/'Income Statement'!D84 -> 3.0042557 | E43: =E42/'Income Statement'!E84 -> -19.656674 | F43: =F42/'Income Statement'!F84 -> 9.9807244 | G43: =G42/'Income Statement'!G84 -> 7.018682 | H43: =H42/'Income Statement'!H84 -> 9.3535775 | I43: =I42/'Income Statement'!I84 -> 9.5187883 | J43: =J42/'Income Statement'!J151 -> 8.4519613 | K43: =K42/'Income Statement'!K151 -> 7.5021955 | L43: =L42/'Income Statement'!L151 -> 17.912894 | M43: =M42/'Income Statement'!M151 -> 16.418323 | N43: =N42/'Income Statement'!N151 -> 11.999778 | O43: =O42/'Income Statement'!O151 -> 16.381185 | P43: =P42/'Income Statement'!P151 -> 61.407701 | Q43: =Q42/'Income Statement'!Q151 -> 22.837203 | ... Z43: =Z42/'Income Statement'!Z151 -> 9.8005322
A44: on GS target Price | H44: =(H42-H30+H30/H27*H28)/'Income Statement'!H84 -> -1.2946329 | I44: =(I42-I30+I30/I27*I28)/'Income Statement'!I84 -> 13.818859 | J44: =(J42-J30+J30/J27*J28)/'Income Statement'!J84 -> 8.4314677 | K44: =(K42-K30+K30/K27*K28)/'Income Statement'!K84 -> 7.4818426 | L44: =(L42-L30+L30/L27*L28)/'Income Statement'!L84 -> 7.2877995 | M44: =(M42-M30+M30/M27*M28)/'Income Statement'!M84 -> 6.5380432 | N44: =(N42-N30+N30/N27*N28)/'Income Statement'!N84 -> 4.826561 | O44: =(O42-O30+O30/O27*O28)/'Income Statement'!O84 -> 7.2855424 | ... Z44: =(Z42-Z30+Z30/Z27*Z28)/'Income Statement'!Z84 -> 5.4078265
A45: Implied P/E | B45: =B27/'Income Statement'!B201 -> #DIV/0! | C45: =C27/'Income Statement'!C201 -> #DIV/0! | D45: =D27/'Income Statement'!D201 -> #DIV/0! | E45: =E27/'Income Statement'!E201 -> #DIV/0! | F45: =F27/'Income Statement'!F201 -> #DIV/0! | G45: =G27/'Income Statement'!G201 -> #DIV/0! | H45: =H27/'Income Statement'!H201 -> #DIV/0! | I45: =I28/'Income Statement'!I201 -> #DIV/0! | J45: =J28/'Income Statement'!J201 -> #DIV/0! | K45: =K28/'Income Statement'!K201 -> #DIV/0! | L45: =L28/'Income Statement'!L201 -> #DIV/0! | M45: =M28/'Income Statement'!M201 -> #DIV/0! | N45: =N28/'Income Statement'!N201 -> #DIV/0! | O45: =O28/'Income Statement'!O201 -> #DIV/0! | P45: =P28/'Income Statement'!P201 -> #DIV/0! | ... Z45: =Z28/'Income Statement'!Z201 -> #DIV/0!
A60: Net vendor financing (assets)/liablities | B60: =B61 -> 526 | C60: =C61 -> 440 | D60: =D61 -> 415 | E60: =E61 -> 429 | F60: =F61 -> 427 | G60: =G61 -> 363 | H60: =H61 -> 181 | I60: =I61 -> 181 | ... Z60: =Z61 -> 4
A61: Off-balance sheet aircraft financing commitments | B61: 526 | C61: 440 | D61: 415 | E61: 429 | F61: 427 | G61: =267+56+40 -> 363 | H61: =124+45+12 -> 181 | I61: =H61 -> 181 | J61: =71+9 -> 80 | K61: =60+8 -> 68 | L61: =182+21 -> 203 | M61: =144+4 -> 148 | N61: 38 | O61: 104 | P61: 14 | Q61: 67 | R61: 8 | S61: 8 | T61: 4 | U61: =T61 -> 4 | V61: =U61 -> 4 | W61: =V61 -> 4 | X61: =W61 -> 4 | Y61: =X61 -> 4 | Z61: =Y61 -> 4 | AB61: Customer Financing Exposure slide on FY results PPT. We use the Off-balance sheet number as the rest is already captured within Net Debt
A62: Less: customer financing collateral value | B62: -791 | C62: -622 | D62: -697 | E62: -972 | F62: -926 | G62: =-627-86-53 -> -766 | H62: =-741-61-48 -> -850 | I62: =H62 -> -850 | J62: =-743-20 -> -763 | K62: =-922-20 -> -942 | L62: =-1157-60 -> -1217 | M62: =-953-64 -> -1017 | N62: -597 | O62: -560 | P62: -279 | Q62: =P62 -> -279 | R62: =Q62 -> -279 | S62: =R62 -> -279 | T62: =S62 -> -279 | U62: =T62 -> -279 | V62: =U62 -> -279 | W62: =V62 -> -279 | X62: =W62 -> -279 | ... Z62: =Y62 -> -279 | AB62: Some people would argue that the collateral should be added back into EV as it's a liquid asset. We don't think so as otherwise other types of debt could be removed, depending on what they had been used to purchase
A64: Less Investments | B64: =B65+B67 -> -3900.4283 | C64: =C65+C67 -> -3309.7939 | D64: =D65+D67 -> -3150.2227 | E64: =E65+E67 -> -2836.2639 | F64: =F65+F67 -> -4148.6498 | G64: =G65+G67 -> -4575.3887 | H64: =H65+H67 -> -1518 | I64: =I65+I67 -> -1354 | ... Z64: =Z65+Z67 -> -9367.7847
A65: Less: Market value of Dassault Aviation | B65: -2911.4283 | C65: -2484.7939 | D65: -2433.2227 | E65: -1936.2639 | F65: -2742.6498 | G65: -3047.3887 | K65: -2188.8009 | L65: 0 | M65: =L65 -> 0 | N65: =M65 -> 0 | O65: =N65 -> 0 | P65: =O65 -> 0 | Q65: =P65 -> 0 | R65: =Q65 -> 0 | S65: =R65 -> 0 | T65: =S65 -> 0 | ... Z65: =Y65 -> 0
A66: Dassault Share price | H66: 744.1 | I66: 872 | J66: 1280.5
...

Sheet Income Statement
A1: ='DCF Valuation'!D51 -> 240
A2: Airbus | B2: 2006 | C2: 2007 | D2: 2008 | E2: 2009 | F2: 2010 | G2: 2011 | H2: 2012 | I2: 2013 | J2: 2014 | K2: 2015 | L2: 2016 | M2: 2017 | N2: 2018 | O2: 2019 | P2: 2020 | Q2: 2021 | R2: 2022 | S2: 2023 | T2: 2024 | U2: 2025 | V2: =U2+1 -> 2026 | W2: =V2+1 -> 2027 | X2: =W2+1 -> 2028 | Y2: =X2+1 -> 2029 | Z2: =Y2+1 -> 2030 | AA2: =Z2+1 -> 2031
A4: Divisional Summary | B4: =B2 -> 2006 | C4: =C2 -> 2007 | D4: =D2 -> 2008 | E4: =E2 -> 2009 | F4: =F2 -> 2010 | G4: =G2 -> 2011 | H4: =H2 -> 2012 | I4: =I2 -> 2013 | ... T4: =T2 -> 2024 | U4: =U$2 -> 2025 | V4: =V$2 -> 2026 | W4: =W$2 -> 2027 | X4: =X$2 -> 2028 | Y4: =Y$2 -> 2029 | Z4: =Z$2 -> 2030 | AA4: =AA$2 -> 2031
A5: Sales
A6: Airbus Division | B6: =#REF! -> #REF! | C6: =#REF! -> #REF! | D6: =#REF! -> #REF! | E6: =#REF! -> #REF! | F6: =#REF! -> #REF! | G6: =#REF! -> #REF! | H6: =#REF! -> #REF! | I6: =#REF! -> #REF!
A7: Airbus Commercial | B7: ='Airbus Commercial'!B2 -> work | C7: ='Airbus Commercial'!C2 -> 25216 | D7: ='Airbus Commercial'!D2 -> 26524 | E7: ='Airbus Commercial'!E2 -> 26370 | F7: ='Airbus Commercial'!F2 -> 27673 | G7: ='Airbus Commercial'!G2 -> 31159 | H7: ='Airbus Commercial'!H2 -> 37624 | I7: ='Airbus Commercial'!I2 -> 39889 | ... U7: ='Airbus Commercial'!U2 -> 52577 | V7: =U7*(1+V17) -> 57945.622 | W7: =V7*(1+W17) -> 67784.666 | X7: =W7*(1+X17) -> 77835.508 | Y7: =X7*(1+Y17) -> 84850.404 | Z7: =Y7*(1+Z17) -> 88711.401 | AA7: =Z7*(1+AA17) -> 91335.261
A8: Airbus Military | B8: ='Airbus Defence & Space'!B39 -> 0 | C8: ='Airbus Defence & Space'!C39 -> 0 | D8: ='Airbus Defence & Space'!D39 -> 0 | E8: ='Airbus Defence & Space'!E39 -> 0 | F8: ='Airbus Defence & Space'!F39 -> 0 | G8: ='Airbus Defence & Space'!G39 -> 0 | H8: ='Airbus Defence & Space'!H39 -> 5632.4 | I8: =#REF! -> #REF! | V8: =U8*(1+V18) -> 0 | W8: =V8*(1+W18) -> 0 | X8: =W8*(1+X18) -> 0 | Y8: =X8*(1+Y18) -> 0 | Z8: =Y8*(1+Z18) -> 0 | AA8: =Z8*(1+AA18) -> 0
A9: Airbus Helicopters | B9: ='Airbus Helicopters'!B2 -> 3803 | C9: ='Airbus Helicopters'!C2 -> 4172 | D9: ='Airbus Helicopters'!D2 -> 4486 | E9: ='Airbus Helicopters'!E2 -> 4570 | F9: ='Airbus Helicopters'!F2 -> 4830 | G9: ='Airbus Helicopters'!G2 -> 5415 | H9: ='Airbus Helicopters'!H2 -> 6264 | I9: ='Airbus Helicopters'!I2 -> 6297 | ... U9: ='Airbus Helicopters'!U2 -> 8972 | V9: =U9*(1+V19) -> 9641.0962 | W9: =V9*(1+W19) -> 10139.801 | X9: =W9*(1+X19) -> 10619.327 | Y9: =X9*(1+Y19) -> 11105.228 | Z9: =Y9*(1+Z19) -> 11598.105 | AA9: =Z9*(1+AA19) -> 12098.144
A10: Astrium | B10: ='Airbus Defence & Space'!B53 -> 0 | C10: ='Airbus Defence & Space'!C53 -> 0 | D10: ='Airbus Defence & Space'!D53 -> 0 | E10: ='Airbus Defence & Space'!E53 -> 0 | F10: ='Airbus Defence & Space'!F53 -> 0 | G10: ='Airbus Defence & Space'!G53 -> 0 | H10: ='Airbus Defence & Space'!H53 -> 5817 | I10: ='Airbus Defence & Space'!I53 -> 5784 | V10: =U10*(1+V20) -> 0 | W10: =V10*(1+W20) -> 0 | X10: =W10*(1+X20) -> 0 | Y10: =X10*(1+Y20) -> 0 | Z10: =Y10*(1+Z20) -> 0 | AA10: =Z10*(1+AA20) -> 0
A11: Cassidian | B11: ='Airbus Defence & Space'!B46 -> 0 | C11: ='Airbus Defence & Space'!C46 -> 0 | D11: ='Airbus Defence & Space'!D46 -> 0 | E11: ='Airbus Defence & Space'!E46 -> 0 | F11: ='Airbus Defence & Space'!F46 -> 0 | G11: ='Airbus Defence & Space'!G46 -> 0 | H11: ='Airbus Defence & Space'!H46 -> 5740 | I11: ='Airbus Defence & Space'!I46 -> 5976 | V11: =U11*(1+V21) -> 0 | W11: =V11*(1+W21) -> 0 | X11: =W11*(1+X21) -> 0 | Y11: =X11*(1+Y21) -> 0 | Z11: =Y11*(1+Z21) -> 0 | AA11: =Z11*(1+AA21) -> 0
A12: Airbus Defence & Space | H12: ='Airbus Defence & Space'!H2 -> 13520 | I12: ='Airbus Defence & Space'!I2 -> 17982 | J12: ='Airbus Defence & Space'!J2 -> 13025 | K12: ='Airbus Defence & Space'!K2 -> 13080 | L12: ='Airbus Defence & Space'!L2 -> 11854 | M12: ='Airbus Defence & Space'!M2 -> 10804 | N12: ='Airbus Defence & Space'!N2 -> 11063 | O12: ='Airbus Defence & Space'!O2 -> 10907 | ... U12: ='Airbus Defence & Space'!U2 -> 13405 | V12: =U12*(1+V22) -> 14277.666 | W12: =V12*(1+W22) -> 15207.698 | X12: =W12*(1+X22) -> 16198.901 | Y12: =X12*(1+Y22) -> 17492.739 | Z12: =Y12*(1+Z22) -> 18894.053 | AA12: =Z12*(1+AA22) -> 20412.006
A13: other | B13: =#REF! -> #REF! | C13: =#REF! -> #REF! | D13: =#REF! -> #REF! | E13: =#REF! -> #REF! | F13: =#REF! -> #REF! | G13: =#REF! -> #REF! | H13: -614 | I13: -1352 | J13: -1116 | K13: -1270 | L13: -1162 | M13: -1445 | N13: -1260 | O13: -1211 | P13: -1035 | Q13: -710 | R13: -972 | S13: -1149 | T13: -1439 | U13: -1439 | V13: =U13/SUM(U7:U12)*SUM(V7:V12) -> -1571.6686 | W13: =V13/SUM(V7:V12)*SUM(W7:W12) -> -1787.9924 | X13: =W13/SUM(W7:W12)*SUM(X7:X12) -> -2009.1887 | Y13: =X13/SUM(X7:X12)*SUM(Y7:Y12) -> -2178.0319 | Z13: =Y13/SUM(Y7:Y12)*SUM(Z7:Z12) -> -2288.5226 | AA13: =Z13/SUM(Z7:Z12)*SUM(AA7:AA12) -> -2377.6389
A14: Group | B14: =SUM(B7:B13) -> #REF! | C14: =SUM(C7:C13) -> #REF! | D14: =SUM(D7:D13) -> #REF! | E14: =SUM(E7:E13) -> #REF! | F14: =SUM(F7:F13) -> #REF! | G14: =SUM(G7:G13)-2000+31 -> #REF! | H14: 56480 | I14: =I7+I9+I12+I13 -> 62816 | J14: =J7+J9+J12+J13 -> 60713 | K14: =K7+K9+K12+K13 -> 64450 | L14: =L7+L9+L12+L13 -> 66581 | M14: =M7+M9+M12+M13 -> 66767 | N14: =N7+N9+N12+N13 -> 63707 | O14: =O7+O9+O12+O13 -> 70478 | P14: =P7+P9+P12+P13 -> 49912 | ... AA14: =AA7+AA9+AA12+AA13 -> 121467.77
A16: Sales Growth
A17: Airbus Commercial | C17: =C7/B7-1 -> #VALUE! | D17: =D7/C7-1 -> 0.051871827 | E17: =E7/D7-1 -> -0.0058060624 | F17: =F7/E7-1 -> 0.049412211 | G17: =G7/F7-1 -> 0.12597116 | H17: =H7/G7-1 -> 0.20748419 | I17: =I7/H7-1 -> 0.060200936 | J17: =J7/I7-1 -> 0.059941337 | ... U17: =U7/T7-1 -> 0.038127394 | V17: ='Airbus Commercial'!V3 -> 0.1021097 | W17: ='Airbus Commercial'!W3 -> 0.16979788 | X17: ='Airbus Commercial'!X3 -> 0.14827605 | Y17: ='Airbus Commercial'!Y3 -> 0.090124629 | Z17: ='Airbus Commercial'!Z3 -> 0.045503571 | AA17: ='Airbus Commercial'!AA3 -> 0.029577488
A18: Airbus Military | C18: =C8/B8-1 -> #DIV/0! | D18: =D8/C8-1 -> #DIV/0! | E18: =E8/D8-1 -> #DIV/0! | F18: =F8/E8-1 -> #DIV/0! | G18: =G8/F8-1 -> #DIV/0! | H18: =H8/G8-1 -> #DIV/0! | I18: =I8/H8-1 -> #REF!
A19: Airbus Helicopters | C19: =C9/B9-1 -> 0.097028662 | D19: =D9/C9-1 -> 0.075263663 | E19: =E9/D9-1 -> 0.018724922 | F19: =F9/E9-1 -> 0.056892779 | G19: =G9/F9-1 -> 0.12111801 | H19: =H9/G9-1 -> 0.1567867 | I19: =I9/H9-1 -> 0.0052681992 | J19: =J9/I9-1 -> 0.036048912 | ... U19: =U9/T9-1 -> 0.12983251 | V19: ='Airbus Helicopters'!V3 -> 0.074576037 | W19: ='Airbus Helicopters'!W3 -> 0.051726993 | X19: ='Airbus Helicopters'!X3 -> 0.047291422 | Y19: ='Airbus Helicopters'!Y3 -> 0.045756289 | Z19: ='Airbus Helicopters'!Z3 -> 0.044382472 | AA19: ='Airbus Helicopters'!AA3 -> 0.043113818
A20: Astrium | C20: =C10/B10-1 -> #DIV/0! | D20: =D10/C10-1 -> #DIV/0! | E20: =E10/D10-1 -> #DIV/0! | F20: =F10/E10-1 -> #DIV/0! | G20: =G10/F10-1 -> #DIV/0! | H20: =H10/G10-1 -> #DIV/0! | I20: =I10/H10-1 -> -0.0056730273
A21: Cassidian | C21: =C11/B11-1 -> #DIV/0! | D21: =D11/C11-1 -> #DIV/0! | E21: =E11/D11-1 -> #DIV/0! | F21: =F11/E11-1 -> #DIV/0! | G21: =G11/F11-1 -> #DIV/0! | H21: =H11/G11-1 -> #DIV/0! | I21: =I11/H11-1 -> 0.041114983
A22: Airbus Defence & Space | I22: =I12/H12-1 -> 0.33002959 | J22: =J12/I12-1 -> -0.27566455 | K22: =K12/J12-1 -> 0.0042226488 | L22: =L12/K12-1 -> -0.093730887 | M22: =M12/L12-1 -> -0.088577695 | N22: =N12/M12-1 -> 0.023972603 | O22: =O12/N12-1 -> -0.014101058 | P22: =P12/O12-1 -> -0.042266434 | ... U22: =U12/T12-1 -> 0.10950174 | V22: ='Airbus Defence & Space'!V3 -> 0.0651 | W22: ='Airbus Defence & Space'!W3 -> 0.065138954 | X22: ='Airbus Defence & Space'!X3 -> 0.065177751 | Y22: ='Airbus Defence & Space'!Y3 -> 0.07987196 | Z22: ='Airbus Defence & Space'!Z3 -> 0.080108317 | AA22: ='Airbus Defence & Space'!AA3 -> 0.080340246
A23: other | C23: =C13/B13-1 -> #REF! | D23: =D13/C13-1 -> #REF! | E23: =E13/D13-1 -> #REF! | F23: =F13/E13-1 -> #REF! | G23: =G13/F13-1 -> #REF! | H23: =H13/G13-1 -> #REF! | I23: =I13/H13-1 -> 1.2019544 | J23: =J13/I13-1 -> -0.17455621 | ... U23: =U13/T13-1 -> 0 | V23: =-(V13/U13-1) -> -0.092194995 | W23: =-(W13/V13-1) -> -0.1376396 | X23: =-(X13/W13-1) -> -0.12371206 | Y23: =-(Y13/X13-1) -> -0.08403556 | Z23: =-(Z13/Y13-1) -> -0.050729576 | AA23: =-(AA13/Z13-1) -> -0.038940547
A24: Group | C24: =C14/B14-1 -> #REF! | D24: =D14/C14-1 -> #REF! | E24: =E14/D14-1 -> #REF! | F24: =F14/E14-1 -> #REF! | G24: =G14/F14-1 -> #REF! | H24: =H14/G14-1 -> #REF! | I24: =I14/H14-1 -> 0.1121813 | J24: =J14/I14-1 -> -0.033478732 | ... AA24: =AA14/Z14-1 -> 0.038940547
A26: Company defined EBIT Adjusted
A27: Airbus Commercial | D27: 2100 | E27: 1070 | F27: 295 | G27: ='Airbus Commercial'!G7 -> 485 | H27: ='Airbus Commercial'!H7 -> 1669 | I27: ='Airbus Commercial'!I7 -> 2216 | J27: ='Airbus Commercial'!J7 -> 2529 | K27: ='Airbus Commercial'!K7 -> 2766 | L27: ='Airbus Commercial'!L7 -> 2811 | M27: ='Airbus Commercial'!M7 -> 3554 | N27: ='Airbus Commercial'!N7 -> 4808 | ... U27: ='Airbus Commercial'!U7 -> 5470 | V27: =V7*V35 -> 5757.7436 | W27: =W7*W35 -> 7168.2228 | X27: =X7*X35 -> 9291.9898 | Y27: =Y7*Y35 -> 10716.437 | Z27: =Z7*Z35 -> 11317.255 | AA27: =AA7*AA35 -> 11676.606
A28: Airbus Helicopters | D28: 293 | E28: 263 | F28: 303 | G28: ='Airbus Helicopters'!G4 -> 259 | H28: ='Airbus Helicopters'!H4 -> 309 | I28: ='Airbus Helicopters'!I4 -> 397 | J28: ='Airbus Helicopters'!J4 -> 413 | K28: ='Airbus Helicopters'!K4 -> 427 | L28: ='Airbus Helicopters'!L4 -> 350 | M28: ='Airbus Helicopters'!M4 -> 337 | N28: ='Airbus Helicopters'!N4 -> 380 | ... U28: ='Airbus Helicopters'!U4 -> 925 | V28: =V37*V9 -> 989.36564 | W28: =W37*W9 -> 1055.2531 | X28: =X37*X9 -> 1124.5583 | Y28: =Y37*Y9 -> 1197.5089 | Z28: =Z37*Z9 -> 1290.4173 | AA28: =AA37*AA9 -> 1341.8893
A29: Airbus Defence & Space | H29: ='Airbus Defence & Space'!H4 -> 720 | I29: ='Airbus Defence & Space'!I4 -> 942 | J29: ='Airbus Defence & Space'!J4 -> 920 | K29: ='Airbus Defence & Space'!K4 -> 1051 | L29: ='Airbus Defence & Space'!L4 -> 1002 | M29: ='Airbus Defence & Space'!M4 -> 872 | N29: ='Airbus Defence & Space'!N4 -> 935 | O29: ='Airbus Defence & Space'!O4 -> 565 | ... U29: ='Airbus Defence & Space'!U4 -> 798 | V29: =V12*V40 -> 930.51314 | W29: =W12*W40 -> 1092.9178 | X29: =X12*X40 -> 1212.3087 | Y29: =Y12*Y40 -> 1375.709 | Z29: =Z12*Z40 -> 1554.7785 | AA29: =AA12*AA40 -> 1769.2296
A30: other | D30: =D31-SUM(D29,D28,D27) -> 937 | E30: =E31-SUM(E29,E28,E27) -> 815 | F30: =F31-SUM(F29,F28,F27) -> 743 | G30: =G31-SUM(G29,G28,G27) -> 1050 | H30: =H31-SUM(H29,H28,H27) -> 266 | I30: =I31-SUM(I29,I28,I27) -> 19 | J30: =J31-SUM(J29,J28,J27) -> 204 | K30: =K31-SUM(K29,K28,K27) -> -136 | L30: -208 | M30: -510 | N30: -289 | O30: -399 | P30: -43 | Q30: 64 | R30: 4 | S30: 56 | T30: 9 | U30: -65 | V30: =U30 -> -65 | W30: =V30+30 -> -35 | X30: =W30 -> -35 | Y30: =X30 -> -35 | Z30: =Y30 -> -35 | AA30: =Z30 -> -35
A31: Group | B31: 3556 | C31: 3614 | D31: 3330 | E31: 2148 | F31: 1341 | G31: 1794 | H31: 2964 | I31: 3574 | J31: 4066 | K31: 4108 | L31: =SUM(L27,L28,L29,L30) -> 3955 | M31: =SUM(M27,M28,M29,M30) -> 4253 | N31: =SUM(N27,N28,N29,N30) -> 5834 | O31: =SUM(O27,O28,O29,O30) -> 6946 | P31: =SUM(P27,P28,P29,P30) -> 1706 | Q31: =SUM(Q27,Q28,Q29,Q30) -> 4865 | R31: =SUM(R27,R28,R29,R30) -> 5627 | S31: =SUM(S27,S28,S29,S30) -> 5838 | ... AA31: =SUM(AA27,AA28,AA29,AA30) -> 14752.725
A33: EBIT margin
A34: Airbus Division | F34: =#REF!/F6 -> #REF! | G34: =#REF!/G6 -> #REF! | H34: =#REF!/H6 -> #REF! | I34: =#REF!/I6 -> #REF!
A35: Airbus Commercial | D35: =D27/D7 -> 0.079173579 | E35: =E27/E7 -> 0.040576413 | F35: =F27/F7 -> 0.01066021 | G35: =G27/G7 -> 0.015565326 | H35: =H27/H7 -> 0.044359983 | I35: =I27/I7 -> 0.055554163 | J35: =J27/J7 -> 0.059815516 | K35: =K27/K7 -> 0.060321891 | ... U35: =U27/U7 -> 0.10403789 | V35: ='Airbus Commercial'!V5 -> 0.0993646 | W35: ='Airbus Commercial'!W5 -> 0.10574992 | X35: ='Airbus Commercial'!X5 -> 0.11937983 | Y35: ='Airbus Commercial'!Y5 -> 0.126298 | Z35: ='Airbus Commercial'!Z5 -> 0.12757385 | AA35: ='Airbus Commercial'!AA5 -> 0.12784335
A36: Airbus Military | D36: =#REF!/D8 -> #REF! | E36: =#REF!/E8 -> #REF! | F36: =#REF!/F8 -> #REF! | G36: =#REF!/G8 -> #REF! | H36: =#REF!/H8 -> #REF! | I36: =#REF!/I8 -> #REF! | J36: =#REF!/J8 -> #REF! | K36: =#REF!/K8 -> #REF! | ... AA36: =#REF!/AA8 -> #REF!
A37: Airbus Helicopters | D37: =D28/D9 -> 0.065314311 | E37: =E28/E9 -> 0.057549234 | F37: =F28/F9 -> 0.062732919 | G37: =G28/G9 -> 0.047830102 | H37: =H28/H9 -> 0.049329502 | I37: =I28/I9 -> 0.063045895 | J37: =J28/J9 -> 0.063304721 | K37: =K28/K9 -> 0.062923666 | ... U37: =U28/U9 -> 0.10309853 | V37: ='Airbus Helicopters'!V5 -> 0.10261962 | W37: ='Airbus Helicopters'!W5 -> 0.1040704 | X37: ='Airbus Helicopters'!X5 -> 0.10589733 | Y37: ='Airbus Helicopters'!Y5 -> 0.1078329 | Z37: ='Airbus Helicopters'!Z5 -> 0.11126104 | AA37: ='Airbus Helicopters'!AA5 -> 0.11091695
A38: Astrium | D38: =#REF!/D10 -> #REF! | E38: =#REF!/E10 -> #REF! | F38: =#REF!/F10 -> #REF! | G38: =#REF!/G10 -> #REF! | H38: =#REF!/H10 -> #REF! | I38: =#REF!/I10 -> #REF! | J38: =#REF!/J10 -> #REF! | K38: =#REF!/K10 -> #REF! | ... AA38: =#REF!/AA10 -> #REF!
A39: Cassidian | D39: =#REF!/D11 -> #REF! | E39: =#REF!/E11 -> #REF! | F39: =#REF!/F11 -> #REF! | G39: =#REF!/G11 -> #REF! | H39: =#REF!/H11 -> #REF! | I39: =#REF!/I11 -> #REF! | J39: =#REF!/J11 -> #REF! | K39: =#REF!/K11 -> #REF! | ... AA39: =#REF!/AA11 -> #REF!
A40: Airbus Defence & Space | H40: =H29/H12 -> 0.053254438 | I40: =I29/I12 -> 0.052385719 | J40: =J29/J12 -> 0.070633397 | K40: =K29/K12 -> 0.080351682 | L40: =L29/L12 -> 0.084528429 | M40: =M29/M12 -> 0.080710848 | N40: =N29/N12 -> 0.084515954 | O40: =O29/O12 -> 0.051801595 | ... U40: =U29/U12 -> 0.059530026 | V40: ='Airbus Defence & Space'!V6 -> 0.065172639 | W40: ='Airbus Defence & Space'!W6 -> 0.07186609 | X40: ='Airbus Defence & Space'!X6 -> 0.074838947 | Y40: ='Airbus Defence & Space'!Y6 -> 0.078644574 | Z40: ='Airbus Defence & Space'!Z6 -> 0.082289306 | AA40: ='Airbus Defence & Space'!AA6 -> 0.086675932
A41: other | D41: =D30/D13 -> #REF! | E41: =E30/E13 -> #REF! | F41: =F30/F13 -> #REF! | G41: =G30/G13 -> #REF! | H41: =H30/H13 -> -0.43322476 | I41: =I30/I13 -> -0.014053254 | J41: =J30/J13 -> -0.1827957 | K41: =K30/K13 -> 0.10708661 | ... AA41: =AA30/AA13 -> 0.014720486
A42: Group | B42: =B31/B14 -> #REF! | C42: =C31/C14 -> #REF! | D42: =D31/D14 -> #REF! | E42: =E31/E14 -> #REF! | F42: =F31/F14 -> #REF! | G42: =G31/G14 -> #REF! | H42: =H31/H14 -> 0.052478754 | I42: =I31/I14 -> 0.056896332 | ... AA42: =AA31/AA14 -> 0.12145382
A44: EBIT Growth
A45: Airbus Commercial | C45: =IFERROR(C27/B27-1,"") | D45: =IFERROR(D27/C27-1,"") | E45: =IFERROR(E27/D27-1,"") -> -0.49047619 | F45: =IFERROR(F27/E27-1,"") -> -0.72429907 | G45: =IFERROR(G27/F27-1,"") -> 0.6440678 | H45: =IFERROR(H27/G27-1,"") -> 2.4412371 | I45: =IFERROR(I27/H27-1,"") -> 0.32774116 | J45: =IFERROR(J27/I27-1,"") -> 0.14124549 | ... AA45: =IFERROR(AA27/Z27-1,"") -> 0.031752475
...

Sheet Cash Flow Statement
A1: ='DCF Valuation'!D51 -> 240
A2: Cash Flow Statement | B2: ='Income Statement'!B2 -> 2006 | C2: ='Income Statement'!C2 -> 2007 | D2: ='Income Statement'!D2 -> 2008 | E2: ='Income Statement'!E2 -> 2009 | F2: ='Income Statement'!F2 -> 2010 | G2: ='Income Statement'!G2 -> 2011 | H2: ='Income Statement'!H2 -> 2012 | I2: ='Income Statement'!I2 -> 2013 | ... T2: ='Income Statement'!T2 -> 2024 | U2: =T2+1 -> 2025 | V2: =U2+1 -> 2026 | W2: =V2+1 -> 2027 | X2: =W2+1 -> 2028 | Y2: =X2+1 -> 2029 | Z2: =Y2+1 -> 2030 | AA2: =Z2+1 -> 2031
A4: Net Income | B4: ='Income Statement'!B101 -> 99 | C4: ='Income Statement'!C101 -> -446 | D4: ='Income Statement'!D101 -> 1572 | E4: ='Income Statement'!E101 -> -763 | F4: ='Income Statement'!F101 -> 553 | G4: ='Income Statement'!G101 -> 1033 | H4: ='Income Statement'!H101 -> 1197 | I4: ='Income Statement'!I101 -> 5025 | ... AA4: ='Income Statement'!AA101 -> 11581.181
A5: Profit to Non-controlling interests | B5: 16 | C5: 9 | D5: 25 | E5: 11 | F5: 19 | G5: 4 | H5: 1 | I5: ='Income Statement'!I103 -> 10 | J5: ='Income Statement'!J103 -> 7 | K5: ='Income Statement'!K103 -> 2 | L5: ='Income Statement'!L103 -> 5 | M5: ='Income Statement'!M103 -> 4 | N5: ='Income Statement'!N103 -> -43 | O5: ='Income Statement'!O103 -> 37 | P5: ='Income Statement'!P103 -> -36 | ... AA5: ='Income Statement'!AA103 -> -261
A6: Interest income | B6: -454 | C6: -502 | D6: -617 | E6: -356 | F6: -316 | G6: -377 | H6: -237 | I6: =-'Income Statement'!I87 -> -168 | J6: =-'Income Statement'!J87 -> -142 | K6: =-'Income Statement'!K87 -> -183 | L6: =-'Income Statement'!L87 -> -247 | M6: =-'Income Statement'!M87 -> -189 | N6: =-'Income Statement'!N87 -> -208 | O6: =-'Income Statement'!O87 -> -228 | P6: =-'Income Statement'!P87 -> -140 | ... AA6: =-'Income Statement'!AA87 -> -1274.6244
A7: Interest expense | B7: 575 | C7: 701 | D7: 581 | E7: 503 | F7: 415 | G7: 364 | H7: 522 | I7: =-'Income Statement'!I88 -> 497 | J7: =-'Income Statement'!J88 -> 462 | K7: =-'Income Statement'!K88 -> 551 | L7: =-'Income Statement'!L88 -> 522 | M7: =-'Income Statement'!M88 -> 517 | N7: =-'Income Statement'!N88 -> 440 | O7: =-'Income Statement'!O88 -> 339 | P7: =-'Income Statement'!P88 -> 411 | ... AA7: =-'Income Statement'!AA88 -> 521.151
A8: Interest received | B8: 380 | C8: 480 | D8: 657 | E8: 382 | F8: 332 | G8: 417 | H8: 198 | I8: 119 | J8: 99 | K8: 131 | L8: 139 | M8: 149 | N8: 186 | O8: 151 | P8: 82 | Q8: 111 | R8: 250 | S8: 690 | T8: 681 | U8: 607 | V8: ='Income Statement'!V87 -> 649.888 | W8: ='Income Statement'!W87 -> 673.03517 | X8: ='Income Statement'!X87 -> 701.74226 | Y8: ='Income Statement'!Y87 -> 770.42669 | Z8: ='Income Statement'!Z87 -> 1014.2026 | AA8: ='Income Statement'!AA87 -> 1274.6244
A9: Interest paid | B9: -271 | C9: -370 | D9: -471 | E9: -331 | F9: -278 | G9: -307 | H9: -351 | I9: -323 | J9: -303 | K9: -388 | L9: -378 | M9: -501 | N9: -292 | O9: -187 | P9: -205 | Q9: -330 | R9: -322 | S9: -606 | T9: -786 | U9: -651 | V9: ='Income Statement'!V88 -> -740.948 | W9: ='Income Statement'!W88 -> -689.95 | X9: ='Income Statement'!X88 -> -649.296 | Y9: ='Income Statement'!Y88 -> -609.73 | Z9: ='Income Statement'!Z88 -> -558.269 | AA9: ='Income Statement'!AA88 -> -521.151
A10: Income tax expense | B10: -81 | C10: -333 | D10: 703 | E10: -220 | F10: 244 | G10: 356 | H10: 449 | I10: =-'Income Statement'!I94 -> 502 | J10: =-'Income Statement'!J94 -> 863 | K10: 677 | L10: =-'Income Statement'!L94 -> 291 | M10: =-'Income Statement'!M94 -> 1693 | N10: =-'Income Statement'!N94 -> 1274 | O10: =-'Income Statement'!O94 -> 2389 | P10: =-'Income Statement'!P94 -> 39 | Q10: =-'Income Statement'!Q94 -> 853 | R10: =-'Income Statement'!R94 -> 939 | S10: =-'Income Statement'!S94 -> 1156 | ... AA10: =-'Income Statement'!AA94 -> 4186.0174
A11: Income taxes paid | B11: -239 | C11: 36 | D11: -252 | E11: 4 | F11: -140 | G11: -100 | H11: -219 | I11: ='Income Statement'!I189 -> 0 | J11: -115 | K11: -595 | L11: -559 | M11: -152 | N11: -897 | O11: -1476 | P11: 79 | Q11: -321 | R11: -790 | S11: -544 | T11: -947 | U11: -965 | V11: ='Income Statement'!V94 -> -2030.5036 | W11: ='Income Statement'!W94 -> -2501.0173 | X11: ='Income Statement'!X94 -> -3144.009 | Y11: ='Income Statement'!Y94 -> -3621.5772 | Z11: ='Income Statement'!Z94 -> -3936.8967 | AA11: ='Income Statement'!AA94 -> -4186.0174
A12: Depreciation | B12: =1691-B14 -> 1554 | C12: =1772-C14 -> 1574 | D12: =1667-D14 -> 1543 | E12: =1826-E14 -> 1483 | F12: =1582-F14 -> 1403 | G12: =1884-G14 -> 1493 | H12: =2053-H14 -> 1618 | I12: =1968-I14 -> 1484.2011 | J12: =2150-J14 -> 1682.3981 | K12: =2466-K14 -> 1969.6163 | L12: =2294-L14 -> 1781.2037 | M12: =2298-M14 -> 1783.7712 | N12: =2444-N14 -> 1899.4259 | O12: =2927-O14 -> 2455 | P12: =2831-P14 -> 2439 | Q12: =2325-Q14 -> 2008 | R12: =2716-R14 -> 2410 | S12: =2242-S14 -> 2106 | T12: =2853-T14 -> 2001 | U12: =3133-U14 -> 2281 | V12: =V13*'Income Statement'!U$58 -> 2281 | W12: =W13*'Income Statement'!V$58 -> 2411.0041 | X12: =X13*'Income Statement'!W$58 -> 2651.5095 | Y12: =Y13*'Income Statement'!X$58 -> 2979.5332 | Z12: =Z13*'Income Statement'!Y$58 -> 3229.92 | AA12: =AA13*'Income Statement'!Z$58 -> 3393.7724
A13: as a % of sales | B13: =B12/'Income Statement'!B$58 -> 0.039407618 | C13: =C12/'Income Statement'!C$58 -> 0.040232089 | D13: =D12/'Income Statement'!D$58 -> 0.035663932 | E13: =E12/'Income Statement'!E$58 -> 0.034631731 | F13: =F12/'Income Statement'!F$58 -> 0.030665326 | G13: =G12/'Income Statement'!G$58 -> 0.030390002 | H13: =H12/'Income Statement'!H$58 -> 0.028647309 | I13: =I12/'Income Statement'!I$58 -> 0.023627756 | ... U13: =U12/'Income Statement'!U$58 -> 0.031027681 | V13: =U13 -> 0.031027681 | W13: =V13-0.1% -> 0.030027681 | X13: =W13-0.1% -> 0.029027681 | Y13: =X13 -> 0.029027681 | Z13: =Y13 -> 0.029027681 | AA13: =Z13 -> 0.029027681
A14: Amortisation | B14: 137 | C14: 198 | D14: 124 | E14: 343 | F14: 179 | G14: 391 | H14: 435 | I14: =I15*'Income Statement'!I$58 -> 483.79887 | J14: =J15*'Income Statement'!J$58 -> 467.60189 | K14: =K15*'Income Statement'!K$58 -> 496.38368 | L14: =L15*'Income Statement'!L$58 -> 512.7963 | M14: =M15*'Income Statement'!M$58 -> 514.22884 | N14: =N15*'Income Statement'!N$58 -> 544.5741 | O14: 472 | P14: 392 | Q14: 317 | R14: 306 | S14: 136 | T14: 852 | U14: 852 | V14: =V15*'Income Statement'!V$58 -> 930.55014 | W14: =W15*'Income Statement'!W$58 -> 1058.6307 | X14: =X15*'Income Statement'!X$58 -> 410.57819 | Y14: =Y15*'Income Statement'!Y$58 -> 445.08136 | Z14: =Z15*'Income Statement'!Z$58 -> 467.66015 | AA14: =AA15*'Income Statement'!AA$58 -> 485.87109
A15: as a % of sales | B15: =B14/'Income Statement'!B$58 -> 0.0034741594 | C15: =C14/'Income Statement'!C$58 -> 0.0050609616 | D15: =D14/'Income Statement'!D$58 -> 0.002866058 | E15: =E14/'Income Statement'!E$58 -> 0.0080099015 | F15: =F14/'Income Statement'!F$58 -> 0.0039123973 | G15: =G14/'Income Statement'!G$58 -> 0.0079588015 | H15: =H14/'Income Statement'!H$58 -> 0.0077018414 | I15: =$H15 -> 0.0077018414 | J15: =$H15 -> 0.0077018414 | K15: =$H15 -> 0.0077018414 | L15: =$H15 -> 0.0077018414 | M15: =$H15 -> 0.0077018414 | N15: =M15*(('Income Statement'!N14+7000)/'Income Statement'!N14) -> 0.0085481046 | O15: =N15 -> 0.0085481046 | P15: =O15 -> 0.0085481046 | Q15: =Q14/'Income Statement'!Q58 -> 0.0060787359 | R15: =R14/'Income Statement'!R58 -> 0.0052073584 | S15: =S14/'Income Statement'!S58 -> 0.0020780491 | T15: =T14/'Income Statement'!T58 -> 0.012306803 | U15: =U14/'Income Statement'!U58 -> 0.011589472 | V15: =U15 -> 0.011589472 | W15: =V15 -> 0.011589472 | X15: 0.004 | Y15: =X15 -> 0.004 | Z15: =Y15 -> 0.004 | AA15: =Z15 -> 0.004
A16: Valuation adjustments | B16: 163 | C16: 582 | D16: 924 | E16: -254 | F16: -366 | G16: -408 | H16: 318 | I16: 16 | J16: 562 | K16: 487 | L16: 1132 | M16: -1755 | N16: -1849 | O16: 600 | P16: 95 | Q16: -863 | R16: -569 | S16: -541 | T16: -640 | U16: -393
A17: Results on disposals on non-current assets | B17: -336 | C17: -125 | D17: -31 | E17: -31 | F17: -75 | G17: -29 | H17: -21 | I17: -58 | J17: -93 | K17: -234 | L17: -1870 | M17: -773 | N17: -261 | O17: -77 | P17: 9 | Q17: -116 | R17: 25 | S17: 64 | T17: 70 | U17: 17
A18: Results of equity investments | B18: -152 | C18: -210 | D18: -188 | E18: -115 | F18: -127 | G18: -164 | H18: -241 | I18: -295 | J18: -840 | K18: -1016 | L18: =-'Income Statement'!L74 -> -231 | M18: =-'Income Statement'!M74 -> -333 | N18: =-'Income Statement'!N74 -> -330 | O18: =-'Income Statement'!O74 -> -299 | P18: =-'Income Statement'!P74 -> -39 | Q18: =-'Income Statement'!Q74 -> -40 | R18: =-'Income Statement'!R74 -> -134 | S18: =-'Income Statement'!S74 -> -267 | ... AA18: =-'Income Statement'!AA74 -> -408.72917
A19: Movement in provisions | B19: 2150 | C19: 2268 | D19: 1 | E19: 1767 | F19: -219 | G19: 230 | H19: 1114 | I19: 605 | J19: 415 | K19: -54 | L19: 1321 | M19: 805 | N19: 1952 | O19: 475 | P19: 1138 | Q19: -1934 | R19: -1016 | S19: -114 | T19: 166 | U19: 314
A20: Change in inventory | B20: -1942 | C20: -2998 | D20: -1210 | E20: -1961 | F20: 705 | G20: -1640 | H20: -1526 | I20: ='Balance Sheet'!H16-'Balance Sheet'!I16 -> -1844 | J20: -3252 | K20: -4133 | L20: -3477 | M20: -2572 | N20: -671 | O20: 117 | P20: 152 | Q20: 2405 | R20: -3218 | S20: -1854 | T20: -3522 | U20: -3989 | V20: =-('Balance Sheet'!V16-'Balance Sheet'!U16) -> -2038.4576 | W20: =-('Balance Sheet'!W16-'Balance Sheet'!V16) -> -5808.1229 | X20: =-('Balance Sheet'!X16-'Balance Sheet'!W16) -> -5121.2667 | Y20: =-('Balance Sheet'!Y16-'Balance Sheet'!X16) -> -2928.3196 | Z20: =-('Balance Sheet'!Z16-'Balance Sheet'!Y16) -> -950.68753 | AA20: =-('Balance Sheet'!AA16-'Balance Sheet'!Z16) -> -2098.0301
A21: Change in receivables | B21: -7 | C21: -148 | D21: -845 | E21: -478 | F21: -345 | G21: 447 | H21: -260 | I21: ='Balance Sheet'!H18-'Balance Sheet'!I18 -> -451 | J21: -700 | K21: -1378 | L21: -1215 | M21: 621 | N21: -881 | O21: 29 | P21: 351 | Q21: 379 | R21: -115 | S21: 258 | T21: -105 | U21: -707 | V21: =-('Balance Sheet'!V18-'Balance Sheet'!U18) -> -1145.4012 | W21: =-('Balance Sheet'!W18-'Balance Sheet'!V18) -> -908.33892 | X21: =-('Balance Sheet'!X18-'Balance Sheet'!W18) -> -647.58004 | Y21: =-('Balance Sheet'!Y18-'Balance Sheet'!X18) -> -380.48665 | Z21: =-('Balance Sheet'!Z18-'Balance Sheet'!Y18) -> -433.01786 | AA21: =-('Balance Sheet'!AA18-'Balance Sheet'!Z18) -> -349.25094
A22: Change in trade liabilities | B22: 686 | C22: 44 | D22: 757 | E22: 192 | F22: -40 | G22: 806 | H22: 754 | I22: =-('Balance Sheet'!I40-'Balance Sheet'!H40) -> 451 | J22: 130 | K22: 1603 | L22: 2398 | M22: 1419 | N22: 2294 | O22: -1625 | P22: -5523 | Q22: 194 | R22: 3309 | S22: 1421 | T22: -1182 | U22: 2791 | V22: =-('Balance Sheet'!V40-'Balance Sheet'!U40) -> 120.25097 | W22: =-('Balance Sheet'!W40-'Balance Sheet'!V40) -> 2330.7839 | X22: =-('Balance Sheet'!X40-'Balance Sheet'!W40) -> 2278.2652 | Y22: =-('Balance Sheet'!Y40-'Balance Sheet'!X40) -> 1816.2658 | Z22: =-('Balance Sheet'!Z40-'Balance Sheet'!Y40) -> 1427.0092 | AA22: =-('Balance Sheet'!AA40-'Balance Sheet'!Z40) -> 1183.6736
A23: Change in working capital | Q23: =Q20+Q21+Q22+Q24+Q25 -> 1067 | R23: =R20+R21+R22+R24+R25 -> 1421 | S23: =S20+S21+S22+S24+S25 -> 1205 | T23: =T20+T21+T22+T24+T25 -> 1337 | U23: =U20+U21+U22+U24+U25 -> 100 | V23: =V20+V21+V22+V24+V25 -> 286.29731 | W23: =W20+W21+W22+W24+W25 -> 1076.5364 | X23: =X20+X21+X22+X24+X25 -> 2094.6614 | ... AA23: =AA20+AA21+AA22+AA24+AA25 -> 986.59515
A24: Advance payments received/ Contract Assets and Liabilities | B24: 1564 | C24: 4817 | D24: 2435 | E24: 2925 | F24: 1698 | G24: 1965 | H24: 1243 | I24: ='Balance Sheet'!#REF!-'Balance Sheet'!#REF! -> #REF! | J24: 1715 | K24: 3752 | L24: 4628 | M24: 1268 | N24: -684 | O24: 1297 | P24: 848 | Q24: -2326 | R24: 3300 | S24: 2277 | T24: 7135 | U24: 3250 | V24: ='Balance Sheet'!U43-'Balance Sheet'!V43 -> 3349.9051 | W24: ='Balance Sheet'!V43-'Balance Sheet'!W43 -> 5462.2143 | X24: ='Balance Sheet'!W43-'Balance Sheet'!X43 -> 5585.243 | Y24: ='Balance Sheet'!X43-'Balance Sheet'!Y43 -> 4263.3225 | Z24: ='Balance Sheet'!Y43-'Balance Sheet'!Z43 -> 2789.9078 | AA24: ='Balance Sheet'!Z43-'Balance Sheet'!AA43 -> 2250.2026
A25: Other assets and liabilities | B25: -444 | C25: -540 | D25: -982 | E25: -257 | F25: 738 | G25: -327 | H25: -141 | J25: -387 | K25: -417 | L25: -837 | M25: -470 | N25: -691 | O25: 2398 | P25: -4065 | Q25: 415 | R25: -1855 | S25: -897 | T25: -989 | U25: -1245
A26: Other | B26: =B27-SUM(B4:B12,B14,B16:B25) -> 1160 | C26: =C27-SUM(C4:C12,C14,C16:C25) -> 61 | D26: =D27-SUM(D4:D12,D14,D16:D25) -> -327 | E26: =E27-SUM(E4:E12,E14,E16:E25) -> -406 | F26: =F27-SUM(F4:F12,F14,F16:F25) -> 63 | G26: =G27-SUM(G4:G12,G14,G16:G25) -> 135 | H26: =H27-SUM(H4:H12,H14,H16:H25) -> -1013 | I26: =I27-SUM(I4:I12,I14,I16:I25) -> #REF! | J26: =J27-SUM(J4:J12,J14,J16:J25) -> -354 | K26: -217 | L26: -290 | M26: =-'Cash Flow Statement'!M83 -> -458 | N26: =-2519 -> -2519 | O26: -1752 | P26: -314 | Q26: -533 | R26: -600 | S26: -668 | T26: -505 | U26: -272 | V26: -450 | W26: =U26 -> -272 | X26: =W26 -> -272 | Y26: =X26 -> -272 | Z26: =Y26 -> -272 | AA26: =Z26 -> -272
A27: Cashflow from Operating activities | B27: 4558 | C27: 5098 | D27: 4399 | E27: 2438 | F27: 4443 | G27: 4289 | H27: 3840 | I27: 1931 | J27: 2560 | K27: =SUM(K4:K12,K14,K16:K26) -> 3750 | L27: =SUM(L4:L12,L14,L16:L26) -> 4621 | M27: =SUM(M4:M12,M14,M16:M26) -> 4444 | N27: =SUM(N4:N12,N14,N16:N26) -> 2318 | O27: =SUM(O4:O12,O14,O16:O26) -> 3753 | P27: =SUM(P4:P12,P14,P16:P26) -> -5420 | Q27: =SUM(Q4:Q12,Q14,Q16:Q19,Q23,Q26) -> 4639 | R27: =SUM(R4:R12,R14,R16:R19,R23,R26) -> 6288 | S27: =SUM(S4:S12,S14,S16:S19,S23,S26) -> 6255 | T27: =SUM(T4:T12,T14,T16:T19,T23,T26) -> 7402 | U27: =SUM(U4:U12,U14,U16:U19,U23,U26) -> 7995 | V27: =SUM(V4:V12,V14,V16:V19,V23,V26) -> 8218.6562 | W27: =SUM(W4:W12,W14,W16:W19,W23,W26) -> 10701.37 | X27: =SUM(X4:X12,X14,X16:X19,X23,X26) -> 13033.968 | ... AA27: =SUM(AA4:AA12,AA14,AA16:AA19,AA23,AA26) -> 15505.69
A28: Purchases of intangible assets, PP&E & Investment property | B28: -2708 | C28: -2028 | D28: -1837 | E28: -1957 | F28: -2250 | G28: -2197 | H28: -3270 | I28: -2949 | J28: -2548 | K28: -2924 | L28: -3060 | M28: -2558 | N28: -2285 | O28: -2340 | P28: -1759 | Q28: -1928 | R28: -2464 | S28: -3051 | T28: -3669 | U28: -3964 | V28: =-V29*'Income Statement'!V$58 -> -4175.2212 | W28: =-W29*'Income Statement'!W$58 -> -4567.2086 | X28: =-X29*'Income Statement'!X$58 -> -5029.5828 | Y28: =-Y29*'Income Statement'!Y$58 -> -5340.9763 | Z28: =-Z29*'Income Statement'!Z$58 -> -5495.0067 | AA28: =-AA29*'Income Statement'!AA$58 -> -5587.5175
A29: as a % of sales | B29: =-B28/'Income Statement'!B$58 -> 0.068671705 | C29: =-C28/'Income Statement'!C$58 -> 0.051836516 | D29: =-D28/'Income Statement'!D$58 -> 0.042459263 | E29: =-E28/'Income Statement'!E$58 -> 0.045700808 | F29: =-F28/'Income Statement'!F$58 -> 0.049178178 | G29: =-G28/'Income Statement'!G$58 -> 0.044719915 | H29: =-H28/'Income Statement'!H$58 -> 0.057896601 | I29: =-I28/'Income Statement'!I$58 -> 0.046946638 | ... U29: =-U28/'Income Statement'!U$58 -> 0.053920969 | V29: 0.052 | W29: =V29-0.2% -> 0.05 | X29: =W29-0.1% -> 0.049 | Y29: =X29-0.1% -> 0.048 | Z29: =Y29-0.1% -> 0.047 | AA29: =Z29-0.1% -> 0.046
A30: Proceeds from disposals of intangible assets, PP&E & Investment Property | B30: 76 | C30: 162 | D30: 35 | E30: 75 | F30: 45 | G30: 79 | H30: 73 | I30: 60 | J30: 232 | K30: 78 | L30: 72 | M30: 177 | N30: 213 | O30: 112 | P30: 228 | Q30: 212 | R30: 101 | S30: 75 | T30: 98 | U30: 69 | V30: =V31*'Income Statement'!V14 -> 75.361455 | W30: =W31*'Income Statement'!W14 -> 85.734175 | X30: =X31*'Income Statement'!X14 -> 96.340526 | Y30: =Y31*'Income Statement'!Y14 -> 104.43656 | Z30: =Z31*'Income Statement'!Z14 -> 109.73458 | AA30: =AA31*'Income Statement'!AA14 -> 114.0077
