Workbook
Name A_ALL_KEYWORDS_TYPE_ScalarContributed_EQTY_200001648: #REF!,#REF!,#REF!,#REF!,#REF!
Name A_ALL_KEYWORDS_TYPE_ScalarContributed_ISSR_208000604: #REF!,#REF!
Name A_ALL_KEYWORDS_TYPE_ScalarReference_EQTY_200001648: #REF!
Name A_ALL_KEYWORDS_TYPE_ScalarReference_ISSR_208000604: #REF!
Name A_ALL_KEYWORDS_TYPE_Vector_EQTY_200001648: #REF!,#REF!,#REF!,#REF!,#REF!,#REF!,#REF!
Name A_ALL_KEYWORDS_TYPE_Vector_ISSR_208000604: #REF!,#REF!,#REF!,#REF!,#REF!,#REF!,#REF!,#REF!,#REF!
Name A_ALL_RTX: #REF!
Name A_ALL_SECTION_KEYWORDS_EQTY_200001648_1314: #REF!
Name A_ALL_SECTION_KEYWORDS_EQTY_200001648_1319: #REF!
Name A_ALL_SECTION_KEYWORDS_EQTY_200001648_131E: #REF!
Name A_ALL_SECTION_KEYWORDS_EQTY_200001648_131O: #REF!
Name A_ALL_SECTION_KEYWORDS_EQTY_200001648_13A: #REF!
Name A_ALL_SECTION_KEYWORDS_EQTY_200001648_13K: #REF!
Name A_ALL_SECTION_KEYWORDS_EQTY_200001648_13U: #REF!
Name A_ALL_SECTION_KEYWORDS_EQTY_200001648_13V: #REF!
Name A_ALL_SECTION_KEYWORDS_EQTY_200001648_13W: #REF!
Name A_ALL_SECTION_KEYWORDS_EQTY_200001648_Reference_Data: #REF!
Name A_ALL_SECTION_KEYWORDS_ISSR_208000604_1314: #REF!
Name A_ALL_SECTION_KEYWORDS_ISSR_208000604_13168: #REF!
Name A_ALL_SECTION_KEYWORDS_ISSR_208000604_1316S: #REF!
Name A_ALL_SECTION_KEYWORDS_ISSR_208000604_1316T: #REF!
Name A_ALL_SECTION_KEYWORDS_ISSR_208000604_1316U: #REF!
Name A_ALL_SECTION_KEYWORDS_ISSR_208000604_1319: #REF!
Name A_ALL_SECTION_KEYWORDS_ISSR_208000604_131E: #REF!
Name A_ALL_SECTION_KEYWORDS_ISSR_208000604_131J: #REF!
Name A_ALL_SECTION_KEYWORDS_ISSR_208000604_131O: #REF!
Name A_ALL_SECTION_KEYWORDS_ISSR_208000604_136E: #REF!,#REF!
Name A_ALL_SECTION_KEYWORDS_ISSR_208000604_13A: #REF!
Name A_ALL_SECTION_KEYWORDS_ISSR_208000604_13U: #REF!
Name A_ALL_SECTION_KEYWORDS_ISSR_208000604_13V: #REF!
Name A_ALL_SECTION_KEYWORDS_ISSR_208000604_Reference_Data: #REF!
Name A_ALL_SECTIONS_EQTY_200001648: #REF!,#REF!,#REF!,#REF!,#REF!,#REF!,#REF!,#REF!,#REF!,#REF!
Name A_ALL_UTX_: #REF!
Name A_CURRENCY_EQTY_200001648_PRI: #REF!
Name A_CURRENCY_EQTY_200001648_PUB: #REF!
Name A_CURRENCY_EQTY_200001648_REP: #REF!
Name A_CURRENCY_ISSR_208000604_REP: #REF!
Name A_KEYWORD_EQTY_200001648_AMER_LIST: #REF!
Name A_KEYWORD_EQTY_200001648_BETA_ANALYST: #REF!
Name A_KEYWORD_EQTY_200001648_BVPS: #REF!
Name A_KEYWORD_EQTY_200001648_BVPS_PUB: #REF!
Name A_KEYWORD_EQTY_200001648_CEEE_EPS: #REF!
Name A_KEYWORD_EQTY_200001648_CF_NI_PRE_PREF: #REF!
Name A_KEYWORD_EQTY_200001648_COMMON_DIV_PAID: #REF!
Name A_KEYWORD_EQTY_200001648_CURRENCY_ISO: #REF!
Name A_KEYWORD_EQTY_200001648_DILUTE_SHARES: #REF!
Name A_KEYWORD_EQTY_200001648_DPS: #REF!
Name A_KEYWORD_EQTY_200001648_DPS_PUB: #REF!
Name A_KEYWORD_EQTY_200001648_EBIT_PUB: #REF!
Name A_KEYWORD_EQTY_200001648_EBITDA_PUB: #REF!
Name A_KEYWORD_EQTY_200001648_EPS: #REF!
Name A_KEYWORD_EQTY_200001648_EPS_EX_ESO_B: #REF!
Name A_KEYWORD_EQTY_200001648_EPS_EX_ESO_D: #REF!
Name A_KEYWORD_EQTY_200001648_EPS_FUL_DIL: #REF!
Name A_KEYWORD_EQTY_200001648_EPS_POST_BASIC: #REF!
Name A_KEYWORD_EQTY_200001648_EPS_PUB: #REF!
Name A_KEYWORD_EQTY_200001648_EPS_PUB_EX_ESO: #REF!
Name A_KEYWORD_EQTY_200001648_EQ_PUB: #REF!
Name A_KEYWORD_EQTY_200001648_ESO_POST_TAX: #REF!
Name A_KEYWORD_EQTY_200001648_ESO_YEAR: #REF!

Sheet __FDSCACHE__
B1: This sheet contains FactSet XML data for use with this workbook's =FDS codes. Modifying the worksheet's contents may damage the workbook's =FDS functionality.

Sheet Cover
D7: Raytheon Technologies (RTX) Model
D8: 45951
B16: Noah Poponak, CFA
B17: (212) 357-0954
B18: noah.poponak@gs.com
B20: Anthony Valentini, CFA
B21: (212) 934-0385
B22: anthony.valentini@gs.com
B24: Connor Dessert
B25: (212) 357-6166
B26: connor.dessert@gs.com
B28: Will Ortmayer
B29: (801) 744-0681
B30: will.ortmayer@gs.com

Sheet Data
B3: RTX Raw Data | C3: 1997 | D3: 1998 | E3: 1999 | F3: 2000 | G3: 2001 | H3: 2002 | I3: 2003 | J3: 1Q04 | K3: 2Q04 | L3: 3Q04 | M3: 4Q04 | N3: 2004 | O3: 1Q05 | P3: 2Q05 | Q3: 3Q05 | R3: 4Q05 | S3: 2005 | T3: 1Q06 | U3: 2Q06 | V3: 3Q06 | W3: 4Q06 | X3: 2006 | Y3: 1Q07 | Z3: 2Q07 | AA3: 3Q07 | AB3: 4Q07 | AC3: 2007 | AD3: 1Q08 | AE3: 2Q08 | AF3: 3Q08 | AG3: 4Q08 | AH3: 2008 | AI3: 1Q09 | AJ3: 2Q09 | AK3: 3Q09 | AL3: 4Q09 | AM3: 2009 | AN3: 1Q10 | AO3: 2Q10 | AP3: 3Q10 | AQ3: 4Q10 | AR3: 2010 | AS3: 1Q11 | AT3: 2Q11 | AU3: 3Q11 | AV3: 4Q11 | AW3: 2011 | AX3: 1Q12 | AY3: 2Q12 | AZ3: 3Q12 | BA3: 4Q12 | BB3: 2012 | BC3: 1Q13 | BD3: 2Q13 | BE3: 3Q13 | BF3: 4Q13 | BG3: 2013 | BH3: 1Q14 | BI3: 2Q14 | BJ3: 3Q14 | BK3: 4Q14 | BL3: 2014 | BM3: 1Q15 | BN3: 2Q15 | BO3: 3Q15 | BP3: 4Q15 | BQ3: 2015 | BR3: 1Q16 | BS3: 2Q16 | BT3: 3Q16 | BU3: 4Q16 | BV3: 2016 | BW3: 1Q17 | BX3: 2Q17 | BY3: 3Q17 | BZ3: 4Q17 | CA3: 2017 | CB3: 1Q18 | CC3: 2Q18 | CD3: 3Q18 | CE3: 4Q18 | CF3: 2018 | CG3: 1Q19 | CH3: 2Q19 | CI3: 3Q19 | CJ3: 4Q19 | CK3: 2019 | CL3: 1Q20 | CM3: 2Q20 | CN3: 3Q20 | CO3: 4Q20 | CP3: 2020 | CQ3: 1Q21 | CR3: 2Q21 | CS3: 3Q21 | CT3: 4Q21 | CU3: 2021 | CV3: 1Q22 | CW3: 2Q22 | CX3: 3Q22 | CY3: 4Q22 | CZ3: 2022 | DA3: 1Q23 | DB3: 2Q23 | DC3: 3Q23 | DD3: 4Q23 | DE3: 2023 | DF3: 1Q24 | DG3: 2Q24 | DH3: 3Q24 | DI3: 4Q24 | DJ3: 2024 | DK3: 1Q25 | DL3: 2Q25 | DM3: 3Q25 | DN3: 4Q25 | DO3: 2025 | DP3: 1Q26 | DQ3: 2Q26 | DR3: 3Q26 | DS3: 4Q26 | DT3: 2026 | DU3: 2027 | DV3: 2028
B4: ($ mn) | C4: 35795 | D4: 36160 | E4: 36525 | F4: 36891 | G4: 37256 | H4: 37621 | I4: 37986 | J4: 38076 | K4: 38168 | L4: 38260 | M4: 38352 | N4: 38352 | O4: 38441 | P4: 38533 | Q4: 38625 | R4: 38717 | S4: 38717 | T4: 38806 | U4: 38898 | V4: 38990 | W4: 39082 | X4: 39082 | Y4: 39171 | Z4: 39263 | AA4: 39355 | AB4: 39447 | AC4: 39447 | AD4: 39537 | AE4: 39629 | AF4: 39721 | AG4: 39813 | AH4: 39813 | AI4: 39902 | AJ4: 39994 | AK4: 40086 | AL4: 40178 | AM4: 40178 | AN4: 40267 | AO4: 40359 | AP4: 40451 | AQ4: 40543 | AR4: 40543 | AS4: 40632 | AT4: 40724 | AU4: 40816 | AV4: 40908 | AW4: 40908 | AX4: 40998 | AY4: 41090 | AZ4: 41182 | BA4: 41274 | BB4: 41274 | BC4: 41363 | BD4: 41455 | BE4: 41547 | BF4: 41639 | BG4: 41639 | BH4: 41728 | BI4: 41820 | BJ4: 41912 | BK4: 42004 | BL4: 42004 | BM4: 42093 | BN4: 42185 | BO4: 42277 | BP4: 42369 | BQ4: 42369 | BR4: 42459 | BS4: 42551 | BT4: 42643 | BU4: 42735 | BV4: 42735 | BW4: 42824 | BX4: 42916 | BY4: 43008 | BZ4: 43100 | CA4: 43100 | CB4: 43189 | CC4: 43281 | CD4: 43373 | CE4: 43465 | CF4: 43465 | CG4: 43554 | CH4: 43646 | CI4: 43738 | CJ4: 43830 | CK4: 43830 | CL4: 43920 | CM4: 44012 | CN4: 44104 | CO4: 44196 | CP4: 44196 | CQ4: 44285 | CR4: 44377 | CS4: 44469 | CT4: 44561 | CU4: 44561 | CV4: 44650 | CW4: 44742 | CX4: 44834 | CY4: 44926 | CZ4: 44926 | DA4: 45015 | DB4: 45107 | DC4: 45199 | DD4: 45291 | DE4: 45291 | DF4: 45381 | DG4: 45473 | DH4: 45565 | DI4: 45657 | DJ4: 45657 | DK4: 45746 | DL4: 45838 | DM4: 45930 | DN4: 46022 | DO4: 46022 | DP4: 46111 | DQ4: 46203 | DR4: 46295 | DS4: 46387 | DT4: 46387 | DU4: 46752 | DV4: 47118
B6: Income Statement
B7: Product sales | CF7: 53157 | CG7: 13651.4 | CH7: 14208.6 | CI7: 14350.14 | CJ7: 14935.86 | CN7: 11469 | CQ7: 11664
B8: Service sales | CF8: 16015 | CG8: 4013.1 | CH8: 4176.9 | CI8: 4361.49 | CJ8: 4539.51 | CN8: 3278 | CQ8: 3587
B9: Net sales | CF9: =CF7+CF8 -> 69172 | CG9: 17664.5 | CH9: 18385.5 | CI9: 18711.63 | CJ9: 19475.37 | CK9: =SUM(CG9:CJ9) -> 74237 | CL9: 18451 | CM9: 14470 | CN9: =CN7+CN8 -> 14747 | CO9: 16419 | CP9: =SUM(CL9:CO9) -> 64087 | CQ9: =CQ7+CQ8 -> 15251 | CR9: 15880 | CS9: 16213 | CT9: 17044 | CV9: 15716 | CW9: 16314 | CX9: 16951 | CY9: 18093 | DA9: 17214 | DB9: 18315 | DC9: 13464 | DD9: 19927 | DF9: 19305 | DG9: 19721 | DH9: 20089 | DI9: 21623 | DK9: 20306 | DL9: 21581 | DM9: 22478
B10: Cost of products sold | CF10: 42281 | CG10: 10703.07 | CH10: 11139.93 | CI10: 11715.41 | CJ10: 12193.59 | CM10: 9620 | CN10: 10322 | CQ10: 9974
B11: Cost of services sold | CF11: 10602 | CG11: 2651.39 | CH11: 2759.61 | CI11: 2912.07 | CJ11: 3030.93 | CM11: 2594 | CN11: 2682 | CQ11: 2563
B12: Cost of goods sold | CF12: =CF10+CF11 -> 52883 | CG12: 13354.46 | CH12: 13899.54 | CI12: 14627.48 | CJ12: 15224.52 | CK12: =SUM(CG12:CJ12) -> 57106 | CM12: =CM10+CM11 -> 12214 | CN12: =CN10+CN11 -> 13004 | CO12: 14266 | CQ12: =CQ10+CQ11 -> 12537 | CR12: 12655 | CS12: 13089 | CT12: 13616 | CV12: 12560 | CW12: 12856 | CX12: 13464 | CY12: 14526 | DA12: 13645 | DB12: 14518 | DC12: 12750 | DD12: 15918 | DF12: 15744 | DG12: 16141 | DH12: 16055 | DI12: 17388 | DK12: 16190 | DL12: 17205 | DM12: 17898
B13: Research and development | CF13: 3252 | CG13: 779.1 | CH13: 810.9 | CI13: 782.04 | CJ13: 813.96 | CK13: =SUM(CG13:CJ13) -> 3186 | CM13: 695 | CN13: 642 | CO13: 710 | CQ13: 589 | CR13: 657 | CS13: 676 | CT13: 810 | CV13: 635 | CW13: 698 | CX13: 662 | CY13: 716 | DA13: 607 | DB13: 729 | DC13: 712 | DD13: 757 | DF13: 669 | DG13: 706 | DH13: 751 | DI13: 808 | DK13: 637 | DL13: 697 | DM13: 684
B14: Selling and administrative expenses | CF14: 5553 | CG14: 1368.08 | CH14: 1423.92 | CI14: 1450.89 | CJ14: 1510.11 | CK14: =SUM(CG14:CJ14) -> 5753 | CM14: 1811 | CN14: 1401 | CO14: 1351 | CQ14: 1220 | CR14: 1368 | CS14: 1229 | CT14: 1407 | CV14: 1469 | CW14: 1424 | CX14: 1391 | CY14: 1379 | DA14: 1398 | DB14: 1635 | DC14: 1401 | DD14: 1445 | DF14: 1394 | DG14: 1449 | DH14: 1389 | DI14: 1574 | DK14: 1448 | DL14: 1573 | DM14: 1436
B15: Charges & other | CM15: -3183 | CT15: -617
B16: Other income (expense), net | CF16: 337 | CG16: 97.02 | CH16: 100.98 | CI16: 75.95 | CJ16: 79.05 | CK16: =SUM(CG16:CJ16) -> 353 | CM16: 82 | CN16: 734 | CO16: 50 | CQ16: 108 | CR16: 82 | CS16: 124 | CT16: =109 -> 109 | CV16: 28 | CW16: 17 | CX16: 46 | CY16: 29 | DA16: 88 | DB16: 25 | DC16: 3 | DD16: -30 | DF16: 372 | DG16: -896 | DH16: 134 | DI16: 258 | DK16: 4 | DL16: 40 | DM16: 63
B17: EBIT | CF17: =CF9-CF12-CF13-CF14+CF16 -> 7821 | CG17: 2259.88 | CH17: 2352.12 | CI17: 1927.17 | CJ17: 2005.83 | CK17: =CK9-CK12-CK13-CK14+CK16 -> 8545 | CL17: 2187 | CM17: -3617 | CN17: =CN9-CN12-CN13-CN14+CN15+CN16 -> 434 | CO17: =CO9-CO12-CO13-CO14+CO15+CO16 -> 142 | CP17: =SUM(CL17:CO17) -> -854 | CQ17: =CQ9-CQ12-CQ13-CQ14+CQ15+CQ16 -> 1013 | CR17: =CR9-CR12-CR13-CR14+CR15+CR16 -> 1282 | CS17: =CS9-CS12-CS13-CS14+CS15+CS16 -> 1343 | CT17: =CT9-CT12-CT13-CT14+CT15+CT16 -> 703 | CV17: =CV9-CV12-CV13-CV14+CV15+CV16 -> 1080 | CW17: =CW9-CW12-CW13-CW14+CW15+CW16 -> 1353 | CX17: =CX9-CX12-CX13-CX14+CX15+CX16 -> 1480 | CY17: =CY9-CY12-CY13-CY14+CY15+CY16 -> 1501 | DA17: =DA9-DA12-DA13-DA14+DA15+DA16 -> 1652 | DB17: =DB9-DB12-DB13-DB14+DB15+DB16 -> 1458 | DC17: =DC9-DC12-DC13-DC14+DC15+DC16 -> -1396 | DD17: =DD9-DD12-DD13-DD14+DD15+DD16 -> 1777 | DF17: =DF9-DF12-DF13-DF14+DF15+DF16 -> 1870 | DG17: =DG9-DG12-DG13-DG14+DG15+DG16 -> 529 | DH17: =DH9-DH12-DH13-DH14+DH15+DH16 -> 2028 | DI17: =DI9-DI12-DI13-DI14+DI15+DI16 -> 2111 | DK17: =DK9-DK12-DK13-DK14+DK15+DK16 -> 2035 | DL17: =DL9-DL12-DL13-DL14+DL15+DL16 -> 2146 | DM17: =DM9-DM12-DM13-DM14+DM15+DM16 -> 2523
B18: Non-service pension (benefit) cost | CF18: -1305 | CG18: -315.07 | CH18: -327.93 | CI18: -278.81 | CJ18: -290.19 | CK18: =SUM(CG18:CJ18) -> -1212 | CL18: -276 | CM18: -225 | CN18: -253 | CO18: -244 | CP18: =SUM(CL18:CO18) -> -998 | CQ18: -491 | CR18: -490 | CS18: -491 | CT18: -472 | CV18: -480 | CW18: -474 | CX18: -468 | CY18: -467 | DA18: -444 | DB18: -447 | DC18: -443 | DD18: -446 | DF18: -386 | DG18: -374 | DH18: -374 | DI18: -384 | DK18: -366 | DL18: -351 | DM18: -364
B19: Interest expense (income), net | CF19: 1001 | CG19: 253.82 | CH19: 264.18 | CI19: 274.89 | CJ19: 286.11 | CK19: =SUM(CG19:CJ19) -> 1079 | CL19: 252 | CM19: 337 | CN19: 350 | CO19: 349 | CP19: =SUM(CL19:CO19) -> 1288 | CQ19: 346 | CR19: 342 | CS19: 358 | CT19: 308 | CV19: 318 | CW19: 329 | CX19: 311 | CY19: 318 | DA19: 315 | DB19: 333 | DC19: 369 | DD19: 488 | DF19: 405 | DG19: 475 | DH19: 496 | DI19: 486 | DK19: 443 | DL19: 457 | DM19: 449
B20: EBT | CF20: =CF17-CF18-CF19 -> 8125 | CG20: 2321.13 | CH20: 2415.87 | CI20: 1931.09 | CJ20: 2009.91 | CK20: =CK17-CK18-CK19 -> 8678 | CL20: =CL17-CL18-CL19 -> 2211 | CM20: =CM17-CM18-CM19 -> -3729 | CN20: =CN17-CN18-CN19 -> 337 | CO20: =CO17-CO18-CO19 -> 37 | CP20: =SUM(CL20:CO20) -> -1144 | CQ20: =CQ17-CQ18-CQ19 -> 1158 | CR20: =CR17-CR18-CR19 -> 1430 | CS20: =CS17-CS18-CS19 -> 1476 | CT20: =CT17-CT18-CT19 -> 867 | CV20: =CV17-CV18-CV19 -> 1242 | CW20: =CW17-CW18-CW19 -> 1498 | CX20: =CX17-CX18-CX19 -> 1637 | CY20: =CY17-CY18-CY19 -> 1650 | DA20: =DA17-DA18-DA19 -> 1781 | DB20: =DB17-DB18-DB19 -> 1572 | DC20: =DC17-DC18-DC19 -> -1322 | DD20: =DD17-DD18-DD19 -> 1735 | DF20: =DF17-DF18-DF19 -> 1851 | DG20: =DG17-DG18-DG19 -> 428 | DH20: =DH17-DH18-DH19 -> 1906 | DI20: =DI17-DI18-DI19 -> 2009 | DK20: =DK17-DK18-DK19 -> 1958 | DL20: =DL17-DL18-DL19 -> 2040 | DM20: =DM17-DM18-DM19 -> 2438
B21: Income tax expense (income) | CF21: 1808 | CG21: 296.94 | CH21: 309.06 | CI21: 299.88 | CJ21: 312.12 | CK21: =SUM(CG21:CJ21) -> 1218 | CL21: 419 | CM21: -23 | CN21: 152 | CO21: -178 | CP21: =SUM(CL21:CO21) -> 370 | CQ21: 345 | CR21: 342 | CS21: 3 | CT21: 96 | CV21: 116 | CW21: 160 | CX21: 242 | CY21: 182 | DA21: 300 | DB21: 213 | DC21: -389 | DD21: 262 | DF21: 108 | DG21: 253 | DH21: 371 | DI21: 449 | DK21: 333 | DL21: 315 | DM21: 432
B22: Net income, continuing ops.
B23: Discontinued ops. & non recurring items: | CM23: 9 | CN23: =13-100 -> -87 | CO23: =-14+3 -> -11 | CP23: =SUM(CL23:CO23) -> -89 | CQ23: -20 | CR23: -8 | CS23: -73 | CT23: -21
B24: Net income | CF24: =CF20-CF21 -> 6317 | CG24: 2024.19 | CH24: 2106.81 | CI24: 1631.21 | CJ24: 1697.79 | CK24: =CK20-CK21 -> 7460 | CL24: =CL20-CL21 -> 1792 | CM24: =CM20-CM21 -> -3706 | CN24: =CN20-CN21 -> 185 | CO24: =CO20-CO21 -> 215 | CP24: =SUM(CL24:CO24) -> -1514 | CQ24: =CQ20-CQ21 -> 813 | CR24: =CR20-CR21 -> 1088 | CS24: =CS20-CS21 -> 1473 | CT24: =CT20-CT21 -> 771 | CV24: =CV20-CV21 -> 1126 | CW24: =CW20-CW21 -> 1338 | CX24: =CX20-CX21 -> 1395 | CY24: =CY20-CY21 -> 1468 | DA24: =DA20-DA21 -> 1481 | DB24: =DB20-DB21 -> 1359 | DC24: =DC20-DC21 -> -933 | DD24: =DD20-DD21 -> 1473 | DF24: =DF20-DF21 -> 1743 | DG24: =DG20-DG21 -> 175 | DH24: =DH20-DH21 -> 1535 | DI24: =DI20-DI21 -> 1560 | DK24: =DK20-DK21 -> 1625 | DL24: =DL20-DL21 -> 1725 | DM24: =DM20-DM21 -> 2006
B25: Non controlling interest | CF25: 163 | CG25: 41.16 | CH25: 42.84 | CI25: 60.27 | CJ25: 62.73 | CK25: =SUM(CG25:CJ25) -> 207 | CL25: 56 | CM25: 24 | CN25: 34 | CO25: 69 | CP25: =SUM(CL25:CO25) -> 183 | CQ25: 41 | CR25: 48 | CS25: 73 | CT25: 86 | CV25: 23 | CW25: 34 | CX25: 8 | CY25: 46 | DA25: 55 | DB25: 32 | DC25: 51 | DD25: 47 | DF25: 34 | DG25: 64 | DH25: 63 | DI25: 78 | DK25: 90 | DL25: 68 | DM25: 88
B26: Net income attributable to shareholders | CF26: =CF24-CF25 -> 6154 | CG26: 1983.03 | CH26: 2063.97 | CI26: 1570.94 | CJ26: 1635.06 | CK26: =CK24-CK25 -> 7253 | CL26: =CL24-CL25 -> 1736 | CM26: =CM24-CM25 -> -3730 | CN26: =CN24-CN25 -> 151 | CO26: =CO24-CO25 -> 146 | CP26: =SUM(CL26:CO26) -> -1697 | CQ26: =CQ24-CQ25 -> 772 | CR26: =CR24-CR25 -> 1040 | CS26: =CS24-CS25 -> 1400 | CT26: =CT24-CT25 -> 685 | CV26: =CV24-CV25 -> 1103 | CW26: =CW24-CW25 -> 1304 | CX26: =CX24-CX25 -> 1387 | CY26: =CY24-CY25 -> 1422 | DA26: =DA24-DA25 -> 1426 | DB26: =DB24-DB25 -> 1327 | DC26: =DC24-DC25 -> -984 | DD26: =DD24-DD25 -> 1426 | DF26: =DF24-DF25 -> 1709 | DG26: =DG24-DG25 -> 111 | DH26: =DH24-DH25 -> 1472 | DI26: =DI24-DI25 -> 1482 | DK26: =DK24-DK25 -> 1535 | DL26: =DL24-DL25 -> 1657 | DM26: =DM24-DM25 -> 1918
B28: Net income, continuing ops. attributable to shareholders
B29: =+B23 -> Discontinued ops. & non recurring items:
B30: =+B26 -> Net income attributable to shareholders
B32: Basic EPS, continuing ops. | CF32: =CF26/CF41 -> 4.2491197 | CG32: 1.32 | CH32: 1.37 | CI32: 1.04 | CJ32: 1.09 | CK32: =CK26/CK41 -> 4.8237563 | CL32: =CL26/CL41 -> 1.1521869 | CM32: =CM26/CM41 -> -2.4845134 | CN32: =CN26/CN41 -> 0.099900761 | CO32: =CO26/CO41 -> 0.096541691 | CP32: =CP26/CP41 -> -1.1225772 | CQ32: =CQ26/CQ41 -> 0.51088611 | CR32: =CR26/CR41 -> 0.69038768 | ... CT32: =CT26/CT41 -> 0.45957732 | CV32: =CV26/CV41 -> 0.74186172 | CW32: =CW26/CW41 -> 0.8815576 | CX32: =CX26/CX41 -> 0.94347323 | CY32: =CY26/CY41 -> 0.9703173 | DA32: =DA26/DA41 -> 0.97524278 | DB32: =DB26/DB41 -> 0.91046312 | DC32: =DC26/DC41 -> -0.67951108 | DD32: =DD26/DD41 -> 1.0524762 | DF32: =DF26/DF41 -> 1.2855423 | DG32: =DG26/DG41 -> 0.083345848 | DH32: =DH26/DH41 -> 1.1041104 | DI32: =DI26/DI41 -> 1.1106115 | DK32: =DK26/DK41 -> 1.1480069 | DL32: =DL26/DL41 -> 1.2360137 | DM32: =DM26/DM41 -> 1.4280396
B33: Discontinued ops. & non recurring items
B34: Basic EPS, reported
B36: Diluted EPS, continuing ops. | CF36: =CF26/CF42 -> 4.2173794 | CG36: 1.31 | CH36: 1.36 | CI36: 1.03 | CJ36: 1.08 | CK36: =CK26/CK42 -> 4.784932 | CL36: =CL26/CL42 -> 1.1436854 | CM36: =CM26/CM42 -> -2.4845134 | CN36: =CN26/CN42 -> 0.099722626 | CO36: =CO26/CO42 -> 0.0963442 | CP36: =CP26/CP42 -> -1.1225772 | CQ36: =CQ26/CQ42 -> 0.50987385 | CR36: =CR26/CR42 -> 0.68714899 | ... CT36: =CT26/CT42 -> 0.45660579 | CV36: =CV26/CV42 -> 0.73636424 | CW36: =CW26/CW42 -> 0.87540279 | CX36: =CX26/CX42 -> 0.93760562 | CY36: =CY26/CY42 -> 0.96321886 | DA36: =DA26/DA42 -> 0.9673043 | DB36: =DB26/DB42 -> 0.90352012 | DC36: =DC26/DC42 -> -0.67596345 | DD36: =DD26/DD42 -> 1.0472204 | DF36: =DF26/DF42 -> 1.2779481 | DG36: =DG26/DG42 -> 0.082706207 | DH36: =DH26/DH42 -> 1.0934482 | DI36: =DI26/DI42 -> 1.098673 | DK36: =DK26/DK42 -> 1.135523 | DL36: =DL26/DL42 -> 1.2237814 | DM36: =DM26/DM42 -> 1.4119552
B37: Discontinued ops. & non recurring items
B38: Diluted EPS, reported
B40: Common shares outstanding
B41: Basic | CF41: 1448.3 | CG41: 1501.7 | CH41: 1501.7 | CI41: 1505.5 | CJ41: 1505.5 | CK41: 1503.6 | CL41: 1506.7 | CM41: 1501.3 | CN41: 1511.5 | CO41: 1512.3 | CP41: 1511.7 | CQ41: 1511.1 | CR41: 1506.4 | CS41: 1497.9 | CT41: 1490.5 | CV41: 1486.8 | CW41: 1479.2 | CX41: 1470.1 | CY41: 1465.5 | DA41: 1462.2 | DB41: 1457.5 | DC41: 1448.1 | DD41: 1354.9 | DF41: 1329.4 | DG41: 1331.8 | DH41: 1333.2 | DI41: 1334.4 | DK41: 1337.1 | DL41: 1340.6 | DM41: 1343.1
B42: Diluted | CF42: 1459.2 | CG42: 1512.5 | CH42: 1512.5 | CI42: 1519.1 | CJ42: 1519.1 | CK42: 1515.8 | CL42: 1517.9 | CM42: 1501.3 | CN42: 1514.2 | CO42: 1515.4 | CP42: 1511.7 | CQ42: 1514.1 | CR42: 1513.5 | CS42: 1505.9 | CT42: 1500.2 | CV42: 1497.9 | CW42: 1489.6 | CX42: 1479.3 | CY42: 1476.3 | DA42: 1474.2 | DB42: 1468.7 | DC42: 1455.7 | DD42: 1361.7 | DF42: 1337.3 | DG42: 1342.1 | DH42: 1346.2 | DI42: 1348.9 | DK42: 1351.8 | DL42: 1354 | DM42: 1358.4
CW45: =71-53 -> 18
B46: Balance Sheet
B48: Assets
B49: Cash and cash equivalents | CH49: 6480 | CJ49: 4937 | CK49: =CJ49 -> 4937 | CM49: 6975 | CN49: 10001 | CO49: 8802 | CP49: =CO49 -> 8802 | CQ49: 8579 | CR49: 8051 | CS49: 7476 | CT49: 7832 | CU49: =CT49 -> 7832 | CV49: 6040 | CW49: 4767 | CX49: 5381 | CY49: 6220 | CZ49: =CY49 -> 6220 | DA49: 5893 | DB49: 5391 | DC49: 5456 | DD49: 6587 | DE49: =DD49 -> 6587 | DF49: 5607 | DG49: 6011 | DH49: 6682 | DI49: 5578 | DJ49: =DI49 -> 5578 | DK49: 5157 | DL49: 4782 | DM49: 5966
B50: Accounts receivable, net | CH50: 9633 | CJ50: 8743 | CK50: =CJ50 -> 8743 | CM50: 9496 | CN50: 10115 | CO50: 9254 | CP50: =CO50 -> 9254 | CQ50: 10037 | CR50: 8912 | CS50: 9538 | CT50: 9661 | CU50: =CT50 -> 9661 | CV50: 9076 | CW50: 10394 | CX50: 9233 | CY50: 9108 | CZ50: =CY50 -> 9108 | DA50: 10069 | DB50: 9903 | DC50: 10058 | DD50: 10838 | DE50: =DD50 -> 10838 | DF50: 10280 | DG50: 10252 | DH50: 10097 | DI50: 10976 | DJ50: =DI50 -> 10976 | DK50: 11426 | DL50: 12385 | DM50: 12837
...

Sheet SEG
B3: RTX Segment Data | C3: 1997 | D3: 1998 | E3: 1999 | F3: 2000 | G3: 2001 | H3: 2002 | I3: 2003 | J3: 1Q04 | K3: 2Q04 | L3: 3Q04 | M3: 4Q04 | N3: 2004 | O3: 1Q05 | P3: 2Q05 | Q3: 3Q05 | R3: 4Q05 | S3: 2005 | T3: 1Q06 | U3: 2Q06 | V3: 3Q06 | W3: 4Q06 | X3: 2006 | Y3: 1Q07 | Z3: 2Q07 | AA3: 3Q07 | AB3: 4Q07 | AC3: 2007 | AD3: 1Q08 | AE3: 2Q08 | AF3: 3Q08 | AG3: 4Q08 | AH3: 2008 | AI3: 1Q09 | AJ3: 2Q09 | AK3: 3Q09 | AL3: 4Q09 | AM3: 2009 | AN3: 1Q10 | AO3: 2Q10 | AP3: 3Q10 | AQ3: 4Q10 | AR3: 2010 | AS3: 1Q11 | AT3: 2Q11 | AU3: 3Q11 | AV3: 4Q11 | AW3: 2011 | AX3: 1Q12 | AY3: 2Q12 | AZ3: 3Q12 | BA3: 4Q12 | BB3: 2012 | BC3: 1Q13 | BD3: 2Q13 | BE3: 3Q13 | BF3: 4Q13 | BG3: 2013 | BH3: 1Q14 | BI3: 2Q14 | BJ3: 3Q14 | BK3: 4Q14 | BL3: 2014 | BM3: 1Q15 | BN3: 2Q15 | BO3: 3Q15 | BP3: 4Q15 | BQ3: 2015 | BR3: 1Q16 | BS3: 2Q16 | BT3: 3Q16 | BU3: 4Q16 | BV3: 2016 | BW3: 1Q17 | BX3: 2Q17 | BY3: 3Q17 | BZ3: 4Q17 | CA3: 2017 | CB3: 1Q18 | CC3: 2Q18 | CD3: 3Q18 | CE3: 4Q18 | CF3: 2018 | CG3: 1Q19 | CH3: 2Q19 | CI3: 3Q19 | CJ3: 4Q19 | CK3: 2019 | CL3: 1Q20 | CM3: 2Q20 | CN3: 3Q20 | CO3: 4Q20 | CP3: 2020 | CQ3: 1Q21 | CR3: 2Q21 | CS3: 3Q21 | CT3: 4Q21 | CU3: 2021 | CV3: 1Q22 | CW3: 2Q22 | CX3: 3Q22 | CY3: 4Q22 | CZ3: 2022 | DA3: 1Q23 | DB3: 2Q23 | DC3: 3Q23 | DD3: 4Q23 | DE3: 2023 | DF3: 1Q24 | DG3: 2Q24 | DH3: 3Q24 | DI3: 4Q24 | DJ3: 2024 | DK3: 1Q25 | DL3: 2Q25 | DM3: 3Q25 | DN3: 4Q25E | DO3: 2025E | DP3: 1Q26E | DQ3: 2Q26E | DR3: 3Q26E | DS3: 4Q26E | DT3: 2026E | DU3: 2027E | DV3: 2028E
B4: ($ mn) | C4: 35795 | D4: 36160 | E4: 36525 | F4: 36891 | G4: 37256 | H4: 37621 | I4: 37986 | J4: 38076 | K4: 38168 | L4: 38260 | M4: 38352 | N4: 38352 | O4: 38441 | P4: 38533 | Q4: 38625 | R4: 38717 | S4: 38717 | T4: 38806 | U4: 38898 | V4: 38990 | W4: 39082 | X4: 39082 | Y4: 39171 | Z4: 39263 | AA4: 39355 | AB4: 39447 | AC4: 39447 | AD4: 39537 | AE4: 39629 | AF4: 39721 | AG4: 39813 | AH4: 39813 | AI4: 39902 | AJ4: 39994 | AK4: 40086 | AL4: 40178 | AM4: 40178 | AN4: 40267 | AO4: 40359 | AP4: 40451 | AQ4: 40543 | AR4: 40543 | AS4: 40632 | AT4: 40724 | AU4: 40816 | AV4: 40908 | AW4: 40908 | AX4: 40998 | AY4: 41090 | AZ4: 41182 | BA4: 41274 | BB4: 41274 | BC4: 41363 | BD4: 41455 | BE4: 41547 | BF4: 41639 | BG4: 41639 | BH4: 41728 | BI4: 41820 | BJ4: 41912 | BK4: 42004 | BL4: 42004 | BM4: 42093 | BN4: 42185 | BO4: 42277 | BP4: 42369 | BQ4: 42369 | BR4: 42459 | BS4: 42551 | BT4: 42643 | BU4: 42735 | BV4: 42735 | BW4: 42824 | BX4: 42916 | BY4: 43008 | BZ4: 43100 | CA4: 43100 | CB4: 43189 | CC4: 43281 | CD4: 43373 | CE4: 43465 | CF4: 43465 | CG4: 43554 | CH4: 43646 | CI4: 43738 | CJ4: 43830 | CK4: 43830 | CL4: 43920 | CM4: 44012 | CN4: 44104 | CO4: 44196 | CP4: 44196 | CQ4: 44285 | CR4: 44377 | CS4: 44469 | CT4: 44561 | CU4: 44561 | CV4: 44650 | CW4: 44742 | CX4: 44834 | CY4: 44926 | CZ4: 44926 | DA4: 45015 | DB4: 45107 | DC4: 45199 | DD4: 45291 | DE4: 45291 | DF4: 45381 | DG4: 45473 | DH4: 45565 | DI4: 45657 | DJ4: 45657 | DK4: 45746 | DL4: 45838 | DM4: 45930 | DN4: 46022 | DO4: 46022 | DP4: 46111 | DQ4: 46203 | DR4: 46295 | DS4: 46387 | DT4: 46387 | DU4: 46752 | DV4: 47118
B6: Revenue
B8: Acquisitions
B9: Various | AZ9: 550 | BA9: 550 | BB9: =SUM(AZ9:BA9) -> 1100 | BC9: 550 | BD9: 375 | BG9: =SUM(BC9:BF9) -> 925
B11: Divestures | BH11: -68 | BI11: 0 | BJ11: 0 | BL11: =SUM(BH11:BK11) -> -68
B12: Misc incl FX | CV12: -15 | CW12: -25 | CZ12: =SUM(CV12:CY12) -> -40 | DC12: -5401 | DE12: =SUM(DA12:DD12) -> -5401 | DJ12: =SUM(DF12:DI12) -> 0 | DO12: =SUM(DK12:DN12) -> 0
B14: Pratt & Whitney | C14: =+Data!C133 -> 7402 | D14: =+Data!D133 -> 7876 | E14: =+Data!E133 -> 7674 | F14: =+Data!F133 -> 7366 | G14: =+Data!G133 -> 7679 | H14: =+Data!H133 -> 7645 | I14: =+Data!I133 -> 7484 | J14: =+Data!J133 -> 1939 | ... CK14: =+Data!CK133 -> 20902 | CL14: =Data!CL133 -> 5353 | CM14: =Data!CM133 -> 3487 | CN14: =Data!CN133 -> 3494 | CO14: =Data!CO133 -> 4890 | CP14: =SUM(CL14:CO14) -> 17224 | CQ14: =Data!CQ133 -> 4030 | CR14: =Data!CR133 -> 4280 | CS14: =Data!CS133 -> 4725 | CT14: =Data!CT133 -> 5115 | CU14: =SUM(CQ14:CT14) -> 18150 | CV14: =Data!CV133 -> 4529 | CW14: =Data!CW133 -> 4969 | CX14: =Data!CX133 -> 5380 | CY14: =Data!CY133 -> 5652 | CZ14: =SUM(CV14:CY14) -> 20530 | DA14: =Data!DA133 -> 5230 | DB14: =Data!DB133 -> 5701 | DC14: =Data!DC133 -> 926 | DD14: =Data!DD133 -> 6439 | DE14: =SUM(DA14:DD14) -> 18296 | DF14: =Data!DF133 -> 6456 | DG14: =Data!DG133 -> 6802 | DH14: =Data!DH133 -> 7239 | DI14: =Data!DI133 -> 7569 | DJ14: =SUM(DF14:DI14) -> 28066 | DK14: =Data!DK133 -> 7366 | DL14: =Data!DL133 -> 7631 | DM14: =Data!DM133 -> 8423 | DN14: =DI14*(1+DN82)+DN65+DN73 -> 8515.125 | DO14: =SUM(DK14:DN14) -> 31935.125 | DP14: =DK14*(1+DP82)+DP65+DP73 -> 8065.77 | DQ14: =DL14*(1+DQ82)+DQ65+DQ73 -> 8333.052 | DR14: =((DM14-DM73)*(1+DR82))+DR65+DR73 -> 9189.493 | DS14: =DN14*(1+DS82)+DS65+DS73 -> 9315.5468 | DT14: =SUM(DP14:DS14) -> 34903.862 | DU14: =DT14*(1+DU82)+DU65+DU73 -> 37765.978 | DV14: =DU14*(1+DV82)+DV65+DV73 -> 40447.363
B16: Acquisitions
B17: Rockwell Collins | CB17: =2180*0.87 -> 1896.6 | CC17: =2208*0.87 -> 1920.96 | CD17: =2266*0.87 -> 1971.42 | CE17: =2113*0.87 -> 1838.31 | CF17: =SUM(CB17:CE17) -> 7627.29
B18: Goodrich | AZ18: 1300 | BA18: 1525 | BB18: =SUM(AZ18:BA18) -> 2825 | BC18: 1800 | BD18: 1800 | BE18: 500 | BF18: 500 | BG18: =SUM(BC18:BF18) -> 4600
B20: Divestures
B21: Simmonds Precision Products 10/25 | DN21: =+-87.5 -> -87.5 | DO21: =+SUM(DK21:DN21) -> -87.5 | DP21: =+-87.5 -> -87.5 | DQ21: =+-87.5 -> -87.5 | DR21: =+-87.5 -> -87.5 | DT21: =+SUM(DP21:DS21) -> -262.5
B22: Collins Actuation - July 2025 | DM22: -263 | DN22: -400 | DO22: =+SUM(DK22:DN22) -> -663 | DP22: -400 | DQ22: -400 | DT22: =+SUM(DP22:DS22) -> -800
B23: Misc incl FX | AZ23: -200 | BA23: -200 | BB23: =SUM(AZ23:BA23) -> -400 | BC23: -25 | BD23: -25 | BE23: -25 | BF23: -25 | BG23: =SUM(BC23:BF23) -> -100 | BK23: -25 | BL23: =SUM(BH23:BK23) -> -25 | CB23: -40 | CC23: -40 | CD23: -40 | CE23: -40 | CF23: =+SUM(CB23:CE23) -> -160 | CV23: -15 | CW23: -20 | CZ23: =SUM(CV23:CY23) -> -35 | DA23: -15 | DB23: -20 | DC23: 57 | DD23: 112 | DE23: =SUM(DA23:DD23) -> 134 | DH23: 30 | DJ23: =SUM(DF23:DI23) -> 30 | DO23: =SUM(DK23:DN23) -> 0
B24: CAS Military GPS | CN24: -65 | CO24: =-360/4 -> -90 | CP24: =SUM(CL24:CO24) -> -155 | CQ24: =-360/4 -> -90 | CR24: -100 | CS24: -70 | CU24: =SUM(CQ24:CT24) -> -260 | CZ24: =SUM(CV24:CY24) -> 0 | DE24: =SUM(DA24:DD24) -> 0 | DJ24: =SUM(DF24:DI24) -> 0 | DO24: =SUM(DK24:DN24) -> 0
B26: Collins Aerospace | C26: =+Data!C134 -> 2804 | D26: =+Data!D134 -> 2891 | E26: =+Data!E134 -> 3810 | F26: =+Data!F134 -> 4992 | G26: =+Data!G134 -> 5292 | H26: =+Data!H134 -> 3453 | I26: =+Data!I134 -> 3598 | J26: =+Data!J134 -> 926 | ... CK26: =+Data!CK134 -> 26028 | CL26: =Data!CL134 -> 4988.9747 | CM26: =Data!CM134 -> 4980.2956 | CN26: =Data!CN134 -> 4992.146 | CO26: =Data!CO134 -> 7027.5837 | CP26: =SUM(CL26:CO26) -> 21989 | CQ26: =Data!CQ134 -> 4991.4661 | CR26: =Data!CR134 -> 5010.5426 | CS26: =Data!CS134 -> 4998.3731 | CT26: =Data!CT134 -> 6151.6183 | CU26: =SUM(CQ26:CT26) -> 21152 | CV26: =Data!CV134 -> 5476 | CW26: =Data!CW134 -> 5627 | CX26: =Data!CX134 -> 5718 | CY26: =Data!CY134 -> 6231 | CZ26: =SUM(CV26:CY26) -> 23052 | DA26: =Data!DA134 -> 6120 | DB26: =Data!DB134 -> 6384 | DC26: =Data!DC134 -> 6629 | DD26: =Data!DD134 -> 7120 | DE26: =SUM(DA26:DD26) -> 26253 | DF26: =Data!DF134 -> 6673 | DG26: =Data!DG134 -> 6999 | DH26: =Data!DH134 -> 7075 | DI26: =Data!DI134 -> 7537 | DJ26: =SUM(DF26:DI26) -> 28284 | DK26: =Data!DK134 -> 7217 | DL26: =Data!DL134 -> 7622 | DM26: =Data!DM134 -> 7621 | DN26: =DI26*(1+DN83)+DN74+DN66 -> 7456.498 | DO26: =SUM(DK26:DN26) -> 29916.498 | DP26: =DK26*(1+DP83)+DP74+DP66 -> 7162.52 | DQ26: =DL26*(1+DQ83)+DQ74+DQ66 -> 7668.04 | DR26: =DM26*(1+DR83)+DR74+DR66 -> 7990.76 | DS26: =DN26*(1+DS83)+DS74+DS66 -> 7926.2574 | DT26: =SUM(DP26:DS26) -> 30747.577 | DU26: =DT26*(1+DU83)+DU66+DU74 -> 32530.937 | DV26: =DU26*(1+DV83)+DV66+DV74 -> 34222.546
B28: Acquisitions
B29: RGNext 02/19 | CG29: 38 | CH29: 60 | CI29: 60 | CJ29: 60 | CK29: =SUM(CG29:CJ29) -> 218 | CL29: 25 | CP29: =SUM(CL29:CO29) -> 25
B30: Collins Mission Systems | CB30: =2180*0.13 -> 283.4 | CC30: =2208*0.13 -> 287.04 | CD30: =2266*0.13 -> 294.58 | CE30: =2113*0.13 -> 274.69 | CF30: =SUM(CB30:CE30) -> 1139.71
B31: Stonesoft 1/16 | BR31: =60/4*2.5/3 -> 12.5 | BS31: =60/4 -> 15 | BT31: =60/4 -> 15 | BU31: =60/4 -> 15 | BV31: =SUM(BR31:BU31) -> 57.5 | BW31: =60/4*0.5/3 -> 2.5
B32: Websense 5/15 | BN32: =375*0.25/3 -> 31.25 | BO32: =375*0.25 -> 93.75 | BP32: =375*0.25 -> 93.75 | BQ32: =SUM(BM32:BP32) -> 218.75 | BR32: 94 | BS32: =385-BQ32-BR32 -> 72.25 | BV32: =SUM(BR32:BU32) -> 166.25
B33: Blackbird 11/14 | BK33: =200/4*2/3 -> 33.333333 | BL33: =SUM(BH33:BK33) -> 33.333333 | BM33: 50 | BN33: 50 | BO33: 50 | BP33: 50 | BQ33: =SUM(BM33:BP33) -> 200
B34: SafeNet 12/12 | BA34: 13.15 | BB34: =SUM(BA34) -> 13.15 | BC34: 65.75 | BD34: 65.75 | BE34: 65.75 | BF34: 52.6 | BG34: =SUM(BC34:BF34) -> 249.85
B35: Applied Signal - 1/11 | AS35: =61*2/3 -> 40.666667 | AT35: 62 | AU35: 67 | AV35: 58 | AW35: =SUM(AS35:AV35) -> 227.66667 | AX35: 20 | BB35: =SUM(AX35:BA35) -> 20
B37: Divestures
B38: Cyber
B39: Training & Logistics 12/21 | CT39: =-1000/12 -> -83.333333 | CU39: =SUM(CQ39:CT39) -> -83.333333 | CV39: -180 | CW39: -200 | CX39: -200 | CY39: -145 | CZ39: =SUM(CV39:CY39) -> -725 | DA39: -180 | DB39: -200 | DC39: -200 | DD39: -35
B40: Airborne Tactical Radios 5/20 | CM40: =-120/12*2 -> -20 | CN40: -25 | CO40: -30 | CP40: =SUM(CL40:CO40) -> -75 | CQ40: =-120/4 -> -30 | CR40: 0 | CU40: =SUM(CQ40:CT40) -> -30
B41: Raytheon Intelligence & Space | BB41: =Data!BB135 -> 13158 | BC41: =Data!BC135 -> 3103 | BD41: =Data!BD135 -> 3190 | BE41: =Data!BE135 -> 3052 | BF41: =Data!BF135 -> 3071 | BG41: =Data!BG135 -> 12416 | BH41: =Data!BH135 -> 2848 | BI41: =Data!BI135 -> 3023 | ... CO41: =Data!CO135 -> 3933 | CP41: =SUM(CL41:CO41) -> 14959 | CQ41: =Data!CQ135 -> 3765 | CR41: =Data!CR135 -> 3805 | CS41: =Data!CS135 -> 3740 | CT41: =Data!CT135 -> 3870 | CU41: =SUM(CQ41:CT41) -> 15180 | CV41: =Data!CV135 -> 3572 | CW41: =Data!CW135 -> 3570 | CX41: =Data!CX135 -> 3626 | CY41: =Data!CY135 -> 3544 | CZ41: =SUM(CV41:CY41) -> 14312 | DA41: =Data!DA135 -> 3565 | DB41: =Data!DB135 -> 3655 | DC41: =Data!DC135 -> 0 | DD41: =Data!DD135 -> 0 | DE41: =SUM(DA41:DD41) -> 7220 | DF41: =Data!DF135 -> 0 | DJ41: =SUM(DF41:DI41) -> 0 | DK41: =Data!DK135 -> 0 | DO41: =SUM(DK41:DN41) -> 0 | DT41: =DO41*(1+DT84)+DT75+DT67 -> 0 | DU41: =DT41*(1+DU84)+DU75+DU67 -> 0 | DV41: =DU41*(1+DV84)+DV75+DV67 -> 0
B43: Acquisitions
B44: Ktech Corp, 6/11 | AU44: =65/4 -> 16.25 | AV44: =65/4 -> 16.25 | AW44: =SUM(AS44:AV44) -> 32.5 | AX44: =65/4 -> 16.25 | AY44: =65/4 -> 16.25 | BB44: =SUM(AX44:BA44) -> 32.5
B46: Divestures
B47: Misc incl FX | CW47: -15 | CX47: -15 | CY47: -15 | CZ47: =SUM(CV47:CY47) -> -45 | DB47: -15 | DC47: -15 | DD47: -15
B48: Raytheon Missiles & Defense | BB48: =Data!BB136 -> 13131 | BC48: =Data!BC136 -> 3232 | BD48: =Data!BD136 -> 3411 | BE48: =Data!BE136 -> 3238 | BF48: =Data!BF136 -> 3207 | BG48: =Data!BG136 -> 13088 | BH48: =Data!BH136 -> 3055 | BI48: =Data!BI136 -> 3088 | ... CO48: =Data!CO136 -> 4184 | CP48: =SUM(CL48:CO48) -> 15343 | CQ48: =Data!CQ136 -> 3793 | CR48: =Data!CR136 -> 3985 | CS48: =Data!CS136 -> 3902 | CT48: =Data!CT136 -> 3859 | CU48: =SUM(CQ48:CT48) -> 15539 | CV48: =Data!CV136 -> 3527 | CW48: =Data!CW136 -> 3558 | CX48: =Data!CX136 -> 3678 | CY48: =Data!CY136 -> 4100 | CZ48: =SUM(CV48:CY48) -> 14863 | DA48: =Data!DA136 -> 3671 | DB48: =Data!DB136 -> 4000 | DC48: =Data!DC136 -> 0 | DD48: =Data!DD136 -> 0 | DE48: =SUM(DA48:DD48) -> 7671 | DF48: =Data!DF136 -> 0 | DJ48: =SUM(DF48:DI48) -> 0 | DK48: =Data!DK136 -> 0 | DO48: =SUM(DK48:DN48) -> 0 | DT48: =DO48*(1+DT85)+DT76+DT68 -> 0 | DU48: =DT48*(1+DU85)+DU76+DU68 -> 0 | DV48: =DU48*(1+DV85)+DV76+DV68 -> 0
B50: Raytheon (Defense recasted) | CL50: =Data!CL137 -> 6408.288 | CM50: =Data!CM137 -> 6318.432 | CN50: =Data!CN137 -> 6441.12 | CO50: =Data!CO137 -> 7009.16 | CP50: =Data!CP137 -> 26177 | CQ50: =Data!CQ137 -> 6545.228 | CR50: =Data!CR137 -> 6746.14 | CS50: =Data!CS137 -> 6617.972 | ... CY50: =Data!CY137 -> 6661 | CZ50: =SUM(CV50:CY50) -> 25176 | DA50: =Data!DA137 -> 6292 | DB50: =Data!DB137 -> 6700 | DC50: =Data!DC137 -> 6472 | DD50: =Data!DD137 -> 6886 | DE50: =SUM(DA50:DD50) -> 26350 | DF50: =Data!DF137 -> 6659 | DG50: =Data!DG137 -> 6581 | DH50: =Data!DH137 -> 6386 | DI50: =Data!DI137 -> 7157 | DJ50: =SUM(DF50:DI50) -> 26783 | DK50: =Data!DK137 -> 6340 | DL50: =Data!DL137 -> 7001 | DM50: =Data!DM137 -> 7045 | DN50: =DI50*(1+DN86)+DN77+DN69 -> 7328.768 | DO50: =SUM(DK50:DN50) -> 27714.768 | DP50: =DK50*(1+DP86)+DP77+DP69 -> 6783.8 | DQ50: =DL50*(1+DQ86)+DQ77+DQ69 -> 7309.044 | DR50: =DM50*(1+DR86)+DR77+DR69 -> 7404.295 | DS50: =DN50*(1+DS86)+DS77+DS69 -> 7739.179 | DT50: =SUM(DP50:DS50) -> 29236.318 | DU50: =DT50*(1+DU86)+DU77+DU69 -> 30785.843 | DV50: =DU50*(1+DV86)+DV77+DV69 -> 32355.921
B52: Acquisitions
B56: Divestitures
B57: Cyber Services Business (Mar 2024) | DG57: -360 | DH57: -390 | DI57: -350 | DJ57: =+SUM(DF57:DI57) -> -1100 | DK57: -350 | DL57: 0 | DO57: =+SUM(DK57:DN57) -> -350
B61: Eliminations & other | BB61: =Data!BB138 -> -2402 | BC61: =Data!BC138 -> -622 | BD61: =Data!BD138 -> -672 | BE61: =Data!BE138 -> -650 | BF61: =Data!BF138 -> -622 | BG61: =Data!BG138 -> -2566 | BH61: =Data!BH138 -> -596 | BI61: =Data!BI138 -> -625 | ... CO61: =Data!CO138 -> 315.25631 | CP61: =SUM(CL61:CO61) -> -790 | CQ61: =Data!CQ138 -> -315.69408 | CR61: =Data!CR138 -> -303.68257 | CS61: =Data!CS138 -> -311.34509 | CT61: =Data!CT138 -> -594.27826 | CU61: =SUM(CQ61:CT61) -> -1525 | CV61: =Data!CV138 -> -363 | CW61: =Data!CW138 -> -415 | CX61: =Data!CX138 -> -455 | CY61: =Data!CY138 -> -451 | CZ61: =SUM(CV61:CY61) -> -1684 | DA61: =Data!DA138 -> -428 | DB61: =Data!DB138 -> -470 | DC61: =Data!DC138 -> -563 | DD61: =Data!DD138 -> -518 | DE61: =SUM(DA61:DD61) -> -1979 | DF61: =Data!DF138 -> -483 | DG61: =Data!DG138 -> -591 | DH61: =Data!DH138 -> -611 | DI61: =Data!DI138 -> -640 | DJ61: =SUM(DF61:DI61) -> -2325 | DK61: =Data!DK138 -> -617 | DL61: =Data!DL138 -> -673 | DM61: =Data!DM138 -> -611 | DN61: -700 | DO61: =SUM(DK61:DN61) -> -2601 | DP61: -600 | DQ61: -650 | DR61: -700 | DS61: -750 | DT61: =SUM(DP61:DS61) -> -2700 | DU61: -2750 | DV61: -2800
...

Sheet IS
B3: RTX Income Statement | C3: 1997 | D3: 1998 | E3: 1999 | F3: 2000 | G3: 2001 | H3: 2002 | I3: 2003 | J3: 1Q04 | K3: 2Q04 | L3: 3Q04 | M3: 4Q04 | N3: 2004 | O3: 1Q05 | P3: 2Q05 | Q3: 3Q05 | R3: 4Q05 | S3: 2005 | T3: 1Q06 | U3: 2Q06 | V3: 3Q06 | W3: 4Q06 | X3: 2006 | Y3: 1Q07 | Z3: 2Q07 | AA3: 3Q07 | AB3: 4Q07 | AC3: 2007 | AD3: 1Q08 | AE3: 2Q08 | AF3: 3Q08 | AG3: 4Q08 | AH3: 2008 | AI3: 1Q09 | AJ3: 2Q09 | AK3: 3Q09 | AL3: 4Q09 | AM3: 2009 | AN3: 1Q10 | AO3: 2Q10 | AP3: 3Q10 | AQ3: 4Q10 | AR3: 2010 | AS3: 1Q11 | AT3: 2Q11 | AU3: 3Q11 | AV3: 4Q11 | AW3: 2011 | AX3: 1Q12 | AY3: 2Q12 | AZ3: 3Q12 | BA3: 4Q12 | BB3: 2012 | BC3: 1Q13 | BD3: 2Q13 | BE3: 3Q13 | BF3: 4Q13 | BG3: 2013 | BH3: 1Q14 | BI3: 2Q14 | BJ3: 3Q14 | BK3: 4Q14 | BL3: 2014 | BM3: 1Q15 | BN3: 2Q15 | BO3: 3Q15 | BP3: 4Q15 | BQ3: 2015 | BR3: 1Q16 | BS3: 2Q16 | BT3: 3Q16 | BU3: 4Q16 | BV3: 2016 | BW3: 1Q17 | BX3: 2Q17 | BY3: 3Q17 | BZ3: 4Q17 | CA3: 2017 | CB3: 1Q18 | CC3: 2Q18 | CD3: 3Q18 | CE3: 4Q18 | CF3: 2018 | CG3: 1Q19 | CH3: 2Q19 | CI3: 3Q19 | CJ3: 4Q19 | CK3: 2019 | CL3: 1Q20E | CM3: 2Q20 | CN3: 3Q20 | CO3: 4Q20 | CP3: 2020 | CQ3: 1Q21 | CR3: 2Q21 | CS3: 3Q21 | CT3: 4Q21 | CU3: 2021 | CV3: 1Q22 | CW3: 2Q22 | CX3: 3Q22 | CY3: 4Q22 | CZ3: 2022 | DA3: 1Q23 | DB3: 2Q23 | DC3: 3Q23 | DD3: 4Q23 | DE3: 2023 | DF3: 1Q24 | DG3: 2Q24 | DH3: 3Q24 | DI3: 4Q24 | DJ3: 2024 | DK3: 1Q25 | DL3: 2Q25 | DM3: 3Q25 | DN3: 4Q25E | DO3: 2025E | DP3: 1Q26E | DQ3: 2Q26E | DR3: 3Q26E | DS3: 4Q26E | DT3: 2026E | DU3: 2027E | DV3: 2028E
B4: ($ mn, except per share data) | C4: 35795 | D4: 36160 | E4: 36525 | F4: 36891 | G4: 37256 | H4: 37621 | I4: 37986 | J4: 38077 | K4: 38168 | L4: 38260 | M4: 38352 | N4: 38352 | O4: 38442 | P4: 38533 | Q4: 38625 | R4: 38717 | S4: 38717 | T4: 38807 | U4: 38898 | V4: 38990 | W4: 39082 | X4: 39082 | Y4: 39172 | Z4: 39263 | AA4: 39355 | AB4: 39447 | AC4: 39447 | AD4: 39538 | AE4: 39629 | AF4: 39721 | AG4: 39813 | AH4: 39813 | AI4: 39903 | AJ4: 39994 | AK4: 40086 | AL4: 40178 | AM4: 40178 | AN4: 40268 | AO4: 40359 | AP4: 40451 | AQ4: 40543 | AR4: 40543 | AS4: 40633 | AT4: 40724 | AU4: 40816 | AV4: 40908 | AW4: 40908 | AX4: 40999 | AY4: 41090 | AZ4: 41182 | BA4: 41274 | BB4: 41274 | BC4: 41364 | BD4: 41455 | BE4: 41547 | BF4: 41639 | BG4: 41639 | BH4: 41729 | BI4: 41820 | BJ4: 41912 | BK4: 42004 | BL4: 42004 | BM4: 42094 | BN4: 42185 | BO4: 42277 | BP4: 42369 | BQ4: 42369 | BR4: 42460 | BS4: 42551 | BT4: 42643 | BU4: 42735 | BV4: 42735 | BW4: 42825 | BX4: 42916 | BY4: 43008 | BZ4: 43100 | CA4: 43100 | CB4: 43190 | CC4: 43281 | CD4: 43373 | CE4: 43465 | CF4: 43465 | CG4: 43555 | CH4: 43646 | CI4: 43738 | CJ4: 43830 | CK4: 43830 | CL4: 43921 | CM4: 44012 | CN4: 44104 | CO4: 44196 | CP4: 44196 | CQ4: 44286 | CR4: 44377 | CS4: 44469 | CT4: 44561 | CU4: 44561 | CV4: 44651 | CW4: 44742 | CX4: 44834 | CY4: 44926 | CZ4: 44926 | DA4: 45016 | DB4: 45107 | DC4: 45199 | DD4: 45291 | DE4: 45291 | DF4: 45382 | DG4: 45473 | DH4: 45565 | DI4: 45657 | DJ4: 45657 | DK4: 45746 | DL4: 45838 | DM4: 45930 | DN4: 46022 | DO4: 46022 | DP4: 46111 | DQ4: 46203 | DR4: 46295 | DS4: 46387 | DT4: 46387 | DU4: =SEG!DU4 -> 46752 | DV4: =SEG!DV4 -> 47118
B6: Net sales | BL6: =SEG!BL62 -> 50640 | BQ6: =SEG!BQ62 -> 50564 | BV6: =SEG!BV62 -> 52569 | CA6: =SEG!CA62 -> 55417 | CF6: =+Data!CF9 -> 69172 | CG6: =+Data!CG9 -> 17664.5 | CH6: =+Data!CH9 -> 18385.5 | CI6: =+Data!CI9 -> 18711.63 | CJ6: =+Data!CJ9 -> 19475.37 | CK6: =SUM(CG6:CJ6) -> 74237 | CL6: =Data!CL9 -> 18451 | CM6: =Data!CM9 -> 14470 | CN6: =Data!CN9 -> 14747 | CO6: =Data!CO9 -> 16419 | CP6: =SUM(CL6:CO6) -> 64087 | CQ6: =Data!CQ9 -> 15251 | CR6: =Data!CR9 -> 15880 | CS6: =Data!CS9 -> 16213 | CT6: =Data!CT9 -> 17044 | CU6: =SUM(CQ6:CT6) -> 64388 | CV6: =Data!CV9 -> 15716 | CW6: =Data!CW9 -> 16314 | CX6: =Data!CX9 -> 16951 | CY6: =Data!CY9 -> 18093 | CZ6: =SUM(CV6:CY6) -> 67074 | DA6: =Data!DA9 -> 17214 | DB6: =Data!DB9 -> 18315 | DC6: =Data!DC9 -> 13464 | DD6: =Data!DD9 -> 19927 | DE6: =SUM(DA6:DD6) -> 68920 | DF6: =Data!DF9 -> 19305 | DG6: =Data!DG9 -> 19721 | DH6: =Data!DH9 -> 20089 | DI6: =Data!DI9 -> 21623 | DJ6: =SUM(DF6:DI6) -> 80738 | DK6: =Data!DK9 -> 20306 | DL6: =Data!DL9 -> 21581 | DM6: =Data!DM9 -> 22478 | DN6: =SEG!DN62 -> 22600.391 | DO6: =SUM(DK6:DN6) -> 86965.391 | DP6: =SEG!DP62 -> 21412.09 | DQ6: =SEG!DQ62 -> 22660.136 | DR6: =SEG!DR62 -> 23884.548 | DS6: =SEG!DS62 -> 24230.983 | DT6: =SUM(DP6:DS6) -> 92187.757 | DU6: =SEG!DU62 -> 98332.758 | DV6: =SEG!DV62 -> 104225.83
B7: Cost of goods sold | CF7: =CF8-CF6 -> -51666.942 | CG7: =CG8-CG6 -> -13710.34 | CH7: =CH8-CH6 -> -13986.66 | CI7: =CI8-CI6 -> -14210.65 | CJ7: =CJ8-CJ6 -> -15298.35 | CK7: =SUM(CG7:CJ7) -> -57206 | CL7: =CL8-CL6 -> -14224.824 | CM7: =CM8-CM6 -> -15638.818 | CN7: =-Data!CN12 -> -13004 | CO7: =-Data!CO12 -> -14266 | CP7: =SUM(CL7:CO7) -> -57133.642 | CQ7: =-Data!CQ12 -> -12537 | CR7: =-Data!CR12 -> -12655 | CS7: =-Data!CS12 -> -13089 | CT7: =-Data!CT12 -> -13616 | CU7: =SUM(CQ7:CT7) -> -51897 | CV7: =-Data!CV12 -> -12560 | CW7: =-Data!CW12 -> -12856 | CX7: =-Data!CX12 -> -13464 | CY7: =-Data!CY12 -> -14526 | CZ7: =SUM(CV7:CY7) -> -53406 | DA7: =-Data!DA12 -> -13645 | DB7: =-Data!DB12 -> -14518 | DC7: =-Data!DC12 -> -12750 | DD7: =-Data!DD12 -> -15918 | DE7: =SUM(DA7:DD7) -> -56831 | DF7: =-Data!DF12 -> -15744 | DG7: =-Data!DG12 -> -16141 | DH7: =-Data!DH12 -> -16055 | DI7: =-Data!DI12 -> -17388 | DJ7: =SUM(DF7:DI7) -> -65328 | DK7: =-Data!DK12 -> -16190 | DL7: =-Data!DL12 -> -17205 | DM7: =-Data!DM12 -> -17898 | DN7: =DN8-DN6 -> -17840.714 | DO7: =SUM(DK7:DN7) -> -69133.714 | DP7: =DP8-DP6 -> -16897.817 | DQ7: =DQ8-DQ6 -> -17794.185 | DR7: =DR8-DR6 -> -18619.87 | DS7: =DS8-DS6 -> -18904.306 | DT7: =SUM(DP7:DS7) -> -72216.177 | DU7: =DU8-DU6 -> -76679.534 | DV7: =DV8-DV6 -> -80914.022
B8: Gross Income | CF8: =CF13-CF10-CF9-CF12 -> 17505.058 | CG8: =CG13-CG10-CG9-CG12 -> 3954.16 | CH8: =CH13-CH10-CH9-CH12 -> 4398.84 | CI8: =CI13-CI10-CI9-CI12 -> 4500.98 | CJ8: =CJ13-CJ10-CJ9-CJ12 -> 4177.02 | CK8: =SUM(CG8:CJ8) -> 17031 | CL8: =CL13-CL10-CL9-CL12 -> 4226.1761 | CM8: =CM13-CM10-CM9-CM12 -> -1168.8181 | CN8: =CN6+CN7 -> 1743 | CO8: =CO6+CO7 -> 2153 | CP8: =SUM(CL8:CO8) -> 6953.358 | CQ8: =CQ6+CQ7 -> 2714 | CR8: =CR6+CR7 -> 3225 | CS8: =CS6+CS7 -> 3124 | CT8: =CT6+CT7 -> 3428 | CU8: =SUM(CQ8:CT8) -> 12491 | CV8: =CV6+CV7 -> 3156 | CW8: =CW6+CW7 -> 3458 | CX8: =CX6+CX7 -> 3487 | CY8: =CY6+CY7 -> 3567 | CZ8: =SUM(CV8:CY8) -> 13668 | DA8: =DA6+DA7 -> 3569 | DB8: =DB6+DB7 -> 3797 | DC8: =DC6+DC7 -> 714 | DD8: =DD6+DD7 -> 4009 | DE8: =SUM(DA8:DD8) -> 12089 | DF8: =DF6+DF7 -> 3561 | DG8: =DG6+DG7 -> 3580 | DH8: =DH6+DH7 -> 4034 | DI8: =DI6+DI7 -> 4235 | DJ8: =SUM(DF8:DI8) -> 15410 | DK8: =DK6+DK7 -> 4116 | DL8: =DL6+DL7 -> 4376 | DM8: =DM6+DM7 -> 4580 | DN8: =DN13-DN10-DN9-DN12 -> 4759.6766 | DO8: =SUM(DK8:DN8) -> 17831.677 | DP8: =DP13-DP10-DP9-DP12 -> 4514.2729 | DQ8: =DQ13-DQ10-DQ9-DQ12 -> 4865.951 | DR8: =DR13-DR10-DR9-DR12 -> 5264.6782 | DS8: =DS13-DS10-DS9-DS12 -> 5326.6776 | DT8: =SUM(DP8:DS8) -> 19971.58 | DU8: =DU13-DU10-DU12-DU9 -> 21653.225 | DV8: =DV13-DV10-DV12-DV9 -> 23311.807
B9: =+Data!B13 -> Research and development | CF9: =-Data!CF13 -> -3252 | CG9: =-Data!CG13 -> -779.1 | CH9: =-Data!CH13 -> -810.9 | CI9: =-Data!CI13 -> -782.04 | CJ9: =-Data!CJ13 -> -813.96 | CK9: =SUM(CG9:CJ9) -> -3186 | CL9: =-CL6*CL51 -> -645.785 | CM9: =-Data!CM13 -> -695 | CN9: =-Data!CN13 -> -642 | CO9: =-Data!CO13 -> -710 | CP9: =SUM(CL9:CO9) -> -2692.785 | CQ9: =-Data!CQ13 -> -589 | CR9: =-Data!CR13 -> -657 | CS9: =-Data!CS13 -> -676 | CT9: =-Data!CT13 -> -810 | CU9: =SUM(CQ9:CT9) -> -2732 | CV9: =-Data!CV13 -> -635 | CW9: =-Data!CW13 -> -698 | CX9: =-Data!CX13 -> -662 | CY9: =-Data!CY13 -> -716 | CZ9: =SUM(CV9:CY9) -> -2711 | DA9: =-Data!DA13 -> -607 | DB9: =-Data!DB13 -> -729 | DC9: =-Data!DC13 -> -712 | DD9: =-Data!DD13 -> -757 | DE9: =SUM(DA9:DD9) -> -2805 | DF9: =-Data!DF13 -> -669 | DG9: =-Data!DG13 -> -706 | DH9: =-Data!DH13 -> -751 | DI9: =-Data!DI13 -> -808 | DJ9: =SUM(DF9:DI9) -> -2934 | DK9: =-Data!DK13 -> -637 | DL9: =-Data!DL13 -> -697 | DM9: =-Data!DM13 -> -684 | DN9: =-DN6*DN51 -> -791.01369 | DO9: =SUM(DK9:DN9) -> -2809.0137 | DP9: =-DP6*DP51 -> -749.42315 | DQ9: =-DQ6*DQ51 -> -793.10476 | DR9: =-DR6*DR51 -> -835.95918 | DS9: =-DS6*DS51 -> -848.08441 | DT9: =SUM(DP9:DS9) -> -3226.5715 | DU9: =-DU6*DU51 -> -3441.6465 | DV9: =-DV6*DV51 -> -3647.904
B10: Selling and administrative expenses | CF10: =-Data!CF14 -> -5553 | CG10: =-Data!CG14 -> -1368.08 | CH10: =-Data!CH14 -> -1423.92 | CI10: =-Data!CI14 -> -1450.89 | CJ10: =-Data!CJ14 -> -1510.11 | CK10: =SUM(CG10:CJ10) -> -5753 | CL10: =-CL6*CL50 -> -1476.08 | CM10: =-Data!CM14 -> -1811 | CN10: =-Data!CN14 -> -1401 | CO10: =-Data!CO14 -> -1351 | CP10: =SUM(CL10:CO10) -> -6039.08 | CQ10: =-Data!CQ14 -> -1220 | CR10: =-Data!CR14 -> -1368 | CS10: =-Data!CS14 -> -1229 | CT10: =-Data!CT14 -> -1407 | CU10: =SUM(CQ10:CT10) -> -5224 | CV10: =-Data!CV14 -> -1469 | CW10: =-Data!CW14 -> -1424 | CX10: =-Data!CX14 -> -1391 | CY10: =-Data!CY14 -> -1379 | CZ10: =SUM(CV10:CY10) -> -5663 | DA10: =-Data!DA14 -> -1398 | DB10: =-Data!DB14 -> -1635 | DC10: =-Data!DC14 -> -1401 | DD10: =-Data!DD14 -> -1445 | DE10: =SUM(DA10:DD10) -> -5879 | DF10: =-Data!DF14 -> -1394 | DG10: =-Data!DG14 -> -1449 | DH10: =-Data!DH14 -> -1389 | DI10: =-Data!DI14 -> -1574 | DJ10: =SUM(DF10:DI10) -> -5806 | DK10: =-Data!DK14 -> -1448 | DL10: =-Data!DL14 -> -1573 | DM10: =-Data!DM14 -> -1436 | DN10: =-DN6*DN50 -> -1695.0293 | DO10: =SUM(DK10:DN10) -> -6152.0293 | DP10: =-DP6*DP50 -> -1605.9067 | DQ10: =-DQ6*DQ50 -> -1699.5102 | DR10: =-DR6*DR50 -> -1791.3411 | DS10: =-DS6*DS50 -> -1817.3237 | DT10: =SUM(DP10:DS10) -> -6914.0818 | DU10: =-DU6*DU50 -> -7374.9569 | DV10: =-DV6*DV50 -> -7816.9372
B11: Charges & other | CL11: 0 | CM11: =Data!CM15 -> -3183 | CN11: =Data!CN15 -> 0 | CO11: =Data!CO15 -> 0 | CP11: =SUM(CL11:CO11) -> -3183 | CQ11: =Data!CQ15 -> 0 | CR11: =Data!CR15 -> 0 | CS11: =Data!CS15 -> 0 | CT11: =Data!CT15 -> -617 | CU11: =SUM(CQ11:CT11) -> -617 | CV11: =Data!CV15 -> 0 | CW11: =Data!CW15 -> 0 | CX11: =Data!CX15 -> 0 | CY11: =Data!CY15 -> 0 | CZ11: =SUM(CV11:CY11) -> 0 | DA11: 0 | DB11: =Data!DB15 -> 0 | DC11: =Data!DC15 -> 0 | DD11: =Data!DD15 -> 0 | DE11: =SUM(DA11:DD11) -> 0 | DF11: 0 | DG11: =Data!DG15 -> 0 | DH11: =Data!DH15 -> 0 | DI11: =Data!DI15 -> 0 | DJ11: =SUM(DF11:DI11) -> 0 | DK11: 0 | DL11: =Data!DL15 -> 0 | DM11: =Data!DM15 -> 0 | DN11: 0 | DO11: =SUM(DK11:DN11) -> 0 | DP11: 0 | DQ11: 0 | DR11: 0 | DS11: 0 | DT11: =SUM(DP11:DS11) -> 0 | DU11: 0 | DV11: 0
B12: Other income (expense) | CF12: =Data!CF16 -> 337 | CG12: =Data!CG16 -> 97.02 | CH12: =Data!CH16 -> 100.98 | CI12: =Data!CI16 -> 75.95 | CJ12: =Data!CJ16 -> 79.05 | CK12: =SUM(CG12:CJ12) -> 353 | CL12: 75 | CM12: =Data!CM16 -> 82 | CN12: =Data!CN16 -> 734 | CO12: =Data!CO16 -> 50 | CP12: =SUM(CL12:CO12) -> 941 | CQ12: =Data!CQ16 -> 108 | CR12: =Data!CR16 -> 82 | CS12: =Data!CS16 -> 124 | CT12: =Data!CT16 -> 109 | CU12: =SUM(CQ12:CT12) -> 423 | CV12: =Data!CV16 -> 28 | CW12: =Data!CW16 -> 17 | CX12: =Data!CX16 -> 46 | CY12: =Data!CY16 -> 29 | CZ12: =SUM(CV12:CY12) -> 120 | DA12: =Data!DA16 -> 88 | DB12: =Data!DB16 -> 25 | DC12: =Data!DC16 -> 3 | DD12: =Data!DD16 -> -30 | DE12: =SUM(DA12:DD12) -> 86 | DF12: =Data!DF16 -> 372 | DG12: =Data!DG16 -> -896 | DH12: =Data!DH16 -> 134 | DI12: =Data!DI16 -> 258 | DJ12: =SUM(DF12:DI12) -> -132 | DK12: =Data!DK16 -> 4 | DL12: =Data!DL16 -> 40 | DM12: =Data!DM16 -> 63 | DN12: 50 | DO12: =SUM(DK12:DN12) -> 157 | DP12: 50 | DQ12: 50 | DR12: 50 | DS12: 50 | DT12: =SUM(DP12:DS12) -> 200 | DU12: 200 | DV12: 200
B13: EBIT | CF13: =SEG!CF144 -> 9037.0576 | CG13: =SEG!CG144 -> 1904 | CH13: =SEG!CH144 -> 2265 | CI13: =SEG!CI144 -> 2344 | CJ13: =SEG!CJ144 -> 1932 | CK13: =SUM(CG13:CJ13) -> 8445 | CL13: =SEG!CL144 -> 2179.3111 | CM13: =SEG!CM144 -> -3592.8181 | CN13: =SUM(CN8:CN12) -> 434 | CO13: =SUM(CO8:CO12) -> 142 | CP13: =SUM(CL13:CO13) -> -837.50699 | CQ13: =SUM(CQ8:CQ12) -> 1013 | CR13: =SUM(CR8:CR12) -> 1282 | CS13: =SUM(CS8:CS12) -> 1343 | CT13: =SUM(CT8:CT12) -> 703 | CU13: =SUM(CQ13:CT13) -> 4341 | CV13: =SUM(CV8:CV12) -> 1080 | CW13: =SUM(CW8:CW12) -> 1353 | CX13: =SUM(CX8:CX12) -> 1480 | CY13: =SUM(CY8:CY12) -> 1501 | CZ13: =SUM(CV13:CY13) -> 5414 | DA13: =SUM(DA8:DA12) -> 1652 | DB13: =SUM(DB8:DB12) -> 1458 | DC13: =SUM(DC8:DC12) -> -1396 | DD13: =SUM(DD8:DD12) -> 1777 | DE13: =SUM(DA13:DD13) -> 3491 | DF13: =SUM(DF8:DF12) -> 1870 | DG13: =SUM(DG8:DG12) -> 529 | DH13: =SUM(DH8:DH12) -> 2028 | DI13: =SUM(DI8:DI12) -> 2111 | DJ13: =SUM(DF13:DI13) -> 6538 | DK13: =SUM(DK8:DK12) -> 2035 | DL13: =SUM(DL8:DL12) -> 2146 | DM13: =SUM(DM8:DM12) -> 2523 | DN13: =SEG!DN144 -> 2323.6336 | DO13: =SUM(DK13:DN13) -> 9027.6336 | DP13: =SEG!DP144 -> 2208.943 | DQ13: =SEG!DQ144 -> 2423.336 | DR13: =SEG!DR144 -> 2687.378 | DS13: =SEG!DS144 -> 2711.2695 | DT13: =SUM(DP13:DS13) -> 10030.926 | DU13: =SEG!DU144 -> 11036.621 | DV13: =SEG!DV144 -> 12046.966
B14: Non-service pension benefit (cost) | CF14: =-Data!CF18 -> 1305 | CG14: =-Data!CG18 -> 315.07 | CH14: =-Data!CH18 -> 327.93 | CI14: =-Data!CI18 -> 278.81 | CJ14: =-Data!CJ18 -> 290.19 | CK14: =SUM(CG14:CJ14) -> 1212 | CL14: =-Data!CL18 -> 276 | CM14: =-Data!CM18 -> 225 | CN14: =-Data!CN18 -> 253 | CO14: =-Data!CO18 -> 244 | CP14: =SUM(CL14:CO14) -> 998 | CQ14: =-Data!CQ18 -> 491 | CR14: =-Data!CR18 -> 490 | CS14: =-Data!CS18 -> 491 | CT14: =-Data!CT18 -> 472 | CU14: =SUM(CQ14:CT14) -> 1944 | CV14: =-Data!CV18 -> 480 | CW14: =-Data!CW18 -> 474 | CX14: =-Data!CX18 -> 468 | CY14: =-Data!CY18 -> 467 | CZ14: =SUM(CV14:CY14) -> 1889 | DA14: =-Data!DA18 -> 444 | DB14: =-Data!DB18 -> 447 | DC14: =-Data!DC18 -> 443 | DD14: =-Data!DD18 -> 446 | DE14: =SUM(DA14:DD14) -> 1780 | DF14: =-Data!DF18 -> 386 | DG14: =-Data!DG18 -> 374 | DH14: =-Data!DH18 -> 374 | DI14: =-Data!DI18 -> 384 | DJ14: =SUM(DF14:DI14) -> 1518 | DK14: =-Data!DK18 -> 366 | DL14: =-Data!DL18 -> 351 | DM14: =-Data!DM18 -> 364 | DN14: 350 | DO14: =SUM(DK14:DN14) -> 1431 | DP14: 325 | DQ14: 325 | DR14: 325 | DS14: 325 | DT14: =SUM(DP14:DS14) -> 1300 | DU14: 1200 | DV14: 1200
B15: Interest expense, net | CF15: =-Data!CF19 -> -1001 | CG15: =-Data!CG19 -> -253.82 | CH15: =-Data!CH19 -> -264.18 | CI15: =-Data!CI19 -> -274.89 | CJ15: =-Data!CJ19 -> -286.11 | CK15: =SUM(CG15:CJ15) -> -1079 | CL15: =-Data!CL19 -> -252 | CM15: =-Data!CM19 -> -337 | CN15: =-Data!CN19 -> -350 | CO15: =-Data!CO19 -> -349 | CP15: =SUM(CL15:CO15) -> -1288 | CQ15: =-Data!CQ19 -> -346 | CR15: =-Data!CR19 -> -342 | CS15: =-Data!CS19 -> -358 | CT15: =-Data!CT19 -> -308 | CU15: =SUM(CQ15:CT15) -> -1354 | CV15: =-Data!CV19 -> -318 | CW15: =-Data!CW19 -> -329 | CX15: =-Data!CX19 -> -311 | CY15: =-Data!CY19 -> -318 | CZ15: =SUM(CV15:CY15) -> -1276 | DA15: =-Data!DA19 -> -315 | DB15: =-Data!DB19 -> -333 | DC15: =-Data!DC19 -> -369 | DD15: =-Data!DD19 -> -488 | DE15: =SUM(DA15:DD15) -> -1505 | DF15: =-Data!DF19 -> -405 | DG15: =-Data!DG19 -> -475 | DH15: =-Data!DH19 -> -496 | DI15: =-Data!DI19 -> -486 | DJ15: =SUM(DF15:DI15) -> -1862 | DK15: =-Data!DK19 -> -443 | DL15: =-Data!DL19 -> -457 | DM15: =-Data!DM19 -> -449 | DN15: =(BS!DN7*0.015/4)-(BS!DN56*(0.05/4)) -> -449.48272 | DO15: =SUM(DK15:DN15) -> -1798.4827 | DP15: =(BS!DP7*0.015/4)-(BS!DP56*(0.0485/4)) -> -437.26572 | DQ15: =(BS!DQ7*0.015/4)-(BS!DQ56*(0.0485/4)) -> -438.36481 | DR15: =(BS!DR7*0.015/4)-(BS!DR56*(0.0485/4)) -> -437.46237 | DS15: =(BS!DS7*0.015/4)-(BS!DS56*(0.0485/4)) -> -430.67342 | DT15: =SUM(DP15:DS15) -> -1743.7663 | DU15: =(BS!DU7*0.015)-(BS!DU56*(0.0485)) -> -1710.2208 | DV15: =(BS!DV7*0.015)-(BS!DV56*(0.0485)) -> -1701.454
B16: EBT | CF16: =SUM(CF13:CF15) -> 9341.0576 | CG16: =SUM(CG13:CG15) -> 1965.25 | CH16: =SUM(CH13:CH15) -> 2328.75 | CI16: =SUM(CI13:CI15) -> 2347.92 | CJ16: =SUM(CJ13:CJ15) -> 1936.08 | CK16: =SUM(CG16:CJ16) -> 8578 | CL16: =SUM(CL13:CL15) -> 2203.3111 | CM16: =SUM(CM13:CM15) -> -3704.8181 | CN16: =SUM(CN13:CN15) -> 337 | CO16: =SUM(CO13:CO15) -> 37 | CP16: =SUM(CL16:CO16) -> -1127.507 | CQ16: =SUM(CQ13:CQ15) -> 1158 | CR16: =SUM(CR13:CR15) -> 1430 | CS16: =SUM(CS13:CS15) -> 1476 | CT16: =SUM(CT13:CT15) -> 867 | CU16: =SUM(CQ16:CT16) -> 4931 | CV16: =SUM(CV13:CV15) -> 1242 | CW16: =SUM(CW13:CW15) -> 1498 | CX16: =SUM(CX13:CX15) -> 1637 | CY16: =SUM(CY13:CY15) -> 1650 | CZ16: =SUM(CV16:CY16) -> 6027 | DA16: =SUM(DA13:DA15) -> 1781 | DB16: =SUM(DB13:DB15) -> 1572 | DC16: =SUM(DC13:DC15) -> -1322 | DD16: =SUM(DD13:DD15) -> 1735 | DE16: =SUM(DA16:DD16) -> 3766 | DF16: =SUM(DF13:DF15) -> 1851 | DG16: =SUM(DG13:DG15) -> 428 | DH16: =SUM(DH13:DH15) -> 1906 | DI16: =SUM(DI13:DI15) -> 2009 | DJ16: =SUM(DF16:DI16) -> 6194 | DK16: =SUM(DK13:DK15) -> 1958 | DL16: =SUM(DL13:DL15) -> 2040 | DM16: =SUM(DM13:DM15) -> 2438 | DN16: =SUM(DN13:DN15) -> 2224.1509 | DO16: =SUM(DK16:DN16) -> 8660.1509 | DP16: =SUM(DP13:DP15) -> 2096.6773 | DQ16: =SUM(DQ13:DQ15) -> 2309.9712 | DR16: =SUM(DR13:DR15) -> 2574.9156 | DS16: =SUM(DS13:DS15) -> 2605.5961 | DT16: =SUM(DP16:DS16) -> 9587.1602 | DU16: =SUM(DU13:DU15) -> 10526.4 | DV16: =SUM(DV13:DV15) -> 11545.512
B17: Income tax expense | CF17: =-Data!CF21 -> -1808 | CG17: =-Data!CG21 -> -296.94 | CH17: =-Data!CH21 -> -309.06 | CI17: =-Data!CI21 -> -299.88 | CJ17: =-Data!CJ21 -> -312.12 | CK17: =SUM(CG17:CJ17) -> -1218 | CL17: =-Data!CL21 -> -419 | CM17: =-Data!CM21 -> 23 | CN17: =-Data!CN21 -> -152 | CO17: =-Data!CO21 -> 178 | CP17: =SUM(CL17:CO17) -> -370 | CQ17: =-Data!CQ21 -> -345 | CR17: =-Data!CR21 -> -342 | CS17: =-Data!CS21 -> -3 | CT17: =-Data!CT21 -> -96 | CU17: =SUM(CQ17:CT17) -> -786 | CV17: =-Data!CV21 -> -116 | CW17: =-Data!CW21 -> -160 | CX17: =-Data!CX21 -> -242 | CY17: =-Data!CY21 -> -182 | CZ17: =SUM(CV17:CY17) -> -700 | DA17: =-Data!DA21 -> -300 | DB17: =-Data!DB21 -> -213 | DC17: =-Data!DC21 -> 389 | DD17: =-Data!DD21 -> -262 | DE17: =SUM(DA17:DD17) -> -386 | DF17: =-Data!DF21 -> -108 | DG17: =-Data!DG21 -> -253 | DH17: =-Data!DH21 -> -371 | DI17: =-Data!DI21 -> -449 | DJ17: =SUM(DF17:DI17) -> -1181 | DK17: =-Data!DK21 -> -333 | DL17: =-Data!DL21 -> -315 | DM17: =-Data!DM21 -> -432 | DN17: =-DN16*DN54 -> -533.79622 | DO17: =SUM(DK17:DN17) -> -1613.7962 | DP17: =-DP16*DP54 -> -398.36869 | DQ17: =-DQ16*DQ54 -> -438.89453 | DR17: =-DR16*DR54 -> -489.23396 | DS17: =-DS16*DS54 -> -495.06325 | DT17: =SUM(DP17:DS17) -> -1821.5604 | DU17: =-DU16*DU54 -> -2000.0161 | DV17: =-DV16*DV54 -> -2193.6472
B18: Minority Interest | CF18: =-Data!CF25 -> -163 | CG18: =-Data!CG25 -> -41.16 | CH18: =-Data!CH25 -> -42.84 | CI18: =-Data!CI25 -> -60.27 | CJ18: =-Data!CJ25 -> -62.73 | CK18: =SUM(CG18:CJ18) -> -207 | CL18: =-Data!CL25 -> -56 | CM18: =-Data!CM25 -> -24 | CN18: =-Data!CN25 -> -34 | CO18: =-Data!CO25 -> -69 | CP18: =SUM(CL18:CO18) -> -183 | CQ18: =-Data!CQ25 -> -41 | CR18: =-Data!CR25 -> -48 | CS18: =-Data!CS25 -> -73 | CT18: =-Data!CT25 -> -86 | CU18: =SUM(CQ18:CT18) -> -248 | CV18: =-Data!CV25 -> -23 | CW18: =-Data!CW25 -> -34 | CX18: =-Data!CX25 -> -8 | CY18: =-Data!CY25 -> -46 | CZ18: =SUM(CV18:CY18) -> -111 | DA18: =-Data!DA25 -> -55 | DB18: =-Data!DB25 -> -32 | DC18: =-Data!DC25 -> -51 | DD18: =-Data!DD25 -> -47 | DE18: =SUM(DA18:DD18) -> -185 | DF18: =-Data!DF25 -> -34 | DG18: =-Data!DG25 -> -64 | DH18: =-Data!DH25 -> -63 | DI18: =-Data!DI25 -> -78 | DJ18: =SUM(DF18:DI18) -> -239 | DK18: =-Data!DK25 -> -90 | DL18: =-Data!DL25 -> -68 | DM18: =-Data!DM25 -> -88 | DN18: -90 | DO18: =SUM(DK18:DN18) -> -336 | DP18: -75 | DQ18: -85 | DR18: -90 | DS18: -95 | DT18: =SUM(DP18:DS18) -> -345 | DU18: -355 | DV18: -375
B19: Net income, continuing ops. | CF19: =SUM(CF16:CF18) -> 7370.0576 | CG19: =SUM(CG16:CG18) -> 1627.15 | CH19: =SUM(CH16:CH18) -> 1976.85 | CI19: =SUM(CI16:CI18) -> 1987.77 | CJ19: =SUM(CJ16:CJ18) -> 1561.23 | CK19: =SUM(CK16:CK18) -> 7153 | CL19: =SUM(CL16:CL18) -> 1728.3111 | CM19: =SUM(CM16:CM18) -> -3705.8181 | ... DV19: =SUM(DV16:DV18) -> 8976.8645
B21: Basic EPS, continuing ops. | CF21: =CF19/CF32 -> 5.0887645 | CG21: =CG19/CG32 -> 1.0835387 | CH21: =CH19/CH32 -> 1.3164081 | CI21: =CI19/CI32 -> 1.3203388 | CJ21: =CJ19/CJ32 -> 1.0370176 | CK21: =CK19/CK32 -> 4.7572493 | CL21: =CL19/CL32 -> 1.1470838 | CM21: =CM19/CM32 -> -2.4684061 | ... DV21: =DV19/DV32 -> 6.8208073
B22: Diluted EPS, continuing ops. | CF22: =CF19/CF33 -> 5.0507522 | CG22: =CG19/CG33 -> 1.0758017 | CH22: =CH19/CH33 -> 1.3070083 | CI22: =CI19/CI33 -> 1.3085182 | CJ22: =CJ19/CJ33 -> 1.0277335 | CK22: =CK19/CK33 -> 4.7189603 | CL22: =CL19/CL33 -> 1.1386199 | CM22: =CM19/CM33 -> -2.4684061 | ... DV22: =DV19/DV33 -> 6.7424249
B24: Adjustments in EBIT | CF24: =-SEG!CF165 -> 741 | CG24: =-SEG!CG165 -> 249 | CH24: =-SEG!CH165 -> 54 | CI24: =-SEG!CI165 -> 41 | CJ24: =-SEG!CJ165 -> 203 | CK24: =SUM(CG24:CJ24) -> 547 | CL24: =-SEG!CL165 -> 132.38889 | CM24: =427+3673 -> 4100 | CN24: =245-29 -> 216 | CO24: 88 | CP24: =SUM(CL24:CO24) -> 4536.3889 | CQ24: 43 | CR24: 56 | CS24: =19 -> 19 | CT24: =-66+25 -> -41 | CU24: =SUM(CQ24:CT24) -> 77 | CV24: 44 | CW24: =12+69 -> 81 | CX24: 24 | CY24: =42+35+7 -> 84 | CZ24: =SUM(CV24:CY24) -> 233 | DA24: 30 | DB24: 68 | DC24: 104 | DD24: 44 | DE24: =SUM(DA24:DD24) -> 246 | DF24: 34 | DG24: 36 | DH24: -128 | DI24: 142 | DJ24: =SUM(DF24:DI24) -> 84 | DK24: 132 | DL24: 51 | DM24: -83 | DN24: =-SEG!DN165 -> 0 | DO24: =SUM(DK24:DN24) -> 100 | DP24: =-SEG!DP165 -> 0 | DQ24: =-SEG!DQ165 -> 0 | DR24: =-SEG!DR165 -> 0 | DS24: =-SEG!DS165 -> 0 | DT24: =SUM(DP24:DS24) -> 0 | DU24: =-SEG!DU165 -> 0 | DV24: =-SEG!DV165 -> 0
B25: Other adjustments | CL25: 0 | CM25: =25-4-88 -> -67 | CN25: =8+5-17 -> -4 | CO25: 4 | CP25: =SUM(CL25:CO25) -> -67 | CQ25: 25 | CR25: 0 | CS25: 32 | CT25: =617+29-12 -> 634 | CU25: =SUM(CQ25:CT25) -> 691 | CV25: =290-5-11 -> 274 | CW25: 0 | CX25: 0 | CY25: 0 | CZ25: =SUM(CV25:CY25) -> 274 | DA25: =-57+2 -> -55 | DB25: =193-17 -> 176 | DC25: 3003 | DD25: =-49+2-1-10-61-3 -> -122 | DE25: =SUM(DA25:DD25) -> 3002 | DF25: =-112+2-9-78-296 -> -493 | DG25: =504+1491+3+7 -> 2005 | DH25: =45+534+4+2 -> 585 | DI25: =79+520 -> 599 | DJ25: =SUM(DF25:DI25) -> 2696 | DK25: =26-43+35-26 -> -8 | DL25: =109-11-33 -> 65 | DM25: 19 | DN25: 0 | DO25: =SUM(DK25:DN25) -> 76 | DP25: 0 | DQ25: 0 | DR25: 0 | DS25: 0 | DT25: =SUM(DP25:DS25) -> 0 | DU25: 0 | DV25: 0
B26: Intangible amortization | CF26: =-SEG!CF141 -> 611.68044 | CG26: =-SEG!CG141 -> 588 | CH26: =-SEG!CH141 -> 571 | CI26: =-SEG!CI141 -> 581 | CJ26: =-SEG!CJ141 -> 594 | CK26: =SUM(CG26:CJ26) -> 2334 | CL26: =-SEG!CL141 -> 644 | CM26: =-SEG!CM141 -> 545 | CN26: =-SEG!CN141 -> 523 | CO26: =-SEG!CO141 -> 561 | CP26: =SUM(CL26:CO26) -> 2273 | CQ26: =-SEG!CQ141 -> 516 | CR26: =-SEG!CR141 -> 519 | CS26: =-SEG!CS141 -> 586 | CT26: =-SEG!CT141 -> 582 | CU26: =SUM(CQ26:CT26) -> 2203 | CV26: =-SEG!CV141 -> 484 | CW26: =-SEG!CW141 -> 448 | CX26: =-SEG!CX141 -> 482 | CY26: =-SEG!CY141 -> 479 | CZ26: =SUM(CV26:CY26) -> 1893 | DA26: =-SEG!DA141 -> 493 | DB26: 489 | DC26: =517+8 -> 525 | DD26: =499+5 -> 504 | DE26: =SUM(DA26:DD26) -> 2011 | DF26: 500 | DG26: 0 | DH26: 0 | DI26: 0 | DJ26: =SUM(DF26:DI26) -> 500 | DK26: 470 | DL26: 487 | DM26: 507 | DN26: =-SEG!DN141 -> 475 | DO26: =SUM(DK26:DN26) -> 1939 | DP26: =-SEG!DP141 -> 470 | DQ26: =-SEG!DQ141 -> 470 | DR26: =-SEG!DR141 -> 470 | DS26: =-SEG!DS141 -> 470 | DT26: =SUM(DP26:DS26) -> 1880 | DU26: =-SEG!DU141 -> 1850 | DV26: =-SEG!DV141 -> 1850
B27: Tax impact | CF27: =-(CF24+CF26)*0.215 -> -290.82629 | CG27: =-(CG24+CG26)*0.215 -> -179.955 | CH27: =-(CH24+CH26)*0.215 -> -134.375 | CI27: =-(CI24+CI26)*0.215 -> -133.73 | CJ27: =-(CJ24+CJ26)*0.215 -> -171.355 | CK27: =SUM(CG27:CJ27) -> -619.415 | CL27: =-(CL24+CL26)*0.1975 -> -153.33681 | CM27: =-321+22+60+46-31 -> -224 | CN27: =12-12-11-11-9 -> -31 | CO27: =260+55-13-2+25-5+4-1 -> 323 | CP27: =SUM(CL27:CO27) -> -85.336806 | CQ27: =-134+148 -> 14 | CR27: =-123+73 -> -50 | CS27: -141 | CT27: =-137-104-5 -> -246 | CU27: =SUM(CQ27:CT27) -> -423 | CV27: -182 | CW27: -111 | CX27: -108 | CY27: -117 | CZ27: =SUM(CV27:CY27) -> -518 | DA27: -101 | DB27: -165 | DC27: -826 | DD27: -99 | DE27: =SUM(DA27:DD27) -> -1191 | DF27: 41 | DG27: -257 | DH27: =11-148+156 -> 19 | DI27: -152 | DJ27: =SUM(DF27:DI27) -> -349 | DK27: -138 | DL27: -142 | DM27: -50 | DN27: =-(DN24+DN26)*0.22 -> -104.5 | DO27: =SUM(DK27:DN27) -> -434.5 | DP27: =-(DP24+DP26)*0.2 -> -94 | DQ27: =-(DQ24+DQ26)*0.2 -> -94 | DR27: =-(DR24+DR26)*0.2 -> -94 | DS27: =-(DS24+DS26)*0.2 -> -94 | DT27: =SUM(DP27:DS27) -> -376 | DU27: =-(DU24+DU26)*0.2 -> -370 | DV27: =-(DV24+DV26)*0.2 -> -370
B28: Adjusted net income | CF28: =CF19+SUM(CF24:CF27) -> 8431.9118 | CG28: =CG19+SUM(CG24:CG27) -> 2284.195 | CH28: =CH19+SUM(CH24:CH27) -> 2467.475 | CI28: =CI19+SUM(CI24:CI27) -> 2476.04 | CJ28: =CJ19+SUM(CJ24:CJ27) -> 2186.875 | CK28: =SUM(CG28:CJ28) -> 9414.585 | CL28: =CL19+SUM(CL24:CL27) -> 2351.3632 | CM28: =CM19+SUM(CM24:CM27) -> 648.1819 | CN28: =CN19+SUM(CN24:CN27) -> 855 | CO28: =CO19+SUM(CO24:CO27) -> 1122 | CP28: =SUM(CL28:CO28) -> 4976.5451 | CQ28: =CQ19+SUM(CQ24:CQ27) -> 1370 | CR28: =CR19+SUM(CR24:CR27) -> 1565 | CS28: =CS19+SUM(CS24:CS27) -> 1896 | CT28: =CT19+SUM(CT24:CT27) -> 1614 | CU28: =SUM(CQ28:CT28) -> 6445 | CV28: =CV19+SUM(CV24:CV27) -> 1723 | CW28: =CW19+SUM(CW24:CW27) -> 1722 | CX28: =CX19+SUM(CX24:CX27) -> 1785 | CY28: =CY19+SUM(CY24:CY27) -> 1868 | CZ28: =SUM(CV28:CY28) -> 7098 | DA28: =DA19+SUM(DA24:DA27) -> 1793 | DB28: =DB19+SUM(DB24:DB27) -> 1895 | DC28: =DC19+SUM(DC24:DC27) -> 1822 | DD28: =DD19+SUM(DD24:DD27) -> 1753 | DE28: =SUM(DA28:DD28) -> 7263 | DF28: =DF19+SUM(DF24:DF27) -> 1791 | DG28: =DG19+SUM(DG24:DG27) -> 1895 | DH28: =DH19+SUM(DH24:DH27) -> 1948 | DI28: =DI19+SUM(DI24:DI27) -> 2071 | DJ28: =SUM(DF28:DI28) -> 7705 | DK28: =DK19+SUM(DK24:DK27) -> 1991 | DL28: =DL19+SUM(DL24:DL27) -> 2118 | DM28: =DM19+SUM(DM24:DM27) -> 2311 | DN28: =DN19+SUM(DN24:DN27) -> 1970.8547 | DO28: =SUM(DK28:DN28) -> 8390.8547 | DP28: =DP19+SUM(DP24:DP27) -> 1999.3086 | DQ28: =DQ19+SUM(DQ24:DQ27) -> 2162.0767 | DR28: =DR19+SUM(DR24:DR27) -> 2371.6816 | DS28: =DS19+SUM(DS24:DS27) -> 2391.5328 | DT28: =SUM(DP28:DS28) -> 8924.5997 | DU28: =DU19+SUM(DU24:DU27) -> 9651.3843 | DV28: =DV19+SUM(DV24:DV27) -> 10456.864
