Workbook
Name A_ALL_BA: #REF!
Name A_ALL_BA_: #REF!
Name A_ALL_KEYWORDS_TYPE_ScalarContributed_EQTY_200000881: #REF!,#REF!,#REF!,#REF!,#REF!
Name A_ALL_KEYWORDS_TYPE_ScalarContributed_ISSR_208000201: #REF!,#REF!
Name A_ALL_KEYWORDS_TYPE_ScalarReference_EQTY_200000881: #REF!
Name A_ALL_KEYWORDS_TYPE_ScalarReference_ISSR_208000201: #REF!
Name A_ALL_KEYWORDS_TYPE_Vector_EQTY_200000881: #REF!,#REF!,#REF!,#REF!,#REF!,#REF!,#REF!
Name A_ALL_KEYWORDS_TYPE_Vector_ISSR_208000201: #REF!,#REF!,#REF!,#REF!,#REF!,#REF!,#REF!,#REF!,#REF!
Name A_ALL_SECTION_KEYWORDS_EQTY_200000881_1314: #REF!
Name A_ALL_SECTION_KEYWORDS_EQTY_200000881_1319: #REF!
Name A_ALL_SECTION_KEYWORDS_EQTY_200000881_131E: #REF!
Name A_ALL_SECTION_KEYWORDS_EQTY_200000881_131O: #REF!
Name A_ALL_SECTION_KEYWORDS_EQTY_200000881_13A: #REF!
Name A_ALL_SECTION_KEYWORDS_EQTY_200000881_13K: #REF!
Name A_ALL_SECTION_KEYWORDS_EQTY_200000881_13U: #REF!
Name A_ALL_SECTION_KEYWORDS_EQTY_200000881_13V: #REF!
Name A_ALL_SECTION_KEYWORDS_EQTY_200000881_13W: #REF!
Name A_ALL_SECTION_KEYWORDS_EQTY_200000881_Reference_Data: #REF!
Name A_ALL_SECTION_KEYWORDS_ISSR_208000201_1314: #REF!
Name A_ALL_SECTION_KEYWORDS_ISSR_208000201_13168: #REF!
Name A_ALL_SECTION_KEYWORDS_ISSR_208000201_1316S: #REF!
Name A_ALL_SECTION_KEYWORDS_ISSR_208000201_1316T: #REF!
Name A_ALL_SECTION_KEYWORDS_ISSR_208000201_1316U: #REF!
Name A_ALL_SECTION_KEYWORDS_ISSR_208000201_1319: #REF!
Name A_ALL_SECTION_KEYWORDS_ISSR_208000201_131E: #REF!
Name A_ALL_SECTION_KEYWORDS_ISSR_208000201_131J: #REF!
Name A_ALL_SECTION_KEYWORDS_ISSR_208000201_131O: #REF!
Name A_ALL_SECTION_KEYWORDS_ISSR_208000201_136E: #REF!,#REF!
Name A_ALL_SECTION_KEYWORDS_ISSR_208000201_13A: #REF!
Name A_ALL_SECTION_KEYWORDS_ISSR_208000201_13U: #REF!
Name A_ALL_SECTION_KEYWORDS_ISSR_208000201_13V: #REF!
Name A_ALL_SECTION_KEYWORDS_ISSR_208000201_Reference_Data: #REF!
Name A_ALL_SECTIONS_EQTY_200000881: #REF!,#REF!,#REF!,#REF!,#REF!,#REF!,#REF!,#REF!,#REF!,#REF!
Name A_CURRENCY_EQTY_200000881_PRI: #REF!
Name A_CURRENCY_EQTY_200000881_PUB: #REF!
Name A_CURRENCY_EQTY_200000881_REP: #REF!
Name A_CURRENCY_ISSR_208000201_REP: #REF!
Name A_KEYWORD_EQTY_200000881_AMER_CONVICTION: #REF!
Name A_KEYWORD_EQTY_200000881_AMER_LIST: #REF!
Name A_KEYWORD_EQTY_200000881_BETA_ANALYST: #REF!
Name A_KEYWORD_EQTY_200000881_BVPS: #REF!
Name A_KEYWORD_EQTY_200000881_BVPS_PUB: #REF!
Name A_KEYWORD_EQTY_200000881_CEEE_EPS: #REF!
Name A_KEYWORD_EQTY_200000881_CF_NI_PRE_PREF: #REF!
Name A_KEYWORD_EQTY_200000881_COMMON_DIV_PAID: #REF!
Name A_KEYWORD_EQTY_200000881_CURRENCY_ISO: #REF!
Name A_KEYWORD_EQTY_200000881_DILUTE_SHARES: #REF!
Name A_KEYWORD_EQTY_200000881_DPS: #REF!
Name A_KEYWORD_EQTY_200000881_DPS_PUB: #REF!
Name A_KEYWORD_EQTY_200000881_EBIT_PUB: #REF!
Name A_KEYWORD_EQTY_200000881_EBITDA_PUB: #REF!
Name A_KEYWORD_EQTY_200000881_EPS: #REF!
Name A_KEYWORD_EQTY_200000881_EPS_EX_ESO_B: #REF!
Name A_KEYWORD_EQTY_200000881_EPS_EX_ESO_D: #REF!
Name A_KEYWORD_EQTY_200000881_EPS_FUL_DIL: #REF!
Name A_KEYWORD_EQTY_200000881_EPS_POST_BASIC: #REF!
Name A_KEYWORD_EQTY_200000881_EPS_PUB: #REF!
Name A_KEYWORD_EQTY_200000881_EPS_PUB_EX_ESO: #REF!
Name A_KEYWORD_EQTY_200000881_EQ_PUB: #REF!
Name A_KEYWORD_EQTY_200000881_ESO_POST_TAX: #REF!

Sheet Cover
D7: Boeing (BA) Model
D8: 46231
B16: Noah Poponak, CFA
B17: (212) 357-0954
B18: noah.poponak@gs.com
B20: Connor Dessert
B21: (212) 357-6166
B22: connor.dessert@gs.com
B24: Nizar Mesani
B25: (212) 934-6965
B26: nizar.mesani@gs.com
B28: Amanda Fenenbock, CFA
B29: (212) 934-0385
B30: amanda.fenenbock@gs.com
... B34: tomas.russo@gs.com

Sheet Data
B3: BA Raw Data | C3: 1997 | D3: 1998 | E3: 1999 | F3: 2000 | G3: 2001 | H3: 2002 | I3: 2003 | J3: 1Q04 | K3: 2Q04 | L3: 3Q04 | M3: 4Q04 | N3: 2004 | O3: 1Q05 | P3: 2Q05 | Q3: 3Q05 | R3: 4Q05 | S3: 2005 | T3: 1Q06 | U3: 2Q06 | V3: 3Q06 | W3: 4Q06 | X3: 2006 | Y3: 1Q07 | Z3: 2Q07 | AA3: 3Q07 | AB3: 4Q07 | AC3: 2007 | AD3: 1Q08 | AE3: 2Q08 | AF3: 3Q08 | AG3: 4Q08 | AH3: 2008 | AI3: 1Q09 | AJ3: 2Q09 | AK3: 3Q09 | AL3: 4Q09 | AM3: 2009 | AN3: 1Q10 | AO3: 2Q10 | AP3: 3Q10 | AQ3: 4Q10 | AR3: 2010 | AS3: 1Q11 | AT3: 2Q11 | AU3: 3Q11 | AV3: 4Q11 | AW3: 2011 | AX3: 1Q12 | AY3: 2Q12 | AZ3: 3Q12 | BA3: 4Q12 | BB3: 2012 | BC3: 1Q13 | BD3: 2Q13 | BE3: 3Q13 | BF3: 4Q13 | BG3: 2013 | BH3: 1Q14 | BI3: 2Q14 | BJ3: 3Q14 | BK3: 4Q14 | BL3: 2014 | BM3: 1Q15 | BN3: 2Q15 | BO3: 3Q15 | BP3: 4Q15 | BQ3: 2015 | BR3: 1Q16 | BS3: 2Q16 | BT3: 3Q16 | BU3: 4Q16 | BV3: 2016 | BW3: 1Q17 | BX3: 2Q17 | BY3: 3Q17 | BZ3: 4Q17 | CA3: 2017 | CB3: 1Q18 | CC3: 2Q18 | CD3: 3Q18 | CE3: 4Q18 | CF3: 2018 | CG3: 1Q19 | CH3: 2Q19 | CI3: 3Q19 | CJ3: 4Q19 | CK3: 2019 | CL3: 1Q20 | CM3: 2Q20 | CN3: 3Q20 | CO3: 4Q20 | CP3: 2020 | CQ3: 1Q21 | CR3: 2Q21 | CS3: 3Q21 | CT3: 4Q21 | CU3: 2021 | CV3: 1Q22 | CW3: 2Q22 | CX3: 3Q22 | CY3: 4Q22 | CZ3: 2022 | DA3: 1Q23 | DB3: 2Q23 | DC3: 3Q23 | DD3: 4Q23 | DE3: 2023 | DF3: 1Q24 | DG3: 2Q24 | DH3: 3Q24 | DI3: 4Q24 | DJ3: 2024 | DK3: 1Q25 | DL3: 2Q25 | DM3: 3Q25 | DN3: 4Q25 | DO3: 2025 | DP3: 1Q26 | DQ3: 2Q26 | DR3: 3Q26 | DS3: 4Q26 | DT3: 2026 | DU3: 1Q27 | DV3: 2Q27 | DW3: 3Q27 | DX3: 4Q27 | DY3: 2027 | DZ3: 2028 | EA3: 2029 | EB3: 2030
B4: ($ mn) | C4: 35795 | D4: 36160 | E4: 36525 | F4: 36891 | G4: 37256 | H4: 37621 | I4: 37986 | J4: 38077 | K4: 38168 | L4: 38260 | M4: 38352 | N4: 38352 | O4: 38442 | P4: 38533 | Q4: 38625 | R4: 38717 | S4: 38717 | T4: 38807 | U4: 38898 | V4: 38990 | W4: 39082 | X4: 39082 | Y4: 39172 | Z4: 39263 | AA4: 39355 | AB4: 39447 | AC4: 39447 | AD4: 39538 | AE4: 39629 | AF4: 39721 | AG4: 39813 | AH4: 39813 | AI4: 39903 | AJ4: 39994 | AK4: 40086 | AL4: 40178 | AM4: 40178 | AN4: 40268 | AO4: 40359 | AP4: 40451 | AQ4: 40543 | AR4: 40543 | AS4: 40633 | AT4: 40724 | AU4: 40816 | AV4: 40908 | AW4: 40908 | AX4: 40999 | AY4: 41090 | AZ4: 41182 | BA4: 41274 | BB4: 41274 | BC4: 41364 | BD4: 41455 | BE4: 41547 | BF4: 41639 | BG4: 41639 | BH4: 41729 | BI4: 41820 | BJ4: 41912 | BK4: 42004 | BL4: 42004 | BM4: 42094 | BN4: 42185 | BO4: 42277 | BP4: 42369 | BQ4: 42369 | BR4: 42460 | BS4: 42551 | BT4: 42643 | BU4: 42735 | BV4: 42735 | BW4: 42825 | BX4: 42916 | BY4: 43008 | BZ4: 43100 | CA4: 43100 | CB4: 43190 | CC4: 43281 | CD4: 43373 | CE4: 43465 | CF4: 43465 | CG4: 43555 | CH4: 43646 | CI4: 43738 | CJ4: 43830 | CK4: 43830 | CL4: 43921 | CM4: 44012 | CN4: 44104 | CO4: 44196 | CP4: 44196 | CQ4: 44286 | CR4: 44377 | CS4: 44469 | CT4: 44561 | CU4: 44561 | CV4: 44651 | CW4: 44742 | CX4: 44834 | CY4: 44926 | CZ4: 44926 | DA4: 45016 | DB4: 45107 | DC4: 45199 | DD4: 45291 | DE4: 45291 | DF4: 45382 | DG4: 45473 | DH4: 45565 | DI4: 45657 | DJ4: 45657 | DK4: 45747 | DL4: 45838 | DM4: 45930 | DN4: 46022 | DO4: 46022 | DP4: 46112 | DQ4: 46203 | DR4: 46295 | DS4: 46387 | DT4: 46387 | DU4: 46477 | DV4: 46568 | DW4: 46660 | DX4: 46752 | DY4: 46752 | DZ4: 47118 | EA4: 47483 | EB4: 47848
B6: Income Statement
B7: Sales of products | N7: 43960 | O7: 10791 | P7: 12394 | Q7: 10334 | R7: =S7-O7-P7-Q7 -> 11879 | S7: 45398 | T7: 12202 | U7: 12848 | V7: 12388 | W7: =X7-T7-U7-V7 -> 15206 | X7: 52644 | Y7: 13229 | Z7: 14787 | AA7: 14177 | AB7: =AC7-Y7-Z7-AA7 -> 14856 | AC7: 57049 | AD7: 13688 | AE7: 14298 | AF7: 12407 | AG7: =AH7-AD7-AE7-AF7 -> 9787 | AH7: 50180 | AI7: 13835 | AJ7: 14296 | AK7: 13967 | AL7: 14934 | AM7: =SUM(AI7:AL7) -> 57032 | AN7: 12316 | AO7: 12624 | AP7: 14077 | AQ7: 13569 | AR7: =SUM(AN7:AQ7) -> 52586 | AS7: 11894 | AT7: 13640 | AU7: 14907 | AV7: =AW7-SUM(AS7:AU7) -> 16960 | AW7: 57401 | AX7: 16685 | AY7: 17341 | AZ7: 17415 | BA7: 19793 | BB7: =SUM(AX7:BA7) -> 71234 | BC7: 16318 | BD7: 19238 | BE7: 19754 | BF7: 21482.4 | BG7: =SUM(BC7:BF7) -> 76792.4 | BH7: 18015 | BI7: 19527 | BJ7: 21378 | BK7: 21768 | BL7: =SUM(BH7:BK7) -> 80688 | BM7: 19485 | BN7: 21923 | BO7: 23000 | BP7: 20847 | BQ7: =SUM(BM7:BP7) -> 85255 | BR7: 19885 | BS7: 22184 | BT7: 21494 | BU7: 20836 | BV7: =SUM(BR7:BU7) -> 84399 | BW7: 19367 | BX7: 20147 | BY7: 21825 | BZ7: 22720 | CA7: =SUM(BW7:BZ7) -> 84059 | CB7: 20820 | CC7: 21565 | CD7: 22463 | CE7: 25381 | CF7: =+SUM(CB7:CE7) -> 90229 | CG7: 20225 | CH7: 13094 | CI7: 17195 | CJ7: 15580 | CK7: =+SUM(CG7:CJ7) -> 66094 | CL7: 14191 | CM7: 9063 | CN7: 11402 | CO7: =CP7-SUM(CL7:CN7) -> 12486 | CP7: 47142 | CQ7: 12518 | CR7: 14154 | CS7: 12552 | CT7: 12162 | CU7: =+SUM(CQ7:CT7) -> 51386 | CV7: 11427 | CW7: 14009 | CX7: 13331 | CY7: 17126 | CZ7: =+SUM(CV7:CY7) -> 55893 | DA7: 14914 | DB7: 16687 | DC7: 15060 | DD7: 18920 | DE7: =+SUM(DA7:DD7) -> 65581 | DF7: 13268 | DG7: 13524 | DH7: 14534 | DI7: 11901 | DJ7: =+SUM(DF7:DI7) -> 53227 | DK7: 16147 | DL7: 19122 | DM7: 19642 | DN7: 20445 | DO7: =+SUM(DK7:DN7) -> 75356 | DP7: 18998 | DQ7: 21366
B8: Sales of services | N8: 8497 | O8: 2196 | P8: 2634 | Q8: 2295 | R8: =S8-O8-P8-Q8 -> 2322 | S8: 9447 | T8: 2062 | U8: 2138 | V8: 2351 | W8: =X8-T8-U8-V8 -> 2335 | X8: 8886 | Y8: 2136 | Z8: 2241 | AA8: 2340 | AB8: =AC8-Y8-Z8-AA8 -> 2621 | AC8: 9338 | AD8: 2302 | AE8: 2664 | AF8: 2886 | AG8: =AH8-AD8-AE8-AF8 -> 2877 | AH8: 10729 | AI8: 2667 | AJ8: 2858 | AK8: 2721 | AL8: 3003 | AM8: =SUM(AI8:AL8) -> 11249 | AN8: 2900 | AO8: 2949 | AP8: 2890 | AQ8: 2981 | AR8: =SUM(AN8:AQ8) -> 11720 | AS8: 3016 | AT8: 2903 | AU8: 2820 | AV8: =AW8-SUM(AS8:AU8) -> 2595 | AW8: 11334 | AX8: 2698 | AY8: 2664 | AZ8: 2593 | BA8: 2509 | BB8: =SUM(AX8:BA8) -> 10464 | BC8: 2575 | BD8: 2577 | BE8: 2376 | BF8: 2303 | BG8: =SUM(BC8:BF8) -> 9831 | BH8: 2450 | BI8: 2518 | BJ8: 2406 | BK8: 2700 | BL8: =SUM(BH8:BK8) -> 10074 | BM8: 2664 | BN8: 2620 | BO8: 2849 | BP8: 2726 | BQ8: =SUM(BM8:BP8) -> 10859 | BR8: 2747 | BS8: 2571 | BT8: 2404 | BU8: 2450 | BV8: =SUM(BR8:BU8) -> 10172 | BW8: 2594 | BX8: 2592 | BY8: 2484 | BZ8: 2648 | CA8: =SUM(BW8:BZ8) -> 10318 | CB8: 2562 | CC8: 2693 | CD8: 2683 | CE8: 2960 | CF8: =+SUM(CB8:CE8) -> 10898 | CG8: 2692 | CH8: 2657 | CI8: 2785 | CJ8: 2331 | CK8: =+SUM(CG8:CJ8) -> 10465 | CL8: 2717 | CM8: 2744 | CN8: 2737 | CO8: =CP8-SUM(CL8:CN8) -> 2818 | CP8: 11016 | CQ8: 2699 | CR8: 2844 | CS8: 2726 | CT8: 2631 | CU8: =+SUM(CQ8:CT8) -> 10900 | CV8: 2564 | CW8: 2672 | CX8: 2625 | CY8: 2854 | CZ8: =+SUM(CV8:CY8) -> 10715 | DA8: 3007 | DB8: 3064 | DC8: 3044 | DD8: 3098 | DE8: =+SUM(DA8:DD8) -> 12213 | DF8: 3301 | DG8: 3342 | DH8: 3306 | DI8: 3341 | DJ8: =+SUM(DF8:DI8) -> 13290 | DK8: 3349 | DL8: 3627 | DM8: 3628 | DN8: 3503 | DO8: =+SUM(DK8:DN8) -> 14107 | DP8: 3219 | DQ8: 3194
B9: Total revenues | C9: 45800 | D9: 56154 | E9: 57993 | F9: 51321 | G9: 58198 | H9: 54069 | I9: 50485 | J9: 12959 | K9: 13088 | L9: 13152 | M9: =N9-SUM(J9:L9) -> 13258 | N9: =SUM(N7:N8) -> 52457 | O9: =SUM(O7:O8) -> 12987 | P9: =SUM(P7:P8) -> 15028 | Q9: =SUM(Q7:Q8) -> 12629 | R9: =S9-O9-P9-Q9 -> 14201 | S9: =SUM(S7:S8) -> 54845 | T9: =SUM(T7:T8) -> 14264 | U9: =SUM(U7:U8) -> 14986 | V9: =SUM(V7:V8) -> 14739 | W9: =X9-T9-U9-V9 -> 17541 | X9: =SUM(X7:X8) -> 61530 | Y9: =SUM(Y7:Y8) -> 15365 | Z9: =SUM(Z7:Z8) -> 17028 | AA9: =SUM(AA7:AA8) -> 16517 | AB9: =AC9-Y9-Z9-AA9 -> 17477 | AC9: =SUM(AC7:AC8) -> 66387 | AD9: =SUM(AD7:AD8) -> 15990 | AE9: =SUM(AE7:AE8) -> 16962 | AF9: =SUM(AF7:AF8) -> 15293 | AG9: =AH9-AD9-AE9-AF9 -> 12664 | AH9: =SUM(AH7:AH8) -> 60909 | AI9: =SUM(AI7:AI8) -> 16502 | AJ9: =SUM(AJ7:AJ8) -> 17154 | AK9: =SUM(AK7:AK8) -> 16688 | AL9: =SUM(AL7:AL8) -> 17937 | AM9: =SUM(AM7:AM8) -> 68281 | AN9: =SUM(AN7:AN8) -> 15216 | AO9: =SUM(AO7:AO8) -> 15573 | ... BW9: =SUM(BW7:BW8) -> 21961 | BX9: 23051 | BY9: 24223 | BZ9: 24770 | CA9: 94005 | CB9: =SUM(CB7:CB8) -> 23382 | CC9: =SUM(CC7:CC8) -> 24258 | CD9: =SUM(CD7:CD8) -> 25146 | CE9: =SUM(CE7:CE8) -> 28341 | CF9: =+SUM(CF7:CF8) -> 101127 | CG9: =SUM(CG7:CG8) -> 22917 | CH9: =SUM(CH7:CH8) -> 15751 | CI9: =SUM(CI7:CI8) -> 19980 | CJ9: =SUM(CJ7:CJ8) -> 17911 | CK9: =+SUM(CK7:CK8) -> 76559 | CL9: =SUM(CL7:CL8) -> 16908 | CM9: =SUM(CM7:CM8) -> 11807 | CN9: =SUM(CN7:CN8) -> 14139 | CO9: =SUM(CO7:CO8) -> 15304 | CP9: =+SUM(CP7:CP8) -> 58158 | CQ9: =SUM(CQ7:CQ8) -> 15217 | CR9: =SUM(CR7:CR8) -> 16998 | CS9: =SUM(CS7:CS8) -> 15278 | CT9: =SUM(CT7:CT8) -> 14793 | CU9: =+SUM(CU7:CU8) -> 62286 | CV9: =SUM(CV7:CV8) -> 13991 | CW9: =SUM(CW7:CW8) -> 16681 | CX9: =SUM(CX7:CX8) -> 15956 | CY9: =SUM(CY7:CY8) -> 19980 | CZ9: =+SUM(CZ7:CZ8) -> 66608 | DA9: =SUM(DA7:DA8) -> 17921 | DB9: =SUM(DB7:DB8) -> 19751 | DC9: =SUM(DC7:DC8) -> 18104 | DD9: =SUM(DD7:DD8) -> 22018 | DE9: =+SUM(DE7:DE8) -> 77794 | DF9: =SUM(DF7:DF8) -> 16569 | DG9: =SUM(DG7:DG8) -> 16866 | DH9: =SUM(DH7:DH8) -> 17840 | DI9: =SUM(DI7:DI8) -> 15242 | DJ9: =+SUM(DJ7:DJ8) -> 66517 | DK9: =SUM(DK7:DK8) -> 19496 | DL9: =SUM(DL7:DL8) -> 22749 | DM9: =SUM(DM7:DM8) -> 23270 | DN9: =SUM(DN7:DN8) -> 23948 | DO9: =+SUM(DO7:DO8) -> 89463 | DP9: =SUM(DP7:DP8) -> 22217 | DQ9: =SUM(DQ7:DQ8) -> 24560
B10: Cost of products | J10: -9360.75 | K10: -9360.75 | L10: -9360.75 | M10: -9360.75 | N10: -37443 | O10: -8830 | P10: -10187 | Q10: -8706 | R10: =S10-O10-P10-Q10 -> -10359 | S10: -38082 | T10: -9618 | U10: -10821 | V10: -9789 | W10: =X10-T10-U10-V10 -> -12262 | X10: -42490 | Y10: -10431 | Z10: -11709 | AA10: -11331 | AB10: =AC10-Y10-Z10-AA10 -> -11904 | AC10: -45375 | AD10: -10788 | AE10: -11637 | AF10: -10311 | AG10: =AH10-AD10-AE10-AF10 -> -8926 | AH10: -41662 | AI10: -11579 | AJ10: -11580 | AK10: -12273 | AL10: -12207 | AM10: =SUM(AI10:AL10) -> -47639 | AN10: -9822 | AO10: -10115 | AP10: -11232 | AQ10: -11025 | AR10: =SUM(AN10:AQ10) -> -42194 | AS10: -9506 | AT10: -10823 | AU10: -12006 | AV10: =AW10-SUM(AS10:AU10) -> -14307 | AW10: -46642 | AX10: -13661 | AY10: -14759 | AZ10: -14683 | BA10: -17206 | BB10: =SUM(AX10:BA10) -> -60309 | BC10: -13728 | BD10: -16437 | BE10: -16865 | BF10: -18610 | BG10: =SUM(BC10:BF10) -> -65640 | BH10: -15258 | BI10: -16674 | BJ10: -18091 | BK10: -18528 | BL10: =SUM(BH10:BK10) -> -68551 | BM10: -16380 | BN10: -19247 | BO10: -19393 | BP10: -18426 | BQ10: =SUM(BM10:BP10) -> -73446 | BR10: -16945 | BS10: -20265 | BT10: -17907 | BU10: -17596 | BV10: =SUM(BR10:BU10) -> -72713 | BW10: -16062 | BX10: -16443 | BY10: -18050 | BZ10: -18509 | CA10: =SUM(BW10:BZ10) -> -69064 | CB10: -16816 | CC10: -17436 | CD10: -18882 | CE10: -19788 | CF10: =+SUM(CB10:CE10) -> -72922 | CG10: -16238 | CH10: -15672 | CI10: -14674 | CJ10: -16293 | CK10: =+SUM(CG10:CJ10) -> -62877 | CL10: -14713 | CM10: -10378 | CN10: -10910 | CO10: =CP10-SUM(CL10:CN10) -> -18567 | CP10: -54568 | CQ10: -11632 | CR10: -12263 | CS10: -11271 | CT10: -14788 | CU10: =+SUM(CQ10:CT10) -> -49954 | CV10: -11412 | CW10: -12284 | CX10: -14541 | CY10: -15732 | CZ10: =+SUM(CV10:CY10) -> -53969 | DA10: -13553 | DB10: -15123 | DC10: -14464 | DD10: -16724 | DE10: =+SUM(DA10:DD10) -> -59864 | DF10: -12064 | DG10: -12907 | DH10: -18413 | DI10: -14010 | DJ10: =+SUM(DF10:DI10) -> -57394 | DK10: -14379 | DL10: -17406 | DM10: -22737 | DN10: -19239 | DO10: =+SUM(DK10:DN10) -> -73761 | DP10: -17031 | DQ10: -19487
B11: Cost of services | C11: -40644 | D11: -50546 | E11: -51320 | F11: -43712 | G11: -48778 | H11: -45499 | I11: -43862 | J11: =-10728-J10 -> -1367.25 | K11: =-10875-K10 -> -1514.25 | L11: =-11164-L10 -> -1803.25 | M11: =N11-SUM(J11:L11) -> -2547.25 | N11: -7232 | O11: -1859 | P11: -2204 | Q11: -1987 | R11: =S11-O11-P11-Q11 -> -1717 | S11: -7767 | T11: -1786 | U11: -1691 | V11: -2014 | W11: =X11-T11-U11-V11 -> -2103 | X11: -7594 | Y11: -1756 | Z11: -1827 | AA11: -1803 | AB11: =AC11-Y11-Z11-AA11 -> -2346 | AC11: -7732 | AD11: -1755 | AE11: -2248 | AF11: -2176 | AG11: =AH11-AD11-AE11-AF11 -> -2288 | AH11: -8467 | AI11: -2119 | AJ11: -2184 | AK11: -2165 | AL11: -2258 | AM11: =SUM(AI11:AL11) -> -8726 | AN11: -2281 | AO11: -2384 | AP11: -2472 | AQ11: -2352 | AR11: =SUM(AN11:AQ11) -> -9489 | AS11: -2510 | AT11: -2348 | AU11: -2319 | AV11: =AW11-SUM(AS11:AU11) -> -1920 | AW11: -9097 | AX11: -2380 | AY11: -1962 | AZ11: -2089 | BA11: -1816 | BB11: =SUM(AX11:BA11) -> -8247 | BC11: -2009 | BD11: -1995 | BE11: -1791 | BF11: -1758 | BG11: =SUM(BC11:BF11) -> -7553 | BH11: -2020 | BI11: -1979 | BJ11: -1966 | BK11: -2167 | BL11: =SUM(BH11:BK11) -> -8132 | BM11: -2100 | BN11: -2086 | BO11: -2191 | BP11: -2201 | BQ11: =SUM(BM11:BP11) -> -8578 | BR11: -2136 | BS11: -2044 | BT11: -1983 | BU11: -1855 | BV11: =SUM(BR11:BU11) -> -8018 | BW11: -1998 | BX11: -1932 | BY11: -1910 | BZ11: -1901 | CA11: =SUM(BW11:BZ11) -> -7741 | CB11: -1992 | CC11: -2083 | CD11: -2140 | CE11: -2284 | CF11: =+SUM(CB11:CE11) -> -8499 | CG11: -2389 | CH11: -2122 | CI11: -2241 | CJ11: -2402 | CK11: =+SUM(CG11:CJ11) -> -9154 | CL11: -2043 | CM11: -2589 | CN11: -2185 | CO11: =CP11-SUM(CL11:CN11) -> -2415 | CP11: -9232 | CQ11: -2167 | CR11: -2316 | CS11: -2288 | CT11: -2512 | CU11: =+SUM(CQ11:CT11) -> -9283 | CV11: -2226 | CW11: -2269 | CX11: -2230 | CY11: -2384 | CZ11: =+SUM(CV11:CY11) -> -9109 | DA11: -2445 | DB11: -2689 | DC11: -2475 | DD11: -2597 | DE11: =+SUM(DA11:DD11) -> -10206 | DF11: -2629 | DG11: -2730 | DH11: -2934 | DI11: -2821 | DJ11: =+SUM(DF11:DI11) -> -11114 | DK11: -2700 | DL11: -2908 | DM11: -2908 | DN11: -2897 | DO11: =+SUM(DK11:DN11) -> -11413 | DP11: -2640 | DQ11: -2659
B12: Boeing Capital Corporation interest expense | C12: 0 | D12: 0 | E12: 0 | F12: 0 | G12: 0 | H12: 0 | I12: -442 | J12: -103 | K12: -89 | L12: -89 | M12: =N12-SUM(J12:L12) -> -69 | N12: -350 | O12: -89 | P12: -90 | Q12: -87 | R12: =S12-O12-P12-Q12 -> -93 | S12: -359 | T12: -90 | U12: -89 | V12: -88 | W12: =X12-T12-U12-V12 -> -86 | X12: -353 | Y12: -79 | Z12: -73 | AA12: -73 | AB12: =AC12-Y12-Z12-AA12 -> -70 | AC12: -295 | AD12: -62 | AE12: -57 | AF12: -54 | AG12: =AH12-AD12-AE12-AF12 -> -50 | AH12: -223 | AI12: -47 | AJ12: -43 | AK12: -42 | AL12: -43 | AM12: =SUM(AI12:AL12) -> -175 | AN12: -41 | AO12: -41 | AP12: -42 | AQ12: -36 | AR12: =SUM(AN12:AQ12) -> -160 | AS12: -33 | AT12: -29 | AU12: -32 | AV12: =AW12-SUM(AS12:AU12) -> -34 | AW12: -128 | AX12: -28 | AY12: -19 | AZ12: -22 | BA12: -19 | BB12: =SUM(AX12:BA12) -> -88 | BC12: -19 | BD12: -18 | BE12: -18 | BF12: -20 | BG12: =SUM(BC12:BF12) -> -75 | BH12: -18 | BI12: -17 | BJ12: -18 | BK12: -16 | BL12: =SUM(BH12:BK12) -> -69 | BM12: -16 | BN12: -17 | BO12: -16 | BP12: -15 | BQ12: =SUM(BM12:BP12) -> -64 | BR12: -16 | BS12: -16 | BT12: -14 | BU12: -13 | BV12: =SUM(BR12:BU12) -> -59 | BW12: -13 | BX12: -13 | BY12: -27 | BZ12: -17 | CA12: =SUM(BW12:BZ12) -> -70 | CB12: -16 | CC12: -17 | CD12: -18 | CE12: -18 | CF12: =+SUM(CB12:CE12) -> -69 | CG12: -18 | CH12: -16 | CI12: -15 | CJ12: -13 | CK12: =+SUM(CG12:CJ12) -> -62 | CL12: -12 | CM12: -11 | CN12: -10 | CO12: =CP12-SUM(CL12:CN12) -> -10 | CP12: -43 | CQ12: -9 | CR12: -9 | CS12: -7 | CT12: -7 | CU12: =+SUM(CQ12:CT12) -> -32 | CV12: -7 | CW12: -6 | CX12: -7 | CY12: -8 | CZ12: =+SUM(CV12:CY12) -> -28 | DE12: =+SUM(DA12:DD12) -> 0 | DJ12: =+SUM(DF12:DI12) -> 0 | DO12: =+SUM(DK12:DN12) -> 0
B13: Total costs and expenses | C13: =SUM(C10:C12) -> -40644 | D13: =SUM(D10:D12) -> -50546 | E13: =SUM(E10:E12) -> -51320 | F13: =SUM(F10:F12) -> -43712 | G13: =SUM(G10:G12) -> -48778 | H13: =SUM(H10:H12) -> -45499 | I13: =SUM(I10:I12) -> -44304 | J13: =SUM(J10:J12) -> -10831 | ... L13: =SUM(L10:L12) -> -11253 | M13: =N13-SUM(J13:L13) -> -11977 | N13: =SUM(N10:N12) -> -45025 | O13: =SUM(O10:O12) -> -10778 | P13: =SUM(P10:P12) -> -12481 | Q13: =SUM(Q10:Q12) -> -10780 | R13: =S13-O13-P13-Q13 -> -12169 | S13: =SUM(S10:S12) -> -46208 | T13: =SUM(T10:T12) -> -11494 | U13: =SUM(U10:U12) -> -12601 | V13: =SUM(V10:V12) -> -11891 | W13: =X13-T13-U13-V13 -> -14451 | X13: =SUM(X10:X12) -> -50437 | Y13: =SUM(Y10:Y12) -> -12266 | Z13: =SUM(Z10:Z12) -> -13609 | AA13: =SUM(AA10:AA12) -> -13207 | AB13: =AC13-Y13-Z13-AA13 -> -14320 | AC13: =SUM(AC10:AC12) -> -53402 | AD13: =SUM(AD10:AD12) -> -12605 | AE13: =SUM(AE10:AE12) -> -13942 | AF13: =SUM(AF10:AF12) -> -12541 | AG13: =AH13-AD13-AE13-AF13 -> -11264 | AH13: =SUM(AH10:AH12) -> -50352 | AI13: =SUM(AI10:AI12) -> -13745 | AJ13: =SUM(AJ10:AJ12) -> -13807 | AK13: =SUM(AK10:AK12) -> -14480 | AL13: =SUM(AL10:AL12) -> -14508 | AM13: =SUM(AM10:AM12) -> -56540 | AN13: =SUM(AN10:AN12) -> -12144 | AO13: =SUM(AO10:AO12) -> -12540 | ... BW13: =SUM(BW10:BW12) -> -18073 | BX13: -18702 | BY13: -19956 | BZ13: -19881 | CA13: -76612 | CB13: =SUM(CB10:CB12) -> -18824 | CC13: =SUM(CC10:CC12) -> -19536 | CD13: =SUM(CD10:CD12) -> -21040 | CE13: =SUM(CE10:CE12) -> -22090 | CF13: =+SUM(CB13:CE13) -> -81490 | CG13: =SUM(CG10:CG12) -> -18645 | CH13: =SUM(CH10:CH12) -> -17810 | CI13: =SUM(CI10:CI12) -> -16930 | CJ13: =SUM(CJ10:CJ12) -> -18708 | CK13: =+SUM(CG13:CJ13) -> -72093 | CL13: =SUM(CL10:CL12) -> -16768 | CM13: =SUM(CM10:CM12) -> -12978 | CN13: =SUM(CN10:CN12) -> -13105 | CO13: =SUM(CO10:CO12) -> -20992 | CP13: =+SUM(CL13:CO13) -> -63843 | CQ13: =SUM(CQ10:CQ12) -> -13808 | CR13: =SUM(CR10:CR12) -> -14588 | CS13: =SUM(CS10:CS12) -> -13566 | CT13: =SUM(CT10:CT12) -> -17307 | CU13: =+SUM(CQ13:CT13) -> -59269 | CV13: =SUM(CV10:CV12) -> -13645 | CW13: =SUM(CW10:CW12) -> -14559 | CX13: =SUM(CX10:CX12) -> -16778 | CY13: =SUM(CY10:CY12) -> -18124 | CZ13: =+SUM(CV13:CY13) -> -63106 | DA13: =SUM(DA10:DA12) -> -15998 | DB13: =SUM(DB10:DB12) -> -17812 | DC13: =SUM(DC10:DC12) -> -16939 | DD13: =SUM(DD10:DD12) -> -19321 | DE13: =+SUM(DA13:DD13) -> -70070 | DF13: =SUM(DF10:DF12) -> -14693 | DG13: =SUM(DG10:DG12) -> -15637 | DH13: =SUM(DH10:DH12) -> -21347 | DI13: =SUM(DI10:DI12) -> -16831 | DJ13: =+SUM(DF13:DI13) -> -68508 | DK13: =SUM(DK10:DK12) -> -17079 | DL13: =SUM(DL10:DL12) -> -20314 | DM13: =SUM(DM10:DM12) -> -25645 | DN13: =SUM(DN10:DN12) -> -22136 | DO13: =+SUM(DK13:DN13) -> -85174 | DP13: =SUM(DP10:DP12) -> -19671 | DQ13: =SUM(DQ10:DQ12) -> -22146
B14: Income from operating investments, net | C14: 0 | D14: 0 | E14: 4 | F14: 64 | G14: 93 | H14: -128 | I14: 28 | J14: 13 | K14: 27 | L14: 27 | M14: =N14-SUM(J14:L14) -> 24 | N14: 91 | O14: 16 | P14: 28 | Q14: 24 | R14: =S14-O14-P14-Q14 -> 20 | S14: 88 | T14: 20 | U14: 33 | V14: 42 | W14: =X14-T14-U14-V14 -> 51 | X14: 146 | Y14: 39 | Z14: 50 | AA14: 11 | AB14: =AC14-Y14-Z14-AA14 -> 88 | AC14: 188 | AD14: 58 | AE14: 65 | AF14: 72 | AG14: =AH14-AD14-AE14-AF14 -> 46 | AH14: 241 | AI14: 32 | AJ14: 70 | AK14: 84 | AL14: 63 | AM14: =SUM(AI14:AL14) -> 249 | AN14: 59 | AO14: 54 | AP14: 74 | AQ14: 80 | AR14: =SUM(AN14:AQ14) -> 267 | AS14: 62 | AT14: 88 | AU14: 52 | AV14: =AW14-SUM(AS14:AU14) -> 76 | AW14: 278 | AX14: 46 | AY14: 45 | AZ14: 120 | BA14: 57 | BB14: =SUM(AX14:BA14) -> 268 | BC14: 45 | BD14: 43 | BE14: 59 | BF14: 67 | BG14: =SUM(BC14:BF14) -> 214 | BH14: 59 | BI14: 61 | BJ14: 92 | BK14: 75 | BL14: =SUM(BH14:BK14) -> 287 | BM14: 79 | BN14: 50 | BO14: 78 | BP14: 67 | BQ14: =SUM(BM14:BP14) -> 274 | BR14: 54 | BS14: 97 | BT14: 69 | BU14: 83 | BV14: =SUM(BR14:BU14) -> 303 | BW14: 81 | BX14: 39 | BY14: 49 | BZ14: 35 | CA14: =SUM(BW14:BZ14) -> 204 | CB14: 74 | CC14: 6 | CD14: 32 | CE14: -1 | CF14: =+SUM(CB14:CE14) -> 111 | CG14: 20 | CH14: -15 | CI14: -8 | CJ14: -1 | CK14: =+SUM(CG14:CJ14) -> -4 | CL14: -2 | CM14: -45 | CN14: -14 | CO14: 70 | CP14: =+SUM(CL14:CO14) -> 9 | CQ14: 37 | CR14: 38 | CS14: 120 | CT14: 15 | CU14: =+SUM(CQ14:CT14) -> 210 | CV14: -20 | CW14: 17 | CX14: -24 | CY14: 11 | CZ14: =+SUM(CV14:CY14) -> -16 | DA14: -27 | DB14: 44 | DC14: 28 | DD14: 1 | DE14: =+SUM(DA14:DD14) -> 46 | DF14: 67 | DG14: 7 | DH14: -15 | DI14: 12 | DJ14: =+SUM(DF14:DI14) -> 71 | DK14: 3 | DL14: 25 | DM14: 14 | DN14: -17 | DO14: =+SUM(DK14:DN14) -> 25 | DP14: -10 | DQ14: 24
B15: General and administrative | C15: -2187 | D15: -1993 | E15: -2044 | F15: -2335 | G15: -2389 | H15: -2534 | I15: -2768 | J15: -710 | K15: -824 | L15: -781 | M15: =N15-SUM(J15:L15) -> -766 | N15: -3081 | O15: -1071 | P15: -1057 | Q15: -1172 | R15: =S15-O15-P15-Q15 -> -928 | S15: -4228 | T15: -1081 | U15: -1162 | V15: -834 | W15: =X15-T15-U15-V15 -> -1094 | X15: -4171 | Y15: -828 | Z15: -976 | AA15: -931 | AB15: =AC15-Y15-Z15-AA15 -> -796 | AC15: -3531 | AD15: -775 | AE15: -835 | AF15: -740 | AG15: =AH15-AD15-AE15-AF15 -> -734 | AH15: -3084 | AI15: -791 | AJ15: -925 | AK15: -868 | AL15: -780 | AM15: =SUM(AI15:AL15) -> -3364 | AN15: -953 | AO15: -778 | AP15: -936 | AQ15: -977 | AR15: =SUM(AN15:AQ15) -> -3644 | AS15: -866 | AT15: -870 | AU15: -807 | AV15: =AW15-SUM(AS15:AU15) -> -865 | AW15: -3408 | AX15: -955 | AY15: -903 | AZ15: -916.4 | BA15: -943 | BB15: =SUM(AX15:BA15) -> -3717.4 | BC15: -971 | BD15: -929 | BE15: -956 | BF15: -1100 | BG15: =SUM(BC15:BF15) -> -3956 | BH15: -877 | BI15: -918 | BJ15: -932 | BK15: -1040 | BL15: =SUM(BH15:BK15) -> -3767 | BM15: -945 | BN15: -760 | BO15: -889 | BP15: -931 | BQ15: =SUM(BM15:BP15) -> -3525 | BR15: -888 | BS15: -806 | BT15: -923 | BU15: -999 | BV15: =SUM(BR15:BU15) -> -3616 | BW15: -929 | BX15: -1043 | BY15: -918 | BZ15: -1205 | CA15: =SUM(BW15:BZ15) -> -4095 | CB15: -997 | CC15: -1194 | CD15: -1154 | CE15: -1222 | CF15: =+SUM(CB15:CE15) -> -4567 | CG15: -1184 | CH15: -672 | CI15: -1001 | CJ15: -1052 | CK15: =+SUM(CG15:CJ15) -> -3909 | CL15: -873 | CM15: -1161 | CN15: -955 | CO15: -1828 | CP15: =+SUM(CL15:CO15) -> -4817 | CQ15: -1032 | CR15: -1040 | CS15: -1097 | CT15: -988 | CU15: =+SUM(CQ15:CT15) -> -4157 | CV15: -863 | CW15: -668 | CX15: -1226 | CY15: -1430 | CZ15: =+SUM(CV15:CY15) -> -4187 | DA15: -1304 | DB15: -1286 | DC15: -1043 | DD15: -1535 | DE15: =+SUM(DA15:DD15) -> -5168 | DF15: -1161 | DG15: -1377 | DH15: -1085 | DI15: -1398 | DJ15: =+SUM(DF15:DI15) -> -5021 | DK15: -1112 | DL15: -1793 | DM15: -1522 | DN15: -1663 | DO15: =+SUM(DK15:DN15) -> -6090 | DP15: -1197 | DQ15: -1428
B16: Research and development expense, net | C16: -1924 | D16: -1895 | E16: -1341 | F16: -1441 | G16: -1936 | H16: -1639 | I16: -1651 | J16: -474 | K16: -522 | L16: -469 | M16: =N16-SUM(J16:L16) -> -414 | N16: -1879 | O16: -492 | P16: -591 | Q16: -521 | R16: =S16-O16-P16-Q16 -> -601 | S16: -2205 | T16: -748 | U16: -739 | V16: -833 | W16: =X16-T16-U16-V16 -> -937 | X16: -3257 | Y16: -999 | Z16: -989 | AA16: -869 | AB16: =AC16-Y16-Z16-AA16 -> -993 | AC16: -3850 | AD16: -869 | AE16: -1005 | AF16: -937 | AG16: =AH16-AD16-AE16-AF16 -> -957 | AH16: -3768 | AI16: -970 | AJ16: -960 | AK16: -3574 | AL16: -1002 | AM16: =SUM(AI16:AL16) -> -6506 | AN16: -1000 | AO16: -1001 | AP16: -986 | AQ16: -1134 | AR16: =SUM(AN16:AQ16) -> -4121 | AS16: -1057 | AT16: -1047 | AU16: -901 | AV16: =AW16-SUM(AS16:AU16) -> -913 | AW16: -3918 | AX16: -835 | AY16: -857 | AZ16: -853.4 | BA16: -753 | BB16: =SUM(AX16:BA16) -> -3298.4 | BC16: -705 | BD16: -763 | BE16: -755 | BF16: -848 | BG16: =SUM(BC16:BF16) -> -3071 | BH16: -809 | BI16: -733 | BJ16: -750 | BK16: -755 | BL16: =SUM(BH16:BK16) -> -3047 | BM16: -769 | BN16: -800 | BO16: -857 | BP16: -905 | BQ16: =SUM(BM16:BP16) -> -3331 | BR16: -917 | BS16: -2127 | BT16: -857 | BU16: -726 | BV16: =SUM(BR16:BU16) -> -4627 | BW16: -836 | BX16: -813 | BY16: -768 | BZ16: -762 | CA16: =SUM(BW16:BZ16) -> -3179 | CB16: -764 | CC16: -827 | CD16: -826 | CE16: -852 | CF16: =+SUM(CB16:CE16) -> -3269 | CG16: -866 | CH16: -826 | CI16: -778 | CJ16: -749 | CK16: =+SUM(CG16:CJ16) -> -3219 | CL16: -672 | CM16: -625 | CN16: -574 | CO16: -605 | CP16: =+SUM(CL16:CO16) -> -2476 | CQ16: -499 | CR16: -497 | CS16: -575 | CT16: -678 | CU16: =+SUM(CQ16:CT16) -> -2249 | CV16: -633 | CW16: -698 | CX16: -727 | CY16: -794 | CZ16: =+SUM(CV16:CY16) -> -2852 | DA16: -741 | DB16: -797 | DC16: -958 | DD16: -881 | DE16: =+SUM(DA16:DD16) -> -3377 | DF16: -868 | DG16: -954 | DH16: -1154 | DI16: -836 | DJ16: =+SUM(DF16:DI16) -> -3812 | DK16: -844 | DL16: -910 | DM16: -897 | DN16: -964 | DO16: =+SUM(DK16:DN16) -> -3615 | DP16: -903 | DQ16: -921
B17: Loss on dispositions/business shutdown, net | C17: -1400 | D17: -153 | E17: =87-209 -> -122 | F17: =-557+34-316 -> -839 | G17: =21-378-935 -> -1292 | H17: =44-447+2 -> -401 | I17: =7-456-913+21 -> -1341 | J17: -119 | K17: =6-164-3 -> -161 | L17: =1-166 -> -165 | M17: =N17-SUM(J17:L17) -> -111 | N17: =23+-576-3 -> -556 | O17: 25 | P17: -117 | Q17: 583 | R17: =S17-O17-P17-Q17 -> 29 | S17: 520 | T17: -2 | U17: 6 | V17: -272 | W17: =X17-T17-U17-V17 -> 42 | X17: -226 | Y17: -2 | Z17: 2 | AA17: -22 | AB17: =AC17-Y17-Z17-AA17 -> 60 | AC17: 38 | AE17: 2 | AG17: =AH17-AD17-AE17-AF17 -> 2 | AH17: 4 | AI17: -3 | AJ17: -3 | AK17: -1 | AL17: -17 | AM17: =SUM(AI17:AL17) -> -24 | AN17: -4 | AO17: -1 | AP17: 14 | AQ17: -3 | AR17: =SUM(AN17:AQ17) -> 6 | AS17: 0 | AT17: 20 | AU17: 0 | AV17: =AW17-SUM(AS17:AU17) -> 4 | AW17: 24 | AX17: 0 | AY17: -2 | AZ17: -1 | BA17: 7 | BB17: =SUM(AX17:BA17) -> 4 | BC17: 22 | BD17: 0 | BE17: -1 | BF17: -1 | BG17: =SUM(BC17:BF17) -> 20 | BH17: 0 | BI17: 2 | BJ17: 0 | BK17: -12 | BL17: =SUM(BH17:BK17) -> -10 | BM17: 1 | BN17: 0 | BO17: -1 | BP17: -1 | BQ17: =SUM(BM17:BP17) -> -1 | BR17: 4 | BS17: -13 | BT17: -1 | BU17: 3 | BV17: =SUM(BR17:BU17) -> -7 | BW17: 2 | BX17: -2 | BY17: 0 | BZ17: 21 | CA17: =SUM(BW17:BZ17) -> 21 | CB17: 4 | CC17: 3 | CD17: 69 | CE17: -1 | CF17: =+SUM(CB17:CE17) -> 75 | CG17: 108 | CH17: 192 | CI17: -4 | CJ17: 395 | CK17: =+SUM(CG17:CJ17) -> 691 | CL17: 54 | CM17: 38 | CN17: 108 | CO17: 2 | CP17: =+SUM(CL17:CO17) -> 202 | CQ17: 2 | CR17: 112 | CS17: 169 | CT17: -6 | CU17: =+SUM(CQ17:CT17) -> 277 | CV17: 1 | CW17: 1 | CX17: 0 | CY17: 4 | CZ17: =+SUM(CV17:CY17) -> 6 | DA17: 0 | DB17: 1 | DC17: 0 | DD17: 1 | DE17: =+SUM(DA17:DD17) -> 2 | DG17: 5 | DH17: 0 | DI17: 41 | DJ17: =+SUM(DF17:DI17) -> 46 | DK17: -3 | DL17: 67 | DM17: -1 | DN17: 9609 | DO17: =+SUM(DK17:DN17) -> 9672 | DP17: 12 | DQ17: 67
B18: Earnings from operations | C18: =SUM(C14:C17)+C9+C13 -> -355 | D18: =SUM(D14:D17)+D9+D13 -> 1567 | E18: =SUM(E14:E17)+E9+E13 -> 3170 | F18: =SUM(F14:F17)+F9+F13 -> 3058 | G18: =SUM(G14:G17)+G9+G13 -> 3896 | H18: =SUM(H14:H17)+H9+H13 -> 3868 | I18: =SUM(I14:I17)+I9+I13 -> 449 | J18: =SUM(J14:J17)+J9+J13 -> 838 | ... L18: =SUM(L14:L17)+L9+L13 -> 511 | M18: =N18-SUM(J18:L18) -> 14 | N18: =SUM(N14:N17)+N9+N13 -> 2007 | O18: =SUM(O14:O17)+O9+O13 -> 687 | P18: =SUM(P14:P17)+P9+P13 -> 810 | Q18: =SUM(Q14:Q17)+Q9+Q13 -> 763 | R18: =S18-O18-P18-Q18 -> 552 | S18: =SUM(S14:S17)+S9+S13 -> 2812 | T18: =SUM(T14:T17)+T9+T13 -> 959 | U18: =SUM(U14:U17)+U9+U13 -> 523 | V18: =SUM(V14:V17)+V9+V13 -> 951 | W18: =X18-T18-U18-V18 -> 1152 | X18: =SUM(X14:X17)+X9+X13 -> 3585 | Y18: =SUM(Y14:Y17)+Y9+Y13 -> 1309 | Z18: =SUM(Z14:Z17)+Z9+Z13 -> 1506 | AA18: =SUM(AA14:AA17)+AA9+AA13 -> 1499 | AB18: =AC18-Y18-Z18-AA18 -> 1516 | AC18: =SUM(AC14:AC17)+AC9+AC13 -> 5830 | AD18: =SUM(AD14:AD17)+AD9+AD13 -> 1799 | AE18: =SUM(AE14:AE17)+AE9+AE13 -> 1247 | AF18: =SUM(AF14:AF17)+AF9+AF13 -> 1147 | AG18: =AH18-AD18-AE18-AF18 -> -243 | AH18: =SUM(AH14:AH17)+AH9+AH13 -> 3950 | AI18: =SUM(AI14:AI17)+AI9+AI13 -> 1025 | AJ18: =SUM(AJ14:AJ17)+AJ9+AJ13 -> 1529 | AK18: =SUM(AK14:AK17)+AK9+AK13 -> -2151 | AL18: =SUM(AL14:AL17)+AL9+AL13 -> 1693 | AM18: =SUM(AM14:AM17)+AM9+AM13 -> 2096 | AN18: =SUM(AN14:AN17)+AN9+AN13 -> 1174 | AO18: =SUM(AO14:AO17)+AO9+AO13 -> 1307 | ... CC18: =SUM(CC14:CC17)+CC9+CC13 -> 2710 | CD18: 2227 | CE18: =SUM(CE14:CE17)+CE9+CE13 -> 4175 | CF18: =SUM(CF14:CF17)+CF9+CF13 -> 11987 | CG18: =SUM(CG14:CG17)+CG9+CG13 -> 2350 | CH18: =SUM(CH14:CH17)+CH9+CH13 -> -3380 | CI18: =SUM(CI14:CI17)+CI9+CI13 -> 1259 | CJ18: =SUM(CJ14:CJ17)+CJ9+CJ13 -> -2204 | CK18: =SUM(CK14:CK17)+CK9+CK13 -> -1975 | CL18: =SUM(CL14:CL17)+CL9+CL13 -> -1353 | ... DQ18: =SUM(DQ14:DQ17)+DQ9+DQ13 -> 156
B19: Other income | BW19: 22 | BX19: 27 | BY19: 45 | BZ19: 35 | CA19: =SUM(BW19:BZ19) -> 129
B20: Non-operating pension expense | BW20: 34 | BX20: 28 | BY20: 26 | BZ20: 29 | CA20: =SUM(BW20:BZ20) -> 117
B21: Non-operating postretirement expense | BW21: -30 | BX21: -30 | BY21: -31 | BZ21: -32 | CA21: =SUM(BW21:BZ21) -> -123
B22: Other (loss)/income, non-operating pension net | C22: 428 | D22: 283 | E22: 585 | F22: 386 | G22: 318 | H22: 42 | I22: 459 | J22: 159 | K22: 66 | L22: 17 | M22: =N22-SUM(J22:L22) -> 46 | N22: 288 | O22: -16 | P22: 81 | Q22: 119 | R22: =S22-O22-P22-Q22 -> 117 | S22: 301 | T22: 86 | U22: =106-571 -> -465 | V22: 104 | W22: =X22-T22-U22-V22 -> 124 | X22: =420-571 -> -151 | Y22: 91 | Z22: 125 | AA22: 139 | AB22: =AC22-Y22-Z22-AA22 -> 129 | AC22: 484 | AD22: 100 | AE22: 102 | AF22: 55 | AG22: =AH22-AD22-AE22-AF22 -> -10 | AH22: 247 | AI22: -36 | AJ22: 47 | AK22: -4 | AL22: -33 | AM22: =SUM(AI22:AL22) -> -26 | AN22: -2 | AO22: 35 | AP22: -13 | AQ22: 32 | AR22: =SUM(AN22:AQ22) -> 52 | AS22: 13 | AT22: 14 | AU22: 49 | AV22: =AW22-SUM(AS22:AU22) -> -29 | AW22: 47 | AX22: 12 | AY22: 10 | AZ22: 17 | BA22: 23 | BB22: =SUM(AX22:BA22) -> 62 | BC22: 9 | BD22: 13 | BE22: 19 | BF22: 15 | BG22: =SUM(BC22:BF22) -> 56 | BH22: 9 | BI22: 11 | BJ22: -9 | BK22: -14 | BL22: =SUM(BH22:BK22) -> -3 | BM22: -12 | BN22: 15 | BO22: -26 | BP22: 10 | BQ22: =SUM(BM22:BP22) -> -13 | BR22: 26 | BS22: 13 | BT22: 2 | BU22: -1 | BV22: =SUM(BR22:BU22) -> 40 | BW22: =SUM(BW19:BW21) -> 26 | BX22: =SUM(BX19:BX21) -> 25 | BY22: =SUM(BY19:BY21) -> 40 | BZ22: =SUM(BZ19:BZ21) -> 32 | CA22: 123 | CB22: 66 | CC22: -15 | CD22: 12 | CE22: 29 | CF22: =+SUM(CB22:CE22) -> 92 | CG22: 106 | CH22: 107 | CI22: 121 | CJ22: 104 | CK22: =+SUM(CG22:CJ22) -> 438 | CL22: 112 | CM22: 94 | CN22: 119 | CO22: 122 | CP22: =+SUM(CL22:CO22) -> 447 | CQ22: 190 | CR22: 199 | CS22: 30 | CT22: 132 | CU22: =+SUM(CQ22:CT22) -> 551 | CV22: 181 | CW22: 253 | CX22: 288 | CY22: 336 | CZ22: =+SUM(CV22:CY22) -> 1058 | DA22: 302 | DB22: 320 | DC22: 297 | DD22: 308 | DE22: =+SUM(DA22:DD22) -> 1227 | DF22: 277 | DG22: 248 | DH22: 265 | DI22: 432 | DJ22: =+SUM(DF22:DI22) -> 1222 | DK22: 323 | DL22: 325 | DM22: 276 | DN22: 201 | DO22: =+SUM(DK22:DN22) -> 1125 | DP22: 194 | DQ22: 79
B23: Interest and debt expense | C23: =-513+99 -> -414 | D23: -453 | E23: -431 | F23: -445 | G23: -650 | H23: -730 | I23: -358 | J23: -84 | K23: -85 | L23: -83 | M23: =N23-SUM(J23:L23) -> -83 | N23: -335 | O23: -87 | P23: -84 | Q23: -70 | R23: =S23-O23-P23-Q23 -> -53 | S23: -294 | T23: -69 | U23: -67 | V23: -67 | W23: =X23-T23-U23-V23 -> -37 | X23: -240 | Y23: -46 | Z23: -46 | AA23: -47 | AB23: =AC23-Y23-Z23-AA23 -> -57 | AC23: -196 | AD23: -46 | AE23: -50 | AF23: -49 | AG23: =AH23-AD23-AE23-AF23 -> -57 | AH23: -202 | AI23: -57 | AJ23: -80 | AK23: -92 | AL23: -110 | AM23: =SUM(AI23:AL23) -> -339 | AN23: -122 | AO23: -132 | AP23: -130 | AQ23: -132 | AR23: =SUM(AN23:AQ23) -> -516 | AS23: -130.2 | AT23: -123 | AU23: -121 | AV23: =AW23-SUM(AS23:AU23) -> -123.8 | AW23: -498 | AX23: -119 | AY23: -112 | AZ23: -115.4 | BA23: -117 | BB23: =SUM(AX23:BA23) -> -463.4 | BC23: -99 | BD23: -96 | BE23: -95 | BF23: -96 | BG23: =SUM(BC23:BF23) -> -386 | BH23: -92 | BI23: -81 | BJ23: -79 | BK23: -81 | BL23: =SUM(BH23:BK23) -> -333 | BM23: -61 | BN23: -75 | BO23: -67 | BP23: -72 | BQ23: =SUM(BM23:BP23) -> -275 | BR23: -73 | BS23: -73 | BT23: -81 | BU23: -79 | BV23: =SUM(BR23:BU23) -> -306 | BW23: -87 | BX23: -93 | BY23: -87 | BZ23: -93 | CA23: =SUM(BW23:BZ23) -> -360 | CB23: -102 | CC23: -109 | CD23: -106 | CE23: -158 | CF23: =+SUM(CB23:CE23) -> -475 | CG23: -123 | CH23: -154 | CI23: -203 | CJ23: -242 | CK23: =+SUM(CG23:CJ23) -> -722 | CL23: -262 | CM23: -553 | CN23: -643 | CO23: -698 | CP23: =+SUM(CL23:CO23) -> -2156 | CQ23: -679 | CR23: -673 | CS23: -669 | CT23: -661 | CU23: =+SUM(CQ23:CT23) -> -2682 | CV23: -630 | CW23: -650 | CX23: -621 | CY23: -632 | CZ23: =+SUM(CV23:CY23) -> -2533 | DA23: -649 | DB23: -621 | DC23: -589 | DD23: -600 | DE23: =+SUM(DA23:DD23) -> -2459 | DF23: -569 | DG23: -673 | DH23: -728 | DI23: -755 | DJ23: =+SUM(DF23:DI23) -> -2725 | DK23: -708 | DL23: -710 | DM23: -694 | DN23: -659 | DO23: =+SUM(DK23:DN23) -> -2771 | DP23: -616 | DQ23: -600
B24: Earnings before income taxes | C24: =C23+C22+C18 -> -341 | D24: =D23+D22+D18 -> 1397 | E24: =E23+E22+E18 -> 3324 | F24: =F23+F22+F18 -> 2999 | G24: =G23+G22+G18 -> 3564 | H24: =H23+H22+H18 -> 3180 | I24: =I23+I22+I18 -> 550 | J24: =J23+J22+J18 -> 913 | ... L24: =L23+L22+L18 -> 445 | M24: =N24-SUM(J24:L24) -> -23 | N24: =N23+N22+N18 -> 1960 | O24: =O23+O22+O18 -> 584 | P24: =P23+P22+P18 -> 807 | Q24: =Q23+Q22+Q18 -> 812 | R24: =S24-O24-P24-Q24 -> 616 | S24: =S23+S22+S18 -> 2819 | T24: =T23+T22+T18 -> 976 | U24: =U23+U22+U18 -> -9 | V24: =V23+V22+V18 -> 988 | W24: =X24-T24-U24-V24 -> 1239 | X24: =X23+X22+X18 -> 3194 | Y24: =Y23+Y22+Y18 -> 1354 | Z24: =Z23+Z22+Z18 -> 1585 | AA24: =AA23+AA22+AA18 -> 1591 | AB24: =AC24-Y24-Z24-AA24 -> 1588 | AC24: =AC23+AC22+AC18 -> 6118 | AD24: =AD23+AD22+AD18 -> 1853 | AE24: =AE23+AE22+AE18 -> 1299 | AF24: =AF23+AF22+AF18 -> 1153 | AG24: =AH24-AD24-AE24-AF24 -> -310 | AH24: =AH18+AH22+AH23 -> 3995 | AI24: =AI18+AI22+AI23 -> 932 | AJ24: =AJ18+AJ22+AJ23 -> 1496 | AK24: =AK18+AK22+AK23 -> -2247 | AL24: =AL18+AL22+AL23 -> 1550 | AM24: =AM18+AM22+AM23 -> 1731 | AN24: =AN18+AN22+AN23 -> 1050 | AO24: =AO18+AO22+AO23 -> 1210 | ... DQ24: =DQ18+DQ22+DQ23 -> -365
B25: Income tax expense | C25: 163 | D25: -277 | E25: -1015 | F25: -871 | G25: -738 | H25: -861 | I25: 168 | J25: -290 | K25: -39 | L25: -7 | M25: =N25-SUM(J25:L25) -> 196 | N25: -140 | O25: -70 | P25: -241 | Q25: 201 | R25: =S25-O25-P25-Q25 -> -147 | S25: -257 | T25: -284 | U25: -151 | V25: -294 | W25: =X25-T25-U25-V25 -> -259 | X25: -988 | Y25: -481 | Z25: -536 | AA25: -482 | AB25: =AC25-Y25-Z25-AA25 -> -561 | AC25: -2060 | AD25: -647 | AE25: -448 | AF25: -470 | AG25: =AH25-AD25-AE25-AF25 -> 224 | AH25: -1341 | AI25: -317 | AJ25: -499 | AK25: 687 | AL25: -267 | AM25: =SUM(AI25:AL25) -> -396 | AN25: -531 | AO25: -421 | AP25: -407 | AQ25: 163 | AR25: =SUM(AN25:AQ25) -> -1196 | AS25: -295 | AT25: -483 | AU25: -548 | AV25: =AW25-SUM(AS25:AU25) -> -56 | AW25: -1382 | AX25: -539 | AY25: -479 | AZ25: -432.4 | BA25: -557 | BB25: =SUM(AX25:BA25) -> -2007.4 | BC25: -332 | BD25: -546 | BE25: -567 | BF25: -201 | BG25: =SUM(BC25:BF25) -> -1646 | BH25: -494 | BI25: -64 | BJ25: -669 | BK25: -464 | BL25: =SUM(BH25:BK25) -> -1691 | BM25: -610 | BN25: -513 | BO25: -783 | BP25: -73 | BQ25: =SUM(BM25:BP25) -> -1979 | BR25: -522 | BS25: 245 | BT25: 76 | BU25: -472 | BV25: =SUM(BR25:BU25) -> -673 | BW25: -566 | BX25: -713 | BY25: -773 | BZ25: 403 | CA25: -1649 | CB25: -362 | CC25: -390 | CD25: 230 | CE25: -622 | CF25: =+SUM(CB25:CE25) -> -1144 | CG25: -184 | CH25: 485 | CI25: -10 | CJ25: 1332 | CK25: =+SUM(CG25:CJ25) -> 1623 | CL25: 862 | CM25: 1028 | CN25: 459 | CO25: 186 | CP25: =+SUM(CL25:CO25) -> 2535 | CQ25: 11 | CR25: 18 | CS25: 178 | CT25: 536 | CU25: =+SUM(CQ25:CT25) -> 743 | CV25: 376 | CW25: -217 | CX25: -176 | CY25: -14 | CZ25: =+SUM(CV25:CY25) -> -31 | DA25: 71 | DB25: 251 | DC25: -538 | DD25: -21 | DE25: =+SUM(DA25:DD25) -> -237 | DF25: 23 | DG25: 76 | DH25: 50 | DI25: 232 | DJ25: =+SUM(DF25:DI25) -> 381 | DK25: -107 | DL25: -51 | DM25: -140 | DN25: -99 | DO25: =+SUM(DK25:DN25) -> -397 | DP25: -33 | DQ25: -63
B26: NCI | CL26: 13 | CM26: 19 | CN26: 17 | CO26: 19 | CP26: =+SUM(CL26:CO26) -> 68 | CQ26: 24 | CR26: 20 | CS26: 23 | CT26: 21 | CV26: 23 | CW26: 33 | CX26: 33 | CY26: 29 | DA26: 11 | DB26: 0 | DC26: 2 | DD26: 7 | DF26: 12 | DG26: 0 | DH26: 4 | DI26: 4 | DK26: -6 | DL26: 1 | DM26: 2 | DN26: 0 | DP26: 3 | DQ26: -16
B27: Net income, continuing ops. | C27: =C24+C25 -> -178 | D27: =D24+D25 -> 1120 | E27: =E24+E25 -> 2309 | F27: =F24+F25 -> 2128 | G27: =G24+G25 -> 2826 | H27: =H24+H25 -> 2319 | I27: =I24+I25 -> 718 | J27: =J24+J25 -> 623 | ... L27: =L24+L25 -> 438 | M27: =N27-SUM(J27:L27) -> 173 | N27: =N24+N25 -> 1820 | O27: =O24+O25 -> 514 | P27: =P24+P25 -> 566 | Q27: =Q24+Q25 -> 1013 | R27: =S27-O27-P27-Q27 -> 469 | S27: =S24+S25 -> 2562 | T27: =T24+T25 -> 692 | U27: =U24+U25 -> -160 | V27: =V24+V25 -> 694 | W27: =X27-T27-U27-V27 -> 980 | X27: =X24+X25 -> 2206 | Y27: =Y24+Y25 -> 873 | Z27: =Z24+Z25 -> 1049 | AA27: =AA24+AA25 -> 1109 | AB27: =AC27-Y27-Z27-AA27 -> 1027 | AC27: =AC24+AC25 -> 4058 | AD27: =AD24+AD25 -> 1206 | AE27: =AE24+AE25 -> 851 | AF27: =AF24+AF25 -> 683 | AG27: =AH27-AD27-AE27-AF27 -> -86 | AH27: =AH24+AH25 -> 2654 | AI27: =AI24+AI25 -> 615 | AJ27: =AJ24+AJ25 -> 997 | AK27: =AK24+AK25 -> -1560 | AL27: =AL24+AL25 -> 1283 | AM27: =AM24+AM25 -> 1335 | AN27: =AN24+AN25 -> 519 | AO27: =AO24+AO25 -> 789 | ... CK27: =CK24+CK25 -> -636 | CL27: =CL24+CL25+CL26 -> -628 | CM27: =CM24+CM25+CM26 -> -2376 | CN27: =CN24+CN25+CN26 -> -449 | CO27: =CO24+CO25+CO26 -> -8420 | CP27: =CP24+CP25+CP26 -> -11873 | CQ27: =CQ24+CQ25+CQ26 -> -537 | CR27: =CR24+CR25+CR26 -> 587 | CS27: =CS24+CS25+CS26 -> -109 | CT27: =CT24+CT25+CT26 -> -4143 | CU27: =CU24+CU25 -> -4290 | CV27: =CV24+CV25+CV26 -> -1219 | CW27: =CW24+CW25+CW26 -> 193 | CX27: =CX24+CX25+CX26 -> -3275 | CY27: =CY24+CY25+CY26 -> -634 | CZ27: =CZ24+CZ25 -> -5053 | DA27: =DA24+DA25+DA26 -> -414 | DB27: =DB24+DB25+DB26 -> -149 | DC27: =DC24+DC25+DC26 -> -1636 | DD27: =DD24+DD25+DD26 -> -23 | DE27: =DE24+DE25 -> -2242 | DF27: =DF24+DF25+DF26 -> -343 | DG27: =DG24+DG25+DG26 -> -1439 | DH27: =DH24+DH25+DH26 -> -6170 | DI27: =DI24+DI25+DI26 -> -3857 | DJ27: =DJ24+DJ25 -> -11829 | DK27: =DK24+DK25+DK26 -> -37 | DL27: =DL24+DL25+DL26 -> -611 | DM27: =DM24+DM25+DM26 -> -5337 | DN27: =DN24+DN25+DN26 -> 8220 | DO27: =DO24+DO25 -> 2238 | DP27: =DP24+DP25+DP26 -> -4 | DQ27: =DQ24+DQ25+DQ26 -> -444
B28: Discontinued ops. & non recurring items | C28: 0 | D28: 0 | E28: 0 | F28: 0 | G28: 1 | H28: -1827 | I28: 0 | J28: 0 | K28: =7+14 -> 21 | L28: =-1+19 -> 18 | M28: =N28-SUM(J28:L28) -> 13 | N28: =52 -> 52 | O28: 21 | Q28: -2 | R28: =S28-O28-P28-Q28 -> -9 | S28: =-7+17 -> 10 | W28: =X28-T28-U28-V28 -> 9 | X28: 9 | Y28: 4 | Z28: 1 | AA28: 5 | AB28: =AC28-Y28-Z28-AA28 -> 6 | AC28: 16 | AD28: 5 | AE28: 1 | AF28: 12 | AG28: =AH28-AD28-AE28-AF28 -> 0 | AH28: 18 | AI28: -5 | AJ28: 1 | AK28: -4 | AL28: -15 | AM28: =SUM(AI28:AL28) -> -23 | AN28: 0 | AO28: -2 | AP28: 0 | AQ28: -2 | AR28: =SUM(AN28:AQ28) -> -4 | AS28: -2 | AT28: -1 | AU28: 4 | AV28: =AW28-SUM(AS28:AU28) -> 6 | AW28: 7 | AX28: -1 | AY28: 0 | BB28: =SUM(AX28:BA28) -> -1 | BC28: 0 | BD28: 1 | BE28: -2 | BF28: 0 | BG28: =SUM(BC28:BF28) -> -1 | BH28: 0 | BI28: 0 | BJ28: 0 | BK28: 0 | BL28: =SUM(BH28:BK28) -> 0 | BM28: 0 | BN28: 0 | BO28: 0 | BP28: 0 | BQ28: =SUM(BM28:BP28) -> 0 | BR28: 0 | BS28: 0 | BT28: 0 | BU28: 0 | BV28: =SUM(BR28:BU28) -> 0 | BW28: 0 | BX28: 0 | BY28: 0 | BZ28: 0 | CA28: =SUM(BW28:BZ28) -> 0 | CB28: 0 | CC28: 0 | CD28: 0 | CE28: 0 | CF28: =SUM(CB28:CE28) -> 0 | CG28: 0 | CK28: =SUM(CG28:CJ28) -> 0 | CP28: =SUM(CL28:CO28) -> 0 | CU28: =SUM(CQ28:CT28) -> 0 | CZ28: =SUM(CV28:CY28) -> 0 | DE28: =SUM(DA28:DD28) -> 0 | DI28: -58 | DJ28: =SUM(DF28:DI28) -> -58 | DK28: -86 | DL28: -86 | DM28: -87 | DN28: -86 | DO28: =SUM(DK28:DN28) -> -345 | DP28: -86 | DQ28: -86
B29: Net income reported | C29: =SUM(C27:C28) -> -178 | D29: =SUM(D27:D28) -> 1120 | E29: =SUM(E27:E28) -> 2309 | F29: =SUM(F27:F28) -> 2128 | G29: =SUM(G27:G28) -> 2827 | H29: =SUM(H27:H28) -> 492 | I29: =SUM(I27:I28) -> 718 | J29: =SUM(J27:J28) -> 623 | ... L29: =SUM(L27:L28) -> 456 | M29: =N29-SUM(J29:L29) -> 186 | N29: =SUM(N27:N28) -> 1872 | O29: =SUM(O27:O28) -> 535 | P29: =SUM(P27:P28) -> 566 | Q29: =SUM(Q27:Q28) -> 1011 | R29: =S29-O29-P29-Q29 -> 460 | S29: =SUM(S27:S28) -> 2572 | T29: =SUM(T27:T28) -> 692 | U29: =SUM(U27:U28) -> -160 | V29: =SUM(V27:V28) -> 694 | W29: =X29-T29-U29-V29 -> 989 | X29: =SUM(X27:X28) -> 2215 | Y29: =SUM(Y27:Y28) -> 877 | Z29: =SUM(Z27:Z28) -> 1050 | AA29: =SUM(AA27:AA28) -> 1114 | AB29: =AC29-Y29-Z29-AA29 -> 1033 | AC29: =SUM(AC27:AC28) -> 4074 | AD29: =SUM(AD27:AD28) -> 1211 | AE29: =SUM(AE27:AE28) -> 852 | AF29: =SUM(AF27:AF28) -> 695 | AG29: =AH29-AD29-AE29-AF29 -> -86 | AH29: =SUM(AH27:AH28) -> 2672 | AI29: =SUM(AI27:AI28) -> 610 | AJ29: =SUM(AJ27:AJ28) -> 998 | AK29: =SUM(AK27:AK28) -> -1564 | AL29: =SUM(AL27:AL28) -> 1268 | AM29: =SUM(AM27:AM28) -> 1312 | AN29: =SUM(AN27:AN28) -> 519 | AO29: =SUM(AO27:AO28) -> 787 | ... CE29: =SUM(CE27:CE28) -> 3424 | CF29: =+SUM(CB29:CE29) -> 10460 | CG29: =SUM(CG27:CG28) -> 2149 | CH29: =SUM(CH27:CH28) -> -2942 | CI29: =SUM(CI27:CI28) -> 1167 | CJ29: =SUM(CJ27:CJ28) -> -1010 | CK29: =+SUM(CG29:CJ29) -> -636 | CL29: =SUM(CL27:CL28) -> -628 | CM29: =SUM(CM27:CM28) -> -2376 | CN29: =SUM(CN27:CN28) -> -449 | CO29: =SUM(CO27:CO28) -> -8420 | CP29: =+SUM(CL29:CO29) -> -11873 | CQ29: =SUM(CQ27:CQ28) -> -537 | CR29: =SUM(CR27:CR28) -> 587 | CS29: =SUM(CS27:CS28) -> -109 | CT29: =SUM(CT27:CT28) -> -4143 | CU29: =+SUM(CQ29:CT29) -> -4202 | CV29: =SUM(CV27:CV28) -> -1219 | CW29: =SUM(CW27:CW28) -> 193 | CX29: =SUM(CX27:CX28) -> -3275 | CY29: =SUM(CY27:CY28) -> -634 | CZ29: =+SUM(CV29:CY29) -> -4935 | DA29: =SUM(DA27:DA28) -> -414 | DB29: =SUM(DB27:DB28) -> -149 | DC29: =SUM(DC27:DC28) -> -1636 | DD29: =SUM(DD27:DD28) -> -23 | DE29: =+SUM(DA29:DD29) -> -2222 | DF29: =SUM(DF27:DF28) -> -343 | DG29: =SUM(DG27:DG28) -> -1439 | DH29: =SUM(DH27:DH28) -> -6170 | DI29: =SUM(DI27:DI28) -> -3915 | DJ29: =+SUM(DF29:DI29) -> -11867 | DK29: =SUM(DK27:DK28) -> -123 | DL29: =SUM(DL27:DL28) -> -697 | DM29: =SUM(DM27:DM28) -> -5424 | DN29: =SUM(DN27:DN28) -> 8134 | DO29: =+SUM(DK29:DN29) -> 1890 | DP29: =SUM(DP27:DP28) -> -90 | DQ29: =SUM(DQ27:DQ28) -> -530
B31: Basic EPS, continuing ops. | C31: =C27/C40 -> -0.18348624 | D31: =D27/D40 -> 1.1467185 | E31: =E27/E40 -> 2.5177189 | F31: =F27/F40 -> 2.4758581 | G31: =G27/G40 -> 3.4623867 | H31: =H27/H40 -> 2.902378 | I31: =I27/I40 -> 0.89738783 | J31: =J27/J40 -> 0.77758362 | ... BY31: =BY27/BY40 -> 3.0252382 | CB31: =CB27/CB40 -> 4.1926202 | CC31: =CC27/CC40 -> 3.76931 | CD31: =CD27/CD40 -> 4.1109951 | CG31: =CG27/CG40 -> 3.7854501 | CH31: =CH27/CH40 -> -5.2098459 | CI31: =CI27/CI40 -> 2.0647558 | CL31: =CL27/CL40 -> -1.1097367 | CM31: =CM27/CM40 -> #DIV/0! | CN31: =CN27/CN40 -> -0.79244617 | CO31: =CO27/CO40 -> #DIV/0! | CQ31: =CQ27/CQ40 -> -0.91732149 | CR31: =CR27/CR40 -> 0.99457811 | CS31: =CS27/CS40 -> -0.18505942 | CT31: =CT27/CT40 -> -7.0184652 | CV31: =CV27/CV40 -> -2.0601656 | CW31: =CW27/CW40 -> 0.32360832 | CX31: =CX27/CX40 -> -5.4922019 | CY31: =CY27/CY40 -> -1.0586074 | DA31: =DA27/DA40 -> -0.68713693 | DB31: =DB27/DB40 -> -0.24607762 | DC31: =DC27/DC40 -> -2.6943347 | DD31: =DD27/DD40 -> -0.037947533 | DF31: =DF27/DF40 -> -0.55936073 | DG31: =DG27/DG40 -> -2.3337658 | DH31: =DH27/DH40 -> -9.9709114 | DI31: =DI27/DI40 -> -5.3711182 | DK31: =DK27/DK40 -> -0.049110698 | DL31: =DL27/DL40 -> -0.80756014 | DM31: =DM27/DM40 -> -7.0232925 | DN31: =DN27/DN40 -> 10.703125 | DP31: =DP27/DP40 -> -0.0050761421 | DQ31: =DQ27/DQ40 -> -0.56159879
B32: Discontinued ops. & non recurring items | C32: =C28/C40 -> 0 | D32: =D28/D40 -> 0 | E32: =E28/E40 -> 0 | F32: =F28/F40 -> 0 | G32: =G28/G40 -> 0.0012251899 | H32: =H28/H40 -> -2.2866083 | I32: =I28/I40 -> 0 | J32: =J28/J40 -> 0 | ... BY32: =BY28/BY40 -> 0 | CB32: =CB28/CB40 -> 0 | CC32: =CC28/CC40 -> 0 | CD32: =CD28/CD40 -> 0 | CG32: =CG28/CG40 -> 0 | CH32: =CH28/CH40 -> 0 | CI32: =CI28/CI40 -> 0 | CL32: =CL28/CL40 -> 0 | CM32: =CM28/CM40 -> #DIV/0! | CN32: =CN28/CN40 -> 0 | CO32: =CO28/CO40 -> #DIV/0! | CQ32: =CQ28/CQ40 -> 0 | CR32: =CR28/CR40 -> 0 | CS32: =CS28/CS40 -> 0 | CT32: =CT28/CT40 -> 0 | CV32: =CV28/CV40 -> 0 | CW32: =CW28/CW40 -> 0 | CX32: =CX28/CX40 -> 0 | CY32: =CY28/CY40 -> 0 | DA32: =DA28/DA40 -> 0 | DB32: =DB28/DB40 -> 0 | DC32: =DC28/DC40 -> 0 | DD32: =DD28/DD40 -> 0 | DF32: =DF28/DF40 -> 0 | DG32: =DG28/DG40 -> 0 | DH32: =DH28/DH40 -> 0 | DI32: =DI28/DI40-0.01 -> -0.090768695 | DK32: =DK28/DK40 -> -0.11414919 | DL32: =DL28/DL40 -> -0.1136664 | DM32: =DM28/DM40 -> -0.11448875 | DN32: =DN28/DN40 -> -0.11197917 | DP32: =DP28/DP40 -> -0.10913706 | DQ32: =DQ28/DQ40 -> -0.10877814
B33: Basic EPS, reported | C33: =SUM(C31:C32) -> -0.18348624 | D33: =SUM(D31:D32) -> 1.1467185 | E33: =SUM(E31:E32) -> 2.5177189 | F33: =SUM(F31:F32) -> 2.4758581 | G33: =SUM(G31:G32) -> 3.4636119 | H33: =SUM(H31:H32) -> 0.61576971 | I33: =SUM(I31:I32) -> 0.89738783 | J33: =SUM(J31:J32) -> 0.77758362 | ... BY33: =SUM(BY31:BY32) -> 3.0252382 | CB33: =SUM(CB31:CB32) -> 4.1926202 | CC33: =SUM(CC31:CC32) -> 3.76931 | CD33: =SUM(CD31:CD32) -> 4.1109951 | CG33: =SUM(CG31:CG32) -> 3.7854501 | CH33: =SUM(CH31:CH32) -> -5.2098459 | CI33: =SUM(CI31:CI32) -> 2.0647558 | CL33: =SUM(CL31:CL32) -> -1.1097367 | CM33: =SUM(CM31:CM32) -> #DIV/0! | CN33: =SUM(CN31:CN32) -> -0.79244617 | CO33: =SUM(CO31:CO32) -> #DIV/0! | CQ33: =SUM(CQ31:CQ32) -> -0.91732149 | CR33: =SUM(CR31:CR32) -> 0.99457811 | CS33: =SUM(CS31:CS32) -> -0.18505942 | CT33: =SUM(CT31:CT32) -> -7.0184652 | CV33: =SUM(CV31:CV32) -> -2.0601656 | CW33: =SUM(CW31:CW32) -> 0.32360832 | CX33: =SUM(CX31:CX32) -> -5.4922019 | CY33: =SUM(CY31:CY32) -> -1.0586074 | DA33: =SUM(DA31:DA32) -> -0.68713693 | DB33: =SUM(DB31:DB32) -> -0.24607762 | DC33: =SUM(DC31:DC32) -> -2.6943347 | DD33: =SUM(DD31:DD32) -> -0.037947533 | DF33: =SUM(DF31:DF32) -> -0.55936073 | DG33: =SUM(DG31:DG32) -> -2.3337658 | DH33: =SUM(DH31:DH32) -> -9.9709114 | DI33: =SUM(DI31:DI32) -> -5.4618869 | DK33: =SUM(DK31:DK32) -> -0.16325989 | DL33: =SUM(DL31:DL32) -> -0.92122654 | DM33: =SUM(DM31:DM32) -> -7.1377813 | DN33: =SUM(DN31:DN32) -> 10.591146 | DP33: =SUM(DP31:DP32) -> -0.1142132 | DQ33: =SUM(DQ31:DQ32) -> -0.67037693
B35: Diluted EPS | C35: =C27/C41 -> -0.18348624 | D35: =D27/D41 -> 1.1583411 | E35: =E27/E41 -> 2.4937898 | F35: =F27/F41 -> 2.4423276 | G35: =G27/G41 -> 3.4076932 | H35: =H27/H41 -> 2.8686294 | I35: =I27/I41 -> 0.88762517 | J35: =J27/J41 -> 0.76828216 | ... CY35: =CY27/CY41 -> -1.0586074 | DA35: =DA27/DA41 -> -0.68713693 | DB35: =DB27/DB41 -> -0.24607762 | DC35: =DC27/DC41 -> -2.6943347 | DD35: =DD27/DD41 -> -0.037947533 | DF35: =DF27/DF41 -> -0.55936073 | DG35: =DG27/DG41 -> -2.3337658 | DH35: =DH27/DH41 -> -9.9709114 | DI35: =DI27/DI41 -> -5.3711182 | DK35: =DK27/DK41 -> -0.049110698 | DL35: =DL27/DL41 -> -0.80756014 | DM35: =DM27/DM41 -> -7.0232925 | DN35: =DN27/DN41 -> 10.339623 | DP35: =DP27/DP41 -> -0.0050761421 | DQ35: =DQ27/DQ41 -> -0.56159879
B36: Discontinued ops. & non recurring items | C36: =C28/C41 -> 0 | D36: =D28/D41 -> 0 | E36: =E28/E41 -> 0 | F36: =F28/F41 -> 0 | G36: =G28/G41 -> 0.0012058362 | H36: =H28/H41 -> -2.2600198 | I36: =I28/I41 -> 0 | J36: =J28/J41 -> 0 | ... CY36: =CY28/CY41 -> 0 | DA36: =DA28/DA41 -> 0 | DB36: =DB28/DB41 -> 0 | DC36: =DC28/DC41 -> 0 | DD36: =DD28/DD41 -> 0 | DF36: =DF28/DF41 -> 0 | DG36: =DG28/DG41 -> 0 | DH36: =DH28/DH41 -> 0 | DI36: =DI28/DI41-0.01 -> -0.090768695 | DK36: =DK28/DK41 -> -0.11414919 | DL36: =DL28/DL41 -> -0.1136664 | DM36: =DM28/DM41 -> -0.11448875 | DN36: =DN28/DN41 -> -0.1081761 | DP36: =DP28/DP41 -> -0.10913706 | DQ36: =DQ28/DQ41 -> -0.10877814
B37: Diluted EPS, reported | C37: =SUM(C35:C36) -> -0.18348624 | D37: =SUM(D35:D36) -> 1.1583411 | E37: =SUM(E35:E36) -> 2.4937898 | F37: =SUM(F35:F36) -> 2.4423276 | G37: =SUM(G35:G36) -> 3.4088991 | H37: =SUM(H35:H36) -> 0.6086096 | I37: =SUM(I35:I36) -> 0.88762517 | J37: =SUM(J35:J36) -> 0.76828216 | ... CY37: =SUM(CY35:CY36) -> -1.0586074 | DA37: =SUM(DA35:DA36) -> -0.68713693 | DB37: =SUM(DB35:DB36) -> -0.24607762 | DC37: =SUM(DC35:DC36) -> -2.6943347 | DD37: =SUM(DD35:DD36) -> -0.037947533 | DF37: =SUM(DF35:DF36) -> -0.55936073 | DG37: =SUM(DG35:DG36) -> -2.3337658 | DH37: =SUM(DH35:DH36) -> -9.9709114 | DI37: =SUM(DI35:DI36) -> -5.4618869 | DK37: =SUM(DK35:DK36) -> -0.16325989 | DL37: =SUM(DL35:DL36) -> -0.92122654 | DM37: =SUM(DM35:DM36) -> -7.1377813 | DN37: =SUM(DN35:DN36) -> 10.231447 | DP37: =SUM(DP35:DP36) -> -0.1142132 | DQ37: =SUM(DQ35:DQ36) -> -0.67037693
B39: Common shares outstanding
B40: Basic | C40: 970.1 | D40: 976.7 | E40: 917.1 | F40: 859.5 | G40: 816.2 | H40: 799 | I40: 800.1 | J40: 801.2 | K40: 807.8 | L40: 808.2 | M40: =N40*4-J40-K40-L40 -> 810.8 | N40: 807 | O40: 798.4 | P40: 793.3 | Q40: 787.3 | R40: =S40*4-O40-P40-Q40 -> 775 | S40: 788.5 | T40: 770.5 | U40: 761.3 | V40: 773 | W40: =X40*4-T40-U40-V40 -> 779.2 | X40: 771 | Y40: 765.4 | Z40: 763.5 | AA40: 759.3 | AB40: =AC40*4-Y40-Z40-AA40 -> 749 | AC40: 759.3 | AD40: 738 | AE40: 725.5 | AF40: 717.5 | AG40: =AH40*4-AD40-AE40-AF40 -> 709.4 | AH40: 722.6 | AI40: 705.3 | AJ40: 705.2 | AK40: 701.3 | AL40: 716.661 | AM40: 709.6 | AN40: 734.8 | AO40: 737.2 | AP40: 739.1 | AQ40: 742.67516 | AR40: 738.1 | AS40: 742.9 | AT40: 745.5 | AU40: 748 | AV40: 749.83784 | AW40: 746.6 | AX40: 752.5 | AY40: 755.9 | AZ40: 756.6 | BA40: 757.8 | BB40: 755.7 | BC40: 762.8 | BD40: 763.3 | BE40: 759.4 | BF40: =BF29/1.63 -> 756.68712 | BG40: 760.8 | BH40: 745 | BI40: 731.1 | BJ40: 722.8 | BK40: 711.5 | BL40: 727.6 | BM40: 705.7 | BN40: 691.2 | BO40: 681.3 | BP40: =BO40-BO41+BP41 -> 673.5 | BQ40: 688 | BR40: 659.6 | BS40: 636.3 | BT40: 625.5 | BU40: =BT40-BT41+BU41 -> 623.1 | BV40: 636.5 | BW40: 614.4 | BX40: 602.5 | BY40: 598.3 | CB40: 590.8 | CC40: 582.6 | CD40: 574.8 | CG40: 567.7 | CH40: 564.7 | CI40: 565.2 | CL40: 565.9 | CN40: 566.6 | CP40: 568.6 | CQ40: 585.4 | CR40: 590.2 | CS40: 589 | CT40: 590.3 | CU40: 587.6 | CV40: 591.7 | CW40: 596.4 | CX40: 596.3 | CY40: 598.9 | DA40: 602.5 | DB40: 605.5 | DC40: 607.2 | DD40: 606.1 | DF40: 613.2 | DG40: 616.6 | DH40: 618.8 | DI40: 718.1 | DK40: 753.4 | DL40: 756.6 | DM40: 759.9 | DN40: 768 | DP40: 788 | DQ40: 790.6
B41: Diluted | C41: 970.1 | D41: 966.9 | E41: 925.9 | F41: 871.3 | G41: 829.3 | H41: 808.4 | I41: 808.9 | J41: 810.9 | K41: 812.3 | L41: 814.8 | M41: =N41*4-J41-K41-L41 -> 814 | N41: 813 | O41: 806.8 | P41: 807.4 | Q41: 802.8 | R41: =S41*4-O41-P41-Q41 -> 794.6 | S41: 802.9 | T41: 791.8 | U41: 761.3 | V41: 784 | W41: =X41*4-T41-U41-V41 -> 813.3 | X41: 787.6 | Y41: 777.4 | Z41: 777 | AA41: 773.4 | AB41: =AC41*4-Y41-Z41-AA41 -> 762.2 | AC41: 772.5 | AD41: 747.4 | AE41: 732.8 | AF41: 721.9 | AG41: =AH41*4-AD41-AE41-AF41 -> 713.9 | AH41: 729 | AI41: 707.4 | AJ41: 707.8 | AK41: 701.3 | AL41: 723.9 | AM41: 713.4 | AN41: 740.1 | AO41: 742.9 | AP41: 744.6 | AQ41: 747 | AR41: 744.3 | AS41: 749 | AT41: 752.6 | AU41: 753.9 | AV41: 757.1 | AW41: 753.1 | AX41: 759.6 | AY41: 762 | AZ41: 765.2 | BA41: 766.3 | BB41: 763.8 | BC41: 768.7 | BD41: 771.8 | BE41: 769.1 | BF41: 768.4 | BG41: 769.5 | BH41: 754.1 | BI41: 740.1 | BJ41: 731.9 | BK41: 724.8 | BL41: 738 | BM41: 714.2 | BN41: 698.9 | BO41: 689 | BP41: 681.2 | BQ41: 696.1 | BR41: 665.8 | BS41: 636.3 | BT41: 632.7 | BU41: 630.3 | BV41: 643.8 | BW41: 621.2 | BX41: 609.6 | BY41: 606.3 | BZ41: 605.1 | CA41: 610.7 | CB41: 597.2 | CC41: 588.7 | CD41: 580.8 | CE41: 577.5 | CF41: 586.15 | CG41: 572.4 | CH41: 565.3 | CI41: 569.2 | CJ41: 565.4 | CK41: 565.4 | CL41: 565.9 | CM41: 566.4 | CN41: 566.6 | CO41: 575.4 | CP41: 568.6 | CQ41: 585.4 | CR41: 590.2 | CS41: 589 | CT41: 590.3 | CU41: 587.6 | CV41: 591.7 | CW41: 596.4 | CX41: 596.3 | CY41: 598.9 | DA41: 602.5 | DB41: 605.5 | DC41: 607.2 | DD41: 606.1 | DF41: 613.2 | DG41: 616.6 | DH41: 618.8 | DI41: 718.1 | DK41: 753.4 | DL41: 756.6 | DM41: 759.9 | DN41: 795 | DP41: 788 | DQ41: 790.6
C43: =IF(ROUND(C35,2)=ROUND((C27/C41),2),"","check") | D43: =IF(ROUND(D35,2)=ROUND((D27/D41),2),"","check") | E43: =IF(ROUND(E35,2)=ROUND((E27/E41),2),"","check") | F43: =IF(ROUND(F35,2)=ROUND((F27/F41),2),"","check") | G43: =IF(ROUND(G35,2)=ROUND((G27/G41),2),"","check") | H43: =IF(ROUND(H35,2)=ROUND((H27/H41),2),"","check") | I43: =IF(ROUND(I35,2)=ROUND((I27/I41),2),"","check") | J43: =IF(ROUND(J35,2)=ROUND((J27/J41),2),"","check") | ... AK43: =IF(ROUND(AK35,2)=ROUND((AK27/AK41),2),"","check")
B45: Balance Sheet
B46: Assets
B47: Cash and cash equivalents | C47: 4420 | D47: 2183 | E47: 3354 | F47: 1010 | G47: 633 | H47: 2333 | I47: 4633 | J47: 3950 | K47: 6184 | L47: 4312 | M47: =N47 -> 3204 | N47: 3204 | O47: 3330 | P47: 4961 | Q47: 4547 | R47: =S47 -> 5412 | S47: 5412 | T47: 6781 | U47: 7567 | V47: 5198 | W47: =X47 -> 6118 | X47: 6118 | Y47: 4836 | Z47: 7156 | AA47: 8948 | AB47: =AC47 -> 7042 | AC47: 7042 | AD47: 7707 | AE47: 5619 | AF47: 4186 | AG47: =AH47 -> 3268 | AH47: 3268 | AI47: 4237 | AJ47: 4599 | AK47: 6095 | AL47: 9215 | AM47: =AL47 -> 9215 | AN47: 4517 | AO47: 4468 | AP47: 2864 | AQ47: 5359 | AR47: =AQ47 -> 5359 | AS47: 5670 | AT47: 5050 | AU47: 5954 | AV47: 10049 | AW47: =AV47 -> 10049 | AX47: 6718 | AY47: 6305 | AZ47: 6582 | BA47: 10341 | BB47: =BA47 -> 10341 | BC47: 8335 | BD47: 8694 | BE47: 10041 | BF47: 9088 | BG47: =BF47 -> 9088 | BH47: 6942 | BI47: 7533 | BJ47: 6655 | BK47: 11733 | BL47: =BK47 -> 11733 | BM47: 8655 | BN47: 9157 | BO47: 9383 | BP47: 11302 | BQ47: =BP47 -> 11302 | BR47: 7886 | BS47: 8605 | BT47: 8986 | BU47: 8801 | BV47: =BU47 -> 8801 | BW47: 8190 | BX47: 8737 | BY47: 8569 | BZ47: 8813 | CA47: =BZ47 -> 8813 | CB47: 9235 | CC47: 8121 | CD47: 8034 | CE47: 7637 | CF47: =CE47 -> 7637 | CG47: 6836 | CH47: 9167 | CI47: 9763 | CJ47: 9485 | CK47: =CJ47 -> 9485 | CL47: 15039 | CM47: 19992 | CN47: 10564 | CO47: 7752 | CP47: =CO47 -> 7752 | CQ47: 7059 | CR47: 8271 | CS47: 9764 | CT47: 8052 | CU47: =CT47 -> 8052 | CV47: 7409 | CW47: 10090 | CX47: 13494 | CY47: 14614 | CZ47: =CY47 -> 14614 | DA47: 10812 | DB47: 7254 | DC47: 6811 | DD47: 12691 | DE47: =DD47 -> 12691 | DF47: 6914 | DG47: 10894 | DH47: 9961 | DI47: 13801 | DJ47: =DI47 -> 13801 | DK47: 10142 | DL47: 7087 | DM47: 6173 | DN47: 10921 | DO47: =DN47 -> 10921 | DP47: 9441 | DQ47: 7239
B48: Short-term investments | C48: 729 | D48: 279 | E48: 100 | F48: 0 | G48: 0 | H48: 0 | I48: 0 | J48: 0 | K48: 0 | L48: 96 | M48: =N48 -> 319 | N48: 319 | O48: 167 | P48: 207 | Q48: 527 | R48: =S48 -> 554 | S48: 554 | T48: 576 | U48: 567 | V48: 423 | W48: =X48 -> 268 | X48: 268 | Y48: 441 | Z48: 475 | AA48: 516 | AB48: =AC48 -> 2266 | AC48: 2266 | AD48: 1881 | AE48: 1752 | AF48: 591 | AG48: =AH48 -> 11 | AH48: 11 | AI48: 213 | AJ48: 171 | AK48: 351 | AL48: 2008 | AM48: =AL48 -> 2008 | AN48: 5845 | AO48: 5558 | AP48: 7102 | AQ48: 5158 | AR48: =AQ48 -> 5158 | AS48: 2102 | AT48: 3752 | AU48: 3279 | AV48: 1223 | AW48: =AV48 -> 1223 | AX48: 3798 | AY48: 4002 | AZ48: 4590 | BA48: 3217 | BB48: =BA48 -> 3217 | BC48: 3518 | BD48: 5631 | BE48: 5870 | BF48: 6170 | BG48: =BF48 -> 6170 | BH48: 5282 | BI48: 3797 | BJ48: 3422 | BK48: 1359 | BL48: =BK48 -> 1359 | BM48: 976 | BN48: 468 | BO48: 474 | BP48: 750 | BQ48: =BP48 -> 750 | BR48: 466 | BS48: 660 | BT48: 682 | BU48: 1228 | BV48: =BU48 -> 1228 | BW48: 1015 | BX48: 1589 | BY48: 1463 | BZ48: 1179 | CA48: =BZ48 -> 1179 | CB48: 656 | CC48: 1649 | CD48: 1956 | CE48: 927 | CF48: =CE48 -> 927 | CG48: 893 | CH48: 439 | CI48: 1150 | CJ48: 545 | CK48: =CJ48 -> 545 | CL48: 488 | CM48: 12438 | CN48: 16552 | CO48: 17838 | CP48: =CO48 -> 17838 | CQ48: 14861 | CR48: 13071 | CS48: 10231 | CT48: 8192 | CU48: =CT48 -> 8192 | CV48: 4873 | CW48: 1358 | CX48: 763 | CY48: 2606 | CZ48: =CY48 -> 2606 | DA48: 3955 | DB48: 6508 | DC48: 6561 | DD48: 3274 | DE48: =DD48 -> 3274 | DF48: 615 | DG48: 1727 | DH48: 509 | DI48: 12481 | DJ48: =DI48 -> 12481 | DK48: 13532 | DL48: 15880 | DM48: 16811 | DN48: 18479 | DO48: =DN48 -> 18479 | DP48: 11464 | DQ48: 12783
...

Sheet BCA margin
