Workbook
Name africa: 0.01
Name africaCountries: #REF!
Name allRegions: #REF!
Name americaRegion: #REF!
Name americas: 0.55
Name americasStates: #REF!
Name AppVersion: "GEG-1.0"
Name asiaPacific: 0.22
Name asiaPacificExJapan: 0.11
Name asiaPacificExJapanCountries: #REF!
Name asiaPacificRegion: #REF!
Name asiaPacificStates: #REF!
Name australasia: 0.02
Name BRICS: 0.1
Name centralEasternEurope: 0.03
Name centralEasternEuropeCountries: #REF!
Name china: 0.07
Name consumerDemandExposure: #REF!
Name consumersExposure: 0
Name countryList: "Country Mapping"
Name developedEuropeExUK: 0.07
Name developedEuropeExUKCountries: #REF!
Name domesticAndForeignExposure: #REF!
Name domesticCostExposure: #REF!
Name EEMEA: 0.15
Name endDemandExposure: #REF!
Name europe: 0.11
Name europeRegion: #REF!
Name europeStates: #REF!
Name india: 0.02
Name instructions: #REF!
Name IQ_CH: 110000
Name IQ_CQ: 5000
Name IQ_CY: 10000
Name IQ_DAILY: 500000
Name IQ_FH: 100000
Name IQ_FQ: 500
Name IQ_FY: 1000
Name IQ_LTM: 2000
Name IQ_MONTH: 15000
Name IQ_NTM: 6000
Name IQ_WEEK: 50000
Name IQ_YTD: 3000
Name italy: 0.01
Name japan: 0.02
Name latinAmerica: 0.03
Name latinAmericaCountries: #REF!
Name Linking_1: #REF!
Name Linking_2: BCA_Model_Annual!$AW$38:$AY$51
Name middleEast: 0.11
Name middleEastAfrica: 0.12
Name middleEastAfricaRegion: #REF!
Name middleEastAfricaStates: #REF!
Name northAmerica: 0.52
Name northAmericaCountries: #REF!
Name otherAfrica: 0.01
Name otherAsiaPacific: 0.06
Name otherCentralEasternEurope: 0.02
Name otherDevelopedEurope: 0.03
Name otherLATAM: 0.03

Sheet CircularReferenceAlert
B2: This workbook contains formulas which intentionally use circular reference calculation. These calculations can be resolved as intended by the originating analyst by applying the following settings in the File >> Options >> Formulas:
B5: 1) Select the Enable iterative calculation check box
B6: 2) Set Maximum Iterations = 100
B7: 3) Set Maximum Change = 0.001
B9: Failure to apply these settings can result in incorrect calculation or unexpected termination of your Microsoft Excel session.

Sheet ImportantDisclosures
A2: 1585 Broadway
A3: New York, NY 10036-8293
A4: United States
A5: Tel: +1 (1)212 761 4000
A7: Authors: Kristine Liwag
A8: Date: 28 Jan 2026
A10: Ticker: BA.N
A11: Stock Rating: Equal-weight
A12: Industry: Aerospace
A13: Industry View: Attractive
A14: Price as of 28 Jan 2026: 245.30
A15: Target Price: 245.00
... A128: Equal-weight and Not-Rated to hold and Underweight to sell recommendations, respectively.
B130: Coverage Universe | D130: Investment Banking Clients (IBC) | G130: Other Material Investment Services Clients (MISC)
A131: Stock Rating Category | B131: Count | C131: % of Total | D131: Count | E131: % of Total IBC | F131: % of Rating Category | G131: Count | H131: % of Total Other MISC
A132: Overweight/Buy | B132: 1519 | C132: 0.41 | D132: 415 | E132: 0.48 | F132: 0.27 | G132: 674 | H132: 0.42
A133: Equal-weight/Hold | B133: 1583 | C133: 0.43 | D133: 362 | E133: 0.42 | F133: 0.23 | G133: 720 | H133: 0.45
A134: Not-Rated/Hold | B134: 4 | C134: 0 | D134: 1 | E134: 0 | F134: 0.25 | G134: 1 | H134: 0
A135: Underweight/Sell | B135: 564 | C135: 0.15 | D135: 87 | E135: 0.1 | F135: 0.15 | G135: 216 | H135: 0.13
A136: Total | B136: 3670 | D136: 865 | G136: 1611
A138: Data include common stock and ADRs currently assigned ratings. Investment Banking Clients are companies
A139: from whom Morgan Stanley received investment banking compensation in the last 12 months. Due to rounding
A140: off of decimals, the percentages provided in the "% of total" column may not add up to exactly 100
A141: percent.
A143: Analyst Stock Ratings
A145: Overweight (O). The stock's total return is expected to exceed the average total return of the analyst's
A146: industry (or industry team's) coverage universe, on a risk-adjusted basis, over the next 12-18 months.
A148: Equal-weight (E). The stock's total return is expected to be in line with the average total return of
A149: the analyst's industry (or industry team's) coverage universe, on a risk-adjusted basis, over the next
A150: 12-18 months.
A152: Not-Rated (NR). Currently the analyst does not have adequate conviction about the stock's total return
A153: relative to the average total return of the analyst's industry (or industry team's) coverage universe,
... A427: © Copyright 2026 Morgan Stanley

Sheet Financial Summary
A1: Financial Summary
B2: =Income_Statement_Annual!B2 -> CY2000A | C2: =Income_Statement_Annual!C2 -> CY2001A | D2: =Income_Statement_Annual!D2 -> CY2002A | E2: =Income_Statement_Annual!E2 -> CY2003A | F2: =Income_Statement_Annual!F2 -> CY2004A | G2: =Income_Statement_Annual!G2 -> CY2005A | H2: =Income_Statement_Annual!H2 -> CY2006A | I2: =Income_Statement_Annual!I2 -> CY2007A | ... AB2: =Income_Statement_Annual!AB2 -> CY2026E
A3: Income Statement
A4: Revenue | B4: =Income_Statement_Annual!B10 -> 51321 | C4: =Income_Statement_Annual!C10 -> 58198 | D4: =Income_Statement_Annual!D10 -> 54061 | E4: =Income_Statement_Annual!E10 -> 50256 | F4: =Income_Statement_Annual!F10 -> 52457 | G4: =Income_Statement_Annual!G10 -> 53621 | H4: =Income_Statement_Annual!H10 -> 61530 | I4: =Income_Statement_Annual!I10 -> 66387 | ... AB4: =Income_Statement_Annual!AB10 -> 99714.978
A5: Revenue Growth | B5: =Income_Statement_Annual!B11 -> -0.11504837 | C5: =Income_Statement_Annual!C11 -> 0.13399973 | D5: =Income_Statement_Annual!D11 -> -0.071084917 | E5: =Income_Statement_Annual!E11 -> -0.070383456 | F5: =Income_Statement_Annual!F11 -> 0.043795766 | G5: =Income_Statement_Annual!G11 -> 0.022189603 | H5: =Income_Statement_Annual!H11 -> 0.14749818 | I5: =Income_Statement_Annual!I11 -> 0.078937104 | ... AB5: =Income_Statement_Annual!AB11 -> 0.11459462
A6: EBITDA | B6: =Income_Statement_Annual!B97 -> 4537 | C6: =Income_Statement_Annual!C97 -> 5639 | D6: =Income_Statement_Annual!D97 -> 4947 | E6: =Income_Statement_Annual!E97 -> 2711 | F6: =Income_Statement_Annual!F97 -> 4071 | G6: =Income_Statement_Annual!G97 -> 4315 | H6: =Income_Statement_Annual!H97 -> 5465 | I6: =Income_Statement_Annual!I97 -> 7316 | ... AB6: =Income_Statement_Annual!AB97 -> 4185.7288
A7: EBITDA Margin | B7: =Income_Statement_Annual!B98 -> 0.088404357 | C7: =Income_Statement_Annual!C98 -> 0.096893364 | D7: =Income_Statement_Annual!D98 -> 0.091507741 | E7: =Income_Statement_Annual!E98 -> 0.053943808 | F7: =Income_Statement_Annual!F98 -> 0.07760642 | G7: =Income_Statement_Annual!G98 -> 0.080472203 | H7: =Income_Statement_Annual!H98 -> 0.088818463 | I7: =Income_Statement_Annual!I98 -> 0.1102023 | ... AB7: =Income_Statement_Annual!AB98 -> 0.041976931
A8: EBIT | B8: =Income_Statement_Annual!B34 -> 3058 | C8: =Income_Statement_Annual!C34 -> 3896 | D8: =Income_Statement_Annual!D34 -> 3450 | E8: =Income_Statement_Annual!E34 -> 1311 | F8: =Income_Statement_Annual!F34 -> 2562 | G8: =Income_Statement_Annual!G34 -> 2812 | H8: =Income_Statement_Annual!H34 -> 3920 | I8: =Income_Statement_Annual!I34 -> 5830 | ... AB8: =Income_Statement_Annual!AB34 -> 2111.9938
A9: EBIT Margin | B9: =Income_Statement_Annual!B35 -> 0.059585745 | C9: =Income_Statement_Annual!C35 -> 0.066943881 | D9: =Income_Statement_Annual!D35 -> 0.0638168 | E9: =Income_Statement_Annual!E35 -> 0.026086437 | F9: =Income_Statement_Annual!F35 -> 0.048840002 | G9: =Income_Statement_Annual!G35 -> 0.05244214 | H9: =Income_Statement_Annual!H35 -> 0.06370876 | I9: =Income_Statement_Annual!I35 -> 0.087818398 | ... AB9: =Income_Statement_Annual!AB35 -> 0.021180306
A10: Pre-Tax Income | B10: =Income_Statement_Annual!B40 -> 2999 | C10: =Income_Statement_Annual!C40 -> 3564 | D10: =Income_Statement_Annual!D40 -> 3180 | E10: =Income_Statement_Annual!E40 -> 1413 | F10: =Income_Statement_Annual!F40 -> 2296 | G10: =Income_Statement_Annual!G40 -> 2755 | H10: =Income_Statement_Annual!H40 -> 4100 | I10: =Income_Statement_Annual!I40 -> 6118 | ... AB10: =Income_Statement_Annual!AB40 -> 527.84551
A11: Tax Rate | B11: =Income_Statement_Annual!B44 -> 0.29043014 | C11: =Income_Statement_Annual!C44 -> 0.20707071 | D11: =Income_Statement_Annual!D44 -> 0.27075472 | E11: =Income_Statement_Annual!E44 -> NM | F11: =Income_Statement_Annual!F44 -> 0.27155488 | G11: =Income_Statement_Annual!G44 -> 0.29152269 | H11: =Income_Statement_Annual!H44 -> 0.27267707 | I11: =Income_Statement_Annual!I44 -> 0.33671134 | ... AB11: =Income_Statement_Annual!AB44 -> 0.1
A12: Net Income Attributable to Boeing Shareholder | B12: =Income_Statement_Annual!B56 -> 2128 | C12: =Income_Statement_Annual!C56 -> 2827 | D12: =Income_Statement_Annual!D56 -> 492 | E12: =Income_Statement_Annual!E56 -> 718 | F12: =Income_Statement_Annual!F56 -> 1872 | G12: =Income_Statement_Annual!G56 -> 2572 | H12: =Income_Statement_Annual!H56 -> 2215 | I12: =Income_Statement_Annual!I56 -> 4074 | ... AB12: =Income_Statement_Annual!AB56 -> 475.06095
A13: EPS | B13: =Income_Statement_Annual!B70 -> 2.4423276 | C13: =Income_Statement_Annual!C70 -> 3.4076932 | D13: =Income_Statement_Annual!D70 -> 2.8686294 | E13: =Income_Statement_Annual!E70 -> 1.856829 | F13: =Income_Statement_Annual!F70 -> 2.0572079 | G13: =Income_Statement_Annual!G70 -> 2.4310064 | H13: =Income_Statement_Annual!H70 -> 3.8204977 | I13: =Income_Statement_Annual!I70 -> 5.2530744 | ... AB13: =Income_Statement_Annual!AB70 -> 0.16056352
A14: Diluted Shares Outstanding (mn) | B14: =Income_Statement_Annual!B79 -> 871.3 | C14: =Income_Statement_Annual!C79 -> 829.3 | D14: =Income_Statement_Annual!D79 -> 808.4 | E14: =Income_Statement_Annual!E79 -> 808.9 | F14: =Income_Statement_Annual!F79 -> 813 | G14: =Income_Statement_Annual!G79 -> 802.9 | H14: =Income_Statement_Annual!H79 -> 787.6 | I14: =Income_Statement_Annual!I79 -> 772.5 | ... AB14: =Income_Statement_Annual!AB79 -> 803.8
A15: Total Book to Bill | B15: 0 | C15: 0.69399292 | D15: 1.0881967 | E15: 1.3277221 | F15: 1.0413863 | G15: 1.8902669 | H15: 1.7318381 | I15: 2.1556028 | J15: 1.4094961 | K15: 0.46737745 | L15: 1.0819208 | M15: 1.5034698 | N15: 1.4259101 | O15: 1.5852949 | P15: 1.6771887 | Q15: 0.86378675 | R15: 0.83285574 | S15: 1.0122121 | T15: 1.1566446 | U15: 0.64631199 | V15: -0.40613261 | W15: 1.2262948 | X15: 1.4035852 | Y15: 2.4887266 | Z15: 0 | AA15: 0 | AB15: 0
A17: Cash Flow Statement
A18: Operating Cash Flow | B18: =Cash_Flow_Annual!B29 -> 5942 | C18: =Cash_Flow_Annual!C29 -> 3894 | D18: =Cash_Flow_Annual!D29 -> 4236 | E18: =Cash_Flow_Annual!E29 -> 2709 | F18: =Cash_Flow_Annual!F29 -> 3504 | G18: =Cash_Flow_Annual!G29 -> 7000 | H18: =Cash_Flow_Annual!H29 -> 7499 | I18: =Cash_Flow_Annual!I29 -> 9584 | ... AB18: =Cash_Flow_Annual!AB29 -> 6229.8022
A19: Capex | B19: =Cash_Flow_Annual!B33 -> -932 | C19: =Cash_Flow_Annual!C33 -> -1189 | D19: =Cash_Flow_Annual!D33 -> -1001 | E19: =Cash_Flow_Annual!E33 -> -741 | F19: =Cash_Flow_Annual!F33 -> -1246 | G19: =Cash_Flow_Annual!G33 -> -1547 | H19: =Cash_Flow_Annual!H33 -> -1681 | I19: =Cash_Flow_Annual!I33 -> -1731 | ... AB19: =Cash_Flow_Annual!AB33 -> -4058.3996
A20: Free Cash Flow | B20: =Cash_Flow_Annual!B77 -> 5010 | C20: =Cash_Flow_Annual!C77 -> 2705 | D20: =Cash_Flow_Annual!D77 -> 3235 | E20: =Cash_Flow_Annual!E77 -> 1968 | F20: =Cash_Flow_Annual!F77 -> 2258 | G20: =Cash_Flow_Annual!G77 -> 5453 | H20: =Cash_Flow_Annual!H77 -> 5818 | I20: =Cash_Flow_Annual!I77 -> 7853 | ... AB20: =Cash_Flow_Annual!AB77 -> 2171.4025
A21: FCF Conversion | B21: =Cash_Flow_Annual!B78 -> 2.3543233 | C21: =Cash_Flow_Annual!C78 -> 0.95684471 | D21: =Cash_Flow_Annual!D78 -> 6.5752033 | E21: =Cash_Flow_Annual!E78 -> 2.7409471 | F21: =Cash_Flow_Annual!F78 -> 1.2061966 | G21: =Cash_Flow_Annual!G78 -> 2.12014 | H21: =Cash_Flow_Annual!H78 -> 2.6266366 | I21: =Cash_Flow_Annual!I78 -> 1.9275896 | ... AB21: =Cash_Flow_Annual!AB78 -> 2.6446301
A22: FCF Returned to Shareholders | B22: =Cash_Flow_Annual!B81 -> 2861 | C22: =Cash_Flow_Annual!C81 -> 2999 | D22: =Cash_Flow_Annual!D81 -> 571 | E22: =Cash_Flow_Annual!E81 -> 572 | F22: =Cash_Flow_Annual!F81 -> 1400 | G22: =Cash_Flow_Annual!G81 -> 3697 | H22: =Cash_Flow_Annual!H81 -> 2654 | I22: =Cash_Flow_Annual!I81 -> 3871 | ... AB22: =Cash_Flow_Annual!AB81 -> 346
A23: % of FCF Returned to Shareholders | B23: =Cash_Flow_Annual!B82 -> 0.57105788 | C23: =Cash_Flow_Annual!C82 -> 1.1086876 | D23: =Cash_Flow_Annual!D82 -> 0.17650696 | E23: =Cash_Flow_Annual!E82 -> 0.29065041 | F23: =Cash_Flow_Annual!F82 -> 0.62001771 | G23: =Cash_Flow_Annual!G82 -> 0.67797543 | H23: =Cash_Flow_Annual!H82 -> 0.45617051 | I23: =Cash_Flow_Annual!I82 -> 0.49293264 | ... AB23: =Cash_Flow_Annual!AB82 -> 0.15934401
A25: Balance Sheet
A26: Total Cash | B26: =Balance_Sheet_Annual!B5 -> 1010 | C26: =Balance_Sheet_Annual!C5 -> 633 | D26: =Balance_Sheet_Annual!D5 -> 2333 | E26: =Balance_Sheet_Annual!E5 -> 4633 | F26: =Balance_Sheet_Annual!F5 -> 3204 | G26: =Balance_Sheet_Annual!G5 -> 5412 | H26: =Balance_Sheet_Annual!H5 -> 6118 | I26: =Balance_Sheet_Annual!I5 -> 7042 | ... AB26: =Balance_Sheet_Annual!AB5 -> 8329.4025
A27: Total Debt | B27: =Balance_Sheet_Annual!B82 -> 8799 | C27: =Balance_Sheet_Annual!C82 -> 12265 | D27: =Balance_Sheet_Annual!D82 -> 14403 | E27: =Balance_Sheet_Annual!E82 -> 14443 | F27: =Balance_Sheet_Annual!F82 -> 12200 | G27: =Balance_Sheet_Annual!G82 -> 10727 | H27: =Balance_Sheet_Annual!H82 -> 9538 | I27: =Balance_Sheet_Annual!I82 -> 8217 | ... AB27: =Balance_Sheet_Annual!AB82 -> 49648
A28: Net Debt | B28: =Balance_Sheet_Annual!B83 -> 7789 | C28: =Balance_Sheet_Annual!C83 -> 11632 | D28: =Balance_Sheet_Annual!D83 -> 12070 | E28: =Balance_Sheet_Annual!E83 -> 9810 | F28: =Balance_Sheet_Annual!F83 -> 8996 | G28: =Balance_Sheet_Annual!G83 -> 5315 | H28: =Balance_Sheet_Annual!H83 -> 3420 | I28: =Balance_Sheet_Annual!I83 -> 1175 | ... AB28: =Balance_Sheet_Annual!AB83 -> 22839.597
A29: Net Debt to EBITDA | B29: =Balance_Sheet_Annual!B85 -> 1.7167732 | C29: =Balance_Sheet_Annual!C85 -> 2.0627771 | D29: =Balance_Sheet_Annual!D85 -> 2.4398625 | E29: =Balance_Sheet_Annual!E85 -> 3.6185909 | F29: =Balance_Sheet_Annual!F85 -> 2.2097765 | G29: =Balance_Sheet_Annual!G85 -> 1.2317497 | H29: =Balance_Sheet_Annual!H85 -> 0.62580055 | I29: =Balance_Sheet_Annual!I85 -> 0.16060689 | ... AB29: =Balance_Sheet_Annual!AB85 -> 5.4565403
A31: Capital Deployment
A32: Dry Powder for M&A | B32: =Balance_Sheet_Annual!B91 -> 0 | C32: =Balance_Sheet_Annual!C91 -> 0 | D32: =Balance_Sheet_Annual!D91 -> 0 | E32: =Balance_Sheet_Annual!E91 -> 0 | F32: =Balance_Sheet_Annual!F91 -> 0 | G32: =Balance_Sheet_Annual!G91 -> 0 | H32: =Balance_Sheet_Annual!H91 -> 0 | I32: =Balance_Sheet_Annual!I91 -> 0 | ... AB32: =Balance_Sheet_Annual!AB91 -> -38348.548
A33: Target EV/EBITDA | B33: =Balance_Sheet_Annual!B92 -> 0 | C33: =Balance_Sheet_Annual!C92 -> 0 | D33: =Balance_Sheet_Annual!D92 -> 0 | E33: =Balance_Sheet_Annual!E92 -> 0 | F33: =Balance_Sheet_Annual!F92 -> 0 | G33: =Balance_Sheet_Annual!G92 -> 0 | H33: =Balance_Sheet_Annual!H92 -> 0 | I33: =Balance_Sheet_Annual!I92 -> 0 | ... AB33: =Balance_Sheet_Annual!AB92 -> 3
A34: EPS Accretion | B34: =Balance_Sheet_Annual!B106 -> 0 | C34: =Balance_Sheet_Annual!C106 -> 0 | D34: =Balance_Sheet_Annual!D106 -> 0 | E34: =Balance_Sheet_Annual!E106 -> 0 | F34: =Balance_Sheet_Annual!F106 -> 0 | G34: =Balance_Sheet_Annual!G106 -> 0 | H34: =Balance_Sheet_Annual!H106 -> 0 | I34: =Balance_Sheet_Annual!I106 -> 0 | ... AB34: =Balance_Sheet_Annual!AB106 -> -0.87943714
A35: Annualized EPS Accretion | B35: =Balance_Sheet_Annual!B107 -> 0 | C35: =Balance_Sheet_Annual!C107 -> 0 | D35: =Balance_Sheet_Annual!D107 -> 0 | E35: =Balance_Sheet_Annual!E107 -> 0 | F35: =Balance_Sheet_Annual!F107 -> 0 | G35: =Balance_Sheet_Annual!G107 -> 0 | H35: =Balance_Sheet_Annual!H107 -> 0 | I35: =Balance_Sheet_Annual!I107 -> 0 | ... AB35: =Balance_Sheet_Annual!AB107 -> -5.4771916
A37: Dry Powder for Incremental Buybacks | B37: =Balance_Sheet_Annual!B111 -> 0 | C37: =Balance_Sheet_Annual!C111 -> 0 | D37: =Balance_Sheet_Annual!D111 -> 0 | E37: =Balance_Sheet_Annual!E111 -> 0 | F37: =Balance_Sheet_Annual!F111 -> 0 | G37: =Balance_Sheet_Annual!G111 -> 0 | H37: =Balance_Sheet_Annual!H111 -> 0 | I37: =Balance_Sheet_Annual!I111 -> 0 | ... AB37: =Balance_Sheet_Annual!AB111 -> -28761.411
A38: Target EV/EBITDA | B38: =Balance_Sheet_Annual!B113 -> 0 | C38: =Balance_Sheet_Annual!C113 -> 0 | D38: =Balance_Sheet_Annual!D113 -> 0 | E38: =Balance_Sheet_Annual!E113 -> 0 | F38: =Balance_Sheet_Annual!F113 -> 0 | G38: =Balance_Sheet_Annual!G113 -> 0 | H38: =Balance_Sheet_Annual!H113 -> 0 | I38: =Balance_Sheet_Annual!I113 -> 0 | ... AB38: =Balance_Sheet_Annual!AB113 -> 3
A39: EPS Accretion | B39: =Balance_Sheet_Annual!B121 -> 0 | C39: =Balance_Sheet_Annual!C121 -> 0 | D39: =Balance_Sheet_Annual!D121 -> 0 | E39: =Balance_Sheet_Annual!E121 -> 0 | F39: =Balance_Sheet_Annual!F121 -> 0 | G39: =Balance_Sheet_Annual!G121 -> 0 | H39: =Balance_Sheet_Annual!H121 -> 0 | I39: =Balance_Sheet_Annual!I121 -> 0 | ... AB39: =Balance_Sheet_Annual!AB121 -> 1.5400309
A40: Annualized EPS Accretion | B40: =Balance_Sheet_Annual!B122 -> 0 | C40: =Balance_Sheet_Annual!C122 -> 0 | D40: =Balance_Sheet_Annual!D122 -> 0 | E40: =Balance_Sheet_Annual!E122 -> 0 | F40: =Balance_Sheet_Annual!F122 -> 0 | G40: =Balance_Sheet_Annual!G122 -> 0 | H40: =Balance_Sheet_Annual!H122 -> 0 | I40: =Balance_Sheet_Annual!I122 -> 0 | ... AB40: =Balance_Sheet_Annual!AB122 -> 9.5914121
A42: Reporting Segment Metrics
A43: Commercial Airplanes (BCA)
A44: Revenue | R44: =BCA_Annual!R3 -> 58012 | S44: =BCA_Annual!S3 -> 58014 | T44: =BCA_Annual!T3 -> 57499 | U44: =BCA_Annual!U3 -> 32255 | V44: =BCA_Annual!V3 -> 16162 | W44: =BCA_Annual!W3 -> 19493 | X44: =BCA_Annual!X3 -> 25867 | Y44: =BCA_Annual!Y3 -> 33901 | ... AB44: =BCA_Annual!AB3 -> 50763.127
A45: Revenue Growth | R45: =BCA_Annual!R4 -> 0 | S45: =BCA_Annual!S4 -> 3.4475626e-05 | T45: =BCA_Annual!T4 -> -0.0088771676 | U45: =BCA_Annual!U4 -> -0.43903372 | V45: =BCA_Annual!V4 -> -0.4989304 | W45: =BCA_Annual!W4 -> 0.20610073 | X45: =BCA_Annual!X4 -> 0.32698918 | Y45: =BCA_Annual!Y4 -> 0.31058878 | ... AB45: =BCA_Annual!AB4 -> 0.22338475
...

Sheet Income_Statement_Annual
A1: Income Statement Annual
B2: CY2000A | C2: CY2001A | D2: CY2002A | E2: CY2003A | F2: CY2004A | G2: CY2005A | H2: CY2006A | I2: CY2007A | J2: CY2008A | K2: CY2009A | L2: CY2010A | M2: CY2011A | N2: CY2012A | O2: CY2013A | P2: CY2014A | Q2: CY2015A | R2: CY2016A | S2: CY2017A | T2: CY2018A | U2: CY2019A | V2: CY2020A | W2: CY2021A | X2: CY2022A | Y2: CY2023A | Z2: CY2024A | AA2: CY2025A | AB2: CY2026E | AC2: CY2027E | AD2: CY2028E | AE2: CY2029E | AF2: CY2030E
A3: =Income_Statement_Qtr!A3 -> Commercial Airplanes (BCA) | B3: =BCA_Annual!B3 -> 0 | C3: =BCA_Annual!C3 -> 0 | D3: =BCA_Annual!D3 -> 0 | E3: =BCA_Annual!E3 -> 0 | F3: =BCA_Annual!F3 -> 0 | G3: =BCA_Annual!G3 -> 0 | H3: =BCA_Annual!H3 -> 0 | I3: =BCA_Annual!I3 -> 0 | ... P3: =BCA_Annual!P3 -> 0 | Q3: =+Income_Statement_Qtr!F3 -> 0 | R3: =+Income_Statement_Qtr!K3 -> 58012 | S3: =+Income_Statement_Qtr!P3 -> 58014 | T3: =+Income_Statement_Qtr!U3 -> 57499 | U3: =+Income_Statement_Qtr!Z3 -> 32255 | V3: =+Income_Statement_Qtr!AE3 -> 16162 | W3: =+Income_Statement_Qtr!AJ3 -> 19493 | X3: =+Income_Statement_Qtr!AO3 -> 25867 | Y3: =+Income_Statement_Qtr!AT3 -> 33901 | Z3: =+Income_Statement_Qtr!AY3 -> 22861 | AA3: =+Income_Statement_Qtr!BD3 -> 41494 | AB3: =+Income_Statement_Qtr!BI3 -> 50763.127 | AC3: =BCA_Annual!AC3 -> 57203.394 | AD3: =BCA_Annual!AD3 -> 59684.099 | AE3: =BCA_Annual!AE3 -> 61238.072 | AF3: =BCA_Annual!AF3 -> 62838.664
A4: =Income_Statement_Qtr!A4 -> Defense, Space & Security (BDS) | B4: =BDS_Annual!B3 -> 0 | C4: =BDS_Annual!C3 -> 0 | D4: =BDS_Annual!D3 -> 0 | E4: =BDS_Annual!E3 -> 0 | F4: =BDS_Annual!F3 -> 0 | G4: =BDS_Annual!G3 -> 0 | H4: =BDS_Annual!H3 -> 0 | I4: =BDS_Annual!I3 -> 0 | ... P4: =BDS_Annual!P3 -> 0 | Q4: =+Income_Statement_Qtr!F4 -> 0 | R4: =+Income_Statement_Qtr!K4 -> 22563 | S4: =+Income_Statement_Qtr!P4 -> 20561 | T4: =+Income_Statement_Qtr!U4 -> 26392 | U4: =+Income_Statement_Qtr!Z4 -> 26227 | V4: =+Income_Statement_Qtr!AE4 -> 26257 | W4: =+Income_Statement_Qtr!AJ4 -> 26540 | X4: =+Income_Statement_Qtr!AO4 -> 23162 | Y4: =+Income_Statement_Qtr!AT4 -> 24933 | Z4: =+Income_Statement_Qtr!AY4 -> 23918 | AA4: =+Income_Statement_Qtr!BD4 -> 27234 | AB4: =+Income_Statement_Qtr!BI4 -> 28228.851 | AC4: =BDS_Annual!AC3 -> 29196.688 | AD4: =BDS_Annual!AD3 -> 30119.099 | AE4: =BDS_Annual!AE3 -> 31087.585 | AF4: =BDS_Annual!AF3 -> 31291.727
A5: =Income_Statement_Qtr!A5 -> Global Services (BGS) | B5: =BGS_Annual!B3 -> 0 | C5: =BGS_Annual!C3 -> 0 | D5: =BGS_Annual!D3 -> 0 | E5: =BGS_Annual!E3 -> 0 | F5: =BGS_Annual!F3 -> 0 | G5: =BGS_Annual!G3 -> 0 | H5: =BGS_Annual!H3 -> 0 | I5: =BGS_Annual!I3 -> 0 | ... P5: =BGS_Annual!P3 -> 0 | Q5: =+Income_Statement_Qtr!F5 -> 0 | R5: =+Income_Statement_Qtr!K5 -> 13925 | S5: =+Income_Statement_Qtr!P5 -> 14581 | T5: =+Income_Statement_Qtr!U5 -> 17056 | U5: =+Income_Statement_Qtr!Z5 -> 18468 | V5: =+Income_Statement_Qtr!AE5 -> 15543 | W5: =+Income_Statement_Qtr!AJ5 -> 16328 | X5: =+Income_Statement_Qtr!AO5 -> 17611 | Y5: =+Income_Statement_Qtr!AT5 -> 19127 | Z5: =+Income_Statement_Qtr!AY5 -> 19954 | AA5: =+Income_Statement_Qtr!BD5 -> 20923 | AB5: =+Income_Statement_Qtr!BI5 -> 20923 | AC5: =BGS_Annual!AC3 -> 22178.38 | AD5: =BGS_Annual!AD3 -> 23509.083 | AE5: =BGS_Annual!AE3 -> 24919.628 | AF5: =BGS_Annual!AF3 -> 26414.805
A6: =Income_Statement_Qtr!A6 -> Boeing Capital (BCC) (Old | B6: 728 | C6: 815 | D6: 994 | E6: 991 | F6: 959 | G6: 966 | H6: 1025 | I6: 815 | J6: 703 | K6: 660 | L6: 639 | M6: 520 | N6: 468 | O6: 408 | P6: 416 | Q6: =+Income_Statement_Qtr!F6 -> 413 | R6: =+Income_Statement_Qtr!K6 -> 298 | S6: =+Income_Statement_Qtr!P6 -> 307 | T6: =+Income_Statement_Qtr!U6 -> 274 | U6: =+Income_Statement_Qtr!Z6 -> 244 | V6: =+Income_Statement_Qtr!AE6 -> 261 | W6: =+Income_Statement_Qtr!AJ6 -> 272 | X6: =+Income_Statement_Qtr!AO6 -> 199 | Y6: =+Income_Statement_Qtr!AT6 -> 0 | Z6: =+Income_Statement_Qtr!AY6 -> 0 | AA6: =+Income_Statement_Qtr!BD6 -> 0 | AB6: =+Income_Statement_Qtr!BI6 -> 0 | AC6: 0 | AD6: 0 | AE6: 0 | AF6: 0
A7: =Income_Statement_Qtr!A7 -> Commercial Airplanes (BCA) (Old) | B7: 31171 | C7: 35056 | D7: 28387 | E7: 22408 | F7: 21037 | G7: 21365 | H7: 28465 | I7: 33386 | J7: 28263 | K7: 34051 | L7: 31834 | M7: 36171 | N7: 49127 | O7: 52981 | P7: 59990 | Q7: =+Income_Statement_Qtr!F7 -> 66048 | R7: =+Income_Statement_Qtr!K7 -> 0 | S7: =+Income_Statement_Qtr!P7 -> 0 | T7: =+Income_Statement_Qtr!U7 -> 0 | U7: =+Income_Statement_Qtr!Z7 -> 0 | V7: =+Income_Statement_Qtr!AE7 -> 0 | W7: =+Income_Statement_Qtr!AJ7 -> 0 | X7: =+Income_Statement_Qtr!AO7 -> 0 | Y7: =+Income_Statement_Qtr!AT7 -> 0 | Z7: =+Income_Statement_Qtr!AY7 -> 0 | AA7: =+Income_Statement_Qtr!BD7 -> 0 | AB7: =+Income_Statement_Qtr!BI7 -> 0 | AC7: 0 | AD7: 0 | AE7: 0 | AF7: 0
A8: =Income_Statement_Qtr!A8 -> Defense, Space & Security (BDS) (Old) | B8: 19963 | C8: 22815 | D8: 24957 | E8: 27361 | F8: 30465 | G8: 31106 | H8: 32439 | I8: 32052 | J8: 32047 | K8: 33661 | L8: 31943 | M8: 31976 | N8: 32607 | O8: 33197 | P8: 30881 | Q8: =+Income_Statement_Qtr!F8 -> 30388 | R8: =+Income_Statement_Qtr!K8 -> 0 | S8: =+Income_Statement_Qtr!P8 -> 0 | T8: =+Income_Statement_Qtr!U8 -> 0 | U8: =+Income_Statement_Qtr!Z8 -> 0 | V8: =+Income_Statement_Qtr!AE8 -> 0 | W8: =+Income_Statement_Qtr!AJ8 -> 0 | X8: =+Income_Statement_Qtr!AO8 -> 0 | Y8: =+Income_Statement_Qtr!AT8 -> 0 | Z8: =+Income_Statement_Qtr!AY8 -> 0 | AA8: =+Income_Statement_Qtr!BD8 -> 0 | AB8: =+Income_Statement_Qtr!BI8 -> 0 | AC8: 0 | AD8: 0 | AE8: 0 | AF8: 0
A9: =Income_Statement_Qtr!A9 -> Unallocated Items, Eliminations and Other | B9: =303-844 -> -541 | C9: =413-901 -> -488 | D9: =536-813 -> -277 | E9: =871-1375 -> -504 | F9: =549-553 -> -4 | G9: =657-473 -> 184 | H9: =299-698 -> -399 | I9: =308-174 -> 134 | J9: =567-671 -> -104 | K9: =165-256 -> -91 | L9: =-248+138 -> -110 | M9: =150-82 -> 68 | N9: =106-610 -> -504 | O9: 37 | P9: -525 | Q9: =+Income_Statement_Qtr!F9 -> -735 | R9: =+Income_Statement_Qtr!K9 -> -227 | S9: =+Income_Statement_Qtr!P9 -> 542 | T9: =+Income_Statement_Qtr!U9 -> -94 | U9: =+Income_Statement_Qtr!Z9 -> -635 | V9: =+Income_Statement_Qtr!AE9 -> -65 | W9: =+Income_Statement_Qtr!AJ9 -> -347 | X9: =+Income_Statement_Qtr!AO9 -> -231 | Y9: =+Income_Statement_Qtr!AT9 -> -167 | Z9: =+Income_Statement_Qtr!AY9 -> -216 | AA9: =+Income_Statement_Qtr!BD9 -> -188 | AB9: =+Income_Statement_Qtr!BI9 -> -200 | AC9: -200 | AD9: -200 | AE9: -200 | AF9: -200
A10: =Income_Statement_Qtr!A10 -> Total Net Sales | B10: =SUM(B3:B9) -> 51321 | C10: =SUM(C3:C9) -> 58198 | D10: =SUM(D3:D9) -> 54061 | E10: =SUM(E3:E9) -> 50256 | F10: =SUM(F3:F9) -> 52457 | G10: =SUM(G3:G9) -> 53621 | H10: =SUM(H3:H9) -> 61530 | I10: =SUM(I3:I9) -> 66387 | ... AF10: =SUM(AF3:AF9) -> 120345.2
A11: =Income_Statement_Qtr!A11 -> YoY | B11: =B10/57993-1 -> -0.11504837 | C11: =C10/B10-1 -> 0.13399973 | D11: =D10/C10-1 -> -0.071084917 | E11: =E10/D10-1 -> -0.070383456 | F11: =F10/E10-1 -> 0.043795766 | G11: =G10/F10-1 -> 0.022189603 | H11: =H10/G10-1 -> 0.14749818 | I11: =I10/H10-1 -> 0.078937104 | J11: =J10/I10-1 -> -0.082516155 | ... P11: =P10/O10-1 -> 0.047781767 | Q11: =+Income_Statement_Qtr!F11 -> 0.058967409 | R11: =+Income_Statement_Qtr!K11 -> -0.016053853 | S11: =+Income_Statement_Qtr!P11 -> -0.0059849214 | T11: =+Income_Statement_Qtr!U11 -> 0.075761928 | U11: =+Income_Statement_Qtr!Z11 -> -0.24294204 | V11: =+Income_Statement_Qtr!AE11 -> -0.24035058 | W11: =+Income_Statement_Qtr!AJ11 -> 0.070979057 | X11: =+Income_Statement_Qtr!AO11 -> 0.06938959 | Y11: =+Income_Statement_Qtr!AT11 -> 0.16793779 | Z11: =+Income_Statement_Qtr!AY11 -> -0.14495977 | AA11: =+Income_Statement_Qtr!BD11 -> 0.34496445 | AB11: =+Income_Statement_Qtr!BI11 -> 0.11459462 | AC11: =AC10/AB10-1 -> 0.086882475 | AD11: =AD10/AC10-1 -> 0.04367859 | AE11: =AE10/AD10-1 -> 0.03477079 | AF11: =AF10/AE10-1 -> 0.028193462
A13: =Income_Statement_Qtr!A13 -> Commercial Airplanes (BCA) | B13: =BCA_Annual!B19 -> 0 | C13: =BCA_Annual!C19 -> 0 | D13: =BCA_Annual!D19 -> 0 | E13: =BCA_Annual!E19 -> 0 | F13: =BCA_Annual!F19 -> 0 | G13: =BCA_Annual!G19 -> 0 | H13: =BCA_Annual!H19 -> 0 | I13: =BCA_Annual!I19 -> 0 | ... P13: =BCA_Annual!P19 -> 0 | Q13: =+Income_Statement_Qtr!F13 -> 0 | R13: =+Income_Statement_Qtr!K13 -> 1995 | S13: =+Income_Statement_Qtr!P13 -> 5452 | T13: =+Income_Statement_Qtr!U13 -> 7830 | U13: =+Income_Statement_Qtr!Z13 -> -6657 | V13: =+Income_Statement_Qtr!AE13 -> -13847 | W13: =+Income_Statement_Qtr!AJ13 -> -6475 | X13: =+Income_Statement_Qtr!AO13 -> -2370 | Y13: =+Income_Statement_Qtr!AT13 -> -1635 | Z13: =+Income_Statement_Qtr!AY13 -> -7969 | AA13: =+Income_Statement_Qtr!BD13 -> -7079 | AB13: =+Income_Statement_Qtr!BI13 -> -994.54108 | AC13: =BCA_Annual!AC19 -> 4404.3018 | AD13: =BCA_Annual!AD19 -> 5872.9449 | AE13: =BCA_Annual!AE19 -> 6048.3803 | AF13: =BCA_Annual!AF19 -> 6229.0787
A14: =Income_Statement_Qtr!A14 -> Defense, Space & Security (BDS) | B14: =BDS_Annual!B19 -> 0 | C14: =BDS_Annual!C19 -> 0 | D14: =BDS_Annual!D19 -> 0 | E14: =BDS_Annual!E19 -> 0 | F14: =BDS_Annual!F19 -> 0 | G14: =BDS_Annual!G19 -> 0 | H14: =BDS_Annual!H19 -> 0 | I14: =BDS_Annual!I19 -> 0 | ... P14: =BDS_Annual!P19 -> 0 | Q14: =+Income_Statement_Qtr!F14 -> 0 | R14: =+Income_Statement_Qtr!K14 -> 1966 | S14: =+Income_Statement_Qtr!P14 -> 2193 | T14: =+Income_Statement_Qtr!U14 -> 1657 | U14: =+Income_Statement_Qtr!Z14 -> 2608 | V14: =+Income_Statement_Qtr!AE14 -> 1539 | W14: =+Income_Statement_Qtr!AJ14 -> 1544 | X14: =+Income_Statement_Qtr!AO14 -> -3544 | Y14: =+Income_Statement_Qtr!AT14 -> -1764 | Z14: =+Income_Statement_Qtr!AY14 -> -5413 | AA14: =+Income_Statement_Qtr!BD14 -> -128 | AB14: =+Income_Statement_Qtr!BI14 -> 796.81656 | AC14: =BDS_Annual!AC19 -> 1490.5286 | AD14: =BDS_Annual!AD19 -> 1971.7166 | AE14: =BDS_Annual!AE19 -> 2043.429 | AF14: =BDS_Annual!AF19 -> 2058.5266
A15: =Income_Statement_Qtr!A15 -> Global Services (BGS) | B15: =BGS_Annual!B19 -> 0 | C15: =BGS_Annual!C19 -> 0 | D15: =BGS_Annual!D19 -> 0 | E15: =BGS_Annual!E19 -> 0 | F15: =BGS_Annual!F19 -> 0 | G15: =BGS_Annual!G19 -> 0 | H15: =BGS_Annual!H19 -> 0 | I15: =BGS_Annual!I19 -> 0 | ... P15: =BGS_Annual!P19 -> 0 | Q15: =+Income_Statement_Qtr!F15 -> 0 | R15: =+Income_Statement_Qtr!K15 -> 2177 | S15: =+Income_Statement_Qtr!P15 -> 2246 | T15: =+Income_Statement_Qtr!U15 -> 2536 | U15: =+Income_Statement_Qtr!Z15 -> 2697 | V15: =+Income_Statement_Qtr!AE15 -> 450 | W15: =+Income_Statement_Qtr!AJ15 -> 2017 | X15: =+Income_Statement_Qtr!AO15 -> 2727 | Y15: =+Income_Statement_Qtr!AT15 -> 3329 | Z15: =+Income_Statement_Qtr!AY15 -> 3618 | AA15: =+Income_Statement_Qtr!BD15 -> 13474 | AB15: =+Income_Statement_Qtr!BI15 -> 3818.4475 | AC15: =BGS_Annual!AC19 -> 3881.2165 | AD15: =BGS_Annual!AD19 -> 4114.0895 | AE15: =BGS_Annual!AE19 -> 4360.9349 | AF15: =BGS_Annual!AF19 -> 4622.591
A16: =Income_Statement_Qtr!A16 -> Boeing Capital (BCC) | B16: 516 | C16: 562 | D16: 72 | E16: 91 | F16: 183 | G16: 232 | H16: 291 | I16: 234 | J16: 162 | K16: 126 | L16: 152 | M16: 113 | N16: 88 | O16: 107 | P16: 92 | Q16: =+Income_Statement_Qtr!F16 -> 50 | R16: =+Income_Statement_Qtr!K16 -> 59 | S16: =+Income_Statement_Qtr!P16 -> 114 | T16: =+Income_Statement_Qtr!U16 -> 79 | U16: =+Income_Statement_Qtr!Z16 -> 28 | V16: =+Income_Statement_Qtr!AE16 -> 63 | W16: =+Income_Statement_Qtr!AJ16 -> 106 | X16: =+Income_Statement_Qtr!AO16 -> 29 | Y16: =+Income_Statement_Qtr!AT16 -> 0 | Z16: =+Income_Statement_Qtr!AY16 -> 0 | AA16: =+Income_Statement_Qtr!BD16 -> 0 | AB16: =+Income_Statement_Qtr!BI16 -> 0 | AC16: 0 | AD16: 0 | AE16: 0 | AF16: 0
A17: =Income_Statement_Qtr!A17 -> Commercial Airplanes (BCA) (Old) | B17: 2736 | C17: 2632 | D17: 2017 | E17: 1048 | F17: 1308 | G17: 1431 | H17: 2733 | I17: 3584 | J17: 3809.1385 | K17: 3462 | L17: 3006 | M17: 3495 | N17: 4711 | O17: 5795 | P17: 6411 | Q17: =+Income_Statement_Qtr!F17 -> 5157 | R17: =+Income_Statement_Qtr!K17 -> 0 | S17: =+Income_Statement_Qtr!P17 -> 0 | T17: =+Income_Statement_Qtr!U17 -> 0 | U17: =+Income_Statement_Qtr!Z17 -> 0 | V17: =+Income_Statement_Qtr!AE17 -> 0 | W17: =+Income_Statement_Qtr!AJ17 -> 0 | X17: =+Income_Statement_Qtr!AO17 -> 0 | Y17: =+Income_Statement_Qtr!AT17 -> 0 | Z17: =+Income_Statement_Qtr!AY17 -> 0 | AA17: =+Income_Statement_Qtr!BD17 -> 0 | AB17: =+Income_Statement_Qtr!BI17 -> 0 | AC17: 0 | AD17: 0 | AE17: 0 | AF17: 0
A18: =Income_Statement_Qtr!A18 -> Defense, Space & Security (BDS) (Old) | B18: 1002 | C18: 1965 | D18: 2009 | E18: 1338 | F18: 2925 | G18: 3919 | H18: 3032 | I18: 3440 | J18: 3480 | K18: 3299 | L18: 2875 | M18: 3158 | N18: 3068 | O18: 3235 | P18: 3133 | Q18: =+Income_Statement_Qtr!F18 -> 3274 | R18: =+Income_Statement_Qtr!K18 -> 0 | S18: =+Income_Statement_Qtr!P18 -> 0 | T18: =+Income_Statement_Qtr!U18 -> 0 | U18: =+Income_Statement_Qtr!Z18 -> 0 | V18: =+Income_Statement_Qtr!AE18 -> 0 | W18: =+Income_Statement_Qtr!AJ18 -> 0 | X18: =+Income_Statement_Qtr!AO18 -> 0 | Y18: =+Income_Statement_Qtr!AT18 -> 0 | Z18: =+Income_Statement_Qtr!AY18 -> 0 | AA18: =+Income_Statement_Qtr!BD18 -> 0 | AB18: =+Income_Statement_Qtr!BI18 -> 0 | AC18: 0 | AD18: 0 | AE18: 0 | AF18: 0
A19: =Income_Statement_Qtr!A19 -> Unallocated Items, Eliminations and Other | B19: -76 | C19: -354 | D19: -432 | E19: -379 | F19: -535 | G19: -363 | H19: -738 | I19: -331 | J19: -307 | K19: -152 | L19: -327 | M19: 66 | N19: -186 | O19: 0 | P19: 0 | Q19: =+Income_Statement_Qtr!F19 -> 0 | R19: =+Income_Statement_Qtr!K19 -> 0 | S19: =+Income_Statement_Qtr!P19 -> 0 | T19: =+Income_Statement_Qtr!U19 -> 0 | U19: =+Income_Statement_Qtr!Z19 -> 0 | V19: =+Income_Statement_Qtr!AE19 -> 0 | W19: =+Income_Statement_Qtr!AJ19 -> 0 | X19: =+Income_Statement_Qtr!AO19 -> 0 | Y19: =+Income_Statement_Qtr!AT19 -> 0 | Z19: =+Income_Statement_Qtr!AY19 -> 0 | AA19: =+Income_Statement_Qtr!BD19 -> 0 | AB19: =+Income_Statement_Qtr!BI19 -> 0 | AC19: 0 | AD19: 0 | AE19: 0 | AF19: 0
A20: =Income_Statement_Qtr!A20 -> Business Segment Operating Profit | B20: =SUM(B13:B19) -> 4178 | C20: =SUM(C13:C19) -> 4805 | D20: =SUM(D13:D19) -> 3666 | E20: =SUM(E13:E19) -> 2098 | F20: =SUM(F13:F19) -> 3881 | G20: =SUM(G13:G19) -> 5219 | H20: =SUM(H13:H19) -> 5318 | I20: =SUM(I13:I19) -> 6927 | ... AF20: =SUM(AF13:AF19) -> 12910.196
A22: =Income_Statement_Qtr!A22 -> Pension FAS/CAS Service Cost Adjustment | B22: ND | C22: ND | D22: ND | E22: 463 | F22: 27 | G22: -846 | H22: -369 | I22: -561 | J22: -208 | K22: 110 | L22: 54 | M22: -269 | N22: -787 | O22: -1374 | P22: -1469 | Q22: =Income_Statement_Qtr!F22 -> -421 | R22: =Income_Statement_Qtr!K22 -> 217 | S22: =Income_Statement_Qtr!P22 -> 1127 | T22: =Income_Statement_Qtr!U22 -> 1005 | U22: =Income_Statement_Qtr!Z22 -> 1071 | V22: =Income_Statement_Qtr!AE22 -> 1024 | W22: =Income_Statement_Qtr!AJ22 -> 882 | X22: =Income_Statement_Qtr!AO22 -> 849 | Y22: =Income_Statement_Qtr!AT22 -> 799 | Z22: =Income_Statement_Qtr!AY22 -> 811 | AA22: =Income_Statement_Qtr!BD22 -> 784 | AB22: =Income_Statement_Qtr!BI22 -> 850 | AC22: 850 | AD22: 850 | AE22: 850 | AF22: 850
A23: =Income_Statement_Qtr!A23 -> Postretirement FAS/CAS Service Cost Adjustment | B23: ND | C23: ND | D23: ND | E23: -257 | F23: -285 | G23: -5 | H23: -103 | I23: -125 | J23: -79 | K23: -93 | L23: -59 | M23: -248 | N23: -112 | O23: 60 | P23: 82 | Q23: =Income_Statement_Qtr!F23 -> 123 | R23: =Income_Statement_Qtr!K23 -> 153 | S23: =Income_Statement_Qtr!P23 -> 311 | T23: =Income_Statement_Qtr!U23 -> 322 | U23: =Income_Statement_Qtr!Z23 -> 344 | V23: =Income_Statement_Qtr!AE23 -> 359 | W23: =Income_Statement_Qtr!AJ23 -> 291 | X23: =Income_Statement_Qtr!AO23 -> 294 | Y23: =Income_Statement_Qtr!AT23 -> 257 | Z23: =Income_Statement_Qtr!AY23 -> 293 | AA23: =Income_Statement_Qtr!BD23 -> 261 | AB23: =Income_Statement_Qtr!BI23 -> 260 | AC23: 260 | AD23: 260 | AE23: 260 | AF23: 260
A24: =Income_Statement_Qtr!A24 -> FAS/CAS Operating Adjustment | B24: =SUM(B22:B23) -> 0 | C24: =SUM(C22:C23) -> 0 | D24: =SUM(D22:D23) -> 0 | E24: =SUM(E22:E23) -> 206 | F24: =SUM(F22:F23) -> -258 | G24: =SUM(G22:G23) -> -851 | H24: =SUM(H22:H23) -> -472 | I24: =SUM(I22:I23) -> -686 | ... AF24: =SUM(AF22:AF23) -> 1110
A25: =Income_Statement_Qtr!A25 -> Share-Based Plans | B25: -316 | C25: -378 | D25: -447 | E25: -456 | F25: -576 | G25: =-999 -> -999 | H25: -680 | I25: -233 | J25: -149 | K25: -189 | L25: -136 | M25: -83 | N25: -81 | O25: -95 | P25: -67 | Q25: =Income_Statement_Qtr!F25 -> -76 | R25: =Income_Statement_Qtr!K25 -> -66 | S25: =Income_Statement_Qtr!P25 -> -77 | T25: =Income_Statement_Qtr!U25 -> -76 | U25: =Income_Statement_Qtr!Z25 -> -65 | V25: =Income_Statement_Qtr!AE25 -> -120 | W25: =Income_Statement_Qtr!AJ25 -> -174 | X25: =Income_Statement_Qtr!AO25 -> -114 | Y25: =Income_Statement_Qtr!AT25 -> 62 | Z25: =Income_Statement_Qtr!AY25 -> 171 | AA25: =Income_Statement_Qtr!BD25 -> -49 | AB25: =Income_Statement_Qtr!BI25 -> 50.5 | AC25: 51.005 | AD25: 51.51505 | AE25: 52.0302 | AF25: 52.0302
A26: =Income_Statement_Qtr!A26 -> Deferred Compensation | B26: 0 | C26: 0 | D26: 0 | E26: 0 | F26: 0 | G26: -186 | H26: -211 | I26: -51 | J26: 223 | K26: -158 | L26: -112 | M26: -61 | N26: -75 | O26: -238 | P26: -44 | Q26: =Income_Statement_Qtr!F26 -> -63 | R26: =Income_Statement_Qtr!K26 -> -46 | S26: =Income_Statement_Qtr!P26 -> -240 | T26: =Income_Statement_Qtr!U26 -> -19 | U26: =Income_Statement_Qtr!Z26 -> -174 | V26: =Income_Statement_Qtr!AE26 -> -93 | W26: =Income_Statement_Qtr!AJ26 -> -126 | X26: =Income_Statement_Qtr!AO26 -> 117 | Y26: =Income_Statement_Qtr!AT26 -> -188 | Z26: =Income_Statement_Qtr!AY26 -> -114 | AA26: =Income_Statement_Qtr!BD26 -> -182 | AB26: =Income_Statement_Qtr!BI26 -> -130 | AC26: -130 | AD26: -130 | AE26: -130 | AF26: -130
A27: =Income_Statement_Qtr!A27 -> Amortization of Previously Capitalized Interest | B27: 0 | C27: 0 | D27: 0 | E27: -53 | F27: -48 | G27: -47 | H27: -48 | I27: -53 | J27: -44 | K27: -53 | L27: -54 | M27: -51 | N27: -70 | O27: -69 | P27: -72 | Q27: =Income_Statement_Qtr!F27 -> -90 | R27: =Income_Statement_Qtr!K27 -> -94 | S27: =Income_Statement_Qtr!P27 -> -96 | T27: =Income_Statement_Qtr!U27 -> -92 | U27: =Income_Statement_Qtr!Z27 -> -89 | V27: =Income_Statement_Qtr!AE27 -> -95 | W27: =Income_Statement_Qtr!AJ27 -> -107 | X27: =Income_Statement_Qtr!AO27 -> -95 | Y27: =Income_Statement_Qtr!AT27 -> -95 | Z27: =Income_Statement_Qtr!AY27 -> -93 | AA27: =Income_Statement_Qtr!BD27 -> -92 | AB27: =Income_Statement_Qtr!BI27 -> -100 | AC27: -100 | AD27: -100 | AE27: -100 | AF27: -100
A28: =Income_Statement_Qtr!A28 -> Customer Financing Impairment | B28: 0 | C28: 0 | D28: 0 | E28: 0 | F28: 0 | G28: 0 | H28: 0 | I28: 0 | J28: 0 | K28: 0 | L28: 0 | M28: 0 | N28: 0 | O28: 0 | P28: 0 | Q28: =Income_Statement_Qtr!F28 -> 0 | R28: =Income_Statement_Qtr!K28 -> 0 | S28: =Income_Statement_Qtr!P28 -> 0 | T28: =Income_Statement_Qtr!U28 -> 0 | U28: =Income_Statement_Qtr!Z28 -> -250 | V28: =Income_Statement_Qtr!AE28 -> 0 | W28: =Income_Statement_Qtr!AJ28 -> 0 | X28: =Income_Statement_Qtr!AO28 -> 0 | Y28: =Income_Statement_Qtr!AT28 -> 0 | Z28: =Income_Statement_Qtr!AY28 -> 0 | AA28: =Income_Statement_Qtr!BD28 -> 0 | AB28: =Income_Statement_Qtr!BI28 -> 0 | AC28: 0 | AD28: 0 | AE28: 0 | AF28: 0
A29: =Income_Statement_Qtr!A29 -> Research and Development Expense, net | B29: 0 | C29: 0 | D29: 0 | E29: 0 | F29: 0 | G29: 0 | H29: 0 | I29: 0 | J29: 0 | K29: 0 | L29: 0 | M29: 0 | N29: 0 | O29: 0 | P29: 0 | Q29: =Income_Statement_Qtr!F29 -> 0 | R29: =Income_Statement_Qtr!K29 -> 0 | S29: =Income_Statement_Qtr!P29 -> 0 | T29: =Income_Statement_Qtr!U29 -> -132 | U29: =Income_Statement_Qtr!Z29 -> -384 | V29: =Income_Statement_Qtr!AE29 -> -240 | W29: =Income_Statement_Qtr!AJ29 -> -184 | X29: =Income_Statement_Qtr!AO29 -> -278 | Y29: =Income_Statement_Qtr!AT29 -> -315 | Z29: =Income_Statement_Qtr!AY29 -> -377 | AA29: =Income_Statement_Qtr!BD29 -> -411 | AB29: =Income_Statement_Qtr!BI29 -> -375 | AC29: -375 | AD29: -375 | AE29: -375 | AF29: -375
A30: =Income_Statement_Qtr!A30 -> Eliminations and Other Unallocated Items | B30: =-442-362 -> -804 | C30: =-368-163 -> -531 | D30: =424-193 -> 231 | E30: =-128-36-320 -> -484 | F30: =15-112-340 -> -437 | G30: =-324 -> -324 | H30: =-322+320+15 -> 13 | I30: -74 | J30: -66 | K30: -211 | L30: -428 | M30: -276 | N30: -266 | O30: =-859+406 -> -453 | P30: -593 | Q30: =Income_Statement_Qtr!F30 -> -511 | R30: =Income_Statement_Qtr!K30 -> -527 | S30: =Income_Statement_Qtr!P30 -> -686 | T30: =Income_Statement_Qtr!U30 -> -1123 | U30: =Income_Statement_Qtr!Z30 -> -1104 | V30: =Income_Statement_Qtr!AE30 -> -1807 | W30: =Income_Statement_Qtr!AJ30 -> -676 | X30: =Income_Statement_Qtr!AO30 -> -1162 | Y30: =Income_Statement_Qtr!AT30 -> -1223 | Z30: =Income_Statement_Qtr!AY30 -> -1634 | AA30: =Income_Statement_Qtr!BD30 -> -2297 | AB30: =Income_Statement_Qtr!BI30 -> -2064.2292 | AC30: -1650.34 | AD30: -1650.34 | AE30: -1650.34 | AF30: -1650.34
A31: =Income_Statement_Qtr!A31 -> Total Unallocated Items | B31: =SUM(B24:B30) -> -1120 | C31: =SUM(C24:C30) -> -909 | D31: =SUM(D24:D30) -> -216 | E31: =SUM(E24:E30) -> -787 | F31: =SUM(F24:F30) -> -1319 | G31: =SUM(G24:G30) -> -2407 | H31: =SUM(H24:H30) -> -1398 | I31: =SUM(I24:I30) -> -1097 | ... AF31: =SUM(AF24:AF30) -> -1093.3098
A32: =Income_Statement_Qtr!A32 -> Settlement With U.S. Department of Justice, net of Accruals | B32: 0 | C32: 0 | D32: 0 | E32: 0 | F32: 0 | G32: 0 | H32: =-571+571 -> 0 | I32: 0 | J32: 0 | K32: 0 | L32: 0 | M32: 0 | N32: 0 | O32: 0 | P32: 0 | Q32: =Income_Statement_Qtr!F32 -> 0 | R32: =Income_Statement_Qtr!K32 -> 0 | S32: =Income_Statement_Qtr!P32 -> 0 | T32: =Income_Statement_Qtr!U32 -> 0 | U32: =Income_Statement_Qtr!Z32 -> 0 | V32: =Income_Statement_Qtr!AE32 -> 0 | W32: =Income_Statement_Qtr!AJ32 -> 0 | X32: =Income_Statement_Qtr!AO32 -> 0 | Y32: =Income_Statement_Qtr!AT32 -> 0 | Z32: =Income_Statement_Qtr!AY32 -> 0 | AA32: =Income_Statement_Qtr!BD32 -> 0 | AB32: =Income_Statement_Qtr!BI32 -> 0 | AC32: 0 | AD32: 0 | AE32: 0 | AF32: 0
A34: =Income_Statement_Qtr!A34 -> Operating Profit | B34: =B20+B31+B32 -> 3058 | C34: =C20+C31+C32 -> 3896 | D34: =D20+D31+D32 -> 3450 | E34: =E20+E31+E32 -> 1311 | F34: =F20+F31+F32 -> 2562 | G34: =G20+G31+G32 -> 2812 | H34: =H20+H31+H32 -> 3920 | I34: =I20+I31+I32 -> 5830 | ... AF34: =AF20+AF31+AF32 -> 11816.886
A35: =Income_Statement_Qtr!A35 -> Operating Margin | B35: =B34/B10 -> 0.059585745 | C35: =C34/C10 -> 0.066943881 | D35: =D34/D10 -> 0.0638168 | E35: =E34/E10 -> 0.026086437 | F35: =F34/F10 -> 0.048840002 | G35: =G34/G10 -> 0.05244214 | H35: =H34/H10 -> 0.06370876 | I35: =I34/I10 -> 0.087818398 | ... P35: =P34/P10 -> 0.08233622 | Q35: =+Income_Statement_Qtr!F35 -> 0.077439291 | R35: =+Income_Statement_Qtr!K35 -> 0.061689101 | S35: =+Income_Statement_Qtr!P35 -> 0.1100367 | T35: =+Income_Statement_Qtr!U35 -> 0.11853412 | U35: =+Income_Statement_Qtr!Z35 -> -0.025797098 | V35: =+Income_Statement_Qtr!AE35 -> -0.21952268 | W35: =+Income_Statement_Qtr!AJ35 -> -0.046591529 | X35: =+Income_Statement_Qtr!AO35 -> -0.053251862 | Y35: =+Income_Statement_Qtr!AT35 -> -0.009936499 | Z35: =+Income_Statement_Qtr!AY35 -> -0.16096637 | AA35: =+Income_Statement_Qtr!BD35 -> 0.047852185 | AB35: =+Income_Statement_Qtr!BI35 -> 0.021180306 | AC35: =AC34/AC10 -> 0.080105509 | AD35: =AD34/AD10 -> 0.096054345 | AE35: =AE34/AE10 -> 0.097051619 | AF35: =AF34/AF10 -> 0.098191593
A37: =Income_Statement_Qtr!A37 -> Interest and Debt Expense | B37: -445 | C37: -650 | D37: -320 | E37: -358 | F37: -335 | G37: -294 | H37: -240 | I37: -196 | J37: -202 | K37: -339 | L37: -516 | M37: -498 | N37: -442 | O37: -386 | P37: -333 | Q37: =+Income_Statement_Qtr!F37 -> -275 | R37: =+Income_Statement_Qtr!K37 -> -306 | S37: =+Income_Statement_Qtr!P37 -> -360 | T37: =+Income_Statement_Qtr!U37 -> -475 | U37: =+Income_Statement_Qtr!Z37 -> -722 | V37: =+Income_Statement_Qtr!AE37 -> -2156 | W37: =+Income_Statement_Qtr!AJ37 -> -2682 | X37: =+Income_Statement_Qtr!AO37 -> -2533 | Y37: =+Income_Statement_Qtr!AT37 -> -2459 | Z37: =+Income_Statement_Qtr!AY37 -> -2725 | AA37: =+Income_Statement_Qtr!BD37 -> -2771 | AB37: =+Income_Statement_Qtr!BI37 -> -2709.1483 | AC37: =-Debt_Annual!AC202 -> -2479.2937 | AD37: =-Debt_Annual!AD202 -> -2263.4693 | AE37: =-Debt_Annual!AE202 -> -2132.2887 | AF37: =-Debt_Annual!AF202 -> -2132.0712
A38: =Income_Statement_Qtr!A38 -> Non-Operating FAS Pension Cost | B38: 0 | C38: 0 | D38: 0 | E38: 0 | F38: 0 | G38: 0 | H38: 0 | I38: 0 | J38: 0 | K38: 0 | L38: 0 | M38: 0 | N38: 0 | O38: 0 | P38: 0 | Q38: =Income_Statement_Qtr!F38 -> 0 | R38: =Income_Statement_Qtr!K38 -> 0 | S38: =Income_Statement_Qtr!P38 -> 0 | T38: =Income_Statement_Qtr!U38 -> 0 | U38: =Income_Statement_Qtr!$Z$38 -> 0 | V38: =Income_Statement_Qtr!AE$38 -> 0 | W38: =Income_Statement_Qtr!AJ$38 -> 0 | X38: =Income_Statement_Qtr!AO$38 -> 0 | Y38: =Income_Statement_Qtr!AT$38 -> 0 | Z38: =Income_Statement_Qtr!AY$38 -> 0 | AA38: =Income_Statement_Qtr!BD$38 -> 0 | AB38: =Income_Statement_Qtr!BI$38 -> 0 | AC38: =AB38 -> 0 | AD38: =AC38 -> 0 | AE38: =AD38 -> 0 | AF38: =AE38 -> 0
A39: =Income_Statement_Qtr!A39 -> Other Non-Operating Expense/ Income, Net | B39: 386 | C39: 318 | D39: 50 | E39: 460 | F39: =288-219 -> 69 | G39: =301-64 -> 237 | H39: 420 | I39: 484 | J39: 247 | K39: -26 | L39: 52 | M39: 47 | N39: 62 | O39: 56 | P39: -3 | Q39: =+Income_Statement_Qtr!F39 -> -13 | R39: =+Income_Statement_Qtr!K39 -> 40 | S39: =+Income_Statement_Qtr!P39 -> 123 | T39: =+Income_Statement_Qtr!U39 -> 92 | U39: =+Income_Statement_Qtr!Z39 -> 438 | V39: =+Income_Statement_Qtr!AE39 -> 447 | W39: =+Income_Statement_Qtr!AJ39 -> 551 | X39: =+Income_Statement_Qtr!AO39 -> 1058 | Y39: =+Income_Statement_Qtr!AT39 -> 1227 | Z39: =+Income_Statement_Qtr!AY39 -> 1222 | AA39: =+Income_Statement_Qtr!BD39 -> 1125 | AB39: =+Income_Statement_Qtr!BI39 -> 1125 | AC39: =AB39 -> 1125 | AD39: =AC39 -> 1125 | AE39: =AD39 -> 1125 | AF39: =AE39 -> 1125
A40: =Income_Statement_Qtr!A40 -> Pre-Tax Income | B40: =SUM(B34,B37:B39) -> 2999 | C40: =SUM(C34,C37:C39) -> 3564 | D40: =SUM(D34,D37:D39) -> 3180 | E40: =SUM(E34,E37:E39) -> 1413 | F40: =SUM(F34,F37:F39) -> 2296 | G40: =SUM(G34,G37:G39) -> 2755 | H40: =SUM(H34,H37:H39) -> 4100 | I40: =SUM(I34,I37:I39) -> 6118 | ... AF40: =SUM(AF34,AF37:AF39) -> 10809.815
A41: =Income_Statement_Qtr!A41 -> YoY | B41: =B40/3324-1 -> -0.097773767 | C41: =C40/B40-1 -> 0.18839613 | D41: =D40/C40-1 -> -0.10774411 | E41: =E40/D40-1 -> -0.55566038 | F41: =F40/E40-1 -> 0.62491154 | G41: =G40/F40-1 -> 0.19991289 | H41: =H40/G40-1 -> 0.48820327 | I41: =I40/H40-1 -> 0.49219512 | J41: =J40/I40-1 -> 0.12228481 | ... P41: =P40/O40-1 -> 0.075173245 | Q41: =+Income_Statement_Qtr!F41 -> 0.0025220681 | R41: =+Income_Statement_Qtr!K41 -> -0.22180294 | S41: =+Income_Statement_Qtr!P41 -> 0.81519397 | T41: =+Income_Statement_Qtr!U41 -> 0.14811517 | U41: =+Income_Statement_Qtr!Z41 -> -1.1946743 | V41: =+Income_Statement_Qtr!AE41 -> 5.4081452 | W41: =+Income_Statement_Qtr!AJ41 -> -0.65232108 | X41: =+Income_Statement_Qtr!AO41 -> -0.0021855752 | Y41: =+Income_Statement_Qtr!AT41 -> -0.60075667 | Z41: =+Income_Statement_Qtr!AY41 -> 5.0897756 | AA41: =+Income_Statement_Qtr!BD41 -> -1.2158067 | AB41: =+Income_Statement_Qtr!BI41 -> -0.79967913 | AC41: =AC40/AB40-1 -> 12.881748 | AD41: =AD40/AC40-1 -> 0.32740573 | AE41: =AE40/AD40-1 -> 0.064328541 | AF41: =AF40/AE40-1 -> 0.044210125
A43: =Income_Statement_Qtr!A43 -> Income Tax Benefit/ (Expense) | B43: -871 | C43: -738 | D43: -861 | E43: =185-(913-(1.01*808.9)) -> 88.989 | F43: =-140-((280+275)-0.44*813)+(219-(0.17*813))-367 -> -623.49 | G43: =-257-570+(64-(0.05*802.9)) -> -803.145 | H43: =-988-((320+15)-(0.24*787.6))+16 -> -1117.976 | I43: -2060 | J43: =-1341-(((2.56*729)/(1-35%))-(2.56*729)) -> -2345.8985 | K43: =-396-((2693+1352)-(3.58*713.4)) -> -1887.028 | L43: =-1196-0.5*744.3+0.2*744.3 -> -1419.29 | M43: =-1382-0.53*750.6 -> -1779.818 | N43: -2007 | O43: =-1646-(406-0.34*767.6) -> -1791.016 | P43: -1691 | Q43: =+Income_Statement_Qtr!F43 -> -1979 | R43: =+Income_Statement_Qtr!K43 -> -673 | S43: =+Income_Statement_Qtr!P43 -> -1649 | T43: =+Income_Statement_Qtr!U43 -> -1144 | U43: =+Income_Statement_Qtr!Z43 -> 1623 | V43: =+Income_Statement_Qtr!AE43 -> 2535 | W43: =+Income_Statement_Qtr!AJ43 -> 743 | X43: =+Income_Statement_Qtr!AO43 -> -31 | Y43: =+Income_Statement_Qtr!AT43 -> -237 | Z43: =+Income_Statement_Qtr!AY43 -> 381 | AA43: =+Income_Statement_Qtr!BD43 -> -397 | AB43: =+Income_Statement_Qtr!BI43 -> -52.784551 | AC43: =IF(AC40<0,0,-AC40*AC44) -> -1450.8288 | AD43: =IF(AD40<0,0,-AD40*AD44) -> -1989.0604 | AE43: =IF(AE40<0,0,-AE40*AE44) -> -2122.1898 | AF43: =IF(AF40<0,0,-AF40*AF44) -> -2216.0121
A44: =Income_Statement_Qtr!A44 -> Tax Rate | B44: =IF(B43>0,"NM",-B43/B40) -> 0.29043014 | C44: =IF(C43>0,"NM",-C43/C40) -> 0.20707071 | D44: =IF(D43>0,"NM",-D43/D40) -> 0.27075472 | E44: =IF(E43>0,"NM",-E43/E40) -> NM | F44: =IF(F43>0,"NM",-F43/F40) -> 0.27155488 | G44: =IF(G43>0,"NM",-G43/G40) -> 0.29152269 | H44: =IF(H43>0,"NM",-H43/H40) -> 0.27267707 | I44: =IF(I43>0,"NM",-I43/I40) -> 0.33671134 | ... P44: =IF(P43>0,"NM",-P43/P40) -> 0.23693429 | Q44: =+Income_Statement_Qtr!F44 -> 0.2765898 | R44: =+Income_Statement_Qtr!K44 -> 0.12086925 | S44: =+Income_Statement_Qtr!P44 -> 0.16315425 | T44: =+Income_Statement_Qtr!U44 -> 0.098586694 | U44: =+Income_Statement_Qtr!Z44 -> NM | V44: =+Income_Statement_Qtr!AE44 -> NM | W44: =+Income_Statement_Qtr!AJ44 -> NM | X44: =+Income_Statement_Qtr!AO44 -> -0.0061728395 | Y44: =+Income_Statement_Qtr!AT44 -> -0.11820449 | Z44: =+Income_Statement_Qtr!AY44 -> NM | AA44: =+Income_Statement_Qtr!BD44 -> -0.05915 | AB44: =+Income_Statement_Qtr!BI44 -> 0.1 | AC44: 0.198 | AD44: 0.2045 | AE44: 0.205 | AF44: 0.205
A46: =Income_Statement_Qtr!A46 -> Net earnings | B46: =B43+B40 -> 2128 | C46: =C43+C40 -> 2826 | D46: =D43+D40 -> 2319 | E46: =E43+E40 -> 1501.989 | F46: =F43+F40 -> 1672.51 | G46: =G43+G40 -> 1951.855 | H46: =H43+H40 -> 2982.024 | I46: =I43+I40 -> 4058 | ... AF46: =AF43+AF40 -> 8593.8031
...

Sheet Income_Statement_Qtr
A1: Income Statement Quarter
B2: 1Q15A | C2: 2Q15A | D2: 3Q15A | E2: 4Q15A | F2: CY2015A | G2: 1Q16A | H2: 2Q16A | I2: 3Q16A | J2: 4Q16A | K2: CY2016A | L2: 1Q17A | M2: 2Q17A | N2: 3Q17A | O2: 4Q17A | P2: CY2017A | Q2: 1Q18A | R2: 2Q18A | S2: 3Q18A | T2: 4Q18A | U2: CY2018A | V2: 1Q19A | W2: 2Q19A | X2: 3Q19A | Y2: 4Q19A | Z2: CY2019A | AA2: 1Q20A | AB2: 2Q20A | AC2: 3Q20A | AD2: 4Q20A | AE2: CY2020E | AF2: 1Q21A | AG2: 2Q21A | AH2: 3Q21A | AI2: 4Q21A | AJ2: CY2021A | AK2: 1Q22A | AL2: 2Q22A | AM2: 3Q22A | AN2: 4Q22A | AO2: CY2022A | AP2: 1Q23A | AQ2: 2Q23A | AR2: 3Q23A | AS2: 4Q23A | AT2: CY2023A | AU2: 1Q24A | AV2: 2Q24A | AW2: 3Q24A | AX2: 4Q24A | AY2: CY2024A | AZ2: 1Q25A | BA2: 2Q25A | BB2: 3Q25A | BC2: 4Q25A | BD2: CY2025A | BE2: 1Q26E | BF2: 2Q26E | BG2: 3Q26E | BH2: 4Q26E | BI2: CY2026E
A3: Commercial Airplanes (BCA) | B3: =BCA_Qtr!B3 -> 0 | C3: =BCA_Qtr!C3 -> 0 | D3: =BCA_Qtr!D3 -> 0 | E3: =BCA_Qtr!E3 -> 0 | F3: =BCA_Qtr!F3 -> 0 | G3: =BCA_Qtr!G3 -> 12787 | H3: =BCA_Qtr!H3 -> 15643 | I3: =BCA_Qtr!I3 -> 15200 | ... BI3: =BCA_Qtr!BI3 -> 50763.127
A4: Defense, Space & Security (BDS) | B4: =BDS_Qtr!B3 -> 0 | C4: =BDS_Qtr!C3 -> 0 | D4: =BDS_Qtr!D3 -> 0 | E4: =BDS_Qtr!E3 -> 0 | F4: =BDS_Qtr!F3 -> 0 | G4: =BDS_Qtr!G3 -> 6136 | H4: =BDS_Qtr!H3 -> 5394 | I4: =BDS_Qtr!I3 -> 5751 | ... BI4: =BDS_Qtr!BI3 -> 28228.851
A5: Global Services (BGS) | B5: =BGS_Qtr!B3 -> 0 | C5: =BGS_Qtr!C3 -> 0 | D5: =BGS_Qtr!D3 -> 0 | E5: =BGS_Qtr!E3 -> 0 | F5: =BGS_Qtr!F3 -> 0 | G5: =BGS_Qtr!G3 -> 3421 | H5: =BGS_Qtr!H3 -> 3581 | I5: =BGS_Qtr!I3 -> 3506 | ... BI5: =BGS_Qtr!BI3 -> 20923
A6: Boeing Capital (BCC) (Old | B6: 86 | C6: 115 | D6: 114 | E6: 98 | F6: 413 | G6: 64 | H6: 84 | I6: 63 | J6: 87 | K6: 298 | L6: 92 | M6: 72 | N6: 70 | O6: 73 | P6: 307 | Q6: 65 | R6: 72 | S6: 77 | T6: 60 | U6: 274 | V6: 66 | W6: 75 | X6: 66 | Y6: 37 | Z6: 244 | AA6: 65 | AB6: 69 | AC6: 71 | AD6: 56 | AE6: 261 | AF6: 60 | AG6: 78 | AH6: 71 | AI6: 63 | AJ6: 272 | AK6: 46 | AL6: 52 | AM6: 52 | AN6: 49 | AO6: 199 | AU6: 0 | AV6: 0 | AZ6: 0 | BA6: 0 | BB6: 0 | BC6: 0 | BD6: =SUM(AZ6:BC6) -> 0 | BE6: 0 | BF6: 0 | BG6: 0 | BH6: 0 | BI6: =SUM(BE6:BH6) -> 0
A7: Commercial Airplanes (BCA) (Old) | B7: 15381 | C7: 16877 | D7: 17692 | E7: 16098 | F7: 66048 | G7: 0 | H7: 0 | I7: 0 | J7: =K7-SUM(G7,H7,I7) -> 0 | K7: 0 | L7: 0 | M7: 0 | N7: 0 | O7: =P7-SUM(L7,M7,N7) -> 0 | P7: 0 | Q7: 0 | R7: 0 | S7: 0 | T7: =U7-SUM(Q7,R7,S7) -> 0 | U7: 0 | V7: 0 | W7: 0 | X7: 0 | Y7: =Z7-SUM(V7,W7,X7) -> 0 | Z7: 0 | AA7: 0 | AB7: 0 | AC7: 0 | AD7: 0 | AE7: =SUM(AA7:AD7) -> 0 | AF7: 0 | AG7: 0 | AH7: 0 | AI7: 0 | AJ7: =SUM(AF7:AI7) -> 0 | AK7: 0 | AL7: 0 | AM7: 0 | AN7: 0 | AO7: =SUM(AK7:AN7) -> 0 | AT7: =SUM(AP7:AS7) -> 0 | AU7: 0 | AV7: 0 | AY7: =SUM(AU7:AX7) -> 0 | AZ7: 0 | BA7: 0 | BB7: 0 | BC7: 0 | BD7: =SUM(AZ7:BC7) -> 0 | BE7: 0 | BF7: 0 | BG7: 0 | BH7: 0 | BI7: =SUM(BE7:BH7) -> 0
A8: Defense, Space & Security (BDS) (Old) | B8: 6709 | C8: 7544 | D8: 8350 | E8: 7785 | F8: 30388 | G8: 0 | H8: 0 | I8: 0 | J8: =K8-SUM(G8,H8,I8) -> 0 | K8: 0 | L8: 0 | M8: 0 | N8: 0 | O8: =P8-SUM(L8,M8,N8) -> 0 | P8: 0 | Q8: 0 | R8: 0 | S8: 0 | T8: =U8-SUM(Q8,R8,S8) -> 0 | U8: 0 | V8: 0 | W8: 0 | X8: 0 | Y8: =Z8-SUM(V8,W8,X8) -> 0 | Z8: 0 | AA8: 0 | AB8: 0 | AC8: 0 | AD8: 0 | AE8: =SUM(AA8:AD8) -> 0 | AF8: 0 | AG8: 0 | AH8: 0 | AI8: 0 | AJ8: =SUM(AF8:AI8) -> 0 | AK8: 0 | AL8: 0 | AM8: 0 | AN8: 0 | AO8: =SUM(AK8:AN8) -> 0 | AT8: =SUM(AP8:AS8) -> 0 | AU8: 0 | AV8: 0 | AY8: =SUM(AU8:AX8) -> 0 | AZ8: 0 | BA8: 0 | BB8: 0 | BC8: 0 | BD8: =SUM(AZ8:BC8) -> 0 | BE8: 0 | BF8: 0 | BG8: 0 | BH8: 0 | BI8: =SUM(BE8:BH8) -> 0
A9: Unallocated Items, Eliminations and Other | B9: -27 | C9: 7 | D9: -307 | E9: =F9-SUM(B9,C9,D9) -> -408 | F9: -735 | G9: 224 | H9: 53 | I9: -622 | J9: =K9-SUM(G9,H9,I9) -> 118 | K9: -227 | L9: 151 | M9: 5 | N9: 131 | O9: =P9-SUM(L9,M9,N9) -> 255 | P9: 542 | Q9: -59 | R9: 37 | S9: -40 | T9: =U9-SUM(Q9,R9,S9) -> -32 | U9: -94 | V9: -177 | W9: -201 | X9: -35 | Y9: =Z9-SUM(V9,W9,X9) -> -222 | Z9: -635 | AA9: -32 | AB9: 29 | AC9: -70 | AD9: 8 | AE9: =SUM(AA9:AD9) -> -65 | AF9: -46 | AG9: -38 | AH9: -90 | AI9: -173 | AJ9: =SUM(AF9:AI9) -> -347 | AK9: -13 | AL9: -79 | AM9: -98 | AN9: =AO9-SUM(AK9:AM9) -> -41 | AO9: -231 | AP9: -42 | AQ9: -2 | AR9: -65 | AS9: =AT9-SUM(AP9:AR9) -> -58 | AT9: -167 | AU9: -79 | AV9: -47 | AW9: -40 | AX9: =AY9-SUM(AU9:AW9) -> -50 | AY9: -216 | AZ9: -12 | BA9: -23 | BB9: -96 | BC9: =BD9-SUM(AZ9:BB9) -> -57 | BD9: -188 | BE9: =$BI9/4 -> -50 | BF9: =$BI9/4 -> -50 | BG9: =$BI9/4 -> -50 | BH9: =BI9-SUM(BE9:BG9) -> -50 | BI9: -200
A10: Total Net Sales | B10: =SUM(B3:B9) -> 22149 | C10: =SUM(C3:C9) -> 24543 | D10: =SUM(D3:D9) -> 25849 | E10: =SUM(E3:E9) -> 23573 | F10: =SUM(F3:F9) -> 96114 | G10: =SUM(G3:G9) -> 22632 | H10: =SUM(H3:H9) -> 24755 | I10: =SUM(I3:I9) -> 23898 | ... BI10: =SUM(BI3:BI9) -> 99714.978
A11: YoY | F11: =F10/Income_Statement_Annual!P10-1 -> 0.058967409 | G11: =G10/B10-1 -> 0.021806854 | H11: =H10/C10-1 -> 0.0086379008 | I11: =I10/D10-1 -> -0.075476808 | J11: =J10/E10-1 -> -0.012174946 | K11: =K10/F10-1 -> -0.016053853 | L11: =L10/G10-1 -> -0.029648286 | M11: =M10/H10-1 -> -0.068834579 | N11: =N10/I10-1 -> 0.013599464 | ... BI11: =BI10/BD10-1 -> 0.11459462
A13: Commercial Airplanes (BCA) | B13: =+BCA_Qtr!B19 -> 0 | C13: =+BCA_Qtr!C19 -> 0 | D13: =+BCA_Qtr!D19 -> 0 | E13: =+BCA_Qtr!E19 -> 0 | F13: =+BCA_Qtr!F19 -> 0 | G13: =+BCA_Qtr!G19 -> 792 | H13: =+BCA_Qtr!H19 -> -1281 | I13: =+BCA_Qtr!I19 -> 1293 | ... BI13: =+BCA_Qtr!BI19 -> -994.54108
A14: Defense, Space & Security (BDS) | B14: =+BDS_Qtr!B19 -> 0 | C14: =+BDS_Qtr!C19 -> 0 | D14: =+BDS_Qtr!D19 -> 0 | E14: =+BDS_Qtr!E19 -> 0 | F14: =+BDS_Qtr!F19 -> 0 | G14: =+BDS_Qtr!G19 -> 517 | H14: =+BDS_Qtr!H19 -> 362 | I14: =+BDS_Qtr!I19 -> 564 | ... BI14: =+BDS_Qtr!BI19 -> 796.81656
A15: Global Services (BGS) | B15: =+BGS_Qtr!B19 -> 0 | C15: =+BGS_Qtr!C19 -> 0 | D15: =+BGS_Qtr!D19 -> 0 | E15: =+BGS_Qtr!E19 -> 0 | F15: =+BGS_Qtr!F19 -> 0 | G15: =+BGS_Qtr!G19 -> 546 | H15: =+BGS_Qtr!H19 -> 539 | I15: =+BGS_Qtr!I19 -> 524 | ... BI15: =+BGS_Qtr!BI19 -> 3818.4475
A16: Boeing Capital (BCC) | B16: 20 | C16: 11 | D16: 10 | E16: 9 | F16: 50 | G16: 5 | H16: 18 | I16: 13 | J16: 23 | K16: 59 | L16: 39 | M16: 25 | N16: 23 | O16: 27 | P16: 114 | Q16: 20 | R16: 24 | S16: 27 | T16: 8 | U16: 79 | V16: 20 | W16: 37 | X16: 29 | Y16: -58 | Z16: 28 | AA16: 24 | AB16: -7 | AC16: 30 | AD16: 16 | AE16: 63 | AF16: 21 | AG16: 36 | AH16: 42 | AI16: 7 | AJ16: 106 | AK16: -36 | AL16: 27 | AM16: 23 | AN16: 15 | AO16: 29 | AU16: 0 | AV16: 0 | AZ16: 0 | BA16: 0 | BB16: 0 | BC16: 0 | BD16: =SUM(AZ16:BC16) -> 0 | BE16: 0 | BF16: 0 | BG16: 0 | BH16: 0 | BI16: =SUM(BE16:BH16) -> 0
A17: Commercial Airplanes (BCA) (Old) | B17: 1617 | C17: 1206 | D17: 1768 | E17: 566 | F17: 5157 | G17: 0 | H17: 0 | I17: 0 | J17: =K17-SUM(G17,H17,I17) -> 0 | K17: 0 | L17: 0 | M17: 0 | N17: 0 | O17: =P17-SUM(L17,M17,N17) -> 0 | P17: 0 | Q17: 0 | R17: 0 | S17: 0 | T17: =U17-SUM(Q17,R17,S17) -> 0 | U17: 0 | V17: 0 | W17: 0 | X17: 0 | Y17: =Z17-SUM(V17,W17,X17) -> 0 | Z17: 0 | AA17: 0 | AB17: 0 | AC17: 0 | AD17: 0 | AE17: =SUM(AA17:AD17) -> 0 | AF17: 0 | AG17: 0 | AH17: 0 | AI17: 0 | AJ17: =SUM(AF17:AI17) -> 0 | AK17: 0 | AL17: 0 | AM17: 0 | AN17: 0 | AO17: =SUM(AK17:AN17) -> 0 | AT17: =SUM(AP17:AS17) -> 0 | AU17: 0 | AV17: 0 | AY17: =SUM(AU17:AX17) -> 0 | AZ17: 0 | BA17: 0 | BB17: 0 | BC17: 0 | BD17: =SUM(AZ17:BC17) -> 0 | BE17: 0 | BF17: 0 | BG17: 0 | BH17: 0 | BI17: =SUM(BE17:BH17) -> 0
A18: Defense, Space & Security (BDS) (Old) | B18: 743 | C18: 546 | D18: 1022 | E18: 963 | F18: 3274 | G18: 0 | H18: 0 | I18: 0 | J18: =K18-SUM(G18,H18,I18) -> 0 | K18: 0 | L18: 0 | M18: 0 | N18: 0 | O18: =P18-SUM(L18,M18,N18) -> 0 | P18: 0 | Q18: 0 | R18: 0 | S18: 0 | T18: =U18-SUM(Q18,R18,S18) -> 0 | U18: 0 | V18: 0 | W18: 0 | X18: 0 | Y18: =Z18-SUM(V18,W18,X18) -> 0 | Z18: 0 | AA18: 0 | AB18: 0 | AC18: 0 | AD18: 0 | AE18: =SUM(AA18:AD18) -> 0 | AF18: 0 | AG18: 0 | AH18: 0 | AI18: 0 | AJ18: =SUM(AF18:AI18) -> 0 | AK18: 0 | AL18: 0 | AM18: 0 | AN18: 0 | AO18: =SUM(AK18:AN18) -> 0 | AT18: =SUM(AP18:AS18) -> 0 | AU18: 0 | AV18: 0 | AY18: =SUM(AU18:AX18) -> 0 | AZ18: 0 | BA18: 0 | BB18: 0 | BC18: 0 | BD18: =SUM(AZ18:BC18) -> 0 | BE18: 0 | BF18: 0 | BG18: 0 | BH18: 0 | BI18: =SUM(BE18:BH18) -> 0
A19: Unallocated Items, Eliminations and Other | B19: 0 | C19: 0 | D19: 0 | E19: =F19-SUM(B19,C19,D19) -> 0 | F19: 0 | G19: 0 | H19: 0 | I19: 0 | J19: =K19-SUM(G19,H19,I19) -> 0 | K19: 0 | L19: 0 | M19: 0 | N19: 0 | O19: =P19-SUM(L19,M19,N19) -> 0 | P19: 0 | Q19: 0 | R19: 0 | S19: 0 | T19: =U19-SUM(Q19,R19,S19) -> 0 | U19: 0 | V19: 0 | W19: 0 | X19: 0 | Y19: =Z19-SUM(V19,W19,X19) -> 0 | Z19: 0 | AA19: 0 | AB19: 0 | AC19: 0 | AD19: 0 | AE19: =SUM(AA19:AD19) -> 0 | AF19: 0 | AG19: 0 | AH19: 0 | AI19: 0 | AJ19: =SUM(AF19:AI19) -> 0 | AK19: 0 | AL19: 0 | AM19: 0 | AN19: =AO19-SUM(AK19:AM19) -> 0 | AO19: 0 | AP19: 0 | AQ19: 0 | AR19: 0 | AS19: =AT19-SUM(AP19:AR19) -> 0 | AT19: 0 | AU19: 0 | AV19: 0 | AW19: 0 | AX19: =AY19-SUM(AU19:AW19) -> 0 | AY19: 0 | AZ19: 0 | BA19: 0 | BB19: 0 | BC19: =BD19-SUM(AZ19:BB19) -> 0 | BD19: 0 | BE19: 0 | BF19: 0 | BG19: 0 | BH19: =BI19-SUM(BE19:BG19) -> 0 | BI19: 0
A20: Business Segment Operating Profit | B20: =SUM(B13:B19) -> 2380 | C20: =SUM(C13:C19) -> 1763 | D20: =SUM(D13:D19) -> 2800 | E20: =SUM(E13:E19) -> 1538 | F20: =SUM(F13:F19) -> 8481 | G20: =SUM(G13:G19) -> 1860 | H20: =SUM(H13:H19) -> -362 | I20: =SUM(I13:I19) -> 2394 | ... BI20: =SUM(BI13:BI19) -> 3620.723
A22: Pension FAS/CAS Service Cost Adjustment | B22: -152 | C22: -57 | D22: -84 | E22: =+F22-SUM(B22:D22) -> -128 | F22: -421 | G22: 45 | H22: 34 | I22: 50 | J22: =+K22-SUM(G22:I22) -> 88 | K22: 217 | L22: 262 | M22: 278 | N22: 271 | O22: =+P22-SUM(L22:N22) -> 316 | P22: 1127 | Q22: 283 | R22: 237 | S22: 260 | T22: =+U22-SUM(Q22:S22) -> 225 | U22: 1005 | V22: 274 | W22: 275 | X22: 274 | Y22: =+Z22-SUM(V22:X22) -> 248 | Z22: 1071 | AA22: =255 -> 255 | AB22: 258 | AC22: 260 | AD22: 251 | AE22: =SUM(AA22:AD22) -> 1024 | AF22: 193 | AG22: 191 | AH22: 192 | AI22: 306 | AJ22: =SUM(AF22:AI22) -> 882 | AK22: 208 | AL22: 205 | AM22: 208 | AN22: 228 | AO22: =SUM(AK22:AN22) -> 849 | AP22: 223 | AQ22: 222 | AR22: 218 | AS22: 136 | AT22: =SUM(AP22:AS22) -> 799 | AU22: 230 | AV22: 230 | AW22: 148 | AX22: 203 | AY22: =SUM(AU22:AX22) -> 811 | AZ22: 193 | BA22: 197 | BB22: 198 | BC22: 196 | BD22: =SUM(AZ22:BC22) -> 784 | BE22: =$BI22/4 -> 212.5 | BF22: =$BI22/4 -> 212.5 | BG22: =$BI22/4 -> 212.5 | BH22: =BI22-SUM(BE22:BG22) -> 212.5 | BI22: 850
A23: Postretirement FAS/CAS Service Cost Adjustment | B23: 39 | C23: 27 | D23: 27 | E23: =+F23-SUM(B23:D23) -> 30 | F23: 123 | G23: 49 | H23: 35 | I23: 38 | J23: =+K23-SUM(G23:I23) -> 31 | K23: 153 | L23: 84 | M23: 79 | N23: 75 | O23: =+P23-SUM(L23:N23) -> 73 | P23: 311 | Q23: 82 | R23: 80 | S23: 77 | T23: =+U23-SUM(Q23:S23) -> 83 | U23: 322 | V23: 90 | W23: 90 | X23: 90 | Y23: =+Z23-SUM(V23:X23) -> 74 | Z23: 344 | AA23: =92 -> 92 | AB23: 97 | AC23: 93 | AD23: 77 | AE23: =SUM(AA23:AD23) -> 359 | AF23: 77 | AG23: 77 | AH23: 78 | AI23: 59 | AJ23: =SUM(AF23:AI23) -> 291 | AK23: 75 | AL23: 79 | AM23: 71 | AN23: 69 | AO23: =SUM(AK23:AN23) -> 294 | AP23: 68 | AQ23: 69 | AR23: 63 | AS23: 57 | AT23: =SUM(AP23:AS23) -> 257 | AU23: 72 | AV23: 72 | AW23: 80 | AX23: 69 | AY23: =SUM(AU23:AX23) -> 293 | AZ23: 69 | BA23: 60 | BB23: 70 | BC23: 62 | BD23: =SUM(AZ23:BC23) -> 261 | BE23: =$BI23/4 -> 65 | BF23: =$BI23/4 -> 65 | BG23: =$BI23/4 -> 65 | BH23: =BI23-SUM(BE23:BG23) -> 65 | BI23: 260
